Workbook

Sheet ReadMe
B2: FRTB IMA — Full Revaluation PnL Vectors for Expected Shortfall (ES)
B3: Illustrative workbook — trade 123456, valuation date 7/23/2026. Demonstrates the mechanics of a full-revaluation Stressed PnL vector: PnL = StressedNPV − BaseNPV, built curve-by-curve and then combined cross-risk-class.
B5: Purpose
B6: Illustrate, end to end, how a full-reval ES PnL vector is constructed: base curve objects → shocked curve objects (10 scenarios, stress date 20-Nov-2008) → base/stressed NPV via full reval → PnL vector, both cross-risk-class and isolated by risk class (IR / Credit / FX).
B8: Tabs
B9: ReadMe | Trade_Info | Curves (Base, Shift Illustration, Shocks+Shocked aligned side-by-side) | SABR (Base, Shocks, Shocked - ATM/RHO/NU/Combined aligned horizontally per scenario) | NPV_Engine | PnL_Summary
B11: Curve shift mechanic
B12: gxlCurveDiscShift is simulated with a sequential (cascading) bootstrap: the simple forward rate implied by the BASE curve between consecutive tenors is bumped by the scenario shock (bps), and the SHOCKED discount factor for tenor i is solved from the SHOCKED discount factor at tenor i-1 (not the base one). 3M is bumped first; 6M relies on the bumped 3M; and so on to 30Y — exactly mirroring the described gxlCurveDiscShift behaviour.
B14: SABR surface mechanic
B15: Each of ATM / RHO / NU is a 10x10 grid (expiry x tenor). Each scenario applies a parameter-level shock size to every grid point, scaled by a per-cell Sensitivity Factor grid (captures the typical stress-period pattern of larger moves at short expiries/tenors). The result is a full shocked vol surface per parameter per scenario, exactly as gxlCurveDiscShift-style functions return a shocked object for curves.
B17: NPV engine
B18: NPV is an ILLUSTRATIVE simplified full-reval pricer (not a production pricer) that consumes: SOFR/ESTRN discount factors (IR discounting), the SABR ATM grid point matching the trade's expiry/tenor (IR_VOL / optionality), Treasury/Agency_FNMA/Eur_Govt discount factors (Credit spread proxy), and the EURUSD curve (FX discount/forward proxy). Base NPV = pricer with ALL curves at BASE. Stressed NPV = pricer with the relevant curve set SHOCKED for scenario s.
... B27: All curve levels, shock sizes and SABR parameters are illustrative placeholder assumptions chosen for demonstration purposes only — they are not calibrated to actual 20-Nov-2008 market data and this is not a production pricing/risk engine.

Sheet Trade_Info
A1: Trade & Valuation Info
A3: Trade ID | B3: 123456
A4: Valuation Date | B4: 7/23/2026
A5: Stress / Shock anchor date | B5: 11/20/2008
A6: Number of scenarios | B6: 10
A7: Notional (USD) | B7: 10000000
A8: Product | B8: EUR-underlying payer swaption vs USD-collateral discounting
A9: Representative discounting tenor | B9: 1Y
A10: Representative SABR grid point (Expiry x Tenor) | B10: 1Y x 10Y
A12: Curve list, MDO used, and risk-class mapping
A13: Curve (MDO) | B13: Risk Class | C13: Notes
A14: Agency_FNMA | B14: Credit | C14: Credit — GSE/agency spread curve
A15: Eur_Govt | B15: Credit | C15: Credit — EUR sovereign curve
A16: SOFR | B16: IR | C16: IR_RATE — USD OIS/SOFR discounting curve
A17: Treasury | B17: Credit | C17: Credit — US Treasury (sovereign benchmark) curve
A18: Sabr_Swaption | B18: IR | C18: IR_VOL — SABR surface (ATM, RHO, NU); handled on SABR_* tabs
A19: EURUSD | B19: FX | C19: FX_RATE — EUR/USD FX curve
A20: ESTRN | B20: IR | C20: IR — EUR €STR discounting curve
A22: Liquidity-Horizon Curve Inclusion by Risk Class
A24: Class | B24: LH10 | C24: LH20 | D24: LH40 | E24: LH60
A25: Credit | B25: Agency_FNMA + Eur_Govt + Treasury | C25: Agency_FNMA + Eur_Govt + Treasury | D25: Agency_FNMA only | E25: —
A26: IR | B26: SOFR + ESTRN + Swaption | C26: Swaption only | D26: Swaption only | E26: Swaption only
A27: FX | B27: EURUSD | C27: — | D27: — | E27: —
A28: Cross | B28: all six | C28: Agency_FNMA + Eur_Govt + Treasury + Swaption | D28: Agency_FNMA + Swaption | E28: Swaption only
A30: Rule: at horizon bucket T, a curve is shocked only if its own assigned Liquidity Horizon >= T. Credit now includes Treasury (LH20) alongside Eur_Govt (LH20) and Agency_FNMA (LH40).

Sheet Curves
A1: Curve Objects — Base -> Shift Mechanics -> Shocks -> Shocked Curves (Combined)
A2: Trade 123456 | Val date 7/23/2026 | Stress anchor 20-Nov-2008
A3: SECTION 1 - BASE CURVE OBJECTS: Discount Factors (as of 7/23/2026)
A5: Curve | B5: Risk Class | C5: 3M | D5: 6M | E5: 1Y | F5: 2Y | G5: 3Y | H5: 5Y | I5: 10Y | J5: 20Y | K5: 30Y
A6: Tenor Date | C6: 10/23/2026 | D6: 1/23/2027 | E6: 7/23/2027 | F6: 7/23/2028 | G6: 7/23/2029 | H6: 7/23/2031 | I6: 7/23/2036 | J6: 7/23/2046 | K6: 7/23/2056
A7: Year Frac (t) | C7: 0.25 | D7: 0.5 | E7: 1 | F7: 2 | G7: 3 | H7: 5 | I7: 10 | J7: 20 | K7: 30
A8: SOFR | B8: IR | C8: 0.989298 | D8: 0.978693 | E8: 0.957768 | F8: 0.917044 | G8: 0.877788 | H8: 0.803523 | I8: 0.640824 | J8: 0.410656 | K8: 0.263158
A9: ESTRN | B9: IR | C9: 0.992271 | D9: 0.984583 | E9: 0.96933 | F9: 0.939319 | G9: 0.909964 | H9: 0.85321 | I9: 0.722527 | J9: 0.522046 | K9: 0.377192
A10: Treasury | B10: Credit | C10: 0.989546 | D10: 0.979182 | E10: 0.958726 | F10: 0.91888 | G10: 0.880425 | H10: 0.80755 | I10: 0.647265 | J10: 0.418952 | K10: 0.271173
A11: Agency_FNMA | B11: Credit | C11: 0.988557 | D11: 0.977226 | E11: 0.954899 | F11: 0.911558 | G11: 0.869924 | H11: 0.79156 | I11: 0.621885 | J11: 0.386741 | K11: 0.240508
A12: Eur_Govt | B12: Credit | C12: 0.991775 | D12: 0.983598 | E12: 0.967393 | F12: 0.935569 | G12: 0.904521 | H12: 0.84472 | I12: 0.70822 | J12: 0.501576 | K12: 0.355226
A13: EURUSD | B13: FX | C13: 0.990041 | D13: 0.980162 | E13: 0.960645 | F13: 0.922563 | G13: 0.885724 | H13: 0.815666 | I13: 0.66034 | J13: 0.436049 | K13: 0.287941
A15: Base DF values are illustrative placeholder inputs (blue), not calibrated to a real curve build.
A17: SECTION 2 - gxlCurveDiscShift STEP-BY-STEP ILLUSTRATION (Curve = SOFR, Scenario 1)
A18: Sequential / cascading bootstrap: base forward rate (Section 1) + scenario shock (bps, Section 3) = shocked forward rate; the SHOCKED discount factor at tenor i is solved off the SHOCKED discount factor at tenor i-1 (not the base one). 3M is shocked first and feeds into 6M, which feeds into 1Y, and so on to 30Y.
A21: Tenor | B21: t | C21: Base DF (prior) | D21: Base DF (current) | E21: Base Fwd Rate (simple, ann.) | F21: Shock (bps) | G21: Shocked Fwd Rate | H21: Shocked DF (current) | I21: Formula logic
A22: 3M | B22: 0.25 | C22: 1 | D22: =C8 -> 0.989298 | E22: =(C22/D22-1)/(0.25-0) -> 0.043271087 | F22: =C37 -> -40.9 | G22: =E22+F22/10000 -> 0.039181087 | H22: =1/(1+G22*(0.25-0)) -> 0.99029974 | I22: Anchors at DF=1, t=0
A23: 6M | B23: 0.5 | C23: =C8 -> 0.989298 | D23: =D8 -> 0.978693 | E23: =(C23/D23-1)/(0.5-0.25) -> 0.04334352 | F23: =D37 -> 34.3 | G23: =E23+F23/10000 -> 0.04677352 | H23: =H22/(1+G23*(0.5-0.25)) -> 0.97885364 | I23: Uses SHOCKED DF from 3M (row above), not base
A24: 1Y | B24: 1 | C24: =D8 -> 0.978693 | D24: =E8 -> 0.957768 | E24: =(C24/D24-1)/(1-0.5) -> 0.043695342 | F24: =E37 -> 31.4 | G24: =E24+F24/10000 -> 0.046835342 | H24: =H23/(1+G24*(1-0.5)) -> 0.95645567 | I24: Uses SHOCKED DF from 6M (row above), not base
A25: 2Y | B25: 2 | C25: =E8 -> 0.957768 | D25: =F8 -> 0.917044 | E25: =(C25/D25-1)/(2-1) -> 0.044407902 | F25: =F37 -> -21.7 | G25: =E25+F25/10000 -> 0.042237902 | H25: =H24/(1+G25*(2-1)) -> 0.9176942 | I25: Uses SHOCKED DF from 1Y (row above), not base
A26: 3Y | B26: 3 | C26: =F8 -> 0.917044 | D26: =G8 -> 0.877788 | E26: =(C26/D26-1)/(3-2) -> 0.044721505 | F26: =G37 -> -13 | G26: =E26+F26/10000 -> 0.043421505 | H26: =H25/(1+G26*(3-2)) -> 0.87950478 | I26: Uses SHOCKED DF from 2Y (row above), not base
A27: 5Y | B27: 5 | C27: =G8 -> 0.877788 | D27: =H8 -> 0.803523 | E27: =(C27/D27-1)/(5-3) -> 0.046212118 | F27: =H37 -> 6.1 | G27: =E27+F27/10000 -> 0.046822118 | H27: =H26/(1+G27*(5-3)) -> 0.80419642 | I27: Uses SHOCKED DF from 3Y (row above), not base
A28: 10Y | B28: 10 | C28: =H8 -> 0.803523 | D28: =I8 -> 0.640824 | E28: =(C28/D28-1)/(10-5) -> 0.050778061 | F28: =I37 -> 2.9 | G28: =E28+F28/10000 -> 0.051068061 | H28: =H27/(1+G28*(10-5)) -> 0.64062025 | I28: Uses SHOCKED DF from 5Y (row above), not base
A29: 20Y | B29: 20 | C29: =I8 -> 0.640824 | D29: =J8 -> 0.410656 | E29: =(C29/D29-1)/(20-10) -> 0.056048858 | F29: =J37 -> 2.1 | G29: =E29+F29/10000 -> 0.056258858 | H29: =H28/(1+G29*(20-10)) -> 0.40997372 | I29: Uses SHOCKED DF from 10Y (row above), not base
A30: 30Y | B30: 30 | C30: =J8 -> 0.410656 | D30: =K8 -> 0.263158 | E30: =(C30/D30-1)/(30-20) -> 0.056049218 | F30: =K37 -> 1.2 | G30: =E30+F30/10000 -> 0.056169218 | H30: =H29/(1+G30*(30-20)) -> 0.2625189 | I30: Uses SHOCKED DF from 20Y (row above), not base
A32: This exact column-H formula pattern is replicated for all 6 curves x 10 scenarios in Sections 3/4 below.
A34: SECTION 3 - SHOCK VECTORS: Forward-Rate Shock (bps), 10 Scenarios (anchor 20-Nov-2008) | M34: SECTION 4 - SHOCKED CURVE OBJECTS (gxlCurveDiscShift output): Discount Factors
A36: Scenario 1 | C36: 3M | D36: 6M | E36: 1Y | F36: 2Y | G36: 3Y | H36: 5Y | I36: 10Y | J36: 20Y | K36: 30Y | M36: Scenario 1 | O36: 3M | P36: 6M | Q36: 1Y | R36: 2Y | S36: 3Y | T36: 5Y | U36: 10Y | V36: 20Y | W36: 30Y
A37: SOFR | B37: IR | C37: -40.9 | D37: 34.3 | E37: 31.4 | F37: -21.7 | G37: -13 | H37: 6.1 | I37: 2.9 | J37: 2.1 | K37: 1.2 | M37: SOFR | N37: IR | O37: =1/(1+(((1/C8-1)/(0.25-0))+C37/10000)*(0.25-0)) -> 0.99029974 | P37: =O37/(1+(((C8/D8-1)/(0.5-0.25))+D37/10000)*(0.5-0.25)) -> 0.97885364 | Q37: =P37/(1+(((D8/E8-1)/(1-0.5))+E37/10000)*(1-0.5)) -> 0.95645567 | R37: =Q37/(1+(((E8/F8-1)/(2-1))+F37/10000)*(2-1)) -> 0.9176942 | S37: =R37/(1+(((F8/G8-1)/(3-2))+G37/10000)*(3-2)) -> 0.87950478 | T37: =S37/(1+(((G8/H8-1)/(5-3))+H37/10000)*(5-3)) -> 0.80419642 | U37: =T37/(1+(((H8/I8-1)/(10-5))+I37/10000)*(10-5)) -> 0.64062025 | V37: =U37/(1+(((I8/J8-1)/(20-10))+J37/10000)*(20-10)) -> 0.40997372 | W37: =V37/(1+(((J8/K8-1)/(30-20))+K37/10000)*(30-20)) -> 0.2625189
A38: ESTRN | B38: IR | C38: -35.5 | D38: 31.9 | E38: 24.1 | F38: 18.3 | G38: -8.9 | H38: 5.7 | I38: 2.8 | J38: 1.3 | K38: 0.6 | M38: ESTRN | N38: IR | O38: =1/(1+(((1/C9-1)/(0.25-0))+C38/10000)*(0.25-0)) -> 0.9931456 | P38: =O38/(1+(((C9/D9-1)/(0.5-0.25))+D38/10000)*(0.5-0.25)) -> 0.98467164 | Q38: =P38/(1+(((D9/E9-1)/(1-0.5))+E38/10000)*(1-0.5)) -> 0.96826858 | R38: =Q38/(1+(((E9/F9-1)/(2-1))+F38/10000)*(2-1)) -> 0.93662947 | S38: =R38/(1+(((F9/G9-1)/(3-2))+G38/10000)*(3-2)) -> 0.90814151 | T38: =S38/(1+(((G9/H9-1)/(5-3))+H38/10000)*(5-3)) -> 0.85059198 | U38: =T38/(1+(((H9/I9-1)/(10-5))+I38/10000)*(10-5)) -> 0.71945701 | V38: =U38/(1+(((I9/J9-1)/(20-10))+J38/10000)*(20-10)) -> 0.51934004 | W38: =V38/(1+(((J9/K9-1)/(30-20))+K38/10000)*(30-20)) -> 0.37507427
A39: Treasury | B39: Credit | C39: 49.9 | D39: 46.7 | E39: -34.6 | F39: 21.6 | G39: 13 | H39: 7.2 | I39: 4.1 | J39: 1.9 | K39: 1.2 | M39: Treasury | N39: Credit | O39: =1/(1+(((1/C10-1)/(0.25-0))+C39/10000)*(0.25-0)) -> 0.98832595 | P39: =O39/(1+(((C10/D10-1)/(0.5-0.25))+D39/10000)*(0.5-0.25)) -> 0.97684621 | Q39: =P39/(1+(((D10/E10-1)/(1-0.5))+E39/10000)*(1-0.5)) -> 0.95806183 | R39: =Q39/(1+(((E10/F10-1)/(2-1))+F39/10000)*(2-1)) -> 0.91634638 | S39: =R39/(1+(((F10/G10-1)/(3-2))+G39/10000)*(3-2)) -> 0.87690515 | T39: =S39/(1+(((G10/H10-1)/(5-3))+H39/10000)*(5-3)) -> 0.80326054 | U39: =T39/(1+(((H10/I10-1)/(10-5))+I39/10000)*(10-5)) -> 0.64277078 | V39: =U39/(1+(((I10/J10-1)/(20-10))+J39/10000)*(20-10)) -> 0.41553203 | W39: =V39/(1+(((J10/K10-1)/(30-20))+K39/10000)*(30-20)) -> 0.26875063
A40: Agency_FNMA | B40: Credit | C40: 75.2 | D40: 60.7 | E40: 51.5 | F40: 44.3 | G40: 26.8 | H40: 15.7 | I40: -6.2 | J40: 3.8 | K40: 2.5 | M40: Agency_FNMA | N40: Credit | O40: =1/(1+(((1/C11-1)/(0.25-0))+C40/10000)*(0.25-0)) -> 0.98672319 | P40: =O40/(1+(((C11/D11-1)/(0.5-0.25))+D40/10000)*(0.5-0.25)) -> 0.97395218 | Q40: =P40/(1+(((D11/E11-1)/(1-0.5))+E40/10000)*(1-0.5)) -> 0.94931135 | R40: =Q40/(1+(((E11/F11-1)/(2-1))+F40/10000)*(2-1)) -> 0.90240774 | S40: =R40/(1+(((F11/G11-1)/(3-2))+G40/10000)*(3-2)) -> 0.8589947 | T40: =S40/(1+(((G11/H11-1)/(5-3))+H40/10000)*(5-3)) -> 0.7793884 | U40: =T40/(1+(((H11/I11-1)/(10-5))+I40/10000)*(10-5)) -> 0.6138174 | V40: =U40/(1+(((I11/J11-1)/(20-10))+J40/10000)*(20-10)) -> 0.38082393 | W40: =V40/(1+(((J11/K11-1)/(30-20))+K40/10000)*(30-20)) -> 0.23646064
A41: Eur_Govt | B41: Credit | C41: 64.8 | D41: 54.8 | E41: 47.2 | F41: 28 | G41: 18.8 | H41: 10.1 | I41: 5.2 | J41: 3 | K41: -1.8 | M41: Eur_Govt | N41: Credit | O41: =1/(1+(((1/C12-1)/(0.25-0))+C41/10000)*(0.25-0)) -> 0.9901841 | P41: =O41/(1+(((C12/D12-1)/(0.5-0.25))+D41/10000)*(0.5-0.25)) -> 0.98068775 | Q41: =P41/(1+(((D12/E12-1)/(1-0.5))+E41/10000)*(1-0.5)) -> 0.96229709 | R41: =Q41/(1+(((E12/F12-1)/(2-1))+F41/10000)*(2-1)) -> 0.92812746 | S41: =R41/(1+(((F12/G12-1)/(3-2))+G41/10000)*(3-2)) -> 0.89569839 | T41: =S41/(1+(((G12/H12-1)/(5-3))+H41/10000)*(5-3)) -> 0.83490567 | U41: =T41/(1+(((H12/I12-1)/(10-5))+I41/10000)*(10-5)) -> 0.69846902 | V41: =U41/(1+(((I12/J12-1)/(20-10))+J41/10000)*(20-10)) -> 0.49362138 | W41: =V41/(1+(((J12/K12-1)/(30-20))+K41/10000)*(30-20)) -> 0.35003861
A42: EURUSD | B42: FX | C42: 23.9 | D42: 26.9 | E42: 18.9 | F42: 16.3 | G42: 11 | H42: 5.2 | I42: 3.4 | J42: 1.9 | K42: 1.2 | M42: EURUSD | N42: FX | O42: =1/(1+(((1/C13-1)/(0.25-0))+C42/10000)*(0.25-0)) -> 0.98945569 | P42: =O42/(1+(((C13/D13-1)/(0.5-0.25))+D42/10000)*(0.5-0.25)) -> 0.97893077 | Q42: =P42/(1+(((D13/E13-1)/(1-0.5))+E42/10000)*(1-0.5)) -> 0.95855049 | R42: =Q42/(1+(((E13/F13-1)/(2-1))+F42/10000)*(2-1)) -> 0.91911276 | S42: =R42/(1+(((F13/G13-1)/(3-2))+G42/10000)*(3-2)) -> 0.88148062 | T42: =S42/(1+(((G13/H13-1)/(5-3))+H42/10000)*(5-3)) -> 0.81098155 | U42: =T42/(1+(((H13/I13-1)/(10-5))+I42/10000)*(10-5)) -> 0.65564525 | V42: =U42/(1+(((I13/J13-1)/(20-10))+J42/10000)*(20-10)) -> 0.43240635 | W42: =V42/(1+(((J13/K13-1)/(30-20))+K42/10000)*(30-20)) -> 0.28530953
A44: Scenario 2 | C44: 3M | D44: 6M | E44: 1Y | F44: 2Y | G44: 3Y | H44: 5Y | I44: 10Y | J44: 20Y | K44: 30Y | M44: Scenario 2 | O44: 3M | P44: 6M | Q44: 1Y | R44: 2Y | S44: 3Y | T44: 5Y | U44: 10Y | V44: 20Y | W44: 30Y
A45: SOFR | B45: IR | C45: 45.8 | D45: 45.7 | E45: 34.7 | F45: 25.1 | G45: 14.8 | H45: 7.9 | I45: 4.1 | J45: 2.4 | K45: 1.4 | M45: SOFR | N45: IR | O45: =1/(1+(((1/C8-1)/(0.25-0))+C45/10000)*(0.25-0)) -> 0.98817864 | P45: =O45/(1+(((C8/D8-1)/(0.5-0.25))+D45/10000)*(0.5-0.25)) -> 0.97648197 | Q45: =P45/(1+(((D8/E8-1)/(1-0.5))+E45/10000)*(1-0.5)) -> 0.95398447 | R45: =Q45/(1+(((E8/F8-1)/(2-1))+F45/10000)*(2-1)) -> 0.9112314 | S45: =R45/(1+(((F8/G8-1)/(3-2))+G45/10000)*(3-2)) -> 0.87099034 | T45: =S45/(1+(((G8/H8-1)/(5-3))+H45/10000)*(5-3)) -> 0.79614896 | U45: =T45/(1+(((H8/I8-1)/(10-5))+I45/10000)*(10-5)) -> 0.63390669 | V45: =U45/(1+(((I8/J8-1)/(20-10))+J45/10000)*(20-10)) -> 0.40559941 | W45: =V45/(1+(((J8/K8-1)/(30-20))+K45/10000)*(30-20)) -> 0.25968464
A46: ESTRN | B46: IR | C46: 34.7 | D46: 37.4 | E46: -28.1 | F46: 20.8 | G46: 10.6 | H46: 5.6 | I46: -3.3 | J46: 1.5 | K46: 0.7 | M46: ESTRN | N46: IR | O46: =1/(1+(((1/C9-1)/(0.25-0))+C46/10000)*(0.25-0)) -> 0.99141759 | P46: =O46/(1+(((C9/D9-1)/(0.5-0.25))+D46/10000)*(0.5-0.25)) -> 0.98282438 | Q46: =P46/(1+(((D9/E9-1)/(1-0.5))+E46/10000)*(1-0.5)) -> 0.9689389 | R46: =Q46/(1+(((E9/F9-1)/(2-1))+F46/10000)*(2-1)) -> 0.93705128 | S46: =R46/(1+(((F9/G9-1)/(3-2))+G46/10000)*(3-2)) -> 0.90683595 | T46: =S46/(1+(((G9/H9-1)/(5-3))+H46/10000)*(5-3)) -> 0.84938506 | U46: =T46/(1+(((H9/I9-1)/(10-5))+I46/10000)*(10-5)) -> 0.72029436 | V46: =U46/(1+(((I9/J9-1)/(20-10))+J46/10000)*(20-10)) -> 0.51986943 | W46: =V46/(1+(((J9/K9-1)/(30-20))+K46/10000)*(30-20)) -> 0.37542949
A47: Treasury | B47: Credit | C47: 53 | D47: 50.5 | E47: 36.1 | F47: 29.7 | G47: 16.7 | H47: 8.5 | I47: 4.5 | J47: 2.2 | K47: 1.4 | M47: Treasury | N47: Credit | O47: =1/(1+(((1/C10-1)/(0.25-0))+C47/10000)*(0.25-0)) -> 0.98825026 | P47: =O47/(1+(((C10/D10-1)/(0.5-0.25))+D47/10000)*(0.5-0.25)) -> 0.97667968 | Q47: =P47/(1+(((D10/E10-1)/(1-0.5))+E47/10000)*(1-0.5)) -> 0.95458892 | R47: =Q47/(1+(((E10/F10-1)/(2-1))+F47/10000)*(2-1)) -> 0.9123179 | S47: =R47/(1+(((F10/G10-1)/(3-2))+G47/10000)*(3-2)) -> 0.87274104 | T47: =S47/(1+(((G10/H10-1)/(5-3))+H47/10000)*(5-3)) -> 0.79925579 | U47: =T47/(1+(((H10/I10-1)/(10-5))+I47/10000)*(10-5)) -> 0.63946383 | V47: =U47/(1+(((I10/J10-1)/(20-10))+J47/10000)*(20-10)) -> 0.41331402 | W47: =V47/(1+(((J10/K10-1)/(30-20))+K47/10000)*(30-20)) -> 0.26728153
A48: Agency_FNMA | B48: Credit | C48: 79.9 | D48: -82.8 | E48: 61.9 | F48: -43.5 | G48: 33.6 | H48: 16.8 | I48: 8.2 | J48: 4.2 | K48: 3 | M48: Agency_FNMA | N48: Credit | O48: =1/(1+(((1/C11-1)/(0.25-0))+C48/10000)*(0.25-0)) -> 0.9866088 | P48: =O48/(1+(((C11/D11-1)/(0.5-0.25))+D48/10000)*(0.5-0.25)) -> 0.97729995 | Q48: =P48/(1+(((D11/E11-1)/(1-0.5))+E48/10000)*(1-0.5)) -> 0.95209186 | R48: =Q48/(1+(((E11/F11-1)/(2-1))+F48/10000)*(2-1)) -> 0.91266819 | S48: =R48/(1+(((F11/G11-1)/(3-2))+G48/10000)*(3-2)) -> 0.86819957 | T48: =S48/(1+(((G11/H11-1)/(5-3))+H48/10000)*(5-3)) -> 0.78758301 | U48: =T48/(1+(((H11/I11-1)/(10-5))+I48/10000)*(10-5)) -> 0.61677378 | V48: =U48/(1+(((I11/J11-1)/(20-10))+J48/10000)*(20-10)) -> 0.38256318 | W48: =V48/(1+(((J11/K11-1)/(30-20))+K48/10000)*(30-20)) -> 0.23746685
A49: Eur_Govt | B49: Credit | C49: 72.6 | D49: -67.8 | E49: 49 | F49: 37.3 | G49: 20.2 | H49: 11.4 | I49: 5.8 | J49: 3 | K49: -2.3 | M49: Eur_Govt | N49: Credit | O49: =1/(1+(((1/C12-1)/(0.25-0))+C49/10000)*(0.25-0)) -> 0.98999294 | P49: =O49/(1+(((C12/D12-1)/(0.5-0.25))+D49/10000)*(0.5-0.25)) -> 0.9834839 | Q49: =P49/(1+(((D12/E12-1)/(1-0.5))+E49/10000)*(1-0.5)) -> 0.96495558 | R49: =Q49/(1+(((E12/F12-1)/(2-1))+F49/10000)*(2-1)) -> 0.9298575 | S49: =R49/(1+(((F12/G12-1)/(3-2))+G49/10000)*(3-2)) -> 0.89724675 | T49: =S49/(1+(((G12/H12-1)/(5-3))+H49/10000)*(5-3)) -> 0.8361463 | U49: =T49/(1+(((H12/I12-1)/(10-5))+I49/10000)*(10-5)) -> 0.6993314 | V49: =U49/(1+(((I12/J12-1)/(20-10))+J49/10000)*(20-10)) -> 0.49423084 | W49: =V49/(1+(((J12/K12-1)/(30-20))+K49/10000)*(30-20)) -> 0.3505951
...

Sheet Curves_Current
A1: Curve Objects — CURRENT PERIOD Shocks + Shocked Curves (normal/recent market conditions)
A2: Same base curves as the Curves tab (Section 1) — only the shock magnitude differs. Current-period shocks are ~30% the size of the 2008 stress-period shocks on the Curves tab, representing normal/recent market conditions rather than a crisis. Used for the 'Full Set - Current Period' and 'Reduced Set - Current Period' cases on FullReduced_NPV_Engine.
A4: SECTION A - CURRENT PERIOD SHOCK VECTORS (bps), 10 Scenarios | M4: SECTION B - CURRENT PERIOD SHOCKED CURVES (Discount Factors)
A6: Scenario 1 | C6: 3M | D6: 6M | E6: 1Y | F6: 2Y | G6: 3Y | H6: 5Y | I6: 10Y | J6: 20Y | K6: 30Y | M6: Scenario 1 | O6: 3M | P6: 6M | Q6: 1Y | R6: 2Y | S6: 3Y | T6: 5Y | U6: 10Y | V6: 20Y | W6: 30Y
A7: SOFR | B7: IR | C7: 12.12 | D7: 10.86 | E7: 8.58 | F7: -5.6 | G7: 3.64 | H7: 2.16 | I7: 0.88 | J7: 0.54 | K7: 0.38 | M7: SOFR | N7: IR | O7: =1/(1+(((1/Curves!C8-1)/(0.25-0))+C7/10000)*(0.25-0)) -> 0.98900154 | P7: =O7/(1+(((Curves!C8/Curves!D8-1)/(0.5-0.25))+D7/10000)*(0.5-0.25)) -> 0.978137 | Q7: =P7/(1+(((Curves!D8/Curves!E8-1)/(1-0.5))+E7/10000)*(1-0.5)) -> 0.95682219 | R7: =Q7/(1+(((Curves!E8/Curves!F8-1)/(2-1))+F7/10000)*(2-1)) -> 0.91662989 | S7: =R7/(1+(((Curves!F8/Curves!G8-1)/(3-2))+G7/10000)*(3-2)) -> 0.87708602 | T7: =S7/(1+(((Curves!G8/Curves!H8-1)/(5-3))+H7/10000)*(5-3)) -> 0.80256304 | U7: =T7/(1+(((Curves!H8/Curves!I8-1)/(10-5))+I7/10000)*(10-5)) -> 0.63983389 | V7: =U7/(1+(((Curves!I8/Curves!J8-1)/(20-10))+J7/10000)*(20-10)) -> 0.40987968 | W7: =V7/(1+(((Curves!J8/Curves!K8-1)/(30-20))+K7/10000)*(30-20)) -> 0.26259657
A8: ESTRN | B8: IR | C8: 9.86 | D8: -9.57 | E8: 6.86 | F8: 4.36 | G8: 3.18 | H8: 1.68 | I8: 0.86 | J8: 0.37 | K8: -0.18 | M8: ESTRN | N8: IR | O8: =1/(1+(((1/Curves!C9-1)/(0.25-0))+C8/10000)*(0.25-0)) -> 0.99202836 | P8: =O8/(1+(((Curves!C9/Curves!D9-1)/(0.5-0.25))+D8/10000)*(0.5-0.25)) -> 0.98457597 | Q8: =P8/(1+(((Curves!D9/Curves!E9-1)/(1-0.5))+E8/10000)*(1-0.5)) -> 0.96899586 | R8: =Q8/(1+(((Curves!E9/Curves!F9-1)/(2-1))+F8/10000)*(2-1)) -> 0.93859865 | S8: =R8/(1+(((Curves!F9/Curves!G9-1)/(3-2))+G8/10000)*(3-2)) -> 0.90898614 | T8: =S8/(1+(((Curves!G9/Curves!H9-1)/(5-3))+H8/10000)*(5-3)) -> 0.8520247 | U8: =T8/(1+(((Curves!H9/Curves!I9-1)/(10-5))+I8/10000)*(10-5)) -> 0.72126061 | V8: =U8/(1+(((Curves!I9/Curves!J9-1)/(20-10))+J8/10000)*(20-10)) -> 0.52099172 | W8: =V8/(1+(((Curves!J9/Curves!K9-1)/(30-20))+K8/10000)*(30-20)) -> 0.37647922
A9: Treasury | B9: Credit | C9: 12.97 | D9: 13.61 | E9: 8.83 | F9: -6.3 | G9: 4.46 | H9: 2.24 | I9: 1.22 | J9: 0.66 | K9: 0.37 | M9: Treasury | N9: Credit | O9: =1/(1+(((1/Curves!C10-1)/(0.25-0))+C9/10000)*(0.25-0)) -> 0.9892286 | P9: =O9/(1+(((Curves!C10/Curves!D10-1)/(0.5-0.25))+D9/10000)*(0.5-0.25)) -> 0.97853846 | Q9: =P9/(1+(((Curves!D10/Curves!E10-1)/(1-0.5))+E9/10000)*(1-0.5)) -> 0.95768192 | R9: =Q9/(1+(((Curves!E10/Curves!F10-1)/(2-1))+F9/10000)*(2-1)) -> 0.91843388 | S9: =R9/(1+(((Curves!F10/Curves!G10-1)/(3-2))+G9/10000)*(3-2)) -> 0.87962166 | T9: =S9/(1+(((Curves!G10/Curves!H10-1)/(5-3))+H9/10000)*(5-3)) -> 0.80648175 | U9: =T9/(1+(((Curves!H10/Curves!I10-1)/(10-5))+I9/10000)*(10-5)) -> 0.64609289 | V9: =U9/(1+(((Curves!I10/Curves!J10-1)/(20-10))+J9/10000)*(20-10)) -> 0.41801476 | W9: =V9/(1+(((Curves!J10/Curves!K10-1)/(30-20))+K9/10000)*(30-20)) -> 0.27050158
A10: Agency_FNMA | B10: Credit | C10: -20.65 | D10: 19.75 | E10: 16.2 | F10: -12.65 | G10: 6.97 | H10: 4.75 | I10: 2.12 | J10: 1.25 | K10: 0.85 | M10: Agency_FNMA | N10: Credit | O10: =1/(1+(((1/Curves!C11-1)/(0.25-0))+C10/10000)*(0.25-0)) -> 0.98906176 | P10: =O10/(1+(((Curves!C11/Curves!D11-1)/(0.5-0.25))+D10/10000)*(0.5-0.25)) -> 0.97724799 | Q10: =P10/(1+(((Curves!D11/Curves!E11-1)/(1-0.5))+E10/10000)*(1-0.5)) -> 0.95416527 | R10: =Q10/(1+(((Curves!E11/Curves!F11-1)/(2-1))+F10/10000)*(2-1)) -> 0.91195884 | S10: =R10/(1+(((Curves!F11/Curves!G11-1)/(3-2))+G10/10000)*(3-2)) -> 0.86972802 | T10: =S10/(1+(((Curves!G11/Curves!H11-1)/(5-3))+H10/10000)*(5-3)) -> 0.79069818 | U10: =T10/(1+(((Curves!H11/Curves!I11-1)/(10-5))+I10/10000)*(10-5)) -> 0.62069101 | V10: =U10/(1+(((Curves!I11/Curves!J11-1)/(20-10))+J10/10000)*(20-10)) -> 0.38569865 | W10: =V10/(1+(((Curves!J11/Curves!K11-1)/(30-20))+K10/10000)*(30-20)) -> 0.23973306
A11: Eur_Govt | B11: Credit | C11: -19.24 | D11: -15.73 | E11: -13.57 | F11: 9.42 | G11: -4.93 | H11: 2.98 | I11: 1.77 | J11: 0.85 | K11: 0.63 | M11: Eur_Govt | N11: Credit | O11: =1/(1+(((1/Curves!C12-1)/(0.25-0))+C11/10000)*(0.25-0)) -> 0.99224835 | P11: =O11/(1+(((Curves!C12/Curves!D12-1)/(0.5-0.25))+D11/10000)*(0.5-0.25)) -> 0.98445139 | Q11: =P11/(1+(((Curves!D12/Curves!E12-1)/(1-0.5))+E11/10000)*(1-0.5)) -> 0.96887888 | R11: =Q11/(1+(((Curves!E12/Curves!F12-1)/(2-1))+F11/10000)*(2-1)) -> 0.93615315 | S11: =R11/(1+(((Curves!F12/Curves!G12-1)/(3-2))+G11/10000)*(3-2)) -> 0.90551737 | T11: =S11/(1+(((Curves!G12/Curves!H12-1)/(5-3))+H11/10000)*(5-3)) -> 0.84518008 | U11: =T11/(1+(((Curves!H12/Curves!I12-1)/(10-5))+I11/10000)*(10-5)) -> 0.70808034 | V11: =U11/(1+(((Curves!I12/Curves!J12-1)/(20-10))+J11/10000)*(20-10)) -> 0.50117539 | W11: =V11/(1+(((Curves!J12/Curves!K12-1)/(30-20))+K11/10000)*(30-20)) -> 0.35478398
A12: EURUSD | B12: FX | C12: 7.83 | D12: 6.65 | E12: 6.3 | F12: 4.58 | G12: 2.79 | H12: 1.86 | I12: 0.96 | J12: 0.56 | K12: 0.35 | M12: EURUSD | N12: FX | O12: =1/(1+(((1/Curves!C13-1)/(0.25-0))+C12/10000)*(0.25-0)) -> 0.98984917 | P12: =O12/(1+(((Curves!C13/Curves!D13-1)/(0.5-0.25))+D12/10000)*(0.5-0.25)) -> 0.97981081 | Q12: =P12/(1+(((Curves!D13/Curves!E13-1)/(1-0.5))+E12/10000)*(1-0.5)) -> 0.96000443 | R12: =Q12/(1+(((Curves!E13/Curves!F13-1)/(2-1))+F12/10000)*(2-1)) -> 0.92154248 | S12: =R12/(1+(((Curves!F13/Curves!G13-1)/(3-2))+G12/10000)*(3-2)) -> 0.88450731 | T12: =S12/(1+(((Curves!G13/Curves!H13-1)/(5-3))+H12/10000)*(5-3)) -> 0.8142666 | U12: =T12/(1+(((Curves!H13/Curves!I13-1)/(10-5))+I12/10000)*(10-5)) -> 0.65895102 | V12: =U12/(1+(((Curves!I13/Curves!J13-1)/(20-10))+J12/10000)*(20-10)) -> 0.43497095 | W12: =V12/(1+(((Curves!J13/Curves!K13-1)/(30-20))+K12/10000)*(30-20)) -> 0.28716275
A14: Scenario 2 | C14: 3M | D14: 6M | E14: 1Y | F14: 2Y | G14: 3Y | H14: 5Y | I14: 10Y | J14: 20Y | K14: 30Y | M14: Scenario 2 | O14: 3M | P14: 6M | Q14: 1Y | R14: 2Y | S14: 3Y | T14: 5Y | U14: 10Y | V14: 20Y | W14: 30Y
A15: SOFR | B15: IR | C15: 13.1 | D15: 12.55 | E15: 10.02 | F15: -7.49 | G15: 5.08 | H15: 2.25 | I15: 1.11 | J15: 0.65 | K15: 0.44 | M15: SOFR | N15: IR | O15: =1/(1+(((1/Curves!C8-1)/(0.25-0))+C15/10000)*(0.25-0)) -> 0.98897758 | P15: =O15/(1+(((Curves!C8/Curves!D8-1)/(0.5-0.25))+D15/10000)*(0.5-0.25)) -> 0.97807243 | Q15: =P15/(1+(((Curves!D8/Curves!E8-1)/(1-0.5))+E15/10000)*(1-0.5)) -> 0.95669164 | R15: =Q15/(1+(((Curves!E8/Curves!F8-1)/(2-1))+F15/10000)*(2-1)) -> 0.9166708 | S15: =R15/(1+(((Curves!F8/Curves!G8-1)/(3-2))+G15/10000)*(3-2)) -> 0.87700433 | T15: =S15/(1+(((Curves!G8/Curves!H8-1)/(5-3))+H15/10000)*(5-3)) -> 0.80247507 | U15: =T15/(1+(((Curves!H8/Curves!I8-1)/(10-5))+I15/10000)*(10-5)) -> 0.63970511 | V15: =U15/(1+(((Curves!I8/Curves!J8-1)/(20-10))+J15/10000)*(20-10)) -> 0.4097683 | W15: =V15/(1+(((Curves!J8/Curves!K8-1)/(30-20))+K15/10000)*(30-20)) -> 0.26251512
A16: ESTRN | B16: IR | C16: 11.68 | D16: 11.38 | E16: 8.82 | F16: -5.37 | G16: 3.66 | H16: -1.82 | I16: 0.94 | J16: 0.47 | K16: 0.25 | M16: ESTRN | N16: IR | O16: =1/(1+(((1/Curves!C9-1)/(0.25-0))+C16/10000)*(0.25-0)) -> 0.99198358 | P16: =O16/(1+(((Curves!C9/Curves!D9-1)/(0.5-0.25))+D16/10000)*(0.5-0.25)) -> 0.98402002 | Q16: =P16/(1+(((Curves!D9/Curves!E9-1)/(1-0.5))+E16/10000)*(1-0.5)) -> 0.96835531 | R16: =Q16/(1+(((Curves!E9/Curves!F9-1)/(2-1))+F16/10000)*(2-1)) -> 0.93886305 | S16: =R16/(1+(((Curves!F9/Curves!G9-1)/(3-2))+G16/10000)*(3-2)) -> 0.90919993 | T16: =S16/(1+(((Curves!G9/Curves!H9-1)/(5-3))+H16/10000)*(5-3)) -> 0.85278464 | U16: =T16/(1+(((Curves!H9/Curves!I9-1)/(10-5))+I16/10000)*(10-5)) -> 0.72187947 | V16: =U16/(1+(((Curves!I9/Curves!J9-1)/(20-10))+J16/10000)*(20-10)) -> 0.52140108 | W16: =V16/(1+(((Curves!J9/Curves!K9-1)/(30-20))+K16/10000)*(30-20)) -> 0.37665799
A17: Treasury | B17: Credit | C17: -16.81 | D17: 14.57 | E17: 11.02 | F17: 8.02 | G17: 4.9 | H17: 2.51 | I17: 1.29 | J17: 0.66 | K17: 0.46 | M17: Treasury | N17: Credit | O17: =1/(1+(((1/Curves!C10-1)/(0.25-0))+C17/10000)*(0.25-0)) -> 0.98995768 | P17: =O17/(1+(((Curves!C10/Curves!D10-1)/(0.5-0.25))+D17/10000)*(0.5-0.25)) -> 0.97923642 | Q17: =P17/(1+(((Curves!D10/Curves!E10-1)/(1-0.5))+E17/10000)*(1-0.5)) -> 0.95826231 | R17: =Q17/(1+(((Curves!E10/Curves!F10-1)/(2-1))+F17/10000)*(2-1)) -> 0.91773015 | S17: =R17/(1+(((Curves!F10/Curves!G10-1)/(3-2))+G17/10000)*(3-2)) -> 0.87891063 | T17: =S17/(1+(((Curves!G10/Curves!H10-1)/(5-3))+H17/10000)*(5-3)) -> 0.80578995 | U17: =T17/(1+(((Curves!H10/Curves!I10-1)/(10-5))+I17/10000)*(10-5)) -> 0.64552057 | V17: =U17/(1+(((Curves!I10/Curves!J10-1)/(20-10))+J17/10000)*(20-10)) -> 0.41764448 | W17: =V17/(1+(((Curves!J10/Curves!K10-1)/(30-20))+K17/10000)*(30-20)) -> 0.27024622
A18: Agency_FNMA | B18: Credit | C18: 27.49 | D18: 21.95 | E18: 18.27 | F18: 14.01 | G18: 9.77 | H18: 5.46 | I18: 2.33 | J18: 1.41 | K18: 1.01 | M18: Agency_FNMA | N18: Credit | O18: =1/(1+(((1/Curves!C11-1)/(0.25-0))+C18/10000)*(0.25-0)) -> 0.98788584 | P18: =O18/(1+(((Curves!C11/Curves!D11-1)/(0.5-0.25))+D18/10000)*(0.5-0.25)) -> 0.97603308 | Q18: =P18/(1+(((Curves!D11/Curves!E11-1)/(1-0.5))+E18/10000)*(1-0.5)) -> 0.95288276 | R18: =Q18/(1+(((Curves!E11/Curves!F11-1)/(2-1))+F18/10000)*(2-1)) -> 0.90841835 | S18: =R18/(1+(((Curves!F11/Curves!G11-1)/(3-2))+G18/10000)*(3-2)) -> 0.86612019 | T18: =S18/(1+(((Curves!G11/Curves!H11-1)/(5-3))+H18/10000)*(5-3)) -> 0.78731654 | U18: =T18/(1+(((Curves!H11/Curves!I11-1)/(10-5))+I18/10000)*(10-5)) -> 0.61798552 | V18: =U18/(1+(((Curves!I11/Curves!J11-1)/(20-10))+J18/10000)*(20-10)) -> 0.38397928 | W18: =V18/(1+(((Curves!J11/Curves!K11-1)/(30-20))+K18/10000)*(30-20)) -> 0.23864064
A19: Eur_Govt | B19: Credit | C19: 19.01 | D19: 17.11 | E19: 15.88 | F19: 10.29 | G19: 6.32 | H19: 3.68 | I19: 1.94 | J19: 0.9 | K19: 0.69 | M19: Eur_Govt | N19: Credit | O19: =1/(1+(((1/Curves!C12-1)/(0.25-0))+C19/10000)*(0.25-0)) -> 0.99130776 | P19: =O19/(1+(((Curves!C12/Curves!D12-1)/(0.5-0.25))+D19/10000)*(0.5-0.25)) -> 0.98271772 | Q19: =P19/(1+(((Curves!D12/Curves!E12-1)/(1-0.5))+E19/10000)*(1-0.5)) -> 0.96577303 | R19: =Q19/(1+(((Curves!E12/Curves!F12-1)/(2-1))+F19/10000)*(2-1)) -> 0.93307377 | S19: =R19/(1+(((Curves!F12/Curves!G12-1)/(3-2))+G19/10000)*(3-2)) -> 0.9015577 | T19: =S19/(1+(((Curves!G12/Curves!H12-1)/(5-3))+H19/10000)*(5-3)) -> 0.84137431 | U19: =T19/(1+(((Curves!H12/Curves!I12-1)/(10-5))+I19/10000)*(10-5)) -> 0.70484173 | V19: =U19/(1+(((Curves!I12/Curves!J12-1)/(20-10))+J19/10000)*(20-10)) -> 0.49886546 | W19: =V19/(1+(((Curves!J12/Curves!K12-1)/(30-20))+K19/10000)*(30-20)) -> 0.35313378
A20: EURUSD | B20: FX | C20: 8.38 | D20: 8.31 | E20: 7.3 | F20: 4.77 | G20: 3.29 | H20: 1.88 | I20: -1.15 | J20: 0.63 | K20: 0.43 | M20: EURUSD | N20: FX | O20: =1/(1+(((1/Curves!C13-1)/(0.25-0))+C20/10000)*(0.25-0)) -> 0.98983569 | P20: =O20/(1+(((Curves!C13/Curves!D13-1)/(0.5-0.25))+D20/10000)*(0.5-0.25)) -> 0.97975723 | Q20: =P20/(1+(((Curves!D13/Curves!E13-1)/(1-0.5))+E20/10000)*(1-0.5)) -> 0.9599049 | R20: =Q20/(1+(((Curves!E13/Curves!F13-1)/(2-1))+F20/10000)*(2-1)) -> 0.92143014 | S20: =R20/(1+(((Curves!F13/Curves!G13-1)/(3-2))+G20/10000)*(3-2)) -> 0.88435704 | T20: =S20/(1+(((Curves!G13/Curves!H13-1)/(5-3))+H20/10000)*(5-3)) -> 0.81412527 | U20: =T20/(1+(((Curves!H13/Curves!I13-1)/(10-5))+I20/10000)*(10-5)) -> 0.65939962 | V20: =U20/(1+(((Curves!I13/Curves!J13-1)/(20-10))+J20/10000)*(20-10)) -> 0.43524696 | W20: =V20/(1+(((Curves!J13/Curves!K13-1)/(30-20))+K20/10000)*(30-20)) -> 0.28732979
A22: Scenario 3 | C22: 3M | D22: 6M | E22: 1Y | F22: 2Y | G22: 3Y | H22: 5Y | I22: 10Y | J22: 20Y | K22: 30Y | M22: Scenario 3 | O22: 3M | P22: 6M | Q22: 1Y | R22: 2Y | S22: 3Y | T22: 5Y | U22: 10Y | V22: 20Y | W22: 30Y
A23: SOFR | B23: IR | C23: 14.57 | D23: -14.93 | E23: 11 | F23: 8.22 | G23: -5.24 | H23: 2.7 | I23: -1.3 | J23: -0.83 | K23: 0.48 | M23: SOFR | N23: IR | O23: =1/(1+(((1/Curves!C8-1)/(0.25-0))+C23/10000)*(0.25-0)) -> 0.98894163 | P23: =O23/(1+(((Curves!C8/Curves!D8-1)/(0.5-0.25))+D23/10000)*(0.5-0.25)) -> 0.97870184 | Q23: =P23/(1+(((Curves!D8/Curves!E8-1)/(1-0.5))+E23/10000)*(1-0.5)) -> 0.95726141 | R23: =Q23/(1+(((Curves!E8/Curves!F8-1)/(2-1))+F23/10000)*(2-1)) -> 0.91583814 | S23: =R23/(1+(((Curves!F8/Curves!G8-1)/(3-2))+G23/10000)*(3-2)) -> 0.87707367 | T23: =S23/(1+(((Curves!G8/Curves!H8-1)/(5-3))+H23/10000)*(5-3)) -> 0.80247244 | U23: =T23/(1+(((Curves!H8/Curves!I8-1)/(10-5))+I23/10000)*(10-5)) -> 0.64031809 | V23: =U23/(1+(((Curves!I8/Curves!J8-1)/(20-10))+J23/10000)*(20-10)) -> 0.41055017 | W23: =V23/(1+(((Curves!J8/Curves!K8-1)/(30-20))+K23/10000)*(30-20)) -> 0.26300928
A24: ESTRN | B24: IR | C24: 12.53 | D24: 11.15 | E24: 9.15 | F24: 6.46 | G24: 4.04 | H24: -2.11 | I24: -0.99 | J24: -0.56 | K24: -0.24 | M24: ESTRN | N24: IR | O24: =1/(1+(((1/Curves!C9-1)/(0.25-0))+C24/10000)*(0.25-0)) -> 0.99196267 | P24: =O24/(1+(((Curves!C9/Curves!D9-1)/(0.5-0.25))+D24/10000)*(0.5-0.25)) -> 0.98400489 | Q24: =P24/(1+(((Curves!D9/Curves!E9-1)/(1-0.5))+E24/10000)*(1-0.5)) -> 0.9683247 | R24: =Q24/(1+(((Curves!E9/Curves!F9-1)/(2-1))+F24/10000)*(2-1)) -> 0.93775779 | S24: =R24/(1+(((Curves!F9/Curves!G9-1)/(3-2))+G24/10000)*(3-2)) -> 0.90809618 | T24: =S24/(1+(((Curves!G9/Curves!H9-1)/(5-3))+H24/10000)*(5-3)) -> 0.85179571 | U24: =T24/(1+(((Curves!H9/Curves!I9-1)/(10-5))+I24/10000)*(10-5)) -> 0.72163183 | V24: =U24/(1+(((Curves!I9/Curves!J9-1)/(20-10))+J24/10000)*(20-10)) -> 0.52161026 | W24: =V24/(1+(((Curves!J9/Curves!K9-1)/(30-20))+K24/10000)*(30-20)) -> 0.37694253
A25: Treasury | B25: Credit | C25: 17.96 | D25: 18.23 | E25: 14.38 | F25: 9.02 | G25: 6.28 | H25: 3.35 | I25: 1.44 | J25: -0.76 | K25: 0.49 | M25: Treasury | N25: Credit | O25: =1/(1+(((1/Curves!C10-1)/(0.25-0))+C25/10000)*(0.25-0)) -> 0.98910653 | P25: =O25/(1+(((Curves!C10/Curves!D10-1)/(0.5-0.25))+D25/10000)*(0.5-0.25)) -> 0.97830594 | Q25: =P25/(1+(((Curves!D10/Curves!E10-1)/(1-0.5))+E25/10000)*(1-0.5)) -> 0.9571944 | R25: =Q25/(1+(((Curves!E10/Curves!F10-1)/(2-1))+F25/10000)*(2-1)) -> 0.91661963 | S25: =R25/(1+(((Curves!F10/Curves!G10-1)/(3-2))+G25/10000)*(3-2)) -> 0.87773108 | T25: =S25/(1+(((Curves!G10/Curves!H10-1)/(5-3))+H25/10000)*(5-3)) -> 0.80458461 | U25: =T25/(1+(((Curves!H10/Curves!I10-1)/(10-5))+I25/10000)*(10-5)) -> 0.64451624 | V25: =U25/(1+(((Curves!I10/Curves!J10-1)/(20-10))+J25/10000)*(20-10)) -> 0.41737814 | W25: =V25/(1+(((Curves!J10/Curves!K10-1)/(30-20))+K25/10000)*(30-20)) -> 0.27006864
A26: Agency_FNMA | B26: Credit | C26: 30.38 | D26: -26.47 | E26: -21.02 | F26: -17.01 | G26: 11.17 | H26: 6.11 | I26: 2.8 | J26: 1.48 | K26: 1.06 | M26: Agency_FNMA | N26: Credit | O26: =1/(1+(((1/Curves!C11-1)/(0.25-0))+C26/10000)*(0.25-0)) -> 0.98781534 | P26: =O26/(1+(((Curves!C11/Curves!D11-1)/(0.5-0.25))+D26/10000)*(0.5-0.25)) -> 0.97713205 | Q26: =P26/(1+(((Curves!D11/Curves!E11-1)/(1-0.5))+E26/10000)*(1-0.5)) -> 0.95578878 | R26: =Q26/(1+(((Curves!E11/Curves!F11-1)/(2-1))+F26/10000)*(2-1)) -> 0.91389136 | S26: =R26/(1+(((Curves!F11/Curves!G11-1)/(3-2))+G26/10000)*(3-2)) -> 0.87122208 | T26: =S26/(1+(((Curves!G11/Curves!H11-1)/(5-3))+H26/10000)*(5-3)) -> 0.79186066 | U26: =T26/(1+(((Curves!H11/Curves!I11-1)/(10-5))+I26/10000)*(10-5)) -> 0.62143769 | V26: =U26/(1+(((Curves!I11/Curves!J11-1)/(20-10))+J26/10000)*(20-10)) -> 0.38610746 | W26: =V26/(1+(((Curves!J11/Curves!K11-1)/(30-20))+K26/10000)*(30-20)) -> 0.23995583
A27: Eur_Govt | B27: Credit | C27: 24.9 | D27: -20.85 | E27: 17.83 | F27: -11.02 | G27: 6.89 | H27: 4.14 | I27: -1.98 | J27: 1.03 | K27: 0.78 | M27: Eur_Govt | N27: Credit | O27: =1/(1+(((1/Curves!C12-1)/(0.25-0))+C27/10000)*(0.25-0)) -> 0.99116308 | P27: =O27/(1+(((Curves!C12/Curves!D12-1)/(0.5-0.25))+D27/10000)*(0.5-0.25)) -> 0.98349954 | Q27: =P27/(1+(((Curves!D12/Curves!E12-1)/(1-0.5))+E27/10000)*(1-0.5)) -> 0.96644877 | R27: =Q27/(1+(((Curves!E12/Curves!F12-1)/(2-1))+F27/10000)*(2-1)) -> 0.935653 | S27: =R27/(1+(((Curves!F12/Curves!G12-1)/(3-2))+G27/10000)*(3-2)) -> 0.90400003 | T27: =S27/(1+(((Curves!G12/Curves!H12-1)/(5-3))+H27/10000)*(5-3)) -> 0.84358117 | U27: =T27/(1+(((Curves!H12/Curves!I12-1)/(10-5))+I27/10000)*(10-5)) -> 0.70785273 | V27: =U27/(1+(((Curves!I12/Curves!J12-1)/(20-10))+J27/10000)*(20-10)) -> 0.50095046 | W27: =V27/(1+(((Curves!J12/Curves!K12-1)/(30-20))+K27/10000)*(30-20)) -> 0.3545871
A28: EURUSD | B28: FX | C28: 11.35 | D28: 10.56 | E28: 8.56 | F28: 5.41 | G28: 3.64 | H28: 2.25 | I28: 1.21 | J28: 0.79 | K28: 0.57 | M28: EURUSD | N28: FX | O28: =1/(1+(((1/Curves!C13-1)/(0.25-0))+C28/10000)*(0.25-0)) -> 0.98976295 | P28: =O28/(1+(((Curves!C13/Curves!D13-1)/(0.5-0.25))+D28/10000)*(0.5-0.25)) -> 0.97963068 | Q28: =P28/(1+(((Curves!D13/Curves!E13-1)/(1-0.5))+E28/10000)*(1-0.5)) -> 0.95972168 | R28: =Q28/(1+(((Curves!E13/Curves!F13-1)/(2-1))+F28/10000)*(2-1)) -> 0.92119767 | S28: =R28/(1+(((Curves!F13/Curves!G13-1)/(3-2))+G28/10000)*(3-2)) -> 0.88410423 | T28: =S28/(1+(((Curves!G13/Curves!H13-1)/(5-3))+H28/10000)*(5-3)) -> 0.81383709 | U28: =T28/(1+(((Curves!H13/Curves!I13-1)/(10-5))+I28/10000)*(10-5)) -> 0.65853682 | V28: =U28/(1+(((Curves!I13/Curves!J13-1)/(20-10))+J28/10000)*(20-10)) -> 0.43463155 | W28: =V28/(1+(((Curves!J13/Curves!K13-1)/(30-20))+K28/10000)*(30-20)) -> 0.28689702
A30: Scenario 4 | C30: 3M | D30: 6M | E30: 1Y | F30: 2Y | G30: 3Y | H30: 5Y | I30: 10Y | J30: 20Y | K30: 30Y | M30: Scenario 4 | O30: 3M | P30: 6M | Q30: 1Y | R30: 2Y | S30: 3Y | T30: 5Y | U30: 10Y | V30: 20Y | W30: 30Y
A31: SOFR | B31: IR | C31: -19.01 | D31: -17.29 | E31: 14.24 | F31: -8.2 | G31: 6.25 | H31: 2.94 | I31: 1.38 | J31: 0.88 | K31: 0.61 | M31: SOFR | N31: IR | O31: =1/(1+(((1/Curves!C8-1)/(0.25-0))+C31/10000)*(0.25-0)) -> 0.98976335 | P31: =O31/(1+(((Curves!C8/Curves!D8-1)/(0.5-0.25))+D31/10000)*(0.5-0.25)) -> 0.97957224 | Q31: =P31/(1+(((Curves!D8/Curves!E8-1)/(1-0.5))+E31/10000)*(1-0.5)) -> 0.95796096 | R31: =Q31/(1+(((Curves!E8/Curves!F8-1)/(2-1))+F31/10000)*(2-1)) -> 0.91794947 | S31: =R31/(1+(((Curves!F8/Curves!G8-1)/(3-2))+G31/10000)*(3-2)) -> 0.87812937 | T31: =S31/(1+(((Curves!G8/Curves!H8-1)/(5-3))+H31/10000)*(5-3)) -> 0.80340306 | U31: =T31/(1+(((Curves!H8/Curves!I8-1)/(10-5))+I31/10000)*(10-5)) -> 0.64037595 | V31: =U31/(1+(((Curves!I8/Curves!J8-1)/(20-10))+J31/10000)*(20-10)) -> 0.41013759 | W31: =V31/(1+(((Curves!J8/Curves!K8-1)/(30-20))+K31/10000)*(30-20)) -> 0.26272309
A32: ESTRN | B32: IR | C32: 15.96 | D32: -12.95 | E32: 10.93 | F32: 6.93 | G32: 4.41 | H32: 2.31 | I32: 1.14 | J32: 0.57 | K32: 0.28 | M32: ESTRN | N32: IR | O32: =1/(1+(((1/Curves!C9-1)/(0.25-0))+C32/10000)*(0.25-0)) -> 0.9918783 | P32: =O32/(1+(((Curves!C9/Curves!D9-1)/(0.5-0.25))+D32/10000)*(0.5-0.25)) -> 0.98450961 | Q32: =P32/(1+(((Curves!D9/Curves!E9-1)/(1-0.5))+E32/10000)*(1-0.5)) -> 0.96873653 | R32: =Q32/(1+(((Curves!E9/Curves!F9-1)/(2-1))+F32/10000)*(2-1)) -> 0.93811392 | S32: =R32/(1+(((Curves!F9/Curves!G9-1)/(3-2))+G32/10000)*(3-2)) -> 0.90840849 | T32: =S32/(1+(((Curves!G9/Curves!H9-1)/(5-3))+H32/10000)*(5-3)) -> 0.8513827 | U32: =T32/(1+(((Curves!H9/Curves!I9-1)/(10-5))+I32/10000)*(10-5)) -> 0.72063174 | V32: =U32/(1+(((Curves!I9/Curves!J9-1)/(20-10))+J32/10000)*(20-10)) -> 0.52046227 | W32: =V32/(1+(((Curves!J9/Curves!K9-1)/(30-20))+K32/10000)*(30-20)) -> 0.37597165
A33: Treasury | B33: Credit | C33: 22.27 | D33: 19.36 | E33: 14.63 | F33: 11.18 | G33: 6.16 | H33: 3.78 | I33: -1.81 | J33: 0.94 | K33: 0.57 | M33: Treasury | N33: Credit | O33: =1/(1+(((1/Curves!C10-1)/(0.25-0))+C33/10000)*(0.25-0)) -> 0.98900113 | P33: =O33/(1+(((Curves!C10/Curves!D10-1)/(0.5-0.25))+D33/10000)*(0.5-0.25)) -> 0.97817436 | Q33: =P33/(1+(((Curves!D10/Curves!E10-1)/(1-0.5))+E33/10000)*(1-0.5)) -> 0.95705395 | R33: =Q33/(1+(((Curves!E10/Curves!F10-1)/(2-1))+F33/10000)*(2-1)) -> 0.9162956 | S33: =R33/(1+(((Curves!F10/Curves!G10-1)/(3-2))+G33/10000)*(3-2)) -> 0.87743088 | T33: =S33/(1+(((Curves!G10/Curves!H10-1)/(5-3))+H33/10000)*(5-3)) -> 0.80424603 | U33: =T33/(1+(((Curves!H10/Curves!I10-1)/(10-5))+I33/10000)*(10-5)) -> 0.64508474 | V33: =U33/(1+(((Curves!I10/Curves!J10-1)/(20-10))+J33/10000)*(20-10)) -> 0.4172869 | W33: =V33/(1+(((Curves!J10/Curves!K10-1)/(30-20))+K33/10000)*(30-20)) -> 0.26999563
A34: Agency_FNMA | B34: Credit | C34: 32.63 | D34: 31.59 | E34: 27.09 | F34: 16.43 | G34: 11.1 | H34: 6.25 | I34: -3.01 | J34: 1.76 | K34: 1.17 | M34: Agency_FNMA | N34: Credit | O34: =1/(1+(((1/Curves!C11-1)/(0.25-0))+C34/10000)*(0.25-0)) -> 0.98776045 | P34: =O34/(1+(((Curves!C11/Curves!D11-1)/(0.5-0.25))+D34/10000)*(0.5-0.25)) -> 0.97567688 | Q34: =P34/(1+(((Curves!D11/Curves!E11-1)/(1-0.5))+E34/10000)*(1-0.5)) -> 0.95212508 | R34: =Q34/(1+(((Curves!E11/Curves!F11-1)/(2-1))+F34/10000)*(2-1)) -> 0.90748666 | S34: =R34/(1+(((Curves!F11/Curves!G11-1)/(3-2))+G34/10000)*(3-2)) -> 0.86512218 | T34: =S34/(1+(((Curves!G11/Curves!H11-1)/(5-3))+H34/10000)*(5-3)) -> 0.78629641 | U34: =T34/(1+(((Curves!H11/Curves!I11-1)/(10-5))+I34/10000)*(10-5)) -> 0.61848097 | V34: =U34/(1+(((Curves!I11/Curves!J11-1)/(20-10))+J34/10000)*(20-10)) -> 0.38420357 | W34: =V34/(1+(((Curves!J11/Curves!K11-1)/(30-20))+K34/10000)*(30-20)) -> 0.23875629
A35: Eur_Govt | B35: Credit | C35: 27.61 | D35: 23.34 | E35: 19.38 | F35: -13.99 | G35: 8.3 | H35: 4.12 | I35: 2.53 | J35: 1.27 | K35: 0.92 | M35: Eur_Govt | N35: Credit | O35: =1/(1+(((1/Curves!C12-1)/(0.25-0))+C35/10000)*(0.25-0)) -> 0.99109652 | P35: =O35/(1+(((Curves!C12/Curves!D12-1)/(0.5-0.25))+D35/10000)*(0.5-0.25)) -> 0.98235664 | Q35: =P35/(1+(((Curves!D12/Curves!E12-1)/(1-0.5))+E35/10000)*(1-0.5)) -> 0.96525217 | R35: =Q35/(1+(((Curves!E12/Curves!F12-1)/(2-1))+F35/10000)*(2-1)) -> 0.93476331 | S35: =R35/(1+(((Curves!F12/Curves!G12-1)/(3-2))+G35/10000)*(3-2)) -> 0.90301742 | T35: =S35/(1+(((Curves!G12/Curves!H12-1)/(5-3))+H35/10000)*(5-3)) -> 0.84266737 | U35: =T35/(1+(((Curves!H12/Curves!I12-1)/(10-5))+I35/10000)*(10-5)) -> 0.70575055 | V35: =U35/(1+(((Curves!I12/Curves!J12-1)/(20-10))+J35/10000)*(20-10)) -> 0.49937792 | W35: =V35/(1+(((Curves!J12/Curves!K12-1)/(30-20))+K35/10000)*(30-20)) -> 0.35343899
A36: EURUSD | B36: FX | C36: 11.12 | D36: 10.6 | E36: 10.14 | F36: 6.2 | G36: 4.74 | H36: 2.53 | I36: 1.43 | J36: 0.86 | K36: 0.6 | M36: EURUSD | N36: FX | O36: =1/(1+(((1/Curves!C13-1)/(0.25-0))+C36/10000)*(0.25-0)) -> 0.98976858 | P36: =O36/(1+(((Curves!C13/Curves!D13-1)/(0.5-0.25))+D36/10000)*(0.5-0.25)) -> 0.97963529 | Q36: =P36/(1+(((Curves!D13/Curves!E13-1)/(1-0.5))+E36/10000)*(1-0.5)) -> 0.95965192 | R36: =Q36/(1+(((Curves!E13/Curves!F13-1)/(2-1))+F36/10000)*(2-1)) -> 0.92106087 | S36: =R36/(1+(((Curves!F13/Curves!G13-1)/(3-2))+G36/10000)*(3-2)) -> 0.88387962 | T36: =S36/(1+(((Curves!G13/Curves!H13-1)/(5-3))+H36/10000)*(5-3)) -> 0.81358839 | U36: =T36/(1+(((Curves!H13/Curves!I13-1)/(10-5))+I36/10000)*(10-5)) -> 0.65827699 | V36: =U36/(1+(((Curves!I13/Curves!J13-1)/(20-10))+J36/10000)*(20-10)) -> 0.43444 | W36: =V36/(1+(((Curves!J13/Curves!K13-1)/(30-20))+K36/10000)*(30-20)) -> 0.28676489
A38: Scenario 5 | C38: 3M | D38: 6M | E38: 1Y | F38: 2Y | G38: 3Y | H38: 5Y | I38: 10Y | J38: 20Y | K38: 30Y | M38: Scenario 5 | O38: 3M | P38: 6M | Q38: 1Y | R38: 2Y | S38: 3Y | T38: 5Y | U38: 10Y | V38: 20Y | W38: 30Y
A39: SOFR | B39: IR | C39: 20.8 | D39: 18.09 | E39: 14.02 | F39: 10.51 | G39: 7.07 | H39: 3.13 | I39: 1.64 | J39: 1.05 | K39: 0.66 | M39: SOFR | N39: IR | O39: =1/(1+(((1/Curves!C8-1)/(0.25-0))+C39/10000)*(0.25-0)) -> 0.98878933 | P39: =O39/(1+(((Curves!C8/Curves!D8-1)/(0.5-0.25))+D39/10000)*(0.5-0.25)) -> 0.97775234 | Q39: =P39/(1+(((Curves!D8/Curves!E8-1)/(1-0.5))+E39/10000)*(1-0.5)) -> 0.95619149 | R39: =Q39/(1+(((Curves!E8/Curves!F8-1)/(2-1))+F39/10000)*(2-1)) -> 0.91461414 | S39: =R39/(1+(((Curves!F8/Curves!G8-1)/(3-2))+G39/10000)*(3-2)) -> 0.8748701 | T39: =S39/(1+(((Curves!G8/Curves!H8-1)/(5-3))+H39/10000)*(5-3)) -> 0.80039331 | U39: =T39/(1+(((Curves!H8/Curves!I8-1)/(10-5))+I39/10000)*(10-5)) -> 0.63791084 | V39: =U39/(1+(((Curves!I8/Curves!J8-1)/(20-10))+J39/10000)*(20-10)) -> 0.4085143 | W39: =V39/(1+(((Curves!J8/Curves!K8-1)/(30-20))+K39/10000)*(30-20)) -> 0.26167488
A40: ESTRN | B40: IR | C40: 16.07 | D40: 15.03 | E40: 12.95 | F40: 8.58 | G40: 4.65 | H40: 2.65 | I40: 1.41 | J40: 0.7 | K40: 0.35 | M40: ESTRN | N40: IR | O40: =1/(1+(((1/Curves!C9-1)/(0.25-0))+C40/10000)*(0.25-0)) -> 0.99187559 | P40: =O40/(1+(((Curves!C9/Curves!D9-1)/(0.5-0.25))+D40/10000)*(0.5-0.25)) -> 0.98382385 | Q40: =P40/(1+(((Curves!D9/Curves!E9-1)/(1-0.5))+E40/10000)*(1-0.5)) -> 0.96796556 | R40: =Q40/(1+(((Curves!E9/Curves!F9-1)/(2-1))+F40/10000)*(2-1)) -> 0.93721757 | S40: =R40/(1+(((Curves!F9/Curves!G9-1)/(3-2))+G40/10000)*(3-2)) -> 0.90751943 | T40: =S40/(1+(((Curves!G9/Curves!H9-1)/(5-3))+H40/10000)*(5-3)) -> 0.85049525 | U40: =T40/(1+(((Curves!H9/Curves!I9-1)/(10-5))+I40/10000)*(10-5)) -> 0.71979833 | V40: =U40/(1+(((Curves!I9/Curves!J9-1)/(20-10))+J40/10000)*(20-10)) -> 0.51981155 | W40: =V40/(1+(((Curves!J9/Curves!K9-1)/(30-20))+K40/10000)*(30-20)) -> 0.3754826
A41: Treasury | B41: Credit | C41: 22.73 | D41: -21.78 | E41: 17.02 | F41: 11.96 | G41: 7.2 | H41: 3.97 | I41: 2.1 | J41: 1.03 | K41: 0.68 | M41: Treasury | N41: Credit | O41: =1/(1+(((1/Curves!C10-1)/(0.25-0))+C41/10000)*(0.25-0)) -> 0.98898988 | P41: =O41/(1+(((Curves!C10/Curves!D10-1)/(0.5-0.25))+D41/10000)*(0.5-0.25)) -> 0.97915927 | Q41: =P41/(1+(((Curves!D10/Curves!E10-1)/(1-0.5))+E41/10000)*(1-0.5)) -> 0.9579056 | R41: =Q41/(1+(((Curves!E10/Curves!F10-1)/(2-1))+F41/10000)*(2-1)) -> 0.9170425 | S41: =R41/(1+(((Curves!F10/Curves!G10-1)/(3-2))+G41/10000)*(3-2)) -> 0.87805865 | T41: =S41/(1+(((Curves!G10/Curves!H10-1)/(5-3))+H41/10000)*(5-3)) -> 0.80479341 | U41: =T41/(1+(((Curves!H10/Curves!I10-1)/(10-5))+I41/10000)*(10-5)) -> 0.64451313 | V41: =U41/(1+(((Curves!I10/Curves!J10-1)/(20-10))+J41/10000)*(20-10)) -> 0.41689287 | W41: =V41/(1+(((Curves!J10/Curves!K10-1)/(30-20))+K41/10000)*(30-20)) -> 0.26972148
A42: Agency_FNMA | B42: Credit | C42: 36.17 | D42: 31.56 | E42: 26.02 | F42: 20.58 | G42: 12.85 | H42: 7.78 | I42: -3.17 | J42: 2.03 | K42: 1.36 | M42: Agency_FNMA | N42: Credit | O42: =1/(1+(((1/Curves!C11-1)/(0.25-0))+C42/10000)*(0.25-0)) -> 0.98767412 | P42: =O42/(1+(((Curves!C11/Curves!D11-1)/(0.5-0.25))+D42/10000)*(0.5-0.25)) -> 0.97559232 | Q42: =P42/(1+(((Curves!D11/Curves!E11-1)/(1-0.5))+E42/10000)*(1-0.5)) -> 0.95209227 | R42: =Q42/(1+(((Curves!E11/Curves!F11-1)/(2-1))+F42/10000)*(2-1)) -> 0.90709659 | S42: =R42/(1+(((Curves!F11/Curves!G11-1)/(3-2))+G42/10000)*(3-2)) -> 0.86460608 | T42: =S42/(1+(((Curves!G11/Curves!H11-1)/(5-3))+H42/10000)*(5-3)) -> 0.78560884 | U42: =T42/(1+(((Curves!H11/Curves!I11-1)/(10-5))+I42/10000)*(10-5)) -> 0.61797903 | V42: =U42/(1+(((Curves!I11/Curves!J11-1)/(20-10))+J42/10000)*(20-10)) -> 0.38382738 | W42: =V42/(1+(((Curves!J11/Curves!K11-1)/(30-20))+K42/10000)*(30-20)) -> 0.23849436
A43: Eur_Govt | B43: Credit | C43: 28.02 | D43: 27.14 | E43: 21.19 | F43: 13.78 | G43: -9.13 | H43: -4.65 | I43: 2.56 | J43: 1.41 | K43: 1.02 | M43: Eur_Govt | N43: Credit | O43: =1/(1+(((1/Curves!C12-1)/(0.25-0))+C43/10000)*(0.25-0)) -> 0.99108645 | P43: =O43/(1+(((Curves!C12/Curves!D12-1)/(0.5-0.25))+D43/10000)*(0.5-0.25)) -> 0.98225417 | Q43: =P43/(1+(((Curves!D12/Curves!E12-1)/(1-0.5))+E43/10000)*(1-0.5)) -> 0.96506567 | R43: =Q43/(1+(((Curves!E12/Curves!F12-1)/(2-1))+F43/10000)*(2-1)) -> 0.93207608 | S43: =R43/(1+(((Curves!F12/Curves!G12-1)/(3-2))+G43/10000)*(3-2)) -> 0.90194014 | T43: =S43/(1+(((Curves!G12/Curves!H12-1)/(5-3))+H43/10000)*(5-3)) -> 0.84304196 | U43: =T43/(1+(((Curves!H12/Curves!I12-1)/(10-5))+I43/10000)*(10-5)) -> 0.70605541 | V43: =U43/(1+(((Curves!I12/Curves!J12-1)/(20-10))+J43/10000)*(20-10)) -> 0.49954415 | W43: =V43/(1+(((Curves!J12/Curves!K12-1)/(30-20))+K43/10000)*(30-20)) -> 0.35353162
A44: EURUSD | B44: FX | C44: -12.66 | D44: 12.1 | E44: 10.69 | F44: 7.43 | G44: -4.91 | H44: 2.77 | I44: 1.65 | J44: 1.01 | K44: 0.67 | M44: EURUSD | N44: FX | O44: =1/(1+(((1/Curves!C13-1)/(0.25-0))+C44/10000)*(0.25-0)) -> 0.99035132 | P44: =O44/(1+(((Curves!C13/Curves!D13-1)/(0.5-0.25))+D44/10000)*(0.5-0.25)) -> 0.98017568 | Q44: =P44/(1+(((Curves!D13/Curves!E13-1)/(1-0.5))+E44/10000)*(1-0.5)) -> 0.96015543 | R44: =Q44/(1+(((Curves!E13/Curves!F13-1)/(2-1))+F44/10000)*(2-1)) -> 0.92143535 | S44: =R44/(1+(((Curves!F13/Curves!G13-1)/(3-2))+G44/10000)*(3-2)) -> 0.88505859 | T44: =S44/(1+(((Curves!G13/Curves!H13-1)/(5-3))+H44/10000)*(5-3)) -> 0.81463761 | U44: =T44/(1+(((Curves!H13/Curves!I13-1)/(10-5))+I44/10000)*(10-5)) -> 0.65906725 | V44: =U44/(1+(((Curves!I13/Curves!J13-1)/(20-10))+J44/10000)*(20-10)) -> 0.43491849 | W44: =V44/(1+(((Curves!J13/Curves!K13-1)/(30-20))+K44/10000)*(30-20)) -> 0.28706747
A46: Scenario 6 | C46: 3M | D46: 6M | E46: 1Y | F46: 2Y | G46: 3Y | H46: 5Y | I46: 10Y | J46: 20Y | K46: 30Y | M46: Scenario 6 | O46: 3M | P46: 6M | Q46: 1Y | R46: 2Y | S46: 3Y | T46: 5Y | U46: 10Y | V46: 20Y | W46: 30Y
A47: SOFR | B47: IR | C47: 21.12 | D47: 19.21 | E47: 15.49 | F47: 11.04 | G47: 7.31 | H47: -3.52 | I47: 1.73 | J47: 1.11 | K47: 0.75 | M47: SOFR | N47: IR | O47: =1/(1+(((1/Curves!C8-1)/(0.25-0))+C47/10000)*(0.25-0)) -> 0.98878151 | P47: =O47/(1+(((Curves!C8/Curves!D8-1)/(0.5-0.25))+D47/10000)*(0.5-0.25)) -> 0.97771753 | Q47: =P47/(1+(((Curves!D8/Curves!E8-1)/(1-0.5))+E47/10000)*(1-0.5)) -> 0.95608873 | R47: =Q47/(1+(((Curves!E8/Curves!F8-1)/(2-1))+F47/10000)*(2-1)) -> 0.91446948 | S47: =R47/(1+(((Curves!F8/Curves!G8-1)/(3-2))+G47/10000)*(3-2)) -> 0.87471165 | T47: =S47/(1+(((Curves!G8/Curves!H8-1)/(5-3))+H47/10000)*(5-3)) -> 0.80122326 | U47: =T47/(1+(((Curves!H8/Curves!I8-1)/(10-5))+I47/10000)*(10-5)) -> 0.63854941 | V47: =U47/(1+(((Curves!I8/Curves!J8-1)/(20-10))+J47/10000)*(20-10)) -> 0.40890752 | W47: =V47/(1+(((Curves!J8/Curves!K8-1)/(30-20))+K47/10000)*(30-20)) -> 0.26191166
...

Sheet SABR
A1: SABR Swaption Vol Surfaces — Base -> Scenario Shocks -> Shocked Surfaces, ATM/RHO/NU/Combined aligned
A2: Swabr_Swaption (IR_VOL) | Trade 123456 | Stress anchor 20-Nov-2008
A3: SECTION 1 - BASE SABR SURFACES (ATM, RHO, NU, Combined Effective Vol aligned horizontally)
B5: Param: ATM | N5: Param: RHO | Z5: Param: NU | AL5: Combined Effective ATM Vol (Hagan approx, beta=1)
B6: Expiry \ Tenor | C6: 1M | D6: 3M | E6: 6M | F6: 1Y | G6: 2Y | H6: 3Y | I6: 5Y | J6: 10Y | K6: 20Y | L6: 30Y | N6: Expiry \ Tenor | O6: 1M | P6: 3M | Q6: 6M | R6: 1Y | S6: 2Y | T6: 3Y | U6: 5Y | V6: 10Y | W6: 20Y | X6: 30Y | Z6: Expiry \ Tenor | AA6: 1M | AB6: 3M | AC6: 6M | AD6: 1Y | AE6: 2Y | AF6: 3Y | AG6: 5Y | AH6: 10Y | AI6: 20Y | AJ6: 30Y | AL6: Expiry \ Tenor | AM6: 1M | AN6: 3M | AO6: 6M | AP6: 1Y | AQ6: 2Y | AR6: 3Y | AS6: 5Y | AT6: 10Y | AU6: 20Y | AV6: 30Y
B7: 1M | C7: 0.5465 | D7: 0.5264 | E7: 0.5197 | F7: 0.4914 | G7: 0.4841 | H7: 0.464 | I7: 0.4412 | J7: 0.4335 | K7: 0.4074 | L7: 0.3987 | N7: 1M | O7: -0.3586 | P7: -0.3387 | Q7: -0.3126 | R7: -0.2851 | S7: -0.2797 | T7: -0.2583 | U7: -0.2308 | V7: -0.2049 | W7: -0.1929 | X7: -0.1771 | Z7: 1M | AA7: 0.8595 | AB7: 0.8187 | AC7: 0.8127 | AD7: 0.7791 | AE7: 0.754 | AF7: 0.7312 | AG7: 0.7128 | AH7: 0.7008 | AI7: 0.6658 | AJ7: 0.6516 | AL7: 1M | AM7: =C7*(1+(((2-3*O7^2)/24*AA7^2)+(O7*AA7*C7/4))*0.0833333333333333) -> 0.54684506 | AN7: =D7*(1+(((2-3*P7^2)/24*AB7^2)+(P7*AB7*D7/4))*0.0833333333333333) -> 0.52682781 | AO7: =E7*(1+(((2-3*Q7^2)/24*AC7^2)+(Q7*AC7*E7/4))*0.0833333333333333) -> 0.5203048 | AP7: =F7*(1+(((2-3*R7^2)/24*AD7^2)+(R7*AD7*F7/4))*0.0833333333333333) -> 0.4921014 | AQ7: =G7*(1+(((2-3*S7^2)/24*AE7^2)+(S7*AE7*G7/4))*0.0833333333333333) -> 0.4847573 | AR7: =H7*(1+(((2-3*T7^2)/24*AF7^2)+(T7*AF7*H7/4))*0.0833333333333333) -> 0.46470322 | AS7: =I7*(1+(((2-3*U7^2)/24*AG7^2)+(U7*AG7*I7/4))*0.0833333333333333) -> 0.44196516 | AT7: =J7*(1+(((2-3*V7^2)/24*AH7^2)+(V7*AH7*J7/4))*0.0833333333333333) -> 0.43432319 | ... AV7: =L7*(1+(((2-3*X7^2)/24*AJ7^2)+(X7*AJ7*L7/4))*0.0833333333333333) -> 0.39943809
B8: 3M | C8: 0.5361 | D8: 0.5141 | E8: 0.501 | F8: 0.4746 | G8: 0.4579 | H8: 0.4441 | I8: 0.4369 | J8: 0.4152 | K8: 0.3963 | L8: 0.385 | N8: 3M | O8: -0.3315 | P8: -0.3151 | Q8: -0.2858 | R8: -0.2682 | S8: -0.2579 | T8: -0.2318 | U8: -0.2134 | V8: -0.1869 | W8: -0.1704 | X8: -0.1598 | Z8: 3M | AA8: 0.8374 | AB8: 0.7979 | AC8: 0.7817 | AD8: 0.7663 | AE8: 0.7319 | AF8: 0.7164 | AG8: 0.6852 | AH8: 0.6756 | AI8: 0.6553 | AJ8: 0.6292 | AL8: 3M | AM8: =C8*(1+(((2-3*O8^2)/24*AA8^2)+(O8*AA8*C8/4))*0.25) -> 0.53765454 | AN8: =D8*(1+(((2-3*P8^2)/24*AB8^2)+(P8*AB8*D8/4))*0.25) -> 0.5157501 | AO8: =E8*(1+(((2-3*Q8^2)/24*AC8^2)+(Q8*AC8*E8/4))*0.25) -> 0.5030917 | AP8: =F8*(1+(((2-3*R8^2)/24*AD8^2)+(R8*AD8*F8/4))*0.25) -> 0.47688634 | AQ8: =G8*(1+(((2-3*S8^2)/24*AE8^2)+(S8*AE8*G8/4))*0.25) -> 0.46002674 | AR8: =H8*(1+(((2-3*T8^2)/24*AF8^2)+(T8*AF8*H8/4))*0.25) -> 0.44641876 | AS8: =I8*(1+(((2-3*U8^2)/24*AG8^2)+(U8*AG8*I8/4))*0.25) -> 0.43913707 | AT8: =J8*(1+(((2-3*V8^2)/24*AH8^2)+(V8*AH8*J8/4))*0.25) -> 0.41758081 | ... AV8: =L8*(1+(((2-3*X8^2)/24*AJ8^2)+(X8*AJ8*L8/4))*0.25) -> 0.38712229
B9: 6M | C9: 0.5242 | D9: 0.4963 | E9: 0.4872 | F9: 0.4686 | G9: 0.4516 | H9: 0.4325 | I9: 0.4235 | J9: 0.4089 | K9: 0.3828 | L9: 0.3699 | N9: 6M | O9: -0.3199 | P9: -0.2876 | Q9: -0.2693 | R9: -0.2429 | S9: -0.2269 | T9: -0.2182 | U9: -0.1967 | V9: -0.1716 | W9: -0.1651 | X9: -0.1369 | Z9: 6M | AA9: 0.7989 | AB9: 0.7757 | AC9: 0.7523 | AD9: 0.7443 | AE9: 0.7093 | AF9: 0.6894 | AG9: 0.67 | AH9: 0.6574 | AI9: 0.6194 | AJ9: 0.6045 | AL9: 6M | AM9: =C9*(1+(((2-3*O9^2)/24*AA9^2)+(O9*AA9*C9/4))*0.5) -> 0.52722206 | AN9: =D9*(1+(((2-3*P9^2)/24*AB9^2)+(P9*AB9*D9/4))*0.5) -> 0.50033027 | AO9: =E9*(1+(((2-3*Q9^2)/24*AC9^2)+(Q9*AC9*E9/4))*0.5) -> 0.49142801 | AP9: =F9*(1+(((2-3*R9^2)/24*AD9^2)+(R9*AD9*F9/4))*0.5) -> 0.47349686 | AQ9: =G9*(1+(((2-3*S9^2)/24*AE9^2)+(S9*AE9*G9/4))*0.5) -> 0.45623289 | AR9: =H9*(1+(((2-3*T9^2)/24*AF9^2)+(T9*AF9*H9/4))*0.5) -> 0.43693584 | AS9: =I9*(1+(((2-3*U9^2)/24*AG9^2)+(U9*AG9*I9/4))*0.5) -> 0.42800691 | AT9: =J9*(1+(((2-3*V9^2)/24*AH9^2)+(V9*AH9*J9/4))*0.5) -> 0.41358023 | ... AV9: =L9*(1+(((2-3*X9^2)/24*AJ9^2)+(X9*AJ9*L9/4))*0.5) -> 0.37395831
B10: 1Y | C10: 0.501 | D10: 0.491 | E10: 0.4731 | F10: 0.4573 | G10: 0.4289 | H10: 0.415 | I10: 0.3972 | J10: 0.391 | K10: 0.3758 | L10: 0.343 | N10: 1Y | O10: -0.2981 | P10: -0.2776 | Q10: -0.2581 | R10: -0.2336 | S10: -0.2121 | T10: -0.1992 | U10: -0.1849 | V10: -0.1572 | W10: -0.1387 | X10: -0.1153 | Z10: 1Y | AA10: 0.7924 | AB10: 0.7649 | AC10: 0.7392 | AD10: 0.719 | AE10: 0.698 | AF10: 0.6633 | AG10: 0.658 | AH10: 0.6334 | AI10: 0.613 | AJ10: 0.5893 | AL10: 1Y | AM10: =C10*(1+(((2-3*O10^2)/24*AA10^2)+(O10*AA10*C10/4))*1) -> 0.50889791 | AN10: =D10*(1+(((2-3*P10^2)/24*AB10^2)+(P10*AB10*D10/4))*1) -> 0.49937444 | AO10: =E10*(1+(((2-3*Q10^2)/24*AC10^2)+(Q10*AC10*E10/4))*1) -> 0.48181419 | AP10: =F10*(1+(((2-3*R10^2)/24*AD10^2)+(R10*AD10*F10/4))*1) -> 0.46660696 | AQ10: =G10*(1+(((2-3*S10^2)/24*AE10^2)+(S10*AE10*G10/4))*1) -> 0.43832998 | AR10: =H10*(1+(((2-3*T10^2)/24*AF10^2)+(T10*AF10*H10/4))*1) -> 0.42362088 | AS10: =I10*(1+(((2-3*U10^2)/24*AG10^2)+(U10*AG10*I10/4))*1) -> 0.40599751 | AT10: =J10*(1+(((2-3*V10^2)/24*AH10^2)+(V10*AH10*J10/4))*1) -> 0.39978212 | ... AV10: =L10*(1+(((2-3*X10^2)/24*AJ10^2)+(X10*AJ10*L10/4))*1) -> 0.35072987
B11: 2Y | C11: 0.4812 | D11: 0.4646 | E11: 0.4421 | F11: 0.436 | G11: 0.4079 | H11: 0.3913 | I11: 0.3775 | J11: 0.3599 | K11: 0.3468 | L11: 0.3244 | N11: 2Y | O11: -0.2822 | P11: -0.2598 | Q11: -0.2413 | R11: -0.2166 | S11: -0.2039 | T11: -0.1675 | U11: -0.1533 | V11: -0.1431 | W11: -0.1216 | X11: -0.1003 | Z11: 2Y | AA11: 0.7584 | AB11: 0.7313 | AC11: 0.7236 | AD11: 0.7043 | AE11: 0.6715 | AF11: 0.6497 | AG11: 0.6195 | AH11: 0.5976 | AI11: 0.5802 | AJ11: 0.5564 | AL11: 2Y | AM11: =C11*(1+(((2-3*O11^2)/24*AA11^2)+(O11*AA11*C11/4))*2) -> 0.49703978 | AN11: =D11*(1+(((2-3*P11^2)/24*AB11^2)+(P11*AB11*D11/4))*2) -> 0.48131351 | AO11: =E11*(1+(((2-3*Q11^2)/24*AC11^2)+(Q11*AC11*E11/4))*2) -> 0.46024736 | AP11: =F11*(1+(((2-3*R11^2)/24*AD11^2)+(R11*AD11*F11/4))*2) -> 0.45500912 | AQ11: =G11*(1+(((2-3*S11^2)/24*AE11^2)+(S11*AE11*G11/4))*2) -> 0.42525237 | AR11: =H11*(1+(((2-3*T11^2)/24*AF11^2)+(T11*AF11*H11/4))*2) -> 0.4093387 | AS11: =I11*(1+(((2-3*U11^2)/24*AG11^2)+(U11*AG11*I11/4))*2) -> 0.39402813 | AT11: =J11*(1+(((2-3*V11^2)/24*AH11^2)+(V11*AH11*J11/4))*2) -> 0.3751252 | ... AV11: =L11*(1+(((2-3*X11^2)/24*AJ11^2)+(X11*AJ11*L11/4))*2) -> 0.337949
B12: 3Y | C12: 0.4732 | D12: 0.4432 | E12: 0.4238 | F12: 0.4257 | G12: 0.4006 | H12: 0.3763 | I12: 0.3675 | J12: 0.3405 | K12: 0.3339 | L12: 0.3262 | N12: 3Y | O12: -0.2455 | P12: -0.2294 | Q12: -0.2187 | R12: -0.1971 | S12: -0.1817 | T12: -0.1501 | U12: -0.1355 | V12: -0.1111 | W12: -0.1006 | X12: -0.0833 | Z12: 3Y | AA12: 0.7451 | AB12: 0.7264 | AC12: 0.7015 | AD12: 0.6783 | AE12: 0.6564 | AF12: 0.6326 | AG12: 0.6001 | AH12: 0.5837 | AI12: 0.5582 | AJ12: 0.5295 | AL12: 3Y | AM12: =C12*(1+(((2-3*O12^2)/24*AA12^2)+(O12*AA12*C12/4))*3) -> 0.50221984 | AN12: =D12*(1+(((2-3*P12^2)/24*AB12^2)+(P12*AB12*D12/4))*3) -> 0.47250063 | AO12: =E12*(1+(((2-3*Q12^2)/24*AC12^2)+(Q12*AC12*E12/4))*3) -> 0.45153145 | AP12: =F12*(1+(((2-3*R12^2)/24*AD12^2)+(R12*AD12*F12/4))*3) -> 0.45364092 | AQ12: =G12*(1+(((2-3*S12^2)/24*AE12^2)+(S12*AE12*G12/4))*3) -> 0.42725869 | AR12: =H12*(1+(((2-3*T12^2)/24*AF12^2)+(T12*AF12*H12/4))*3) -> 0.40259075 | AS12: =I12*(1+(((2-3*U12^2)/24*AG12^2)+(U12*AG12*I12/4))*3) -> 0.3914384 | AT12: =J12*(1+(((2-3*V12^2)/24*AH12^2)+(V12*AH12*J12/4))*3) -> 0.36332663 | ... AV12: =L12*(1+(((2-3*X12^2)/24*AJ12^2)+(X12*AJ12*L12/4))*3) -> 0.34530624
B13: 5Y | C13: 0.4406 | D13: 0.4289 | E13: 0.4119 | F13: 0.4039 | G13: 0.3925 | H13: 0.3656 | I13: 0.3587 | J13: 0.3431 | K13: 0.3258 | L13: 0.2973 | N13: 5Y | O13: -0.2389 | P13: -0.2194 | Q13: -0.2005 | R13: -0.1809 | S13: -0.1531 | T13: -0.1281 | U13: -0.1099 | V13: -0.0976 | W13: -0.0747 | X13: -0.0523 | Z13: 5Y | AA13: 0.7084 | AB13: 0.6977 | AC13: 0.6804 | AD13: 0.6556 | AE13: 0.6328 | AF13: 0.6051 | AG13: 0.5769 | AH13: 0.5669 | AI13: 0.5355 | AJ13: 0.5227 | AL13: 5Y | AM13: =C13*(1+(((2-3*O13^2)/24*AA13^2)+(O13*AA13*C13/4))*5) -> 0.48377362 | AN13: =D13*(1+(((2-3*P13^2)/24*AB13^2)+(P13*AB13*D13/4))*5) -> 0.47441256 | AO13: =E13*(1+(((2-3*Q13^2)/24*AC13^2)+(Q13*AC13*E13/4))*5) -> 0.45763017 | AP13: =F13*(1+(((2-3*R13^2)/24*AD13^2)+(R13*AD13*F13/4))*5) -> 0.44849862 | AQ13: =G13*(1+(((2-3*S13^2)/24*AE13^2)+(S13*AE13*G13/4))*5) -> 0.43702889 | AR13: =H13*(1+(((2-3*T13^2)/24*AF13^2)+(T13*AF13*H13/4))*5) -> 0.40705248 | AS13: =I13*(1+(((2-3*U13^2)/24*AG13^2)+(U13*AG13*I13/4))*5) -> 0.39734363 | AT13: =J13*(1+(((2-3*V13^2)/24*AH13^2)+(V13*AH13*J13/4))*5) -> 0.38024529 | ... AV13: =L13*(1+(((2-3*X13^2)/24*AJ13^2)+(X13*AJ13*L13/4))*5) -> 0.32798535
B14: 10Y | C14: 0.4428 | D14: 0.4146 | E14: 0.398 | F14: 0.3923 | G14: 0.3712 | H14: 0.3434 | I14: 0.3259 | J14: 0.3097 | K14: 0.3081 | L14: 0.2895 | N14: 10Y | O14: -0.221 | P14: -0.1879 | Q14: -0.1654 | R14: -0.1524 | S14: -0.1391 | T14: -0.1157 | U14: -0.1046 | V14: -0.0875 | W14: -0.0489 | X14: -0.0359 | Z14: 10Y | AA14: 0.695 | AB14: 0.6809 | AC14: 0.6487 | AD14: 0.6352 | AE14: 0.6121 | AF14: 0.5776 | AG14: 0.5561 | AH14: 0.5347 | AI14: 0.5115 | AJ14: 0.4962 | AL14: 10Y | AM14: =C14*(1+(((2-3*O14^2)/24*AA14^2)+(O14*AA14*C14/4))*10) -> 0.53268924 | AN14: =D14*(1+(((2-3*P14^2)/24*AB14^2)+(P14*AB14*D14/4))*10) -> 0.51131867 | AO14: =E14*(1+(((2-3*Q14^2)/24*AC14^2)+(Q14*AC14*E14/4))*10) -> 0.489352 | AP14: =F14*(1+(((2-3*R14^2)/24*AD14^2)+(R14*AD14*F14/4))*10) -> 0.48236331 | AQ14: =G14*(1+(((2-3*S14^2)/24*AE14^2)+(S14*AE14*G14/4))*10) -> 0.45440356 | AR14: =H14*(1+(((2-3*T14^2)/24*AF14^2)+(T14*AF14*H14/4))*10) -> 0.4172528 | AS14: =I14*(1+(((2-3*U14^2)/24*AG14^2)+(U14*AG14*I14/4))*10) -> 0.39306283 | AT14: =J14*(1+(((2-3*V14^2)/24*AH14^2)+(V14*AH14*J14/4))*10) -> 0.37142103 | ... AV14: =L14*(1+(((2-3*X14^2)/24*AJ14^2)+(X14*AJ14*L14/4))*10) -> 0.345052
B15: 20Y | C15: 0.4119 | D15: 0.3984 | E15: 0.376 | F15: 0.3749 | G15: 0.3471 | H15: 0.3325 | I15: 0.3183 | J15: 0.3081 | K15: 0.2817 | L15: 0.275 | N15: 20Y | O15: -0.1944 | P15: -0.1744 | Q15: -0.1551 | R15: -0.1457 | S15: -0.1179 | T15: -0.1036 | U15: -0.0877 | V15: -0.0523 | W15: -0.0454 | X15: -0.02 | Z15: 20Y | AA15: 0.6767 | AB15: 0.6511 | AC15: 0.6243 | AD15: 0.6059 | AE15: 0.5844 | AF15: 0.5668 | AG15: 0.531 | AH15: 0.5179 | AI15: 0.4894 | AJ15: 0.4678 | AL15: 20Y | AM15: =C15*(1+(((2-3*O15^2)/24*AA15^2)+(O15*AA15*C15/4))*20) -> 0.59684836 | AN15: =D15*(1+(((2-3*P15^2)/24*AB15^2)+(P15*AB15*D15/4))*20) -> 0.57693169 | AO15: =E15*(1+(((2-3*Q15^2)/24*AC15^2)+(Q15*AC15*E15/4))*20) -> 0.54298392 | AP15: =F15*(1+(((2-3*R15^2)/24*AD15^2)+(R15*AD15*F15/4))*20) -> 0.53494279 | AQ15: =G15*(1+(((2-3*S15^2)/24*AE15^2)+(S15*AE15*G15/4))*20) -> 0.49904651 | AR15: =H15*(1+(((2-3*T15^2)/24*AF15^2)+(T15*AF15*H15/4))*20) -> 0.47520702 | AS15: =I15*(1+(((2-3*U15^2)/24*AG15^2)+(U15*AG15*I15/4))*20) -> 0.4425641 | AT15: =J15*(1+(((2-3*V15^2)/24*AH15^2)+(V15*AH15*J15/4))*20) -> 0.43241022 | ... AV15: =L15*(1+(((2-3*X15^2)/24*AJ15^2)+(X15*AJ15*L15/4))*20) -> 0.3717023
