Workbook

Sheet ReadMe
B2: FRTB IMA — Full Revaluation PnL Vectors for Expected Shortfall (ES)
B3: Illustrative workbook — trade 123456, valuation date 7/23/2026. Demonstrates the mechanics of a full-revaluation Stressed PnL vector: PnL = StressedNPV − BaseNPV, built curve-by-curve and then combined cross-risk-class.
B5: Purpose
B6: Illustrate, end to end, how a full-reval ES PnL vector is constructed: base curve objects → shocked curve objects (10 scenarios, stress date 20-Nov-2008) → base/stressed NPV via full reval → PnL vector, both cross-risk-class and isolated by risk class (IR / Credit / FX).
B8: Tabs
B9: Trade_Info | Base_Curves | Curve_Shocks_bps | Curve_Shift_Illustration | Shocked_Curves_DF | SABR_Base | SABR_Shocks | SABR_Shocked | NPV_Engine | PnL_Summary
B11: Curve shift mechanic
B12: gxlCurveDiscShift is simulated with a sequential (cascading) bootstrap: the simple forward rate implied by the BASE curve between consecutive tenors is bumped by the scenario shock (bps), and the SHOCKED discount factor for tenor i is solved from the SHOCKED discount factor at tenor i-1 (not the base one). 3M is bumped first; 6M relies on the bumped 3M; and so on to 30Y — exactly mirroring the described gxlCurveDiscShift behaviour.
B14: SABR surface mechanic
B15: Each of ATM / RHO / NU is a 10x10 grid (expiry x tenor). Each scenario applies a parameter-level shock size to every grid point, scaled by a per-cell Sensitivity Factor grid (captures the typical stress-period pattern of larger moves at short expiries/tenors). The result is a full shocked vol surface per parameter per scenario, exactly as gxlCurveDiscShift-style functions return a shocked object for curves.
B17: NPV engine
B18: NPV is an ILLUSTRATIVE simplified full-reval pricer (not a production pricer) that consumes: SOFR/ESTRN discount factors (IR discounting), the SABR ATM grid point matching the trade's expiry/tenor (IR_VOL / optionality), Treasury/Agency_FNMA/Eur_Govt discount factors (Credit spread proxy), and the EURUSD curve (FX discount/forward proxy). Base NPV = pricer with ALL curves at BASE. Stressed NPV = pricer with the relevant curve set SHOCKED for scenario s.
... B27: All curve levels, shock sizes and SABR parameters are illustrative placeholder assumptions chosen for demonstration purposes only — they are not calibrated to actual 20-Nov-2008 market data and this is not a production pricing/risk engine.

Sheet Trade_Info
A1: Trade & Valuation Info
A3: Trade ID | B3: 123456
A4: Valuation Date | B4: 7/23/2026
A5: Stress / Shock anchor date | B5: 11/20/2008
A6: Number of scenarios | B6: 10
A7: Notional (USD) | B7: 10000000
A8: Product | B8: EUR-underlying payer swaption vs USD-collateral discounting
A9: Representative discounting tenor | B9: 1Y
A10: Representative SABR grid point (Expiry x Tenor) | B10: 1Y x 10Y
A12: Curve list, MDO used, and risk-class mapping
A13: Curve (MDO) | B13: Risk Class | C13: Notes
A14: Agency_FNMA | B14: Credit | C14: Credit — GSE/agency spread curve
A15: Eur_Govt | B15: Credit | C15: Credit — EUR sovereign curve
A16: SOFR | B16: IR | C16: IR_RATE — USD OIS/SOFR discounting curve
A17: Treasury | B17: Credit | C17: Credit — US Treasury (sovereign benchmark) curve
A18: Sabr_Swaption | B18: IR | C18: IR_VOL — SABR surface (ATM, RHO, NU); handled on SABR_* tabs
A19: EURUSD | B19: FX | C19: FX_RATE — EUR/USD FX curve
A20: ESTRN | B20: IR | C20: IR — EUR €STR discounting curve

Sheet Base_Curves
A1: Base Curve Objects — Discount Factors (as of 7/23/2026)
A3: Curve | B3: Risk Class | C3: 3M | D3: 6M | E3: 1Y | F3: 2Y | G3: 3Y | H3: 5Y | I3: 10Y | J3: 20Y | K3: 30Y
A4: Tenor Date | C4: 10/23/2026 | D4: 1/23/2027 | E4: 7/23/2027 | F4: 7/23/2028 | G4: 7/23/2029 | H4: 7/23/2031 | I4: 7/23/2036 | J4: 7/23/2046 | K4: 7/23/2056
A5: Year Frac (t) | C5: 0.25 | D5: 0.5 | E5: 1 | F5: 2 | G5: 3 | H5: 5 | I5: 10 | J5: 20 | K5: 30
A6: SOFR | B6: IR | C6: 0.989298 | D6: 0.978693 | E6: 0.957768 | F6: 0.917044 | G6: 0.877788 | H6: 0.803523 | I6: 0.640824 | J6: 0.410656 | K6: 0.263158
A7: ESTRN | B7: IR | C7: 0.992271 | D7: 0.984583 | E7: 0.96933 | F7: 0.939319 | G7: 0.909964 | H7: 0.85321 | I7: 0.722527 | J7: 0.522046 | K7: 0.377192
A8: Treasury | B8: Credit | C8: 0.989546 | D8: 0.979182 | E8: 0.958726 | F8: 0.91888 | G8: 0.880425 | H8: 0.80755 | I8: 0.647265 | J8: 0.418952 | K8: 0.271173
A9: Agency_FNMA | B9: Credit | C9: 0.988557 | D9: 0.977226 | E9: 0.954899 | F9: 0.911558 | G9: 0.869924 | H9: 0.79156 | I9: 0.621885 | J9: 0.386741 | K9: 0.240508
A10: Eur_Govt | B10: Credit | C10: 0.991775 | D10: 0.983598 | E10: 0.967393 | F10: 0.935569 | G10: 0.904521 | H10: 0.84472 | I10: 0.70822 | J10: 0.501576 | K10: 0.355226
A11: EURUSD | B11: FX | C11: 0.990041 | D11: 0.980162 | E11: 0.960645 | F11: 0.922563 | G11: 0.885724 | H11: 0.815666 | I11: 0.66034 | J11: 0.436049 | K11: 0.287941
A13: Note: base DF values are illustrative placeholder inputs (blue), not calibrated to a real curve build.

Sheet Curve_Shocks_bps
A1: Shock Vectors — Forward-Rate Shock (bps) per Tenor, 10 Scenarios, Stress Anchor 20-Nov-2008
A3: Scenario 1 | C3: 3M | D3: 6M | E3: 1Y | F3: 2Y | G3: 3Y | H3: 5Y | I3: 10Y | J3: 20Y | K3: 30Y
A4: SOFR | B4: IR | C4: -40.9 | D4: 34.3 | E4: 31.4 | F4: -21.7 | G4: -13 | H4: 6.1 | I4: 2.9 | J4: 2.1 | K4: 1.2
A5: ESTRN | B5: IR | C5: -35.5 | D5: 31.9 | E5: 24.1 | F5: 18.3 | G5: -8.9 | H5: 5.7 | I5: 2.8 | J5: 1.3 | K5: 0.6
A6: Treasury | B6: Credit | C6: 49.9 | D6: 46.7 | E6: -34.6 | F6: 21.6 | G6: 13 | H6: 7.2 | I6: 4.1 | J6: 1.9 | K6: 1.2
A7: Agency_FNMA | B7: Credit | C7: 75.2 | D7: 60.7 | E7: 51.5 | F7: 44.3 | G7: 26.8 | H7: 15.7 | I7: -6.2 | J7: 3.8 | K7: 2.5
A8: Eur_Govt | B8: Credit | C8: 64.8 | D8: 54.8 | E8: 47.2 | F8: 28 | G8: 18.8 | H8: 10.1 | I8: 5.2 | J8: 3 | K8: -1.8
A9: EURUSD | B9: FX | C9: 23.9 | D9: 26.9 | E9: 18.9 | F9: 16.3 | G9: 11 | H9: 5.2 | I9: 3.4 | J9: 1.9 | K9: 1.2
A11: Scenario 2 | C11: 3M | D11: 6M | E11: 1Y | F11: 2Y | G11: 3Y | H11: 5Y | I11: 10Y | J11: 20Y | K11: 30Y
A12: SOFR | B12: IR | C12: 45.8 | D12: 45.7 | E12: 34.7 | F12: 25.1 | G12: 14.8 | H12: 7.9 | I12: 4.1 | J12: 2.4 | K12: 1.4
A13: ESTRN | B13: IR | C13: 34.7 | D13: 37.4 | E13: -28.1 | F13: 20.8 | G13: 10.6 | H13: 5.6 | I13: -3.3 | J13: 1.5 | K13: 0.7
A14: Treasury | B14: Credit | C14: 53 | D14: 50.5 | E14: 36.1 | F14: 29.7 | G14: 16.7 | H14: 8.5 | I14: 4.5 | J14: 2.2 | K14: 1.4
A15: Agency_FNMA | B15: Credit | C15: 79.9 | D15: -82.8 | E15: 61.9 | F15: -43.5 | G15: 33.6 | H15: 16.8 | I15: 8.2 | J15: 4.2 | K15: 3
A16: Eur_Govt | B16: Credit | C16: 72.6 | D16: -67.8 | E16: 49 | F16: 37.3 | G16: 20.2 | H16: 11.4 | I16: 5.8 | J16: 3 | K16: -2.3
A17: EURUSD | B17: FX | C17: 34 | D17: 32.1 | E17: 26.4 | F17: 16.9 | G17: -11.3 | H17: 6.8 | I17: 3.7 | J17: 2.3 | K17: 1.7
A19: Scenario 3 | C19: 3M | D19: 6M | E19: 1Y | F19: 2Y | G19: 3Y | H19: 5Y | I19: 10Y | J19: 20Y | K19: 30Y
A20: SOFR | B20: IR | C20: 53.3 | D20: 45.4 | E20: 43 | F20: 26.6 | G20: 16.2 | H20: 8.8 | I20: 4.1 | J20: 2.4 | K20: 1.8
A21: ESTRN | B21: IR | C21: -41.9 | D21: 42.4 | E21: 34 | F21: 21.7 | G21: 13.3 | H21: 6.7 | I21: 3.4 | J21: 1.8 | K21: 0.9
A22: Treasury | B22: Credit | C22: 56.8 | D22: 62.4 | E22: 40.6 | F22: 29.5 | G22: 20.7 | H22: 10.3 | I22: 5.6 | J22: 2.7 | K22: -1.8
A23: Agency_FNMA | B23: Credit | C23: 102.4 | D23: 90.6 | E23: -69.8 | F23: 49 | G23: 33.7 | H23: 20.1 | I23: 9 | J23: 5.3 | K23: -3.7
A24: Eur_Govt | B24: Credit | C24: 78.1 | D24: 64 | E24: 58.6 | F24: 41.3 | G24: -24.3 | H24: 12.2 | I24: 7.6 | J24: 3.7 | K24: -2.5
A25: EURUSD | B25: FX | C25: 34 | D25: 35.2 | E25: 30.2 | F25: -18.5 | G25: 13.9 | H25: 7.8 | I25: 4.1 | J25: 2.8 | K25: 1.9
A27: Scenario 4 | C27: 3M | D27: 6M | E27: 1Y | F27: 2Y | G27: 3Y | H27: 5Y | I27: 10Y | J27: 20Y | K27: 30Y
A28: SOFR | B28: IR | C28: 54.8 | D28: 53 | E28: 46.7 | F28: 31.2 | G28: -20.7 | H28: 10.5 | I28: 4.7 | J28: 3 | K28: 2.1
A29: ESTRN | B29: IR | C29: 45.7 | D29: 43.3 | E29: 40.5 | F29: 25.3 | G29: 16 | H29: -8.5 | I29: 4.3 | J29: 2.1 | K29: 0.9
A30: Treasury | B30: Credit | C30: 71.9 | D30: 65.5 | E30: 48.6 | F30: 33.3 | G30: 20 | H30: 12 | I30: 6.2 | J30: -2.9 | K30: 2
A31: Agency_FNMA | B31: Credit | C31: 105.6 | D31: 102.5 | E31: 81.6 | F31: 58.5 | G31: 37.2 | H31: 23.3 | I31: 10.5 | J31: 5.7 | K31: 3.6
A32: Eur_Govt | B32: Credit | C32: 88.1 | D32: 81.2 | E32: 63.7 | F32: 44.4 | G32: 29 | H32: 13.9 | I32: 8.1 | J32: 4.2 | K32: 3.1
A33: EURUSD | B33: FX | C33: -37.7 | D33: 36.1 | E33: -33.5 | F33: 21.5 | G33: 14.1 | H33: 8.9 | I33: -5.1 | J33: 3.1 | K33: 1.9
A35: Scenario 5 | C35: 3M | D35: 6M | E35: 1Y | F35: 2Y | G35: 3Y | H35: 5Y | I35: 10Y | J35: 20Y | K35: 30Y
A36: SOFR | B36: IR | C36: 62.9 | D36: -60.7 | E36: 47.7 | F36: 32.8 | G36: 22.5 | H36: 11.2 | I36: 5.8 | J36: 3.4 | K36: 2.3
A37: ESTRN | B37: IR | C37: 58.2 | D37: 49.3 | E37: 40.3 | F37: 28.6 | G37: 16.8 | H37: 8.3 | I37: 4.3 | J37: -2.2 | K37: 1.1
A38: Treasury | B38: Credit | C38: -79.3 | D38: 70.5 | E38: 54.3 | F38: 38.1 | G38: 24.5 | H38: 13.9 | I38: -6.5 | J38: 3.2 | K38: 2.3
A39: Agency_FNMA | B39: Credit | C39: 119.6 | D39: 110.7 | E39: 89.7 | F39: -65.4 | G39: 43 | H39: 23.9 | I39: -10.9 | J39: -6.7 | K39: 4.3
A40: Eur_Govt | B40: Credit | C40: 92.2 | D40: 83.3 | E40: 66.8 | F40: 47.4 | G40: 32 | H40: 17.1 | I40: -8.5 | J40: 4.1 | K40: 3.5
A41: EURUSD | B41: FX | C41: 45 | D41: 42.7 | E41: 37.5 | F41: 22.5 | G41: 15.6 | H41: 10 | I41: 5.7 | J41: 3.1 | K41: -2.3
A43: Scenario 6 | C43: 3M | D43: 6M | E43: 1Y | F43: 2Y | G43: 3Y | H43: 5Y | I43: 10Y | J43: 20Y | K43: 30Y
A44: SOFR | B44: IR | C44: 75.7 | D44: -63.1 | E44: 53.1 | F44: 38.5 | G44: -24.9 | H44: 12.4 | I44: 5.7 | J44: 3.8 | K44: 2.3
A45: ESTRN | B45: IR | C45: 62.8 | D45: 53.9 | E45: 46 | F45: 31.6 | G45: 17.2 | H45: 9.9 | I45: 5 | J45: 2.5 | K45: 1.2
A46: Treasury | B46: Credit | C46: 85.1 | D46: 78 | E46: 58.6 | F46: -44.2 | G46: 28 | H46: 14.5 | I46: -7.1 | J46: 3.8 | K46: 2.3
...

Sheet Curve_Shift_Illustration
A1: gxlCurveDiscShift — Step-by-Step Illustration (Curve = SOFR, Scenario 1)
A2: Sequential / cascading bootstrap: forward rate is derived from BASE discount factors between consecutive tenors, bumped by the scenario shock (bps), then the SHOCKED discount factor is solved off the PRIOR SHOCKED discount factor (not the prior base one). 3M is shocked first and feeds into 6M, which feeds into 1Y, etc.
A4: Tenor | B4: t | C4: Base DF (prior) | D4: Base DF (current) | E4: Base Fwd Rate (simple, ann.) | F4: Shock (bps) | G4: Shocked Fwd Rate | H4: Shocked DF (current) | I4: Formula logic
A5: 3M | B5: 0.25 | C5: 1 | D5: =Base_Curves!C6 -> 0.989298 | E5: =(C5/D5-1)/(0.25-0) -> 0.043271087 | F5: =Curve_Shocks_bps!C4 -> -40.9 | G5: =E5+F5/10000 -> 0.039181087 | H5: =1/(1+G5*(0.25-0)) -> 0.99029974 | I5: Anchors at DF=1, t=0
A6: 6M | B6: 0.5 | C6: =Base_Curves!C6 -> 0.989298 | D6: =Base_Curves!D6 -> 0.978693 | E6: =(C6/D6-1)/(0.5-0.25) -> 0.04334352 | F6: =Curve_Shocks_bps!D4 -> 34.3 | G6: =E6+F6/10000 -> 0.04677352 | H6: =H5/(1+G6*(0.5-0.25)) -> 0.97885364 | I6: Uses SHOCKED DF from 3M (row above), not base
A7: 1Y | B7: 1 | C7: =Base_Curves!D6 -> 0.978693 | D7: =Base_Curves!E6 -> 0.957768 | E7: =(C7/D7-1)/(1-0.5) -> 0.043695342 | F7: =Curve_Shocks_bps!E4 -> 31.4 | G7: =E7+F7/10000 -> 0.046835342 | H7: =H6/(1+G7*(1-0.5)) -> 0.95645567 | I7: Uses SHOCKED DF from 6M (row above), not base
A8: 2Y | B8: 2 | C8: =Base_Curves!E6 -> 0.957768 | D8: =Base_Curves!F6 -> 0.917044 | E8: =(C8/D8-1)/(2-1) -> 0.044407902 | F8: =Curve_Shocks_bps!F4 -> -21.7 | G8: =E8+F8/10000 -> 0.042237902 | H8: =H7/(1+G8*(2-1)) -> 0.9176942 | I8: Uses SHOCKED DF from 1Y (row above), not base
A9: 3Y | B9: 3 | C9: =Base_Curves!F6 -> 0.917044 | D9: =Base_Curves!G6 -> 0.877788 | E9: =(C9/D9-1)/(3-2) -> 0.044721505 | F9: =Curve_Shocks_bps!G4 -> -13 | G9: =E9+F9/10000 -> 0.043421505 | H9: =H8/(1+G9*(3-2)) -> 0.87950478 | I9: Uses SHOCKED DF from 2Y (row above), not base
A10: 5Y | B10: 5 | C10: =Base_Curves!G6 -> 0.877788 | D10: =Base_Curves!H6 -> 0.803523 | E10: =(C10/D10-1)/(5-3) -> 0.046212118 | F10: =Curve_Shocks_bps!H4 -> 6.1 | G10: =E10+F10/10000 -> 0.046822118 | H10: =H9/(1+G10*(5-3)) -> 0.80419642 | I10: Uses SHOCKED DF from 3Y (row above), not base
A11: 10Y | B11: 10 | C11: =Base_Curves!H6 -> 0.803523 | D11: =Base_Curves!I6 -> 0.640824 | E11: =(C11/D11-1)/(10-5) -> 0.050778061 | F11: =Curve_Shocks_bps!I4 -> 2.9 | G11: =E11+F11/10000 -> 0.051068061 | H11: =H10/(1+G11*(10-5)) -> 0.64062025 | I11: Uses SHOCKED DF from 5Y (row above), not base
A12: 20Y | B12: 20 | C12: =Base_Curves!I6 -> 0.640824 | D12: =Base_Curves!J6 -> 0.410656 | E12: =(C12/D12-1)/(20-10) -> 0.056048858 | F12: =Curve_Shocks_bps!J4 -> 2.1 | G12: =E12+F12/10000 -> 0.056258858 | H12: =H11/(1+G12*(20-10)) -> 0.40997372 | I12: Uses SHOCKED DF from 10Y (row above), not base
A13: 30Y | B13: 30 | C13: =Base_Curves!J6 -> 0.410656 | D13: =Base_Curves!K6 -> 0.263158 | E13: =(C13/D13-1)/(30-20) -> 0.056049218 | F13: =Curve_Shocks_bps!K4 -> 1.2 | G13: =E13+F13/10000 -> 0.056169218 | H13: =H12/(1+G13*(30-20)) -> 0.2625189 | I13: Uses SHOCKED DF from 20Y (row above), not base
A15: This exact column-H formula pattern is replicated for all 6 curves x 10 scenarios on the Shocked_Curves_DF tab.

Sheet Shocked_Curves_DF
A1: Shocked Curve Objects — Discount Factors (gxlCurveDiscShift output), All Curves x 10 Scenarios
A2: Same cascading-bootstrap formula as Curve_Shift_Illustration: base forward rate (from Base_Curves) + scenario shock (bps, from Curve_Shocks_bps) = shocked forward rate; shocked DF at tenor i is solved off the SHOCKED DF at tenor i-1.
A4: Scenario 1 | C4: 3M | D4: 6M | E4: 1Y | F4: 2Y | G4: 3Y | H4: 5Y | I4: 10Y | J4: 20Y | K4: 30Y
A5: SOFR | B5: IR | C5: =1/(1+(((1/Base_Curves!C6-1)/(0.25-0))+Curve_Shocks_bps!C4/10000)*(0.25-0)) -> 0.99029974 | D5: =C5/(1+(((Base_Curves!C6/Base_Curves!D6-1)/(0.5-0.25))+Curve_Shocks_bps!D4/10000)*(0.5-0.25)) -> 0.97885364 | E5: =D5/(1+(((Base_Curves!D6/Base_Curves!E6-1)/(1-0.5))+Curve_Shocks_bps!E4/10000)*(1-0.5)) -> 0.95645567 | F5: =E5/(1+(((Base_Curves!E6/Base_Curves!F6-1)/(2-1))+Curve_Shocks_bps!F4/10000)*(2-1)) -> 0.9176942 | G5: =F5/(1+(((Base_Curves!F6/Base_Curves!G6-1)/(3-2))+Curve_Shocks_bps!G4/10000)*(3-2)) -> 0.87950478 | H5: =G5/(1+(((Base_Curves!G6/Base_Curves!H6-1)/(5-3))+Curve_Shocks_bps!H4/10000)*(5-3)) -> 0.80419642 | I5: =H5/(1+(((Base_Curves!H6/Base_Curves!I6-1)/(10-5))+Curve_Shocks_bps!I4/10000)*(10-5)) -> 0.64062025 | J5: =I5/(1+(((Base_Curves!I6/Base_Curves!J6-1)/(20-10))+Curve_Shocks_bps!J4/10000)*(20-10)) -> 0.40997372 | K5: =J5/(1+(((Base_Curves!J6/Base_Curves!K6-1)/(30-20))+Curve_Shocks_bps!K4/10000)*(30-20)) -> 0.2625189
A6: ESTRN | B6: IR | C6: =1/(1+(((1/Base_Curves!C7-1)/(0.25-0))+Curve_Shocks_bps!C5/10000)*(0.25-0)) -> 0.9931456 | D6: =C6/(1+(((Base_Curves!C7/Base_Curves!D7-1)/(0.5-0.25))+Curve_Shocks_bps!D5/10000)*(0.5-0.25)) -> 0.98467164 | E6: =D6/(1+(((Base_Curves!D7/Base_Curves!E7-1)/(1-0.5))+Curve_Shocks_bps!E5/10000)*(1-0.5)) -> 0.96826858 | F6: =E6/(1+(((Base_Curves!E7/Base_Curves!F7-1)/(2-1))+Curve_Shocks_bps!F5/10000)*(2-1)) -> 0.93662947 | G6: =F6/(1+(((Base_Curves!F7/Base_Curves!G7-1)/(3-2))+Curve_Shocks_bps!G5/10000)*(3-2)) -> 0.90814151 | H6: =G6/(1+(((Base_Curves!G7/Base_Curves!H7-1)/(5-3))+Curve_Shocks_bps!H5/10000)*(5-3)) -> 0.85059198 | I6: =H6/(1+(((Base_Curves!H7/Base_Curves!I7-1)/(10-5))+Curve_Shocks_bps!I5/10000)*(10-5)) -> 0.71945701 | J6: =I6/(1+(((Base_Curves!I7/Base_Curves!J7-1)/(20-10))+Curve_Shocks_bps!J5/10000)*(20-10)) -> 0.51934004 | K6: =J6/(1+(((Base_Curves!J7/Base_Curves!K7-1)/(30-20))+Curve_Shocks_bps!K5/10000)*(30-20)) -> 0.37507427
A7: Treasury | B7: Credit | C7: =1/(1+(((1/Base_Curves!C8-1)/(0.25-0))+Curve_Shocks_bps!C6/10000)*(0.25-0)) -> 0.98832595 | D7: =C7/(1+(((Base_Curves!C8/Base_Curves!D8-1)/(0.5-0.25))+Curve_Shocks_bps!D6/10000)*(0.5-0.25)) -> 0.97684621 | E7: =D7/(1+(((Base_Curves!D8/Base_Curves!E8-1)/(1-0.5))+Curve_Shocks_bps!E6/10000)*(1-0.5)) -> 0.95806183 | F7: =E7/(1+(((Base_Curves!E8/Base_Curves!F8-1)/(2-1))+Curve_Shocks_bps!F6/10000)*(2-1)) -> 0.91634638 | G7: =F7/(1+(((Base_Curves!F8/Base_Curves!G8-1)/(3-2))+Curve_Shocks_bps!G6/10000)*(3-2)) -> 0.87690515 | H7: =G7/(1+(((Base_Curves!G8/Base_Curves!H8-1)/(5-3))+Curve_Shocks_bps!H6/10000)*(5-3)) -> 0.80326054 | I7: =H7/(1+(((Base_Curves!H8/Base_Curves!I8-1)/(10-5))+Curve_Shocks_bps!I6/10000)*(10-5)) -> 0.64277078 | J7: =I7/(1+(((Base_Curves!I8/Base_Curves!J8-1)/(20-10))+Curve_Shocks_bps!J6/10000)*(20-10)) -> 0.41553203 | K7: =J7/(1+(((Base_Curves!J8/Base_Curves!K8-1)/(30-20))+Curve_Shocks_bps!K6/10000)*(30-20)) -> 0.26875063
A8: Agency_FNMA | B8: Credit | C8: =1/(1+(((1/Base_Curves!C9-1)/(0.25-0))+Curve_Shocks_bps!C7/10000)*(0.25-0)) -> 0.98672319 | D8: =C8/(1+(((Base_Curves!C9/Base_Curves!D9-1)/(0.5-0.25))+Curve_Shocks_bps!D7/10000)*(0.5-0.25)) -> 0.97395218 | E8: =D8/(1+(((Base_Curves!D9/Base_Curves!E9-1)/(1-0.5))+Curve_Shocks_bps!E7/10000)*(1-0.5)) -> 0.94931135 | F8: =E8/(1+(((Base_Curves!E9/Base_Curves!F9-1)/(2-1))+Curve_Shocks_bps!F7/10000)*(2-1)) -> 0.90240774 | G8: =F8/(1+(((Base_Curves!F9/Base_Curves!G9-1)/(3-2))+Curve_Shocks_bps!G7/10000)*(3-2)) -> 0.8589947 | H8: =G8/(1+(((Base_Curves!G9/Base_Curves!H9-1)/(5-3))+Curve_Shocks_bps!H7/10000)*(5-3)) -> 0.7793884 | I8: =H8/(1+(((Base_Curves!H9/Base_Curves!I9-1)/(10-5))+Curve_Shocks_bps!I7/10000)*(10-5)) -> 0.6138174 | J8: =I8/(1+(((Base_Curves!I9/Base_Curves!J9-1)/(20-10))+Curve_Shocks_bps!J7/10000)*(20-10)) -> 0.38082393 | K8: =J8/(1+(((Base_Curves!J9/Base_Curves!K9-1)/(30-20))+Curve_Shocks_bps!K7/10000)*(30-20)) -> 0.23646064
A9: Eur_Govt | B9: Credit | C9: =1/(1+(((1/Base_Curves!C10-1)/(0.25-0))+Curve_Shocks_bps!C8/10000)*(0.25-0)) -> 0.9901841 | D9: =C9/(1+(((Base_Curves!C10/Base_Curves!D10-1)/(0.5-0.25))+Curve_Shocks_bps!D8/10000)*(0.5-0.25)) -> 0.98068775 | E9: =D9/(1+(((Base_Curves!D10/Base_Curves!E10-1)/(1-0.5))+Curve_Shocks_bps!E8/10000)*(1-0.5)) -> 0.96229709 | F9: =E9/(1+(((Base_Curves!E10/Base_Curves!F10-1)/(2-1))+Curve_Shocks_bps!F8/10000)*(2-1)) -> 0.92812746 | G9: =F9/(1+(((Base_Curves!F10/Base_Curves!G10-1)/(3-2))+Curve_Shocks_bps!G8/10000)*(3-2)) -> 0.89569839 | H9: =G9/(1+(((Base_Curves!G10/Base_Curves!H10-1)/(5-3))+Curve_Shocks_bps!H8/10000)*(5-3)) -> 0.83490567 | I9: =H9/(1+(((Base_Curves!H10/Base_Curves!I10-1)/(10-5))+Curve_Shocks_bps!I8/10000)*(10-5)) -> 0.69846902 | J9: =I9/(1+(((Base_Curves!I10/Base_Curves!J10-1)/(20-10))+Curve_Shocks_bps!J8/10000)*(20-10)) -> 0.49362138 | K9: =J9/(1+(((Base_Curves!J10/Base_Curves!K10-1)/(30-20))+Curve_Shocks_bps!K8/10000)*(30-20)) -> 0.35003861
A10: EURUSD | B10: FX | C10: =1/(1+(((1/Base_Curves!C11-1)/(0.25-0))+Curve_Shocks_bps!C9/10000)*(0.25-0)) -> 0.98945569 | D10: =C10/(1+(((Base_Curves!C11/Base_Curves!D11-1)/(0.5-0.25))+Curve_Shocks_bps!D9/10000)*(0.5-0.25)) -> 0.97893077 | E10: =D10/(1+(((Base_Curves!D11/Base_Curves!E11-1)/(1-0.5))+Curve_Shocks_bps!E9/10000)*(1-0.5)) -> 0.95855049 | F10: =E10/(1+(((Base_Curves!E11/Base_Curves!F11-1)/(2-1))+Curve_Shocks_bps!F9/10000)*(2-1)) -> 0.91911276 | G10: =F10/(1+(((Base_Curves!F11/Base_Curves!G11-1)/(3-2))+Curve_Shocks_bps!G9/10000)*(3-2)) -> 0.88148062 | H10: =G10/(1+(((Base_Curves!G11/Base_Curves!H11-1)/(5-3))+Curve_Shocks_bps!H9/10000)*(5-3)) -> 0.81098155 | I10: =H10/(1+(((Base_Curves!H11/Base_Curves!I11-1)/(10-5))+Curve_Shocks_bps!I9/10000)*(10-5)) -> 0.65564525 | J10: =I10/(1+(((Base_Curves!I11/Base_Curves!J11-1)/(20-10))+Curve_Shocks_bps!J9/10000)*(20-10)) -> 0.43240635 | K10: =J10/(1+(((Base_Curves!J11/Base_Curves!K11-1)/(30-20))+Curve_Shocks_bps!K9/10000)*(30-20)) -> 0.28530953
A12: Scenario 2 | C12: 3M | D12: 6M | E12: 1Y | F12: 2Y | G12: 3Y | H12: 5Y | I12: 10Y | J12: 20Y | K12: 30Y
A13: SOFR | B13: IR | C13: =1/(1+(((1/Base_Curves!C6-1)/(0.25-0))+Curve_Shocks_bps!C12/10000)*(0.25-0)) -> 0.98817864 | D13: =C13/(1+(((Base_Curves!C6/Base_Curves!D6-1)/(0.5-0.25))+Curve_Shocks_bps!D12/10000)*(0.5-0.25)) -> 0.97648197 | E13: =D13/(1+(((Base_Curves!D6/Base_Curves!E6-1)/(1-0.5))+Curve_Shocks_bps!E12/10000)*(1-0.5)) -> 0.95398447 | F13: =E13/(1+(((Base_Curves!E6/Base_Curves!F6-1)/(2-1))+Curve_Shocks_bps!F12/10000)*(2-1)) -> 0.9112314 | G13: =F13/(1+(((Base_Curves!F6/Base_Curves!G6-1)/(3-2))+Curve_Shocks_bps!G12/10000)*(3-2)) -> 0.87099034 | H13: =G13/(1+(((Base_Curves!G6/Base_Curves!H6-1)/(5-3))+Curve_Shocks_bps!H12/10000)*(5-3)) -> 0.79614896 | I13: =H13/(1+(((Base_Curves!H6/Base_Curves!I6-1)/(10-5))+Curve_Shocks_bps!I12/10000)*(10-5)) -> 0.63390669 | J13: =I13/(1+(((Base_Curves!I6/Base_Curves!J6-1)/(20-10))+Curve_Shocks_bps!J12/10000)*(20-10)) -> 0.40559941 | K13: =J13/(1+(((Base_Curves!J6/Base_Curves!K6-1)/(30-20))+Curve_Shocks_bps!K12/10000)*(30-20)) -> 0.25968464
A14: ESTRN | B14: IR | C14: =1/(1+(((1/Base_Curves!C7-1)/(0.25-0))+Curve_Shocks_bps!C13/10000)*(0.25-0)) -> 0.99141759 | D14: =C14/(1+(((Base_Curves!C7/Base_Curves!D7-1)/(0.5-0.25))+Curve_Shocks_bps!D13/10000)*(0.5-0.25)) -> 0.98282438 | E14: =D14/(1+(((Base_Curves!D7/Base_Curves!E7-1)/(1-0.5))+Curve_Shocks_bps!E13/10000)*(1-0.5)) -> 0.9689389 | F14: =E14/(1+(((Base_Curves!E7/Base_Curves!F7-1)/(2-1))+Curve_Shocks_bps!F13/10000)*(2-1)) -> 0.93705128 | G14: =F14/(1+(((Base_Curves!F7/Base_Curves!G7-1)/(3-2))+Curve_Shocks_bps!G13/10000)*(3-2)) -> 0.90683595 | H14: =G14/(1+(((Base_Curves!G7/Base_Curves!H7-1)/(5-3))+Curve_Shocks_bps!H13/10000)*(5-3)) -> 0.84938506 | I14: =H14/(1+(((Base_Curves!H7/Base_Curves!I7-1)/(10-5))+Curve_Shocks_bps!I13/10000)*(10-5)) -> 0.72029436 | J14: =I14/(1+(((Base_Curves!I7/Base_Curves!J7-1)/(20-10))+Curve_Shocks_bps!J13/10000)*(20-10)) -> 0.51986943 | K14: =J14/(1+(((Base_Curves!J7/Base_Curves!K7-1)/(30-20))+Curve_Shocks_bps!K13/10000)*(30-20)) -> 0.37542949
A15: Treasury | B15: Credit | C15: =1/(1+(((1/Base_Curves!C8-1)/(0.25-0))+Curve_Shocks_bps!C14/10000)*(0.25-0)) -> 0.98825026 | D15: =C15/(1+(((Base_Curves!C8/Base_Curves!D8-1)/(0.5-0.25))+Curve_Shocks_bps!D14/10000)*(0.5-0.25)) -> 0.97667968 | E15: =D15/(1+(((Base_Curves!D8/Base_Curves!E8-1)/(1-0.5))+Curve_Shocks_bps!E14/10000)*(1-0.5)) -> 0.95458892 | F15: =E15/(1+(((Base_Curves!E8/Base_Curves!F8-1)/(2-1))+Curve_Shocks_bps!F14/10000)*(2-1)) -> 0.9123179 | G15: =F15/(1+(((Base_Curves!F8/Base_Curves!G8-1)/(3-2))+Curve_Shocks_bps!G14/10000)*(3-2)) -> 0.87274104 | H15: =G15/(1+(((Base_Curves!G8/Base_Curves!H8-1)/(5-3))+Curve_Shocks_bps!H14/10000)*(5-3)) -> 0.79925579 | I15: =H15/(1+(((Base_Curves!H8/Base_Curves!I8-1)/(10-5))+Curve_Shocks_bps!I14/10000)*(10-5)) -> 0.63946383 | J15: =I15/(1+(((Base_Curves!I8/Base_Curves!J8-1)/(20-10))+Curve_Shocks_bps!J14/10000)*(20-10)) -> 0.41331402 | K15: =J15/(1+(((Base_Curves!J8/Base_Curves!K8-1)/(30-20))+Curve_Shocks_bps!K14/10000)*(30-20)) -> 0.26728153
A16: Agency_FNMA | B16: Credit | C16: =1/(1+(((1/Base_Curves!C9-1)/(0.25-0))+Curve_Shocks_bps!C15/10000)*(0.25-0)) -> 0.9866088 | D16: =C16/(1+(((Base_Curves!C9/Base_Curves!D9-1)/(0.5-0.25))+Curve_Shocks_bps!D15/10000)*(0.5-0.25)) -> 0.97729995 | E16: =D16/(1+(((Base_Curves!D9/Base_Curves!E9-1)/(1-0.5))+Curve_Shocks_bps!E15/10000)*(1-0.5)) -> 0.95209186 | F16: =E16/(1+(((Base_Curves!E9/Base_Curves!F9-1)/(2-1))+Curve_Shocks_bps!F15/10000)*(2-1)) -> 0.91266819 | G16: =F16/(1+(((Base_Curves!F9/Base_Curves!G9-1)/(3-2))+Curve_Shocks_bps!G15/10000)*(3-2)) -> 0.86819957 | H16: =G16/(1+(((Base_Curves!G9/Base_Curves!H9-1)/(5-3))+Curve_Shocks_bps!H15/10000)*(5-3)) -> 0.78758301 | I16: =H16/(1+(((Base_Curves!H9/Base_Curves!I9-1)/(10-5))+Curve_Shocks_bps!I15/10000)*(10-5)) -> 0.61677378 | J16: =I16/(1+(((Base_Curves!I9/Base_Curves!J9-1)/(20-10))+Curve_Shocks_bps!J15/10000)*(20-10)) -> 0.38256318 | K16: =J16/(1+(((Base_Curves!J9/Base_Curves!K9-1)/(30-20))+Curve_Shocks_bps!K15/10000)*(30-20)) -> 0.23746685
A17: Eur_Govt | B17: Credit | C17: =1/(1+(((1/Base_Curves!C10-1)/(0.25-0))+Curve_Shocks_bps!C16/10000)*(0.25-0)) -> 0.98999294 | D17: =C17/(1+(((Base_Curves!C10/Base_Curves!D10-1)/(0.5-0.25))+Curve_Shocks_bps!D16/10000)*(0.5-0.25)) -> 0.9834839 | E17: =D17/(1+(((Base_Curves!D10/Base_Curves!E10-1)/(1-0.5))+Curve_Shocks_bps!E16/10000)*(1-0.5)) -> 0.96495558 | F17: =E17/(1+(((Base_Curves!E10/Base_Curves!F10-1)/(2-1))+Curve_Shocks_bps!F16/10000)*(2-1)) -> 0.9298575 | G17: =F17/(1+(((Base_Curves!F10/Base_Curves!G10-1)/(3-2))+Curve_Shocks_bps!G16/10000)*(3-2)) -> 0.89724675 | H17: =G17/(1+(((Base_Curves!G10/Base_Curves!H10-1)/(5-3))+Curve_Shocks_bps!H16/10000)*(5-3)) -> 0.8361463 | I17: =H17/(1+(((Base_Curves!H10/Base_Curves!I10-1)/(10-5))+Curve_Shocks_bps!I16/10000)*(10-5)) -> 0.6993314 | J17: =I17/(1+(((Base_Curves!I10/Base_Curves!J10-1)/(20-10))+Curve_Shocks_bps!J16/10000)*(20-10)) -> 0.49423084 | K17: =J17/(1+(((Base_Curves!J10/Base_Curves!K10-1)/(30-20))+Curve_Shocks_bps!K16/10000)*(30-20)) -> 0.3505951
A18: EURUSD | B18: FX | C18: =1/(1+(((1/Base_Curves!C11-1)/(0.25-0))+Curve_Shocks_bps!C17/10000)*(0.25-0)) -> 0.98920855 | D18: =C18/(1+(((Base_Curves!C11/Base_Curves!D11-1)/(0.5-0.25))+Curve_Shocks_bps!D17/10000)*(0.5-0.25)) -> 0.97856039 | E18: =D18/(1+(((Base_Curves!D11/Base_Curves!E11-1)/(1-0.5))+Curve_Shocks_bps!E17/10000)*(1-0.5)) -> 0.95783612 | F18: =E18/(1+(((Base_Curves!E11/Base_Curves!F11-1)/(2-1))+Curve_Shocks_bps!F17/10000)*(2-1)) -> 0.91837494 | G18: =F18/(1+(((Base_Curves!F11/Base_Curves!G11-1)/(3-2))+Curve_Shocks_bps!G17/10000)*(3-2)) -> 0.88266075 | H18: =G18/(1+(((Base_Curves!G11/Base_Curves!H11-1)/(5-3))+Curve_Shocks_bps!H17/10000)*(5-3)) -> 0.81182829 | I18: =H18/(1+(((Base_Curves!H11/Base_Curves!I11-1)/(10-5))+Curve_Shocks_bps!I17/10000)*(10-5)) -> 0.65625023 | J18: =I18/(1+(((Base_Curves!I11/Base_Curves!J11-1)/(20-10))+Curve_Shocks_bps!J17/10000)*(20-10)) -> 0.4326912 | K18: =J18/(1+(((Base_Curves!J11/Base_Curves!K11-1)/(30-20))+Curve_Shocks_bps!K17/10000)*(30-20)) -> 0.28540332
A20: Scenario 3 | C20: 3M | D20: 6M | E20: 1Y | F20: 2Y | G20: 3Y | H20: 5Y | I20: 10Y | J20: 20Y | K20: 30Y
A21: SOFR | B21: IR | C21: =1/(1+(((1/Base_Curves!C6-1)/(0.25-0))+Curve_Shocks_bps!C20/10000)*(0.25-0)) -> 0.98799559 | D21: =C21/(1+(((Base_Curves!C6/Base_Curves!D6-1)/(0.5-0.25))+Curve_Shocks_bps!D20/10000)*(0.5-0.25)) -> 0.97630832 | E21: =D21/(1+(((Base_Curves!D6/Base_Curves!E6-1)/(1-0.5))+Curve_Shocks_bps!E20/10000)*(1-0.5)) -> 0.95342826 | F21: =E21/(1+(((Base_Curves!E6/Base_Curves!F6-1)/(2-1))+Curve_Shocks_bps!F20/10000)*(2-1)) -> 0.91056965 | G21: =F21/(1+(((Base_Curves!F6/Base_Curves!G6-1)/(3-2))+Curve_Shocks_bps!G20/10000)*(3-2)) -> 0.87024136 | H21: =G21/(1+(((Base_Curves!G6/Base_Curves!H6-1)/(5-3))+Curve_Shocks_bps!H20/10000)*(5-3)) -> 0.79533348 | I21: =H21/(1+(((Base_Curves!H6/Base_Curves!I6-1)/(10-5))+Curve_Shocks_bps!I20/10000)*(10-5)) -> 0.63325739 | J21: =I21/(1+(((Base_Curves!I6/Base_Curves!J6-1)/(20-10))+Curve_Shocks_bps!J20/10000)*(20-10)) -> 0.40518397 | K21: =J21/(1+(((Base_Curves!J6/Base_Curves!K6-1)/(30-20))+Curve_Shocks_bps!K20/10000)*(30-20)) -> 0.25935223
A22: ESTRN | B22: IR | C22: =1/(1+(((1/Base_Curves!C7-1)/(0.25-0))+Curve_Shocks_bps!C21/10000)*(0.25-0)) -> 0.99330344 | D22: =C22/(1+(((Base_Curves!C7/Base_Curves!D7-1)/(0.5-0.25))+Curve_Shocks_bps!D21/10000)*(0.5-0.25)) -> 0.98457188 | E22: =D22/(1+(((Base_Curves!D7/Base_Curves!E7-1)/(1-0.5))+Curve_Shocks_bps!E21/10000)*(1-0.5)) -> 0.96769945 | F22: =E22/(1+(((Base_Curves!E7/Base_Curves!F7-1)/(2-1))+Curve_Shocks_bps!F21/10000)*(2-1)) -> 0.93577118 | G22: =F22/(1+(((Base_Curves!F7/Base_Curves!G7-1)/(3-2))+Curve_Shocks_bps!G21/10000)*(3-2)) -> 0.90536056 | H22: =G22/(1+(((Base_Curves!G7/Base_Curves!H7-1)/(5-3))+Curve_Shocks_bps!H21/10000)*(5-3)) -> 0.84782844 | I22: =H22/(1+(((Base_Curves!H7/Base_Curves!I7-1)/(10-5))+Curve_Shocks_bps!I21/10000)*(10-5)) -> 0.7169376 | J22: =I22/(1+(((Base_Curves!I7/Base_Curves!J7-1)/(20-10))+Curve_Shocks_bps!J21/10000)*(20-10)) -> 0.51733468 | K22: =J22/(1+(((Base_Curves!J7/Base_Curves!K7-1)/(30-20))+Curve_Shocks_bps!K21/10000)*(30-20)) -> 0.37354504
A23: Treasury | B23: Credit | C23: =1/(1+(((1/Base_Curves!C8-1)/(0.25-0))+Curve_Shocks_bps!C22/10000)*(0.25-0)) -> 0.98815749 | D23: =C23/(1+(((Base_Curves!C8/Base_Curves!D8-1)/(0.5-0.25))+Curve_Shocks_bps!D22/10000)*(0.5-0.25)) -> 0.97630095 | E23: =D23/(1+(((Base_Curves!D8/Base_Curves!E8-1)/(1-0.5))+Curve_Shocks_bps!E22/10000)*(1-0.5)) -> 0.95400896 | F23: =E23/(1+(((Base_Curves!E8/Base_Curves!F8-1)/(2-1))+Curve_Shocks_bps!F22/10000)*(2-1)) -> 0.91178104 | G23: =F23/(1+(((Base_Curves!F8/Base_Curves!G8-1)/(3-2))+Curve_Shocks_bps!G22/10000)*(3-2)) -> 0.87189384 | H23: =G23/(1+(((Base_Curves!G8/Base_Curves!H8-1)/(5-3))+Curve_Shocks_bps!H22/10000)*(5-3)) -> 0.79821677 | I23: =H23/(1+(((Base_Curves!H8/Base_Curves!I8-1)/(10-5))+Curve_Shocks_bps!I22/10000)*(10-5)) -> 0.63835164 | J23: =I23/(1+(((Base_Curves!I8/Base_Curves!J8-1)/(20-10))+Curve_Shocks_bps!J22/10000)*(20-10)) -> 0.41246187 | K23: =J23/(1+(((Base_Curves!J8/Base_Curves!K8-1)/(30-20))+Curve_Shocks_bps!K22/10000)*(30-20)) -> 0.26728357
A24: Agency_FNMA | B24: Credit | C24: =1/(1+(((1/Base_Curves!C9-1)/(0.25-0))+Curve_Shocks_bps!C23/10000)*(0.25-0)) -> 0.98606157 | D24: =C24/(1+(((Base_Curves!C9/Base_Curves!D9-1)/(0.5-0.25))+Curve_Shocks_bps!D23/10000)*(0.5-0.25)) -> 0.97258152 | E24: =D24/(1+(((Base_Curves!D9/Base_Curves!E9-1)/(1-0.5))+Curve_Shocks_bps!E23/10000)*(1-0.5)) -> 0.95361271 | F24: =E24/(1+(((Base_Curves!E9/Base_Curves!F9-1)/(2-1))+Curve_Shocks_bps!F23/10000)*(2-1)) -> 0.90609176 | G24: =F24/(1+(((Base_Curves!F9/Base_Curves!G9-1)/(3-2))+Curve_Shocks_bps!G23/10000)*(3-2)) -> 0.86193537 | H24: =G24/(1+(((Base_Curves!G9/Base_Curves!H9-1)/(5-3))+Curve_Shocks_bps!H23/10000)*(5-3)) -> 0.78143261 | I24: =H24/(1+(((Base_Curves!H9/Base_Curves!I9-1)/(10-5))+Curve_Shocks_bps!I23/10000)*(10-5)) -> 0.61176563 | J24: =I24/(1+(((Base_Curves!I9/Base_Curves!J9-1)/(20-10))+Curve_Shocks_bps!J23/10000)*(20-10)) -> 0.37919808 | K24: =J24/(1+(((Base_Curves!J9/Base_Curves!K9-1)/(30-20))+Curve_Shocks_bps!K23/10000)*(30-20)) -> 0.23636104
A25: Eur_Govt | B25: Credit | C25: =1/(1+(((1/Base_Curves!C10-1)/(0.25-0))+Curve_Shocks_bps!C24/10000)*(0.25-0)) -> 0.9898582 | D25: =C25/(1+(((Base_Curves!C10/Base_Curves!D10-1)/(0.5-0.25))+Curve_Shocks_bps!D24/10000)*(0.5-0.25)) -> 0.9801417 | E25: =D25/(1+(((Base_Curves!D10/Base_Curves!E10-1)/(1-0.5))+Curve_Shocks_bps!E24/10000)*(1-0.5)) -> 0.96122366 | F25: =E25/(1+(((Base_Curves!E10/Base_Curves!F10-1)/(2-1))+Curve_Shocks_bps!F24/10000)*(2-1)) -> 0.92590443 | G25: =F25/(1+(((Base_Curves!F10/Base_Curves!G10-1)/(3-2))+Curve_Shocks_bps!G24/10000)*(3-2)) -> 0.8972852 | H25: =G25/(1+(((Base_Curves!G10/Base_Curves!H10-1)/(5-3))+Curve_Shocks_bps!H24/10000)*(5-3)) -> 0.83605747 | I25: =H25/(1+(((Base_Curves!H10/Base_Curves!I10-1)/(10-5))+Curve_Shocks_bps!I24/10000)*(10-5)) -> 0.69873115 | J25: =I25/(1+(((Base_Curves!I10/Base_Curves!J10-1)/(20-10))+Curve_Shocks_bps!J24/10000)*(20-10)) -> 0.49356246 | K25: =J25/(1+(((Base_Curves!J10/Base_Curves!K10-1)/(30-20))+Curve_Shocks_bps!K24/10000)*(30-20)) -> 0.35017065
A26: EURUSD | B26: FX | C26: =1/(1+(((1/Base_Curves!C11-1)/(0.25-0))+Curve_Shocks_bps!C25/10000)*(0.25-0)) -> 0.98920855 | D26: =C26/(1+(((Base_Curves!C11/Base_Curves!D11-1)/(0.5-0.25))+Curve_Shocks_bps!D25/10000)*(0.5-0.25)) -> 0.97848538 | E26: =D26/(1+(((Base_Curves!D11/Base_Curves!E11-1)/(1-0.5))+Curve_Shocks_bps!E25/10000)*(1-0.5)) -> 0.9575846 | F26: =E26/(1+(((Base_Curves!E11/Base_Curves!F11-1)/(2-1))+Curve_Shocks_bps!F25/10000)*(2-1)) -> 0.92126069 | G26: =F26/(1+(((Base_Curves!F11/Base_Curves!G11-1)/(3-2))+Curve_Shocks_bps!G25/10000)*(3-2)) -> 0.88329494 | H26: =G26/(1+(((Base_Curves!G11/Base_Curves!H11-1)/(5-3))+Curve_Shocks_bps!H25/10000)*(5-3)) -> 0.81226217 | I26: =H26/(1+(((Base_Curves!H11/Base_Curves!I11-1)/(10-5))+Curve_Shocks_bps!I25/10000)*(10-5)) -> 0.65649482 | J26: =I26/(1+(((Base_Curves!I11/Base_Curves!J11-1)/(20-10))+Curve_Shocks_bps!J25/10000)*(20-10)) -> 0.43270981 | K26: =J26/(1+(((Base_Curves!J11/Base_Curves!K11-1)/(30-20))+Curve_Shocks_bps!K25/10000)*(30-20)) -> 0.28537795
A28: Scenario 4 | C28: 3M | D28: 6M | E28: 1Y | F28: 2Y | G28: 3Y | H28: 5Y | I28: 10Y | J28: 20Y | K28: 30Y
A29: SOFR | B29: IR | C29: =1/(1+(((1/Base_Curves!C6-1)/(0.25-0))+Curve_Shocks_bps!C28/10000)*(0.25-0)) -> 0.98795898 | D29: =C29/(1+(((Base_Curves!C6/Base_Curves!D6-1)/(0.5-0.25))+Curve_Shocks_bps!D28/10000)*(0.5-0.25)) -> 0.97608888 | E29: =D29/(1+(((Base_Curves!D6/Base_Curves!E6-1)/(1-0.5))+Curve_Shocks_bps!E28/10000)*(1-0.5)) -> 0.95304179 | F29: =E29/(1+(((Base_Curves!E6/Base_Curves!F6-1)/(2-1))+Curve_Shocks_bps!F28/10000)*(2-1)) -> 0.90980086 | G29: =F29/(1+(((Base_Curves!F6/Base_Curves!G6-1)/(3-2))+Curve_Shocks_bps!G28/10000)*(3-2)) -> 0.87258385 | H29: =G29/(1+(((Base_Curves!G6/Base_Curves!H6-1)/(5-3))+Curve_Shocks_bps!H28/10000)*(5-3)) -> 0.79722661 | I29: =H29/(1+(((Base_Curves!H6/Base_Curves!I6-1)/(10-5))+Curve_Shocks_bps!I28/10000)*(10-5)) -> 0.63461314 | J29: =I29/(1+(((Base_Curves!I6/Base_Curves!J6-1)/(20-10))+Curve_Shocks_bps!J28/10000)*(20-10)) -> 0.4058956 | K29: =J29/(1+(((Base_Curves!J6/Base_Curves!K6-1)/(30-20))+Curve_Shocks_bps!K28/10000)*(30-20)) -> 0.25975786
A30: ESTRN | B30: IR | C30: =1/(1+(((1/Base_Curves!C7-1)/(0.25-0))+Curve_Shocks_bps!C29/10000)*(0.25-0)) -> 0.99114737 | D30: =C30/(1+(((Base_Curves!C7/Base_Curves!D7-1)/(0.5-0.25))+Curve_Shocks_bps!D29/10000)*(0.5-0.25)) -> 0.98241285 | E30: =D30/(1+(((Base_Curves!D7/Base_Curves!E7-1)/(1-0.5))+Curve_Shocks_bps!E29/10000)*(1-0.5)) -> 0.96526908 | F30: =E30/(1+(((Base_Curves!E7/Base_Curves!F7-1)/(2-1))+Curve_Shocks_bps!F29/10000)*(2-1)) -> 0.93309617 | G30: =F30/(1+(((Base_Curves!F7/Base_Curves!G7-1)/(3-2))+Curve_Shocks_bps!G29/10000)*(3-2)) -> 0.90253671 | H30: =G30/(1+(((Base_Curves!G7/Base_Curves!H7-1)/(5-3))+Curve_Shocks_bps!H29/10000)*(5-3)) -> 0.84759699 | I30: =H30/(1+(((Base_Curves!H7/Base_Curves!I7-1)/(10-5))+Curve_Shocks_bps!I29/10000)*(10-5)) -> 0.71646924 | J30: =I30/(1+(((Base_Curves!I7/Base_Curves!J7-1)/(20-10))+Curve_Shocks_bps!J29/10000)*(20-10)) -> 0.51688483 | K30: =J30/(1+(((Base_Curves!J7/Base_Curves!K7-1)/(30-20))+Curve_Shocks_bps!K29/10000)*(30-20)) -> 0.37322022
A31: Treasury | B31: Credit | C31: =1/(1+(((1/Base_Curves!C8-1)/(0.25-0))+Curve_Shocks_bps!C30/10000)*(0.25-0)) -> 0.98778901 | D31: =C31/(1+(((Base_Curves!C8/Base_Curves!D8-1)/(0.5-0.25))+Curve_Shocks_bps!D30/10000)*(0.5-0.25)) -> 0.97586217 | E31: =D31/(1+(((Base_Curves!D8/Base_Curves!E8-1)/(1-0.5))+Curve_Shocks_bps!E30/10000)*(1-0.5)) -> 0.95320762 | F31: =E31/(1+(((Base_Curves!E8/Base_Curves!F8-1)/(2-1))+Curve_Shocks_bps!F30/10000)*(2-1)) -> 0.91068443 | G31: =F31/(1+(((Base_Curves!F8/Base_Curves!G8-1)/(3-2))+Curve_Shocks_bps!G30/10000)*(3-2)) -> 0.87090351 | H31: =G31/(1+(((Base_Curves!G8/Base_Curves!H8-1)/(5-3))+Curve_Shocks_bps!H30/10000)*(5-3)) -> 0.79706201 | I31: =H31/(1+(((Base_Curves!H8/Base_Curves!I8-1)/(10-5))+Curve_Shocks_bps!I30/10000)*(10-5)) -> 0.63727526 | J31: =I31/(1+(((Base_Curves!I8/Base_Curves!J8-1)/(20-10))+Curve_Shocks_bps!J30/10000)*(20-10)) -> 0.41326171 | K31: =J31/(1+(((Base_Curves!J8/Base_Curves!K8-1)/(30-20))+Curve_Shocks_bps!K30/10000)*(30-20)) -> 0.26714405
A32: Agency_FNMA | B32: Credit | C32: =1/(1+(((1/Base_Curves!C9-1)/(0.25-0))+Curve_Shocks_bps!C31/10000)*(0.25-0)) -> 0.98598379 | D32: =C32/(1+(((Base_Curves!C9/Base_Curves!D9-1)/(0.5-0.25))+Curve_Shocks_bps!D31/10000)*(0.5-0.25)) -> 0.97221953 | E32: =D32/(1+(((Base_Curves!D9/Base_Curves!E9-1)/(1-0.5))+Curve_Shocks_bps!E31/10000)*(1-0.5)) -> 0.94623448 | F32: =E32/(1+(((Base_Curves!E9/Base_Curves!F9-1)/(2-1))+Curve_Shocks_bps!F31/10000)*(2-1)) -> 0.89827037 | G32: =F32/(1+(((Base_Curves!F9/Base_Curves!G9-1)/(3-2))+Curve_Shocks_bps!G31/10000)*(3-2)) -> 0.85421074 | H32: =G32/(1+(((Base_Curves!G9/Base_Curves!H9-1)/(5-3))+Curve_Shocks_bps!H31/10000)*(5-3)) -> 0.77398036 | I32: =H32/(1+(((Base_Curves!H9/Base_Curves!I9-1)/(10-5))+Curve_Shocks_bps!I31/10000)*(10-5)) -> 0.60557587 | J32: =I32/(1+(((Base_Curves!I9/Base_Curves!J9-1)/(20-10))+Curve_Shocks_bps!J31/10000)*(20-10)) -> 0.37526836 | K32: =J32/(1+(((Base_Curves!J9/Base_Curves!K9-1)/(30-20))+Curve_Shocks_bps!K31/10000)*(30-20)) -> 0.23285205
A33: Eur_Govt | B33: Credit | C33: =1/(1+(((1/Base_Curves!C10-1)/(0.25-0))+Curve_Shocks_bps!C32/10000)*(0.25-0)) -> 0.9896133 | D33: =C33/(1+(((Base_Curves!C10/Base_Curves!D10-1)/(0.5-0.25))+Curve_Shocks_bps!D32/10000)*(0.5-0.25)) -> 0.97948217 | E33: =D33/(1+(((Base_Curves!D10/Base_Curves!E10-1)/(1-0.5))+Curve_Shocks_bps!E32/10000)*(1-0.5)) -> 0.9603367 | F33: =E33/(1+(((Base_Curves!E10/Base_Curves!F10-1)/(2-1))+Curve_Shocks_bps!F32/10000)*(2-1)) -> 0.92477391 | G33: =F33/(1+(((Base_Curves!F10/Base_Curves!G10-1)/(3-2))+Curve_Shocks_bps!G32/10000)*(3-2)) -> 0.89158437 | H33: =G33/(1+(((Base_Curves!G10/Base_Curves!H10-1)/(5-3))+Curve_Shocks_bps!H32/10000)*(5-3)) -> 0.83048255 | I33: =H33/(1+(((Base_Curves!H10/Base_Curves!I10-1)/(10-5))+Curve_Shocks_bps!I32/10000)*(10-5)) -> 0.69392694 | J33: =I33/(1+(((Base_Curves!I10/Base_Curves!J10-1)/(20-10))+Curve_Shocks_bps!J32/10000)*(20-10)) -> 0.48999586 | K33: =J33/(1+(((Base_Curves!J10/Base_Curves!K10-1)/(30-20))+Curve_Shocks_bps!K32/10000)*(30-20)) -> 0.3462645
A34: EURUSD | B34: FX | C34: =1/(1+(((1/Base_Curves!C11-1)/(0.25-0))+Curve_Shocks_bps!C33/10000)*(0.25-0)) -> 0.99096568 | D34: =C34/(1+(((Base_Curves!C11/Base_Curves!D11-1)/(0.5-0.25))+Curve_Shocks_bps!D33/10000)*(0.5-0.25)) -> 0.98020165 | E34: =D34/(1+(((Base_Curves!D11/Base_Curves!E11-1)/(1-0.5))+Curve_Shocks_bps!E33/10000)*(1-0.5)) -> 0.96226356 | F34: =E34/(1+(((Base_Curves!E11/Base_Curves!F11-1)/(2-1))+Curve_Shocks_bps!F33/10000)*(2-1)) -> 0.92221324 | G34: =F34/(1+(((Base_Curves!F11/Base_Curves!G11-1)/(3-2))+Curve_Shocks_bps!G33/10000)*(3-2)) -> 0.88419128 | H34: =G34/(1+(((Base_Curves!G11/Base_Curves!H11-1)/(5-3))+Curve_Shocks_bps!H33/10000)*(5-3)) -> 0.81292196 | I34: =H34/(1+(((Base_Curves!H11/Base_Curves!I11-1)/(10-5))+Curve_Shocks_bps!I33/10000)*(10-5)) -> 0.65947994 | J34: =I34/(1+(((Base_Curves!I11/Base_Curves!J11-1)/(20-10))+Curve_Shocks_bps!J33/10000)*(20-10)) -> 0.43459144 | K34: =J34/(1+(((Base_Curves!J11/Base_Curves!K11-1)/(30-20))+Curve_Shocks_bps!K33/10000)*(30-20)) -> 0.28661891
A36: Scenario 5 | C36: 3M | D36: 6M | E36: 1Y | F36: 2Y | G36: 3Y | H36: 5Y | I36: 10Y | J36: 20Y | K36: 30Y
A37: SOFR | B37: IR | C37: =1/(1+(((1/Base_Curves!C6-1)/(0.25-0))+Curve_Shocks_bps!C36/10000)*(0.25-0)) -> 0.98776137 | D37: =C37/(1+(((Base_Curves!C6/Base_Curves!D6-1)/(0.5-0.25))+Curve_Shocks_bps!D36/10000)*(0.5-0.25)) -> 0.97864201 | E37: =D37/(1+(((Base_Curves!D6/Base_Curves!E6-1)/(1-0.5))+Curve_Shocks_bps!E36/10000)*(1-0.5)) -> 0.95548798 | F37: =E37/(1+(((Base_Curves!E6/Base_Curves!F6-1)/(2-1))+Curve_Shocks_bps!F36/10000)*(2-1)) -> 0.91199677 | G37: =F37/(1+(((Base_Curves!F6/Base_Curves!G6-1)/(3-2))+Curve_Shocks_bps!G36/10000)*(3-2)) -> 0.8710808 | H37: =G37/(1+(((Base_Curves!G6/Base_Curves!H6-1)/(5-3))+Curve_Shocks_bps!H36/10000)*(5-3)) -> 0.79575158 | I37: =H37/(1+(((Base_Curves!H6/Base_Curves!I6-1)/(10-5))+Curve_Shocks_bps!I36/10000)*(10-5)) -> 0.63316178 | J37: =I37/(1+(((Base_Curves!I6/Base_Curves!J6-1)/(20-10))+Curve_Shocks_bps!J36/10000)*(20-10)) -> 0.40486374 | K37: =J37/(1+(((Base_Curves!J6/Base_Curves!K6-1)/(30-20))+Curve_Shocks_bps!K36/10000)*(30-20)) -> 0.25906435
A38: ESTRN | B38: IR | C38: =1/(1+(((1/Base_Curves!C7-1)/(0.25-0))+Curve_Shocks_bps!C37/10000)*(0.25-0)) -> 0.99084047 | D38: =C38/(1+(((Base_Curves!C7/Base_Curves!D7-1)/(0.5-0.25))+Curve_Shocks_bps!D37/10000)*(0.5-0.25)) -> 0.98196266 | E38: =D38/(1+(((Base_Curves!D7/Base_Curves!E7-1)/(1-0.5))+Curve_Shocks_bps!E37/10000)*(1-0.5)) -> 0.96483623 | F38: =E38/(1+(((Base_Curves!E7/Base_Curves!F7-1)/(2-1))+Curve_Shocks_bps!F37/10000)*(2-1)) -> 0.93238031 | G38: =F38/(1+(((Base_Curves!F7/Base_Curves!G7-1)/(3-2))+Curve_Shocks_bps!G37/10000)*(3-2)) -> 0.90177452 | H38: =G38/(1+(((Base_Curves!G7/Base_Curves!H7-1)/(5-3))+Curve_Shocks_bps!H37/10000)*(5-3)) -> 0.8442173 | I38: =H38/(1+(((Base_Curves!H7/Base_Curves!I7-1)/(10-5))+Curve_Shocks_bps!I37/10000)*(10-5)) -> 0.71361241 | J38: =I38/(1+(((Base_Curves!I7/Base_Curves!J7-1)/(20-10))+Curve_Shocks_bps!J37/10000)*(20-10)) -> 0.51642585 | K38: =J38/(1+(((Base_Curves!J7/Base_Curves!K7-1)/(30-20))+Curve_Shocks_bps!K37/10000)*(30-20)) -> 0.37283497
A39: Treasury | B39: Credit | C39: =1/(1+(((1/Base_Curves!C8-1)/(0.25-0))+Curve_Shocks_bps!C38/10000)*(0.25-0)) -> 0.99149108 | D39: =C39/(1+(((Base_Curves!C8/Base_Curves!D8-1)/(0.5-0.25))+Curve_Shocks_bps!D38/10000)*(0.5-0.25)) -> 0.9793986 | E39: =D39/(1+(((Base_Curves!D8/Base_Curves!E8-1)/(1-0.5))+Curve_Shocks_bps!E38/10000)*(1-0.5)) -> 0.95639571 | F39: =E39/(1+(((Base_Curves!E8/Base_Curves!F8-1)/(2-1))+Curve_Shocks_bps!F38/10000)*(2-1)) -> 0.91331146 | G39: =F39/(1+(((Base_Curves!F8/Base_Curves!G8-1)/(3-2))+Curve_Shocks_bps!G38/10000)*(3-2)) -> 0.87304007 | H39: =G39/(1+(((Base_Curves!G8/Base_Curves!H8-1)/(5-3))+Curve_Shocks_bps!H38/10000)*(5-3)) -> 0.79873964 | I39: =H39/(1+(((Base_Curves!H8/Base_Curves!I8-1)/(10-5))+Curve_Shocks_bps!I38/10000)*(10-5)) -> 0.64187539 | J39: =I39/(1+(((Base_Curves!I8/Base_Curves!J8-1)/(20-10))+Curve_Shocks_bps!J38/10000)*(20-10)) -> 0.41460474 | K39: =J39/(1+(((Base_Curves!J8/Base_Curves!K8-1)/(30-20))+Curve_Shocks_bps!K38/10000)*(30-20)) -> 0.26796026
A40: Agency_FNMA | B40: Credit | C40: =1/(1+(((1/Base_Curves!C9-1)/(0.25-0))+Curve_Shocks_bps!C39/10000)*(0.25-0)) -> 0.98564365 | D40: =C40/(1+(((Base_Curves!C9/Base_Curves!D9-1)/(0.5-0.25))+Curve_Shocks_bps!D39/10000)*(0.5-0.25)) -> 0.97168772 | E40: =D40/(1+(((Base_Curves!D9/Base_Curves!E9-1)/(1-0.5))+Curve_Shocks_bps!E39/10000)*(1-0.5)) -> 0.94534426 | F40: =E40/(1+(((Base_Curves!E9/Base_Curves!F9-1)/(2-1))+Curve_Shocks_bps!F39/10000)*(2-1)) -> 0.90810638 | G40: =F40/(1+(((Base_Curves!F9/Base_Curves!G9-1)/(3-2))+Curve_Shocks_bps!G39/10000)*(3-2)) -> 0.86308826 | H40: =G40/(1+(((Base_Curves!G9/Base_Curves!H9-1)/(5-3))+Curve_Shocks_bps!H39/10000)*(5-3)) -> 0.78193906 | I40: =H40/(1+(((Base_Curves!H9/Base_Curves!I9-1)/(10-5))+Curve_Shocks_bps!I39/10000)*(10-5)) -> 0.61696807 | J40: =I40/(1+(((Base_Curves!I9/Base_Curves!J9-1)/(20-10))+Curve_Shocks_bps!J39/10000)*(20-10)) -> 0.38528859 | K40: =J40/(1+(((Base_Curves!J9/Base_Curves!K9-1)/(30-20))+Curve_Shocks_bps!K39/10000)*(30-20)) -> 0.23896575
A41: Eur_Govt | B41: Credit | C41: =1/(1+(((1/Base_Curves!C10-1)/(0.25-0))+Curve_Shocks_bps!C40/10000)*(0.25-0)) -> 0.98951293 | D41: =C41/(1+(((Base_Curves!C10/Base_Curves!D10-1)/(0.5-0.25))+Curve_Shocks_bps!D40/10000)*(0.5-0.25)) -> 0.97933194 | E41: =D41/(1+(((Base_Curves!D10/Base_Curves!E10-1)/(1-0.5))+Curve_Shocks_bps!E40/10000)*(1-0.5)) -> 0.96004351 | F41: =E41/(1+(((Base_Curves!E10/Base_Curves!F10-1)/(2-1))+Curve_Shocks_bps!F40/10000)*(2-1)) -> 0.92422457 | G41: =F41/(1+(((Base_Curves!F10/Base_Curves!G10-1)/(3-2))+Curve_Shocks_bps!G40/10000)*(3-2)) -> 0.8907971 | H41: =G41/(1+(((Base_Curves!G10/Base_Curves!H10-1)/(5-3))+Curve_Shocks_bps!H40/10000)*(5-3)) -> 0.82925488 | I41: =H41/(1+(((Base_Curves!H10/Base_Curves!I10-1)/(10-5))+Curve_Shocks_bps!I40/10000)*(10-5)) -> 0.69774013 | J41: =I41/(1+(((Base_Curves!I10/Base_Curves!J10-1)/(20-10))+Curve_Shocks_bps!J40/10000)*(20-10)) -> 0.49272322 | K41: =J41/(1+(((Base_Curves!J10/Base_Curves!K10-1)/(30-20))+Curve_Shocks_bps!K40/10000)*(30-20)) -> 0.34809344
A42: EURUSD | B42: FX | C42: =1/(1+(((1/Base_Curves!C11-1)/(0.25-0))+Curve_Shocks_bps!C41/10000)*(0.25-0)) -> 0.98893952 | D42: =C42/(1+(((Base_Curves!C11/Base_Curves!D11-1)/(0.5-0.25))+Curve_Shocks_bps!D41/10000)*(0.5-0.25)) -> 0.97803788 | E42: =D42/(1+(((Base_Curves!D11/Base_Curves!E11-1)/(1-0.5))+Curve_Shocks_bps!E41/10000)*(1-0.5)) -> 0.95680489 | F42: =E42/(1+(((Base_Curves!E11/Base_Curves!F11-1)/(2-1))+Curve_Shocks_bps!F41/10000)*(2-1)) -> 0.91689389 | G42: =F42/(1+(((Base_Curves!F11/Base_Curves!G11-1)/(3-2))+Curve_Shocks_bps!G41/10000)*(3-2)) -> 0.87896483 | H42: =G42/(1+(((Base_Curves!G11/Base_Curves!H11-1)/(5-3))+Curve_Shocks_bps!H41/10000)*(5-3)) -> 0.80795336 | I42: =H42/(1+(((Base_Curves!H11/Base_Curves!I11-1)/(10-5))+Curve_Shocks_bps!I41/10000)*(10-5)) -> 0.65259036 | J42: =I42/(1+(((Base_Curves!I11/Base_Curves!J11-1)/(20-10))+Curve_Shocks_bps!J41/10000)*(20-10)) -> 0.43005126 | K42: =J42/(1+(((Base_Curves!J11/Base_Curves!K11-1)/(30-20))+Curve_Shocks_bps!K41/10000)*(30-20)) -> 0.28441241
A44: Scenario 6 | C44: 3M | D44: 6M | E44: 1Y | F44: 2Y | G44: 3Y | H44: 5Y | I44: 10Y | J44: 20Y | K44: 30Y
A45: SOFR | B45: IR | C45: =1/(1+(((1/Base_Curves!C6-1)/(0.25-0))+Curve_Shocks_bps!C44/10000)*(0.25-0)) -> 0.98744925 | D45: =C45/(1+(((Base_Curves!C6/Base_Curves!D6-1)/(0.5-0.25))+Curve_Shocks_bps!D44/10000)*(0.5-0.25)) -> 0.97839094 | E45: =D45/(1+(((Base_Curves!D6/Base_Curves!E6-1)/(1-0.5))+Curve_Shocks_bps!E44/10000)*(1-0.5)) -> 0.9549911 | F45: =E45/(1+(((Base_Curves!E6/Base_Curves!F6-1)/(2-1))+Curve_Shocks_bps!F44/10000)*(2-1)) -> 0.91102686 | G45: =F45/(1+(((Base_Curves!F6/Base_Curves!G6-1)/(3-2))+Curve_Shocks_bps!G44/10000)*(3-2)) -> 0.8741118 | H45: =G45/(1+(((Base_Curves!G6/Base_Curves!H6-1)/(5-3))+Curve_Shocks_bps!H44/10000)*(5-3)) -> 0.79834544 | I45: =H45/(1+(((Base_Curves!H6/Base_Curves!I6-1)/(10-5))+Curve_Shocks_bps!I44/10000)*(10-5)) -> 0.63525092 | J45: =I45/(1+(((Base_Curves!I6/Base_Curves!J6-1)/(20-10))+Curve_Shocks_bps!J44/10000)*(20-10)) -> 0.40609574 | K45: =J45/(1+(((Base_Curves!J6/Base_Curves!K6-1)/(30-20))+Curve_Shocks_bps!K44/10000)*(30-20)) -> 0.25985268
A46: ESTRN | B46: IR | C46: =1/(1+(((1/Base_Curves!C7-1)/(0.25-0))+Curve_Shocks_bps!C45/10000)*(0.25-0)) -> 0.99072758 | D46: =C46/(1+(((Base_Curves!C7/Base_Curves!D7-1)/(0.5-0.25))+Curve_Shocks_bps!D45/10000)*(0.5-0.25)) -> 0.98173889 | E46: =D46/(1+(((Base_Curves!D7/Base_Curves!E7-1)/(1-0.5))+Curve_Shocks_bps!E45/10000)*(1-0.5)) -> 0.96434632 | F46: =E46/(1+(((Base_Curves!E7/Base_Curves!F7-1)/(2-1))+Curve_Shocks_bps!F45/10000)*(2-1)) -> 0.93163679 | G46: =F46/(1+(((Base_Curves!F7/Base_Curves!G7-1)/(3-2))+Curve_Shocks_bps!G45/10000)*(3-2)) -> 0.90102055 | H46: =G46/(1+(((Base_Curves!G7/Base_Curves!H7-1)/(5-3))+Curve_Shocks_bps!H45/10000)*(5-3)) -> 0.84325883 | I46: =H46/(1+(((Base_Curves!H7/Base_Curves!I7-1)/(10-5))+Curve_Shocks_bps!I45/10000)*(10-5)) -> 0.7125914 | J46: =I46/(1+(((Base_Curves!I7/Base_Curves!J7-1)/(20-10))+Curve_Shocks_bps!J45/10000)*(20-10)) -> 0.51393891 | K46: =J46/(1+(((Base_Curves!J7/Base_Curves!K7-1)/(30-20))+Curve_Shocks_bps!K45/10000)*(30-20)) -> 0.37101273
...

Sheet SABR_Base
B1: SABR Base Vol Surfaces — Swabr_Swaption (10x10 grids: Expiry x Tenor)
B3: Param: ATM
B4: Expiry \ Tenor | C4: 1M | D4: 3M | E4: 6M | F4: 1Y | G4: 2Y | H4: 3Y | I4: 5Y | J4: 10Y | K4: 20Y | L4: 30Y
B5: 1M | C5: 0.5465 | D5: 0.5264 | E5: 0.5197 | F5: 0.4914 | G5: 0.4841 | H5: 0.464 | I5: 0.4412 | J5: 0.4335 | K5: 0.4074 | L5: 0.3987
B6: 3M | C6: 0.5247 | D6: 0.5085 | E6: 0.4985 | F6: 0.4899 | G6: 0.4591 | H6: 0.4445 | I6: 0.4359 | J6: 0.4256 | K6: 0.4015 | L6: 0.3813
B7: 6M | C7: 0.5262 | D7: 0.4909 | E7: 0.4905 | F7: 0.4625 | G7: 0.4429 | H7: 0.4257 | I7: 0.4128 | J7: 0.4063 | K7: 0.3769 | L7: 0.3683
B8: 1Y | C8: 0.5028 | D8: 0.4808 | E8: 0.4676 | F8: 0.4413 | G8: 0.4245 | H8: 0.4108 | I8: 0.4036 | J8: 0.3819 | K8: 0.3629 | L8: 0.3517
B9: 2Y | C9: 0.4824 | D9: 0.4627 | E9: 0.4559 | F9: 0.4373 | G9: 0.4115 | H9: 0.4015 | I9: 0.3838 | J9: 0.3742 | K9: 0.3546 | L9: 0.3291
B10: 3Y | C10: 0.4763 | D10: 0.4424 | E10: 0.4317 | F10: 0.4218 | G10: 0.393 | H10: 0.3831 | I10: 0.3575 | J10: 0.3534 | K10: 0.3386 | L10: 0.3181
B11: 5Y | C11: 0.4575 | D11: 0.4296 | E11: 0.4206 | F11: 0.4019 | G11: 0.3849 | H11: 0.3658 | I11: 0.3568 | J11: 0.3422 | K11: 0.3161 | L11: 0.3033
B12: 10Y | C12: 0.4245 | D12: 0.4207 | E12: 0.4029 | F12: 0.3932 | G12: 0.3731 | H12: 0.3457 | I12: 0.331 | J12: 0.32 | K12: 0.2905 | L12: 0.2826
B13: 20Y | C13: 0.41 | D13: 0.3923 | E13: 0.3745 | F13: 0.372 | G13: 0.3426 | H13: 0.3283 | I13: 0.3145 | J13: 0.3074 | K13: 0.2749 | L13: 0.2657
B14: 30Y | C14: 0.401 | D14: 0.391 | E14: 0.3731 | F14: 0.3573 | G14: 0.3289 | H14: 0.315 | I14: 0.2972 | J14: 0.291 | K14: 0.2758 | L14: 0.243
B17: Param: RHO
B18: Expiry \ Tenor | C18: 1M | D18: 3M | E18: 6M | F18: 1Y | G18: 2Y | H18: 3Y | I18: 5Y | J18: 10Y | K18: 20Y | L18: 30Y
B19: 1M | C19: -0.3565 | D19: -0.3359 | E19: -0.3164 | F19: -0.292 | G19: -0.2704 | H19: -0.2575 | I19: -0.2433 | J19: -0.2155 | K19: -0.1971 | L19: -0.1737
B20: 3M | C20: -0.3215 | D20: -0.3073 | E20: -0.2914 | F20: -0.2699 | G20: -0.2493 | H20: -0.2423 | I20: -0.2059 | J20: -0.1888 | K20: -0.1675 | L20: -0.1496
B21: 6M | C21: -0.3133 | D21: -0.2937 | E21: -0.2802 | F21: -0.2501 | G21: -0.2421 | H21: -0.2225 | I21: -0.2003 | J21: -0.1818 | K21: -0.1588 | L21: -0.1451
B22: 1Y | C22: -0.3017 | D22: -0.2792 | E22: -0.2607 | F22: -0.2361 | G22: -0.2234 | H22: -0.187 | I22: -0.1727 | J22: -0.1626 | K22: -0.1411 | L22: -0.1197
B23: 2Y | C23: -0.2749 | D23: -0.2603 | E23: -0.2264 | F23: -0.204 | G23: -0.1951 | H23: -0.1753 | I23: -0.1638 | J23: -0.1441 | K23: -0.1198 | L23: -0.1019
B24: 3Y | C24: -0.2462 | D24: -0.2401 | E24: -0.2234 | F24: -0.1854 | G24: -0.1744 | H24: -0.1626 | I24: -0.1352 | J24: -0.1261 | K24: -0.0967 | L24: -0.0682
B25: 5Y | C25: -0.2261 | D25: -0.21 | E25: -0.1992 | F25: -0.1777 | G25: -0.1622 | H25: -0.1307 | I25: -0.116 | J25: -0.0916 | K25: -0.0812 | L25: -0.0639
B26: 10Y | C26: -0.2077 | D26: -0.1847 | E26: -0.1679 | F26: -0.1494 | G26: -0.1297 | H26: -0.1119 | I26: -0.1027 | J26: -0.0774 | K26: -0.0612 | L26: -0.0483
B27: 20Y | C27: -0.2039 | D27: -0.1794 | E27: -0.1604 | F27: -0.1323 | G27: -0.1075 | H27: -0.0983 | I27: -0.069 | J27: -0.0486 | K27: -0.0298 | L27: -0.0222
B28: 30Y | C28: -0.1806 | D28: -0.161 | E28: -0.1422 | F28: -0.1226 | G28: -0.0947 | H28: -0.0698 | I28: -0.0515 | J28: -0.0393 | K28: -0.0164 | L28: 0.006
B31: Param: NU
B32: Expiry \ Tenor | C32: 1M | D32: 3M | E32: 6M | F32: 1Y | G32: 2Y | H32: 3Y | I32: 5Y | J32: 10Y | K32: 20Y | L32: 30Y
B33: 1M | C33: 0.8417 | D33: 0.831 | E33: 0.8138 | F33: 0.789 | G33: 0.7661 | H33: 0.7384 | I33: 0.7102 | J33: 0.7002 | K33: 0.6689 | L33: 0.656
B34: 3M | C34: 0.8372 | D34: 0.8035 | E34: 0.7814 | F34: 0.77 | G34: 0.7434 | H34: 0.7101 | I34: 0.687 | J34: 0.6652 | K34: 0.6581 | L34: 0.6339
B35: 6M | C35: 0.7985 | D35: 0.7899 | E35: 0.7707 | F35: 0.742 | G35: 0.7137 | H35: 0.6954 | I35: 0.6648 | J35: 0.6403 | K35: 0.6372 | L35: 0.6085
B36: 1Y | C36: 0.7839 | D36: 0.7698 | E36: 0.7376 | F36: 0.7241 | G36: 0.701 | H36: 0.6664 | I36: 0.645 | J36: 0.6236 | K36: 0.6004 | L36: 0.5851
B37: 2Y | C37: 0.7563 | D37: 0.7373 | E37: 0.7093 | F37: 0.7026 | G37: 0.6693 | H37: 0.6492 | I37: 0.6294 | J37: 0.6136 | K37: 0.5817 | L37: 0.5695
B38: 3Y | C38: 0.7389 | D38: 0.7173 | E38: 0.6949 | F38: 0.6626 | G38: 0.6488 | H38: 0.6214 | I38: 0.5956 | J38: 0.5893 | K38: 0.5546 | L38: 0.5384
B39: 5Y | C39: 0.7212 | D39: 0.6956 | E39: 0.6687 | F39: 0.6504 | G39: 0.6289 | H39: 0.6112 | I39: 0.5755 | J39: 0.5623 | K39: 0.5339 | L39: 0.5122
B40: 10Y | C40: 0.6999 | D40: 0.6724 | E40: 0.6512 | F40: 0.633 | G40: 0.6138 | H40: 0.5822 | I40: 0.5634 | J40: 0.539 | K40: 0.5169 | L40: 0.4983
B41: 20Y | C41: 0.6713 | D41: 0.6507 | E41: 0.6273 | F41: 0.6144 | G41: 0.5873 | H41: 0.5686 | I41: 0.5477 | J41: 0.5119 | K41: 0.4956 | L41: 0.4811
B42: 30Y | C42: 0.6568 | D42: 0.6205 | E42: 0.598 | F42: 0.5822 | G42: 0.5526 | H42: 0.5337 | I42: 0.5081 | J42: 0.4978 | K42: 0.4779 | L42: 0.4579

Sheet SABR_Shocks
B1: SABR Scenario Shocks — Parameter-level shock size per scenario + per-cell Sensitivity Factor grid
B2: Shocked(i,j) = Base(i,j) + ScenarioShockSize(param,scenario) x SensitivityFactor(i,j). ScenarioShockSize is the parallel move applied to the whole surface for that scenario; SensitivityFactor reshapes it across the grid (illustrative: larger moves at short expiry/short tenor, typical of a stress period).
B4: Scenario Shock Size (per param, parallel move applied before sensitivity scaling)
B5: Scenario | C5: ATM | D5: RHO | E5: NU
B6: Scenario 1 | C6: 0.0099 | D6: 0.0057 | E6: 0.0224
B7: Scenario 2 | C7: 0.0125 | D7: 0.0065 | E7: 0.0206
B8: Scenario 3 | C8: 0.012 | D8: 0.0077 | E8: 0.0249
B9: Scenario 4 | C9: 0.0205 | D9: 0.0056 | E9: 0.0233
B10: Scenario 5 | C10: 0.0159 | D10: 0.0125 | E10: 0.0331
B11: Scenario 6 | C11: 0.0178 | D11: 0.0151 | E11: 0.041
B12: Scenario 7 | C12: 0.0263 | D12: 0.0133 | E12: 0.0317
B13: Scenario 8 | C13: 0.0224 | D13: 0.0138 | E13: 0.0338
B14: Scenario 9 | C14: 0.0265 | D14: 0.0127 | E14: 0.0369
B15: Scenario 10 | C15: 0.0316 | D15: 0.0155 | E15: 0.0535
B18: Sensitivity Factor Grid (shared shape across ATM/RHO/NU; applied to all scenarios)
B19: Expiry \ Tenor | C19: 1M | D19: 3M | E19: 6M | F19: 1Y | G19: 2Y | H19: 3Y | I19: 5Y | J19: 10Y | K19: 20Y | L19: 30Y
B20: 1M | C20: 1.601 | D20: 1.518 | E20: 1.42 | F20: 1.34 | G20: 1.237 | H20: 1.137 | I20: 1.09 | J20: 1 | K20: 0.9 | L20: 0.802
B21: 3M | C21: 1.499 | D21: 1.404 | E21: 1.317 | F21: 1.214 | G21: 1.166 | H21: 1.054 | I21: 0.991 | J21: 0.873 | K21: 0.817 | L21: 0.721
B22: 6M | C22: 1.39 | D22: 1.313 | E22: 1.265 | F22: 1.148 | G22: 1.089 | H22: 0.964 | I22: 0.854 | J22: 0.798 | K22: 0.717 | L22: 0.596
B23: 1Y | C23: 1.305 | D23: 1.23 | E23: 1.178 | F23: 1.075 | G23: 0.947 | H23: 0.865 | I23: 0.766 | J23: 0.674 | K23: 0.628 | L23: 0.501
B24: 2Y | C24: 1.244 | D24: 1.147 | E24: 1.041 | F24: 0.984 | G24: 0.858 | H24: 0.799 | I24: 0.677 | J24: 0.605 | K24: 0.503 | L24: 0.416
B25: 3Y | C25: 1.178 | D25: 1.078 | E25: 0.958 | F25: 0.903 | G25: 0.773 | H25: 0.694 | I25: 0.631 | J25: 0.529 | K25: 0.406 | L25: 0.369
B26: 5Y | C26: 1.043 | D26: 0.955 | E26: 0.896 | F26: 0.78 | G26: 0.688 | H26: 0.584 | I26: 0.495 | J26: 0.435 | K26: 0.325 | L26: 0.256
B27: 10Y | C27: 0.962 | D27: 0.877 | E27: 0.818 | F27: 0.699 | G27: 0.614 | H27: 0.542 | I27: 0.411 | J27: 0.319 | K27: 0.275 | L27: 0.179
B28: 20Y | C28: 0.865 | D28: 0.771 | E28: 0.714 | F28: 0.636 | G28: 0.502 | H28: 0.457 | I28: 0.363 | J28: 0.256 | K28: 0.155 | L28: 0.15
B29: 30Y | C29: 0.762 | D29: 0.728 | E29: 0.594 | F29: 0.532 | G29: 0.415 | H29: 0.359 | I29: 0.256 | J29: 0.15 | K29: 0.15 | L29: 0.15

Sheet SABR_Shocked
B1: SABR Shocked Vol Surfaces — 10x10 grids x 3 params x 10 scenarios
B2: Shocked(i,j) = SABR_Base!(param,i,j) + SABR_Shocks!ScenarioShockSize(param,scenario) x SABR_Shocks!SensitivityFactor(i,j)
B4: SCENARIO 1
B5: Param: ATM
B6: Expiry \ Tenor | C6: 1M | D6: 3M | E6: 6M | F6: 1Y | G6: 2Y | H6: 3Y | I6: 5Y | J6: 10Y | K6: 20Y | L6: 30Y
B7: 1M | C7: =SABR_Base!C5+SABR_Shocks!$C$6*SABR_Shocks!C20 -> 0.5623499 | D7: =SABR_Base!D5+SABR_Shocks!$C$6*SABR_Shocks!D20 -> 0.5414282 | E7: =SABR_Base!E5+SABR_Shocks!$C$6*SABR_Shocks!E20 -> 0.533758 | F7: =SABR_Base!F5+SABR_Shocks!$C$6*SABR_Shocks!F20 -> 0.504666 | G7: =SABR_Base!G5+SABR_Shocks!$C$6*SABR_Shocks!G20 -> 0.4963463 | H7: =SABR_Base!H5+SABR_Shocks!$C$6*SABR_Shocks!H20 -> 0.4752563 | I7: =SABR_Base!I5+SABR_Shocks!$C$6*SABR_Shocks!I20 -> 0.451991 | J7: =SABR_Base!J5+SABR_Shocks!$C$6*SABR_Shocks!J20 -> 0.4434 | ... L7: =SABR_Base!L5+SABR_Shocks!$C$6*SABR_Shocks!L20 -> 0.4066398
B8: 3M | C8: =SABR_Base!C6+SABR_Shocks!$C$6*SABR_Shocks!C21 -> 0.5395401 | D8: =SABR_Base!D6+SABR_Shocks!$C$6*SABR_Shocks!D21 -> 0.5223996 | E8: =SABR_Base!E6+SABR_Shocks!$C$6*SABR_Shocks!E21 -> 0.5115383 | F8: =SABR_Base!F6+SABR_Shocks!$C$6*SABR_Shocks!F21 -> 0.5019186 | G8: =SABR_Base!G6+SABR_Shocks!$C$6*SABR_Shocks!G21 -> 0.4706434 | H8: =SABR_Base!H6+SABR_Shocks!$C$6*SABR_Shocks!H21 -> 0.4549346 | I8: =SABR_Base!I6+SABR_Shocks!$C$6*SABR_Shocks!I21 -> 0.4457109 | J8: =SABR_Base!J6+SABR_Shocks!$C$6*SABR_Shocks!J21 -> 0.4342427 | ... L8: =SABR_Base!L6+SABR_Shocks!$C$6*SABR_Shocks!L21 -> 0.3884379
B9: 6M | C9: =SABR_Base!C7+SABR_Shocks!$C$6*SABR_Shocks!C22 -> 0.539961 | D9: =SABR_Base!D7+SABR_Shocks!$C$6*SABR_Shocks!D22 -> 0.5038987 | E9: =SABR_Base!E7+SABR_Shocks!$C$6*SABR_Shocks!E22 -> 0.5030235 | F9: =SABR_Base!F7+SABR_Shocks!$C$6*SABR_Shocks!F22 -> 0.4738652 | G9: =SABR_Base!G7+SABR_Shocks!$C$6*SABR_Shocks!G22 -> 0.4536811 | H9: =SABR_Base!H7+SABR_Shocks!$C$6*SABR_Shocks!H22 -> 0.4352436 | I9: =SABR_Base!I7+SABR_Shocks!$C$6*SABR_Shocks!I22 -> 0.4212546 | J9: =SABR_Base!J7+SABR_Shocks!$C$6*SABR_Shocks!J22 -> 0.4142002 | ... L9: =SABR_Base!L7+SABR_Shocks!$C$6*SABR_Shocks!L22 -> 0.3742004
B10: 1Y | C10: =SABR_Base!C8+SABR_Shocks!$C$6*SABR_Shocks!C23 -> 0.5157195 | D10: =SABR_Base!D8+SABR_Shocks!$C$6*SABR_Shocks!D23 -> 0.492977 | E10: =SABR_Base!E8+SABR_Shocks!$C$6*SABR_Shocks!E23 -> 0.4792622 | F10: =SABR_Base!F8+SABR_Shocks!$C$6*SABR_Shocks!F23 -> 0.4519425 | G10: =SABR_Base!G8+SABR_Shocks!$C$6*SABR_Shocks!G23 -> 0.4338753 | H10: =SABR_Base!H8+SABR_Shocks!$C$6*SABR_Shocks!H23 -> 0.4193635 | I10: =SABR_Base!I8+SABR_Shocks!$C$6*SABR_Shocks!I23 -> 0.4111834 | J10: =SABR_Base!J8+SABR_Shocks!$C$6*SABR_Shocks!J23 -> 0.3885726 | ... L10: =SABR_Base!L8+SABR_Shocks!$C$6*SABR_Shocks!L23 -> 0.3566599
B11: 2Y | C11: =SABR_Base!C9+SABR_Shocks!$C$6*SABR_Shocks!C24 -> 0.4947156 | D11: =SABR_Base!D9+SABR_Shocks!$C$6*SABR_Shocks!D24 -> 0.4740553 | E11: =SABR_Base!E9+SABR_Shocks!$C$6*SABR_Shocks!E24 -> 0.4662059 | F11: =SABR_Base!F9+SABR_Shocks!$C$6*SABR_Shocks!F24 -> 0.4470416 | G11: =SABR_Base!G9+SABR_Shocks!$C$6*SABR_Shocks!G24 -> 0.4199942 | H11: =SABR_Base!H9+SABR_Shocks!$C$6*SABR_Shocks!H24 -> 0.4094101 | I11: =SABR_Base!I9+SABR_Shocks!$C$6*SABR_Shocks!I24 -> 0.3905023 | J11: =SABR_Base!J9+SABR_Shocks!$C$6*SABR_Shocks!J24 -> 0.3801895 | ... L11: =SABR_Base!L9+SABR_Shocks!$C$6*SABR_Shocks!L24 -> 0.3332184
B12: 3Y | C12: =SABR_Base!C10+SABR_Shocks!$C$6*SABR_Shocks!C25 -> 0.4879622 | D12: =SABR_Base!D10+SABR_Shocks!$C$6*SABR_Shocks!D25 -> 0.4530722 | E12: =SABR_Base!E10+SABR_Shocks!$C$6*SABR_Shocks!E25 -> 0.4411842 | F12: =SABR_Base!F10+SABR_Shocks!$C$6*SABR_Shocks!F25 -> 0.4307397 | G12: =SABR_Base!G10+SABR_Shocks!$C$6*SABR_Shocks!G25 -> 0.4006527 | H12: =SABR_Base!H10+SABR_Shocks!$C$6*SABR_Shocks!H25 -> 0.3899706 | I12: =SABR_Base!I10+SABR_Shocks!$C$6*SABR_Shocks!I25 -> 0.3637469 | J12: =SABR_Base!J10+SABR_Shocks!$C$6*SABR_Shocks!J25 -> 0.3586371 | ... L12: =SABR_Base!L10+SABR_Shocks!$C$6*SABR_Shocks!L25 -> 0.3217531
B13: 5Y | C13: =SABR_Base!C11+SABR_Shocks!$C$6*SABR_Shocks!C26 -> 0.4678257 | D13: =SABR_Base!D11+SABR_Shocks!$C$6*SABR_Shocks!D26 -> 0.4390545 | E13: =SABR_Base!E11+SABR_Shocks!$C$6*SABR_Shocks!E26 -> 0.4294704 | F13: =SABR_Base!F11+SABR_Shocks!$C$6*SABR_Shocks!F26 -> 0.409622 | G13: =SABR_Base!G11+SABR_Shocks!$C$6*SABR_Shocks!G26 -> 0.3917112 | H13: =SABR_Base!H11+SABR_Shocks!$C$6*SABR_Shocks!H26 -> 0.3715816 | I13: =SABR_Base!I11+SABR_Shocks!$C$6*SABR_Shocks!I26 -> 0.3617005 | J13: =SABR_Base!J11+SABR_Shocks!$C$6*SABR_Shocks!J26 -> 0.3465065 | ... L13: =SABR_Base!L11+SABR_Shocks!$C$6*SABR_Shocks!L26 -> 0.3058344
B14: 10Y | C14: =SABR_Base!C12+SABR_Shocks!$C$6*SABR_Shocks!C27 -> 0.4340238 | D14: =SABR_Base!D12+SABR_Shocks!$C$6*SABR_Shocks!D27 -> 0.4293823 | E14: =SABR_Base!E12+SABR_Shocks!$C$6*SABR_Shocks!E27 -> 0.4109982 | F14: =SABR_Base!F12+SABR_Shocks!$C$6*SABR_Shocks!F27 -> 0.4001201 | G14: =SABR_Base!G12+SABR_Shocks!$C$6*SABR_Shocks!G27 -> 0.3791786 | H14: =SABR_Base!H12+SABR_Shocks!$C$6*SABR_Shocks!H27 -> 0.3510658 | I14: =SABR_Base!I12+SABR_Shocks!$C$6*SABR_Shocks!I27 -> 0.3350689 | J14: =SABR_Base!J12+SABR_Shocks!$C$6*SABR_Shocks!J27 -> 0.3231581 | ... L14: =SABR_Base!L12+SABR_Shocks!$C$6*SABR_Shocks!L27 -> 0.2843721
B15: 20Y | C15: =SABR_Base!C13+SABR_Shocks!$C$6*SABR_Shocks!C28 -> 0.4185635 | D15: =SABR_Base!D13+SABR_Shocks!$C$6*SABR_Shocks!D28 -> 0.3999329 | E15: =SABR_Base!E13+SABR_Shocks!$C$6*SABR_Shocks!E28 -> 0.3815686 | F15: =SABR_Base!F13+SABR_Shocks!$C$6*SABR_Shocks!F28 -> 0.3782964 | G15: =SABR_Base!G13+SABR_Shocks!$C$6*SABR_Shocks!G28 -> 0.3475698 | H15: =SABR_Base!H13+SABR_Shocks!$C$6*SABR_Shocks!H28 -> 0.3328243 | I15: =SABR_Base!I13+SABR_Shocks!$C$6*SABR_Shocks!I28 -> 0.3180937 | J15: =SABR_Base!J13+SABR_Shocks!$C$6*SABR_Shocks!J28 -> 0.3099344 | ... L15: =SABR_Base!L13+SABR_Shocks!$C$6*SABR_Shocks!L28 -> 0.267185
