Workbook

Sheet ReadMe
B2: FRTB IMA — Full Revaluation PnL Vectors for Expected Shortfall (ES)
B3: Illustrative workbook — trade 123456, valuation date 7/23/2026. Demonstrates the mechanics of a full-revaluation Stressed PnL vector: PnL = StressedNPV − BaseNPV, built curve-by-curve and then combined cross-risk-class.
B5: Purpose
B6: Illustrate, end to end, how a full-reval ES PnL vector is constructed: base curve objects → shocked curve objects (10 scenarios, stress date 20-Nov-2008) → base/stressed NPV via full reval → PnL vector, both cross-risk-class and isolated by risk class (IR / Credit / FX).
B8: Tabs
B9: ReadMe | Trade_Info | Curves (Base, Shift Illustration, Shocks+Shocked aligned side-by-side) | SABR (Base, Shocks, Shocked - ATM/RHO/NU/Combined aligned horizontally per scenario) | NPV_Engine | PnL_Summary
B11: Curve shift mechanic
B12: gxlCurveDiscShift is simulated with a sequential (cascading) bootstrap: the simple forward rate implied by the BASE curve between consecutive tenors is bumped by the scenario shock (bps), and the SHOCKED discount factor for tenor i is solved from the SHOCKED discount factor at tenor i-1 (not the base one). 3M is bumped first; 6M relies on the bumped 3M; and so on to 30Y — exactly mirroring the described gxlCurveDiscShift behaviour.
B14: SABR surface mechanic
B15: Each of ATM / RHO / NU is a 10x10 grid (expiry x tenor). Each scenario applies a parameter-level shock size to every grid point, scaled by a per-cell Sensitivity Factor grid (captures the typical stress-period pattern of larger moves at short expiries/tenors). The result is a full shocked vol surface per parameter per scenario, exactly as gxlCurveDiscShift-style functions return a shocked object for curves.
B17: NPV engine
B18: NPV is an ILLUSTRATIVE simplified full-reval pricer (not a production pricer) that consumes: SOFR/ESTRN discount factors (IR discounting), the SABR ATM grid point matching the trade's expiry/tenor (IR_VOL / optionality), Treasury/Agency_FNMA/Eur_Govt discount factors (Credit spread proxy), and the EURUSD curve (FX discount/forward proxy). Base NPV = pricer with ALL curves at BASE. Stressed NPV = pricer with the relevant curve set SHOCKED for scenario s.
... B27: All curve levels, shock sizes and SABR parameters are illustrative placeholder assumptions chosen for demonstration purposes only — they are not calibrated to actual 20-Nov-2008 market data and this is not a production pricing/risk engine.

Sheet Trade_Info
A1: Trade & Valuation Info
A3: Trade ID | B3: 123456
A4: Valuation Date | B4: 7/23/2026
A5: Stress / Shock anchor date | B5: 11/20/2008
A6: Number of scenarios | B6: 10
A7: Notional (USD) | B7: 10000000
A8: Product | B8: EUR-underlying payer swaption vs USD-collateral discounting
A9: Representative discounting tenor | B9: 1Y
A10: Representative SABR grid point (Expiry x Tenor) | B10: 1Y x 10Y
A12: Curve list, MDO used, and risk-class mapping
A13: Curve (MDO) | B13: Risk Class | C13: Notes
A14: Agency_FNMA | B14: Credit | C14: Credit — GSE/agency spread curve
A15: Eur_Govt | B15: Credit | C15: Credit — EUR sovereign curve
A16: SOFR | B16: IR | C16: IR_RATE — USD OIS/SOFR discounting curve
A17: Treasury | B17: Credit | C17: Credit — US Treasury (sovereign benchmark) curve
A18: Sabr_Swaption | B18: IR | C18: IR_VOL — SABR surface (ATM, RHO, NU); handled on SABR_* tabs
A19: EURUSD | B19: FX | C19: FX_RATE — EUR/USD FX curve
A20: ESTRN | B20: IR | C20: IR — EUR €STR discounting curve
A22: Liquidity-Horizon Curve Inclusion by Risk Class
A24: Class | B24: LH10 | C24: LH20 | D24: LH40 | E24: LH60
A25: Credit | B25: Agency_FNMA + Eur_Govt | C25: Agency_FNMA + Eur_Govt | D25: Agency_FNMA only | E25: —
A26: IR | B26: SOFR + ESTRN + Swaption | C26: Swaption only | D26: Swaption only | E26: Swaption only
A27: FX | B27: EURUSD | C27: — | D27: — | E27: —
A28: Cross | B28: all six | C28: Agency_FNMA + Eur_Govt + Swaption | D28: Agency_FNMA + Swaption | E28: Swaption only
A30: Rule: at horizon bucket T, a curve is shocked only if its own assigned Liquidity Horizon >= T. Note: IR LH20 = Swaption only (updated from the original placeholder dash once the LH20 bucket was added).

Sheet Curves
A1: Curve Objects — Base -> Shift Mechanics -> Shocks -> Shocked Curves (Combined)
A2: Trade 123456 | Val date 7/23/2026 | Stress anchor 20-Nov-2008
A3: SECTION 1 - BASE CURVE OBJECTS: Discount Factors (as of 7/23/2026)
A5: Curve | B5: Risk Class | C5: 3M | D5: 6M | E5: 1Y | F5: 2Y | G5: 3Y | H5: 5Y | I5: 10Y | J5: 20Y | K5: 30Y
A6: Tenor Date | C6: 10/23/2026 | D6: 1/23/2027 | E6: 7/23/2027 | F6: 7/23/2028 | G6: 7/23/2029 | H6: 7/23/2031 | I6: 7/23/2036 | J6: 7/23/2046 | K6: 7/23/2056
A7: Year Frac (t) | C7: 0.25 | D7: 0.5 | E7: 1 | F7: 2 | G7: 3 | H7: 5 | I7: 10 | J7: 20 | K7: 30
A8: SOFR | B8: IR | C8: 0.989298 | D8: 0.978693 | E8: 0.957768 | F8: 0.917044 | G8: 0.877788 | H8: 0.803523 | I8: 0.640824 | J8: 0.410656 | K8: 0.263158
A9: ESTRN | B9: IR | C9: 0.992271 | D9: 0.984583 | E9: 0.96933 | F9: 0.939319 | G9: 0.909964 | H9: 0.85321 | I9: 0.722527 | J9: 0.522046 | K9: 0.377192
A10: Treasury | B10: Credit | C10: 0.989546 | D10: 0.979182 | E10: 0.958726 | F10: 0.91888 | G10: 0.880425 | H10: 0.80755 | I10: 0.647265 | J10: 0.418952 | K10: 0.271173
A11: Agency_FNMA | B11: Credit | C11: 0.988557 | D11: 0.977226 | E11: 0.954899 | F11: 0.911558 | G11: 0.869924 | H11: 0.79156 | I11: 0.621885 | J11: 0.386741 | K11: 0.240508
A12: Eur_Govt | B12: Credit | C12: 0.991775 | D12: 0.983598 | E12: 0.967393 | F12: 0.935569 | G12: 0.904521 | H12: 0.84472 | I12: 0.70822 | J12: 0.501576 | K12: 0.355226
A13: EURUSD | B13: FX | C13: 0.990041 | D13: 0.980162 | E13: 0.960645 | F13: 0.922563 | G13: 0.885724 | H13: 0.815666 | I13: 0.66034 | J13: 0.436049 | K13: 0.287941
A15: Base DF values are illustrative placeholder inputs (blue), not calibrated to a real curve build.
A17: SECTION 2 - gxlCurveDiscShift STEP-BY-STEP ILLUSTRATION (Curve = SOFR, Scenario 1)
A18: Sequential / cascading bootstrap: base forward rate (Section 1) + scenario shock (bps, Section 3) = shocked forward rate; the SHOCKED discount factor at tenor i is solved off the SHOCKED discount factor at tenor i-1 (not the base one). 3M is shocked first and feeds into 6M, which feeds into 1Y, and so on to 30Y.
A21: Tenor | B21: t | C21: Base DF (prior) | D21: Base DF (current) | E21: Base Fwd Rate (simple, ann.) | F21: Shock (bps) | G21: Shocked Fwd Rate | H21: Shocked DF (current) | I21: Formula logic
A22: 3M | B22: 0.25 | C22: 1 | D22: =C8 -> 0.989298 | E22: =(C22/D22-1)/(0.25-0) -> 0.043271087 | F22: =C37 -> -40.9 | G22: =E22+F22/10000 -> 0.039181087 | H22: =1/(1+G22*(0.25-0)) -> 0.99029974 | I22: Anchors at DF=1, t=0
A23: 6M | B23: 0.5 | C23: =C8 -> 0.989298 | D23: =D8 -> 0.978693 | E23: =(C23/D23-1)/(0.5-0.25) -> 0.04334352 | F23: =D37 -> 34.3 | G23: =E23+F23/10000 -> 0.04677352 | H23: =H22/(1+G23*(0.5-0.25)) -> 0.97885364 | I23: Uses SHOCKED DF from 3M (row above), not base
A24: 1Y | B24: 1 | C24: =D8 -> 0.978693 | D24: =E8 -> 0.957768 | E24: =(C24/D24-1)/(1-0.5) -> 0.043695342 | F24: =E37 -> 31.4 | G24: =E24+F24/10000 -> 0.046835342 | H24: =H23/(1+G24*(1-0.5)) -> 0.95645567 | I24: Uses SHOCKED DF from 6M (row above), not base
A25: 2Y | B25: 2 | C25: =E8 -> 0.957768 | D25: =F8 -> 0.917044 | E25: =(C25/D25-1)/(2-1) -> 0.044407902 | F25: =F37 -> -21.7 | G25: =E25+F25/10000 -> 0.042237902 | H25: =H24/(1+G25*(2-1)) -> 0.9176942 | I25: Uses SHOCKED DF from 1Y (row above), not base
A26: 3Y | B26: 3 | C26: =F8 -> 0.917044 | D26: =G8 -> 0.877788 | E26: =(C26/D26-1)/(3-2) -> 0.044721505 | F26: =G37 -> -13 | G26: =E26+F26/10000 -> 0.043421505 | H26: =H25/(1+G26*(3-2)) -> 0.87950478 | I26: Uses SHOCKED DF from 2Y (row above), not base
A27: 5Y | B27: 5 | C27: =G8 -> 0.877788 | D27: =H8 -> 0.803523 | E27: =(C27/D27-1)/(5-3) -> 0.046212118 | F27: =H37 -> 6.1 | G27: =E27+F27/10000 -> 0.046822118 | H27: =H26/(1+G27*(5-3)) -> 0.80419642 | I27: Uses SHOCKED DF from 3Y (row above), not base
A28: 10Y | B28: 10 | C28: =H8 -> 0.803523 | D28: =I8 -> 0.640824 | E28: =(C28/D28-1)/(10-5) -> 0.050778061 | F28: =I37 -> 2.9 | G28: =E28+F28/10000 -> 0.051068061 | H28: =H27/(1+G28*(10-5)) -> 0.64062025 | I28: Uses SHOCKED DF from 5Y (row above), not base
A29: 20Y | B29: 20 | C29: =I8 -> 0.640824 | D29: =J8 -> 0.410656 | E29: =(C29/D29-1)/(20-10) -> 0.056048858 | F29: =J37 -> 2.1 | G29: =E29+F29/10000 -> 0.056258858 | H29: =H28/(1+G29*(20-10)) -> 0.40997372 | I29: Uses SHOCKED DF from 10Y (row above), not base
A30: 30Y | B30: 30 | C30: =J8 -> 0.410656 | D30: =K8 -> 0.263158 | E30: =(C30/D30-1)/(30-20) -> 0.056049218 | F30: =K37 -> 1.2 | G30: =E30+F30/10000 -> 0.056169218 | H30: =H29/(1+G30*(30-20)) -> 0.2625189 | I30: Uses SHOCKED DF from 20Y (row above), not base
A32: This exact column-H formula pattern is replicated for all 6 curves x 10 scenarios in Sections 3/4 below.
A34: SECTION 3 - SHOCK VECTORS: Forward-Rate Shock (bps), 10 Scenarios (anchor 20-Nov-2008) | M34: SECTION 4 - SHOCKED CURVE OBJECTS (gxlCurveDiscShift output): Discount Factors
A36: Scenario 1 | C36: 3M | D36: 6M | E36: 1Y | F36: 2Y | G36: 3Y | H36: 5Y | I36: 10Y | J36: 20Y | K36: 30Y | M36: Scenario 1 | O36: 3M | P36: 6M | Q36: 1Y | R36: 2Y | S36: 3Y | T36: 5Y | U36: 10Y | V36: 20Y | W36: 30Y
A37: SOFR | B37: IR | C37: -40.9 | D37: 34.3 | E37: 31.4 | F37: -21.7 | G37: -13 | H37: 6.1 | I37: 2.9 | J37: 2.1 | K37: 1.2 | M37: SOFR | N37: IR | O37: =1/(1+(((1/C8-1)/(0.25-0))+C37/10000)*(0.25-0)) -> 0.99029974 | P37: =O37/(1+(((C8/D8-1)/(0.5-0.25))+D37/10000)*(0.5-0.25)) -> 0.97885364 | Q37: =P37/(1+(((D8/E8-1)/(1-0.5))+E37/10000)*(1-0.5)) -> 0.95645567 | R37: =Q37/(1+(((E8/F8-1)/(2-1))+F37/10000)*(2-1)) -> 0.9176942 | S37: =R37/(1+(((F8/G8-1)/(3-2))+G37/10000)*(3-2)) -> 0.87950478 | T37: =S37/(1+(((G8/H8-1)/(5-3))+H37/10000)*(5-3)) -> 0.80419642 | U37: =T37/(1+(((H8/I8-1)/(10-5))+I37/10000)*(10-5)) -> 0.64062025 | V37: =U37/(1+(((I8/J8-1)/(20-10))+J37/10000)*(20-10)) -> 0.40997372 | W37: =V37/(1+(((J8/K8-1)/(30-20))+K37/10000)*(30-20)) -> 0.2625189
A38: ESTRN | B38: IR | C38: -35.5 | D38: 31.9 | E38: 24.1 | F38: 18.3 | G38: -8.9 | H38: 5.7 | I38: 2.8 | J38: 1.3 | K38: 0.6 | M38: ESTRN | N38: IR | O38: =1/(1+(((1/C9-1)/(0.25-0))+C38/10000)*(0.25-0)) -> 0.9931456 | P38: =O38/(1+(((C9/D9-1)/(0.5-0.25))+D38/10000)*(0.5-0.25)) -> 0.98467164 | Q38: =P38/(1+(((D9/E9-1)/(1-0.5))+E38/10000)*(1-0.5)) -> 0.96826858 | R38: =Q38/(1+(((E9/F9-1)/(2-1))+F38/10000)*(2-1)) -> 0.93662947 | S38: =R38/(1+(((F9/G9-1)/(3-2))+G38/10000)*(3-2)) -> 0.90814151 | T38: =S38/(1+(((G9/H9-1)/(5-3))+H38/10000)*(5-3)) -> 0.85059198 | U38: =T38/(1+(((H9/I9-1)/(10-5))+I38/10000)*(10-5)) -> 0.71945701 | V38: =U38/(1+(((I9/J9-1)/(20-10))+J38/10000)*(20-10)) -> 0.51934004 | W38: =V38/(1+(((J9/K9-1)/(30-20))+K38/10000)*(30-20)) -> 0.37507427
A39: Treasury | B39: Credit | C39: 49.9 | D39: 46.7 | E39: -34.6 | F39: 21.6 | G39: 13 | H39: 7.2 | I39: 4.1 | J39: 1.9 | K39: 1.2 | M39: Treasury | N39: Credit | O39: =1/(1+(((1/C10-1)/(0.25-0))+C39/10000)*(0.25-0)) -> 0.98832595 | P39: =O39/(1+(((C10/D10-1)/(0.5-0.25))+D39/10000)*(0.5-0.25)) -> 0.97684621 | Q39: =P39/(1+(((D10/E10-1)/(1-0.5))+E39/10000)*(1-0.5)) -> 0.95806183 | R39: =Q39/(1+(((E10/F10-1)/(2-1))+F39/10000)*(2-1)) -> 0.91634638 | S39: =R39/(1+(((F10/G10-1)/(3-2))+G39/10000)*(3-2)) -> 0.87690515 | T39: =S39/(1+(((G10/H10-1)/(5-3))+H39/10000)*(5-3)) -> 0.80326054 | U39: =T39/(1+(((H10/I10-1)/(10-5))+I39/10000)*(10-5)) -> 0.64277078 | V39: =U39/(1+(((I10/J10-1)/(20-10))+J39/10000)*(20-10)) -> 0.41553203 | W39: =V39/(1+(((J10/K10-1)/(30-20))+K39/10000)*(30-20)) -> 0.26875063
A40: Agency_FNMA | B40: Credit | C40: 75.2 | D40: 60.7 | E40: 51.5 | F40: 44.3 | G40: 26.8 | H40: 15.7 | I40: -6.2 | J40: 3.8 | K40: 2.5 | M40: Agency_FNMA | N40: Credit | O40: =1/(1+(((1/C11-1)/(0.25-0))+C40/10000)*(0.25-0)) -> 0.98672319 | P40: =O40/(1+(((C11/D11-1)/(0.5-0.25))+D40/10000)*(0.5-0.25)) -> 0.97395218 | Q40: =P40/(1+(((D11/E11-1)/(1-0.5))+E40/10000)*(1-0.5)) -> 0.94931135 | R40: =Q40/(1+(((E11/F11-1)/(2-1))+F40/10000)*(2-1)) -> 0.90240774 | S40: =R40/(1+(((F11/G11-1)/(3-2))+G40/10000)*(3-2)) -> 0.8589947 | T40: =S40/(1+(((G11/H11-1)/(5-3))+H40/10000)*(5-3)) -> 0.7793884 | U40: =T40/(1+(((H11/I11-1)/(10-5))+I40/10000)*(10-5)) -> 0.6138174 | V40: =U40/(1+(((I11/J11-1)/(20-10))+J40/10000)*(20-10)) -> 0.38082393 | W40: =V40/(1+(((J11/K11-1)/(30-20))+K40/10000)*(30-20)) -> 0.23646064
A41: Eur_Govt | B41: Credit | C41: 64.8 | D41: 54.8 | E41: 47.2 | F41: 28 | G41: 18.8 | H41: 10.1 | I41: 5.2 | J41: 3 | K41: -1.8 | M41: Eur_Govt | N41: Credit | O41: =1/(1+(((1/C12-1)/(0.25-0))+C41/10000)*(0.25-0)) -> 0.9901841 | P41: =O41/(1+(((C12/D12-1)/(0.5-0.25))+D41/10000)*(0.5-0.25)) -> 0.98068775 | Q41: =P41/(1+(((D12/E12-1)/(1-0.5))+E41/10000)*(1-0.5)) -> 0.96229709 | R41: =Q41/(1+(((E12/F12-1)/(2-1))+F41/10000)*(2-1)) -> 0.92812746 | S41: =R41/(1+(((F12/G12-1)/(3-2))+G41/10000)*(3-2)) -> 0.89569839 | T41: =S41/(1+(((G12/H12-1)/(5-3))+H41/10000)*(5-3)) -> 0.83490567 | U41: =T41/(1+(((H12/I12-1)/(10-5))+I41/10000)*(10-5)) -> 0.69846902 | V41: =U41/(1+(((I12/J12-1)/(20-10))+J41/10000)*(20-10)) -> 0.49362138 | W41: =V41/(1+(((J12/K12-1)/(30-20))+K41/10000)*(30-20)) -> 0.35003861
A42: EURUSD | B42: FX | C42: 23.9 | D42: 26.9 | E42: 18.9 | F42: 16.3 | G42: 11 | H42: 5.2 | I42: 3.4 | J42: 1.9 | K42: 1.2 | M42: EURUSD | N42: FX | O42: =1/(1+(((1/C13-1)/(0.25-0))+C42/10000)*(0.25-0)) -> 0.98945569 | P42: =O42/(1+(((C13/D13-1)/(0.5-0.25))+D42/10000)*(0.5-0.25)) -> 0.97893077 | Q42: =P42/(1+(((D13/E13-1)/(1-0.5))+E42/10000)*(1-0.5)) -> 0.95855049 | R42: =Q42/(1+(((E13/F13-1)/(2-1))+F42/10000)*(2-1)) -> 0.91911276 | S42: =R42/(1+(((F13/G13-1)/(3-2))+G42/10000)*(3-2)) -> 0.88148062 | T42: =S42/(1+(((G13/H13-1)/(5-3))+H42/10000)*(5-3)) -> 0.81098155 | U42: =T42/(1+(((H13/I13-1)/(10-5))+I42/10000)*(10-5)) -> 0.65564525 | V42: =U42/(1+(((I13/J13-1)/(20-10))+J42/10000)*(20-10)) -> 0.43240635 | W42: =V42/(1+(((J13/K13-1)/(30-20))+K42/10000)*(30-20)) -> 0.28530953
A44: Scenario 2 | C44: 3M | D44: 6M | E44: 1Y | F44: 2Y | G44: 3Y | H44: 5Y | I44: 10Y | J44: 20Y | K44: 30Y | M44: Scenario 2 | O44: 3M | P44: 6M | Q44: 1Y | R44: 2Y | S44: 3Y | T44: 5Y | U44: 10Y | V44: 20Y | W44: 30Y
A45: SOFR | B45: IR | C45: 45.8 | D45: 45.7 | E45: 34.7 | F45: 25.1 | G45: 14.8 | H45: 7.9 | I45: 4.1 | J45: 2.4 | K45: 1.4 | M45: SOFR | N45: IR | O45: =1/(1+(((1/C8-1)/(0.25-0))+C45/10000)*(0.25-0)) -> 0.98817864 | P45: =O45/(1+(((C8/D8-1)/(0.5-0.25))+D45/10000)*(0.5-0.25)) -> 0.97648197 | Q45: =P45/(1+(((D8/E8-1)/(1-0.5))+E45/10000)*(1-0.5)) -> 0.95398447 | R45: =Q45/(1+(((E8/F8-1)/(2-1))+F45/10000)*(2-1)) -> 0.9112314 | S45: =R45/(1+(((F8/G8-1)/(3-2))+G45/10000)*(3-2)) -> 0.87099034 | T45: =S45/(1+(((G8/H8-1)/(5-3))+H45/10000)*(5-3)) -> 0.79614896 | U45: =T45/(1+(((H8/I8-1)/(10-5))+I45/10000)*(10-5)) -> 0.63390669 | V45: =U45/(1+(((I8/J8-1)/(20-10))+J45/10000)*(20-10)) -> 0.40559941 | W45: =V45/(1+(((J8/K8-1)/(30-20))+K45/10000)*(30-20)) -> 0.25968464
A46: ESTRN | B46: IR | C46: 34.7 | D46: 37.4 | E46: -28.1 | F46: 20.8 | G46: 10.6 | H46: 5.6 | I46: -3.3 | J46: 1.5 | K46: 0.7 | M46: ESTRN | N46: IR | O46: =1/(1+(((1/C9-1)/(0.25-0))+C46/10000)*(0.25-0)) -> 0.99141759 | P46: =O46/(1+(((C9/D9-1)/(0.5-0.25))+D46/10000)*(0.5-0.25)) -> 0.98282438 | Q46: =P46/(1+(((D9/E9-1)/(1-0.5))+E46/10000)*(1-0.5)) -> 0.9689389 | R46: =Q46/(1+(((E9/F9-1)/(2-1))+F46/10000)*(2-1)) -> 0.93705128 | S46: =R46/(1+(((F9/G9-1)/(3-2))+G46/10000)*(3-2)) -> 0.90683595 | T46: =S46/(1+(((G9/H9-1)/(5-3))+H46/10000)*(5-3)) -> 0.84938506 | U46: =T46/(1+(((H9/I9-1)/(10-5))+I46/10000)*(10-5)) -> 0.72029436 | V46: =U46/(1+(((I9/J9-1)/(20-10))+J46/10000)*(20-10)) -> 0.51986943 | W46: =V46/(1+(((J9/K9-1)/(30-20))+K46/10000)*(30-20)) -> 0.37542949
A47: Treasury | B47: Credit | C47: 53 | D47: 50.5 | E47: 36.1 | F47: 29.7 | G47: 16.7 | H47: 8.5 | I47: 4.5 | J47: 2.2 | K47: 1.4 | M47: Treasury | N47: Credit | O47: =1/(1+(((1/C10-1)/(0.25-0))+C47/10000)*(0.25-0)) -> 0.98825026 | P47: =O47/(1+(((C10/D10-1)/(0.5-0.25))+D47/10000)*(0.5-0.25)) -> 0.97667968 | Q47: =P47/(1+(((D10/E10-1)/(1-0.5))+E47/10000)*(1-0.5)) -> 0.95458892 | R47: =Q47/(1+(((E10/F10-1)/(2-1))+F47/10000)*(2-1)) -> 0.9123179 | S47: =R47/(1+(((F10/G10-1)/(3-2))+G47/10000)*(3-2)) -> 0.87274104 | T47: =S47/(1+(((G10/H10-1)/(5-3))+H47/10000)*(5-3)) -> 0.79925579 | U47: =T47/(1+(((H10/I10-1)/(10-5))+I47/10000)*(10-5)) -> 0.63946383 | V47: =U47/(1+(((I10/J10-1)/(20-10))+J47/10000)*(20-10)) -> 0.41331402 | W47: =V47/(1+(((J10/K10-1)/(30-20))+K47/10000)*(30-20)) -> 0.26728153
A48: Agency_FNMA | B48: Credit | C48: 79.9 | D48: -82.8 | E48: 61.9 | F48: -43.5 | G48: 33.6 | H48: 16.8 | I48: 8.2 | J48: 4.2 | K48: 3 | M48: Agency_FNMA | N48: Credit | O48: =1/(1+(((1/C11-1)/(0.25-0))+C48/10000)*(0.25-0)) -> 0.9866088 | P48: =O48/(1+(((C11/D11-1)/(0.5-0.25))+D48/10000)*(0.5-0.25)) -> 0.97729995 | Q48: =P48/(1+(((D11/E11-1)/(1-0.5))+E48/10000)*(1-0.5)) -> 0.95209186 | R48: =Q48/(1+(((E11/F11-1)/(2-1))+F48/10000)*(2-1)) -> 0.91266819 | S48: =R48/(1+(((F11/G11-1)/(3-2))+G48/10000)*(3-2)) -> 0.86819957 | T48: =S48/(1+(((G11/H11-1)/(5-3))+H48/10000)*(5-3)) -> 0.78758301 | U48: =T48/(1+(((H11/I11-1)/(10-5))+I48/10000)*(10-5)) -> 0.61677378 | V48: =U48/(1+(((I11/J11-1)/(20-10))+J48/10000)*(20-10)) -> 0.38256318 | W48: =V48/(1+(((J11/K11-1)/(30-20))+K48/10000)*(30-20)) -> 0.23746685
A49: Eur_Govt | B49: Credit | C49: 72.6 | D49: -67.8 | E49: 49 | F49: 37.3 | G49: 20.2 | H49: 11.4 | I49: 5.8 | J49: 3 | K49: -2.3 | M49: Eur_Govt | N49: Credit | O49: =1/(1+(((1/C12-1)/(0.25-0))+C49/10000)*(0.25-0)) -> 0.98999294 | P49: =O49/(1+(((C12/D12-1)/(0.5-0.25))+D49/10000)*(0.5-0.25)) -> 0.9834839 | Q49: =P49/(1+(((D12/E12-1)/(1-0.5))+E49/10000)*(1-0.5)) -> 0.96495558 | R49: =Q49/(1+(((E12/F12-1)/(2-1))+F49/10000)*(2-1)) -> 0.9298575 | S49: =R49/(1+(((F12/G12-1)/(3-2))+G49/10000)*(3-2)) -> 0.89724675 | T49: =S49/(1+(((G12/H12-1)/(5-3))+H49/10000)*(5-3)) -> 0.8361463 | U49: =T49/(1+(((H12/I12-1)/(10-5))+I49/10000)*(10-5)) -> 0.6993314 | V49: =U49/(1+(((I12/J12-1)/(20-10))+J49/10000)*(20-10)) -> 0.49423084 | W49: =V49/(1+(((J12/K12-1)/(30-20))+K49/10000)*(30-20)) -> 0.3505951
...

Sheet SABR
A1: SABR Swaption Vol Surfaces — Base -> Scenario Shocks -> Shocked Surfaces, ATM/RHO/NU/Combined aligned
A2: Swabr_Swaption (IR_VOL) | Trade 123456 | Stress anchor 20-Nov-2008
A3: SECTION 1 - BASE SABR SURFACES (ATM, RHO, NU, Combined Effective Vol aligned horizontally)
B5: Param: ATM | N5: Param: RHO | Z5: Param: NU | AL5: Combined Effective ATM Vol (Hagan approx, beta=1)
B6: Expiry \ Tenor | C6: 1M | D6: 3M | E6: 6M | F6: 1Y | G6: 2Y | H6: 3Y | I6: 5Y | J6: 10Y | K6: 20Y | L6: 30Y | N6: Expiry \ Tenor | O6: 1M | P6: 3M | Q6: 6M | R6: 1Y | S6: 2Y | T6: 3Y | U6: 5Y | V6: 10Y | W6: 20Y | X6: 30Y | Z6: Expiry \ Tenor | AA6: 1M | AB6: 3M | AC6: 6M | AD6: 1Y | AE6: 2Y | AF6: 3Y | AG6: 5Y | AH6: 10Y | AI6: 20Y | AJ6: 30Y | AL6: Expiry \ Tenor | AM6: 1M | AN6: 3M | AO6: 6M | AP6: 1Y | AQ6: 2Y | AR6: 3Y | AS6: 5Y | AT6: 10Y | AU6: 20Y | AV6: 30Y
B7: 1M | C7: 0.5465 | D7: 0.5264 | E7: 0.5197 | F7: 0.4914 | G7: 0.4841 | H7: 0.464 | I7: 0.4412 | J7: 0.4335 | K7: 0.4074 | L7: 0.3987 | N7: 1M | O7: -0.3586 | P7: -0.3387 | Q7: -0.3126 | R7: -0.2851 | S7: -0.2797 | T7: -0.2583 | U7: -0.2308 | V7: -0.2049 | W7: -0.1929 | X7: -0.1771 | Z7: 1M | AA7: 0.8595 | AB7: 0.8187 | AC7: 0.8127 | AD7: 0.7791 | AE7: 0.754 | AF7: 0.7312 | AG7: 0.7128 | AH7: 0.7008 | AI7: 0.6658 | AJ7: 0.6516 | AL7: 1M | AM7: =C7*(1+(((2-3*O7^2)/24*AA7^2)+(O7*AA7*C7/4))*0.0833333333333333) -> 0.54684506 | AN7: =D7*(1+(((2-3*P7^2)/24*AB7^2)+(P7*AB7*D7/4))*0.0833333333333333) -> 0.52682781 | AO7: =E7*(1+(((2-3*Q7^2)/24*AC7^2)+(Q7*AC7*E7/4))*0.0833333333333333) -> 0.5203048 | AP7: =F7*(1+(((2-3*R7^2)/24*AD7^2)+(R7*AD7*F7/4))*0.0833333333333333) -> 0.4921014 | AQ7: =G7*(1+(((2-3*S7^2)/24*AE7^2)+(S7*AE7*G7/4))*0.0833333333333333) -> 0.4847573 | AR7: =H7*(1+(((2-3*T7^2)/24*AF7^2)+(T7*AF7*H7/4))*0.0833333333333333) -> 0.46470322 | AS7: =I7*(1+(((2-3*U7^2)/24*AG7^2)+(U7*AG7*I7/4))*0.0833333333333333) -> 0.44196516 | AT7: =J7*(1+(((2-3*V7^2)/24*AH7^2)+(V7*AH7*J7/4))*0.0833333333333333) -> 0.43432319 | ... AV7: =L7*(1+(((2-3*X7^2)/24*AJ7^2)+(X7*AJ7*L7/4))*0.0833333333333333) -> 0.39943809
B8: 3M | C8: 0.5361 | D8: 0.5141 | E8: 0.501 | F8: 0.4746 | G8: 0.4579 | H8: 0.4441 | I8: 0.4369 | J8: 0.4152 | K8: 0.3963 | L8: 0.385 | N8: 3M | O8: -0.3315 | P8: -0.3151 | Q8: -0.2858 | R8: -0.2682 | S8: -0.2579 | T8: -0.2318 | U8: -0.2134 | V8: -0.1869 | W8: -0.1704 | X8: -0.1598 | Z8: 3M | AA8: 0.8374 | AB8: 0.7979 | AC8: 0.7817 | AD8: 0.7663 | AE8: 0.7319 | AF8: 0.7164 | AG8: 0.6852 | AH8: 0.6756 | AI8: 0.6553 | AJ8: 0.6292 | AL8: 3M | AM8: =C8*(1+(((2-3*O8^2)/24*AA8^2)+(O8*AA8*C8/4))*0.25) -> 0.53765454 | AN8: =D8*(1+(((2-3*P8^2)/24*AB8^2)+(P8*AB8*D8/4))*0.25) -> 0.5157501 | AO8: =E8*(1+(((2-3*Q8^2)/24*AC8^2)+(Q8*AC8*E8/4))*0.25) -> 0.5030917 | AP8: =F8*(1+(((2-3*R8^2)/24*AD8^2)+(R8*AD8*F8/4))*0.25) -> 0.47688634 | AQ8: =G8*(1+(((2-3*S8^2)/24*AE8^2)+(S8*AE8*G8/4))*0.25) -> 0.46002674 | AR8: =H8*(1+(((2-3*T8^2)/24*AF8^2)+(T8*AF8*H8/4))*0.25) -> 0.44641876 | AS8: =I8*(1+(((2-3*U8^2)/24*AG8^2)+(U8*AG8*I8/4))*0.25) -> 0.43913707 | AT8: =J8*(1+(((2-3*V8^2)/24*AH8^2)+(V8*AH8*J8/4))*0.25) -> 0.41758081 | ... AV8: =L8*(1+(((2-3*X8^2)/24*AJ8^2)+(X8*AJ8*L8/4))*0.25) -> 0.38712229
B9: 6M | C9: 0.5242 | D9: 0.4963 | E9: 0.4872 | F9: 0.4686 | G9: 0.4516 | H9: 0.4325 | I9: 0.4235 | J9: 0.4089 | K9: 0.3828 | L9: 0.3699 | N9: 6M | O9: -0.3199 | P9: -0.2876 | Q9: -0.2693 | R9: -0.2429 | S9: -0.2269 | T9: -0.2182 | U9: -0.1967 | V9: -0.1716 | W9: -0.1651 | X9: -0.1369 | Z9: 6M | AA9: 0.7989 | AB9: 0.7757 | AC9: 0.7523 | AD9: 0.7443 | AE9: 0.7093 | AF9: 0.6894 | AG9: 0.67 | AH9: 0.6574 | AI9: 0.6194 | AJ9: 0.6045 | AL9: 6M | AM9: =C9*(1+(((2-3*O9^2)/24*AA9^2)+(O9*AA9*C9/4))*0.5) -> 0.52722206 | AN9: =D9*(1+(((2-3*P9^2)/24*AB9^2)+(P9*AB9*D9/4))*0.5) -> 0.50033027 | AO9: =E9*(1+(((2-3*Q9^2)/24*AC9^2)+(Q9*AC9*E9/4))*0.5) -> 0.49142801 | AP9: =F9*(1+(((2-3*R9^2)/24*AD9^2)+(R9*AD9*F9/4))*0.5) -> 0.47349686 | AQ9: =G9*(1+(((2-3*S9^2)/24*AE9^2)+(S9*AE9*G9/4))*0.5) -> 0.45623289 | AR9: =H9*(1+(((2-3*T9^2)/24*AF9^2)+(T9*AF9*H9/4))*0.5) -> 0.43693584 | AS9: =I9*(1+(((2-3*U9^2)/24*AG9^2)+(U9*AG9*I9/4))*0.5) -> 0.42800691 | AT9: =J9*(1+(((2-3*V9^2)/24*AH9^2)+(V9*AH9*J9/4))*0.5) -> 0.41358023 | ... AV9: =L9*(1+(((2-3*X9^2)/24*AJ9^2)+(X9*AJ9*L9/4))*0.5) -> 0.37395831
B10: 1Y | C10: 0.501 | D10: 0.491 | E10: 0.4731 | F10: 0.4573 | G10: 0.4289 | H10: 0.415 | I10: 0.3972 | J10: 0.391 | K10: 0.3758 | L10: 0.343 | N10: 1Y | O10: -0.2981 | P10: -0.2776 | Q10: -0.2581 | R10: -0.2336 | S10: -0.2121 | T10: -0.1992 | U10: -0.1849 | V10: -0.1572 | W10: -0.1387 | X10: -0.1153 | Z10: 1Y | AA10: 0.7924 | AB10: 0.7649 | AC10: 0.7392 | AD10: 0.719 | AE10: 0.698 | AF10: 0.6633 | AG10: 0.658 | AH10: 0.6334 | AI10: 0.613 | AJ10: 0.5893 | AL10: 1Y | AM10: =C10*(1+(((2-3*O10^2)/24*AA10^2)+(O10*AA10*C10/4))*1) -> 0.50889791 | AN10: =D10*(1+(((2-3*P10^2)/24*AB10^2)+(P10*AB10*D10/4))*1) -> 0.49937444 | AO10: =E10*(1+(((2-3*Q10^2)/24*AC10^2)+(Q10*AC10*E10/4))*1) -> 0.48181419 | AP10: =F10*(1+(((2-3*R10^2)/24*AD10^2)+(R10*AD10*F10/4))*1) -> 0.46660696 | AQ10: =G10*(1+(((2-3*S10^2)/24*AE10^2)+(S10*AE10*G10/4))*1) -> 0.43832998 | AR10: =H10*(1+(((2-3*T10^2)/24*AF10^2)+(T10*AF10*H10/4))*1) -> 0.42362088 | AS10: =I10*(1+(((2-3*U10^2)/24*AG10^2)+(U10*AG10*I10/4))*1) -> 0.40599751 | AT10: =J10*(1+(((2-3*V10^2)/24*AH10^2)+(V10*AH10*J10/4))*1) -> 0.39978212 | ... AV10: =L10*(1+(((2-3*X10^2)/24*AJ10^2)+(X10*AJ10*L10/4))*1) -> 0.35072987
B11: 2Y | C11: 0.4812 | D11: 0.4646 | E11: 0.4421 | F11: 0.436 | G11: 0.4079 | H11: 0.3913 | I11: 0.3775 | J11: 0.3599 | K11: 0.3468 | L11: 0.3244 | N11: 2Y | O11: -0.2822 | P11: -0.2598 | Q11: -0.2413 | R11: -0.2166 | S11: -0.2039 | T11: -0.1675 | U11: -0.1533 | V11: -0.1431 | W11: -0.1216 | X11: -0.1003 | Z11: 2Y | AA11: 0.7584 | AB11: 0.7313 | AC11: 0.7236 | AD11: 0.7043 | AE11: 0.6715 | AF11: 0.6497 | AG11: 0.6195 | AH11: 0.5976 | AI11: 0.5802 | AJ11: 0.5564 | AL11: 2Y | AM11: =C11*(1+(((2-3*O11^2)/24*AA11^2)+(O11*AA11*C11/4))*2) -> 0.49703978 | AN11: =D11*(1+(((2-3*P11^2)/24*AB11^2)+(P11*AB11*D11/4))*2) -> 0.48131351 | AO11: =E11*(1+(((2-3*Q11^2)/24*AC11^2)+(Q11*AC11*E11/4))*2) -> 0.46024736 | AP11: =F11*(1+(((2-3*R11^2)/24*AD11^2)+(R11*AD11*F11/4))*2) -> 0.45500912 | AQ11: =G11*(1+(((2-3*S11^2)/24*AE11^2)+(S11*AE11*G11/4))*2) -> 0.42525237 | AR11: =H11*(1+(((2-3*T11^2)/24*AF11^2)+(T11*AF11*H11/4))*2) -> 0.4093387 | AS11: =I11*(1+(((2-3*U11^2)/24*AG11^2)+(U11*AG11*I11/4))*2) -> 0.39402813 | AT11: =J11*(1+(((2-3*V11^2)/24*AH11^2)+(V11*AH11*J11/4))*2) -> 0.3751252 | ... AV11: =L11*(1+(((2-3*X11^2)/24*AJ11^2)+(X11*AJ11*L11/4))*2) -> 0.337949
B12: 3Y | C12: 0.4732 | D12: 0.4432 | E12: 0.4238 | F12: 0.4257 | G12: 0.4006 | H12: 0.3763 | I12: 0.3675 | J12: 0.3405 | K12: 0.3339 | L12: 0.3262 | N12: 3Y | O12: -0.2455 | P12: -0.2294 | Q12: -0.2187 | R12: -0.1971 | S12: -0.1817 | T12: -0.1501 | U12: -0.1355 | V12: -0.1111 | W12: -0.1006 | X12: -0.0833 | Z12: 3Y | AA12: 0.7451 | AB12: 0.7264 | AC12: 0.7015 | AD12: 0.6783 | AE12: 0.6564 | AF12: 0.6326 | AG12: 0.6001 | AH12: 0.5837 | AI12: 0.5582 | AJ12: 0.5295 | AL12: 3Y | AM12: =C12*(1+(((2-3*O12^2)/24*AA12^2)+(O12*AA12*C12/4))*3) -> 0.50221984 | AN12: =D12*(1+(((2-3*P12^2)/24*AB12^2)+(P12*AB12*D12/4))*3) -> 0.47250063 | AO12: =E12*(1+(((2-3*Q12^2)/24*AC12^2)+(Q12*AC12*E12/4))*3) -> 0.45153145 | AP12: =F12*(1+(((2-3*R12^2)/24*AD12^2)+(R12*AD12*F12/4))*3) -> 0.45364092 | AQ12: =G12*(1+(((2-3*S12^2)/24*AE12^2)+(S12*AE12*G12/4))*3) -> 0.42725869 | AR12: =H12*(1+(((2-3*T12^2)/24*AF12^2)+(T12*AF12*H12/4))*3) -> 0.40259075 | AS12: =I12*(1+(((2-3*U12^2)/24*AG12^2)+(U12*AG12*I12/4))*3) -> 0.3914384 | AT12: =J12*(1+(((2-3*V12^2)/24*AH12^2)+(V12*AH12*J12/4))*3) -> 0.36332663 | ... AV12: =L12*(1+(((2-3*X12^2)/24*AJ12^2)+(X12*AJ12*L12/4))*3) -> 0.34530624
B13: 5Y | C13: 0.4406 | D13: 0.4289 | E13: 0.4119 | F13: 0.4039 | G13: 0.3925 | H13: 0.3656 | I13: 0.3587 | J13: 0.3431 | K13: 0.3258 | L13: 0.2973 | N13: 5Y | O13: -0.2389 | P13: -0.2194 | Q13: -0.2005 | R13: -0.1809 | S13: -0.1531 | T13: -0.1281 | U13: -0.1099 | V13: -0.0976 | W13: -0.0747 | X13: -0.0523 | Z13: 5Y | AA13: 0.7084 | AB13: 0.6977 | AC13: 0.6804 | AD13: 0.6556 | AE13: 0.6328 | AF13: 0.6051 | AG13: 0.5769 | AH13: 0.5669 | AI13: 0.5355 | AJ13: 0.5227 | AL13: 5Y | AM13: =C13*(1+(((2-3*O13^2)/24*AA13^2)+(O13*AA13*C13/4))*5) -> 0.48377362 | AN13: =D13*(1+(((2-3*P13^2)/24*AB13^2)+(P13*AB13*D13/4))*5) -> 0.47441256 | AO13: =E13*(1+(((2-3*Q13^2)/24*AC13^2)+(Q13*AC13*E13/4))*5) -> 0.45763017 | AP13: =F13*(1+(((2-3*R13^2)/24*AD13^2)+(R13*AD13*F13/4))*5) -> 0.44849862 | AQ13: =G13*(1+(((2-3*S13^2)/24*AE13^2)+(S13*AE13*G13/4))*5) -> 0.43702889 | AR13: =H13*(1+(((2-3*T13^2)/24*AF13^2)+(T13*AF13*H13/4))*5) -> 0.40705248 | AS13: =I13*(1+(((2-3*U13^2)/24*AG13^2)+(U13*AG13*I13/4))*5) -> 0.39734363 | AT13: =J13*(1+(((2-3*V13^2)/24*AH13^2)+(V13*AH13*J13/4))*5) -> 0.38024529 | ... AV13: =L13*(1+(((2-3*X13^2)/24*AJ13^2)+(X13*AJ13*L13/4))*5) -> 0.32798535
B14: 10Y | C14: 0.4428 | D14: 0.4146 | E14: 0.398 | F14: 0.3923 | G14: 0.3712 | H14: 0.3434 | I14: 0.3259 | J14: 0.3097 | K14: 0.3081 | L14: 0.2895 | N14: 10Y | O14: -0.221 | P14: -0.1879 | Q14: -0.1654 | R14: -0.1524 | S14: -0.1391 | T14: -0.1157 | U14: -0.1046 | V14: -0.0875 | W14: -0.0489 | X14: -0.0359 | Z14: 10Y | AA14: 0.695 | AB14: 0.6809 | AC14: 0.6487 | AD14: 0.6352 | AE14: 0.6121 | AF14: 0.5776 | AG14: 0.5561 | AH14: 0.5347 | AI14: 0.5115 | AJ14: 0.4962 | AL14: 10Y | AM14: =C14*(1+(((2-3*O14^2)/24*AA14^2)+(O14*AA14*C14/4))*10) -> 0.53268924 | AN14: =D14*(1+(((2-3*P14^2)/24*AB14^2)+(P14*AB14*D14/4))*10) -> 0.51131867 | AO14: =E14*(1+(((2-3*Q14^2)/24*AC14^2)+(Q14*AC14*E14/4))*10) -> 0.489352 | AP14: =F14*(1+(((2-3*R14^2)/24*AD14^2)+(R14*AD14*F14/4))*10) -> 0.48236331 | AQ14: =G14*(1+(((2-3*S14^2)/24*AE14^2)+(S14*AE14*G14/4))*10) -> 0.45440356 | AR14: =H14*(1+(((2-3*T14^2)/24*AF14^2)+(T14*AF14*H14/4))*10) -> 0.4172528 | AS14: =I14*(1+(((2-3*U14^2)/24*AG14^2)+(U14*AG14*I14/4))*10) -> 0.39306283 | AT14: =J14*(1+(((2-3*V14^2)/24*AH14^2)+(V14*AH14*J14/4))*10) -> 0.37142103 | ... AV14: =L14*(1+(((2-3*X14^2)/24*AJ14^2)+(X14*AJ14*L14/4))*10) -> 0.345052
B15: 20Y | C15: 0.4119 | D15: 0.3984 | E15: 0.376 | F15: 0.3749 | G15: 0.3471 | H15: 0.3325 | I15: 0.3183 | J15: 0.3081 | K15: 0.2817 | L15: 0.275 | N15: 20Y | O15: -0.1944 | P15: -0.1744 | Q15: -0.1551 | R15: -0.1457 | S15: -0.1179 | T15: -0.1036 | U15: -0.0877 | V15: -0.0523 | W15: -0.0454 | X15: -0.02 | Z15: 20Y | AA15: 0.6767 | AB15: 0.6511 | AC15: 0.6243 | AD15: 0.6059 | AE15: 0.5844 | AF15: 0.5668 | AG15: 0.531 | AH15: 0.5179 | AI15: 0.4894 | AJ15: 0.4678 | AL15: 20Y | AM15: =C15*(1+(((2-3*O15^2)/24*AA15^2)+(O15*AA15*C15/4))*20) -> 0.59684836 | AN15: =D15*(1+(((2-3*P15^2)/24*AB15^2)+(P15*AB15*D15/4))*20) -> 0.57693169 | AO15: =E15*(1+(((2-3*Q15^2)/24*AC15^2)+(Q15*AC15*E15/4))*20) -> 0.54298392 | AP15: =F15*(1+(((2-3*R15^2)/24*AD15^2)+(R15*AD15*F15/4))*20) -> 0.53494279 | AQ15: =G15*(1+(((2-3*S15^2)/24*AE15^2)+(S15*AE15*G15/4))*20) -> 0.49904651 | AR15: =H15*(1+(((2-3*T15^2)/24*AF15^2)+(T15*AF15*H15/4))*20) -> 0.47520702 | AS15: =I15*(1+(((2-3*U15^2)/24*AG15^2)+(U15*AG15*I15/4))*20) -> 0.4425641 | AT15: =J15*(1+(((2-3*V15^2)/24*AH15^2)+(V15*AH15*J15/4))*20) -> 0.43241022 | ... AV15: =L15*(1+(((2-3*X15^2)/24*AJ15^2)+(X15*AJ15*L15/4))*20) -> 0.3717023
B16: 30Y | C16: 0.4054 | D16: 0.3835 | E16: 0.3679 | F16: 0.3552 | G16: 0.3416 | H16: 0.3155 | I16: 0.3023 | J16: 0.2834 | K16: 0.2669 | L16: 0.2539 | N16: 30Y | O16: -0.176 | P16: -0.1549 | Q16: -0.1366 | R16: -0.1078 | S16: -0.0932 | T16: -0.0702 | U16: -0.0495 | V16: -0.0437 | W16: -0.0183 | X16: 0.0089 | Z16: 30Y | AA16: 0.6568 | AB16: 0.6205 | AC16: 0.598 | AD16: 0.5822 | AE16: 0.5526 | AF16: 0.5337 | AG16: 0.5081 | AH16: 0.4978 | AI16: 0.4779 | AJ16: 0.4579 | AL16: 30Y | AM16: =C16*(1+(((2-3*O16^2)/24*AA16^2)+(O16*AA16*C16/4))*30) -> 0.67980865 | AN16: =D16*(1+(((2-3*P16^2)/24*AB16^2)+(P16*AB16*D16/4))*30) -> 0.63333314 | AO16: =E16*(1+(((2-3*Q16^2)/24*AC16^2)+(Q16*AC16*E16/4))*30) -> 0.60467785 | AP16: =F16*(1+(((2-3*R16^2)/24*AD16^2)+(R16*AD16*F16/4))*30) -> 0.59155905 | AQ16: =G16*(1+(((2-3*S16^2)/24*AE16^2)+(S16*AE16*G16/4))*30) -> 0.55391162 | AR16: =H16*(1+(((2-3*T16^2)/24*AF16^2)+(T16*AF16*H16/4))*30) -> 0.5105333 | AS16: =I16*(1+(((2-3*U16^2)/24*AG16^2)+(U16*AG16*I16/4))*30) -> 0.47945336 | AT16: =J16*(1+(((2-3*V16^2)/24*AH16^2)+(V16*AH16*J16/4))*30) -> 0.445363 | ... AV16: =L16*(1+(((2-3*X16^2)/24*AJ16^2)+(X16*AJ16*L16/4))*30) -> 0.38894412
A18: Combined = Hagan SABR ATM-vol asymptotic approximation with beta=1 (lognormal): sigma_ATM = alpha*(1+((2-3*rho^2)/24*nu^2+rho*nu*alpha/4)*T). Collapses ATM/RHO/NU into one usable vol surface per scenario.
A20: SECTION 2 - SCENARIO SHOCKS: Per-Param Shock Size + Sensitivity Factor Grid
B21: Shocked(i,j) = Base(i,j) + ScenarioShockSize(param,scenario) x SensitivityFactor(i,j) for ATM/RHO/NU. Combined Effective Vol is then recomputed from the SHOCKED ATM/RHO/NU via the same Hagan formula shown in Section 1 - i.e. the single 'shocked SABR curve' is derived, not separately shocked.
B24: Scenario Shock Size (per param, parallel move applied before sensitivity scaling)
B25: Scenario | C25: ATM | D25: RHO | E25: NU
B26: Scenario 1 | C26: 0.0099 | D26: 0.0057 | E26: 0.0224
B27: Scenario 2 | C27: 0.0125 | D27: 0.0065 | E27: 0.0206
B28: Scenario 3 | C28: 0.012 | D28: 0.0077 | E28: 0.0249
B29: Scenario 4 | C29: 0.0205 | D29: 0.0056 | E29: 0.0233
B30: Scenario 5 | C30: 0.0159 | D30: 0.0125 | E30: 0.0331
B31: Scenario 6 | C31: 0.0178 | D31: 0.0151 | E31: 0.041
B32: Scenario 7 | C32: 0.0263 | D32: 0.0133 | E32: 0.0317
B33: Scenario 8 | C33: 0.0224 | D33: 0.0138 | E33: 0.0338
B34: Scenario 9 | C34: 0.0265 | D34: 0.0127 | E34: 0.0369
B35: Scenario 10 | C35: 0.0316 | D35: 0.0155 | E35: 0.0535
B38: Sensitivity Factor Grid (shared shape across ATM/RHO/NU; applied to all scenarios)
B39: Expiry \ Tenor | C39: 1M | D39: 3M | E39: 6M | F39: 1Y | G39: 2Y | H39: 3Y | I39: 5Y | J39: 10Y | K39: 20Y | L39: 30Y
B40: 1M | C40: 1.601 | D40: 1.518 | E40: 1.42 | F40: 1.34 | G40: 1.237 | H40: 1.137 | I40: 1.09 | J40: 1 | K40: 0.9 | L40: 0.802
B41: 3M | C41: 1.499 | D41: 1.404 | E41: 1.317 | F41: 1.214 | G41: 1.166 | H41: 1.054 | I41: 0.991 | J41: 0.873 | K41: 0.817 | L41: 0.721
B42: 6M | C42: 1.39 | D42: 1.313 | E42: 1.265 | F42: 1.148 | G42: 1.089 | H42: 0.964 | I42: 0.854 | J42: 0.798 | K42: 0.717 | L42: 0.596
B43: 1Y | C43: 1.305 | D43: 1.23 | E43: 1.178 | F43: 1.075 | G43: 0.947 | H43: 0.865 | I43: 0.766 | J43: 0.674 | K43: 0.628 | L43: 0.501
B44: 2Y | C44: 1.244 | D44: 1.147 | E44: 1.041 | F44: 0.984 | G44: 0.858 | H44: 0.799 | I44: 0.677 | J44: 0.605 | K44: 0.503 | L44: 0.416
B45: 3Y | C45: 1.178 | D45: 1.078 | E45: 0.958 | F45: 0.903 | G45: 0.773 | H45: 0.694 | I45: 0.631 | J45: 0.529 | K45: 0.406 | L45: 0.369
B46: 5Y | C46: 1.043 | D46: 0.955 | E46: 0.896 | F46: 0.78 | G46: 0.688 | H46: 0.584 | I46: 0.495 | J46: 0.435 | K46: 0.325 | L46: 0.256
B47: 10Y | C47: 0.962 | D47: 0.877 | E47: 0.818 | F47: 0.699 | G47: 0.614 | H47: 0.542 | I47: 0.411 | J47: 0.319 | K47: 0.275 | L47: 0.179
...

Sheet NPV_Engine
A1: Full-Reval NPV Engine — Cross / IR / Credit / FX (Base vs Stressed, Trade 123456)
A2: Illustrative simplified full-reval pricer (NOT a production model): NPV = Notional x DF_SOFR(1Y) x [DF_ESTRN(1Y)/DF_ESTRN_base(1Y)] x [1+0.5x(SABR_EffVol(1Yx10Y)-SABR_EffVol_base)] x [AVERAGE(DF_Treasury,DF_Agency_FNMA,DF_Eur_Govt)(1Y)/DF_SOFR(1Y)] x [DF_EURUSD(1Y)/DF_EURUSD_base(1Y)]. SABR_EffVol is the single Combined Effective Vol pulled from the SABR tab (Hagan formula collapsing ATM/RHO/NU into one number at the 1Yx10Y grid point). Each risk-class table below feeds this same pricer with only that risk class curves/surface shocked; the rest held at BASE.
A4: Notional (USD) | B4: =Trade_Info!B7 -> 10000000
A6: Reference base constants
A7: DF_SOFR_base(1Y) | B7: =Curves!E8 -> 0.957768
A8: DF_ESTRN_base(1Y) | B8: =Curves!E9 -> 0.96933
A9: DF_Treasury_base(1Y) | B9: =Curves!E10 -> 0.958726
A10: DF_Agency_FNMA_base(1Y) | B10: =Curves!E11 -> 0.954899
A11: DF_Eur_Govt_base(1Y) | B11: =Curves!E12 -> 0.967393
A12: DF_EURUSD_base(1Y) | B12: =Curves!E13 -> 0.960645
A13: SABR EffVol_base(1Yx10Y) | B13: =SABR!AT10 -> 0.39978212
A16: Cross — Full-Reval NPV
A17: Case | B17: DF_SOFR(1Y) | C17: DF_ESTRN(1Y) | D17: SABR EffVol(1Yx10Y) | E17: DF_Treasury(1Y) | F17: DF_Agency_FNMA(1Y) | G17: DF_Eur_Govt(1Y) | H17: DF_EURUSD(1Y) | I17: NPV (USD)
A18: Base | B18: =$B$7 -> 0.957768 | C18: =$B$8 -> 0.96933 | D18: =$B$13 -> 0.39978212 | E18: =$B$9 -> 0.958726 | F18: =$B$10 -> 0.954899 | G18: =$B$11 -> 0.967393 | H18: =$B$12 -> 0.960645 | I18: =$B$4*B18*(C18/$B$8)*(1+0.5*(D18-$B$13))*(AVERAGE(E18,F18,G18)/B18)*(H18/$B$12) -> 9603393.3
A19: Scenario 1 | B19: =Curves!Q37 -> 0.95645567 | C19: =Curves!Q38 -> 0.96826858 | D19: =SABR!AT60 -> 0.40653854 | E19: =Curves!Q39 -> 0.95806183 | F19: =Curves!Q40 -> 0.94931135 | G19: =Curves!Q41 -> 0.96229709 | H19: =Curves!Q42 -> 0.95855049 | I19: =$B$4*B19*(C19/$B$8)*(1+0.5*(D19-$B$13))*(AVERAGE(E19,F19,G19)/B19)*(H19/$B$12) -> 9566468.7
A20: Scenario 2 | B20: =Curves!Q45 -> 0.95398447 | C20: =Curves!Q46 -> 0.9689389 | D20: =SABR!AT74 -> 0.40831258 | E20: =Curves!Q47 -> 0.95458892 | F20: =Curves!Q48 -> 0.95209186 | G20: =Curves!Q49 -> 0.96495558 | H20: =Curves!Q50 -> 0.95783612 | I20: =$B$4*B20*(C20/$B$8)*(1+0.5*(D20-$B$13))*(AVERAGE(E20,F20,G20)/B20)*(H20/$B$12) -> 9580973.5
A21: Scenario 3 | B21: =Curves!Q53 -> 0.95342826 | C21: =Curves!Q54 -> 0.96769945 | D21: =SABR!AT88 -> 0.40797143 | E21: =Curves!Q55 -> 0.95400896 | F21: =Curves!Q56 -> 0.95361271 | G21: =Curves!Q57 -> 0.96122366 | H21: =Curves!Q58 -> 0.9575846 | I21: =$B$4*B21*(C21/$B$8)*(1+0.5*(D21-$B$13))*(AVERAGE(E21,F21,G21)/B21)*(H21/$B$12) -> 9555284.1
A22: Scenario 4 | B22: =Curves!Q61 -> 0.95304179 | C22: =Curves!Q62 -> 0.96526908 | D22: =SABR!AT102 -> 0.41377023 | E22: =Curves!Q63 -> 0.95320762 | F22: =Curves!Q64 -> 0.94623448 | G22: =Curves!Q65 -> 0.9603367 | H22: =Curves!Q66 -> 0.96226356 | I22: =$B$4*B22*(C22/$B$8)*(1+0.5*(D22-$B$13))*(AVERAGE(E22,F22,G22)/B22)*(H22/$B$12) -> 9575158
A23: Scenario 5 | B23: =Curves!Q69 -> 0.95548798 | C23: =Curves!Q70 -> 0.96483623 | D23: =SABR!AT116 -> 0.41063226 | E23: =Curves!Q71 -> 0.95639571 | F23: =Curves!Q72 -> 0.94534426 | G23: =Curves!Q73 -> 0.96004351 | H23: =Curves!Q74 -> 0.95680489 | I23: =$B$4*B23*(C23/$B$8)*(1+0.5*(D23-$B$13))*(AVERAGE(E23,F23,G23)/B23)*(H23/$B$12) -> 9508404.1
A24: Scenario 6 | B24: =Curves!Q77 -> 0.9549911 | C24: =Curves!Q78 -> 0.96434632 | D24: =SABR!AT130 -> 0.41192843 | E24: =Curves!Q79 -> 0.9521379 | F24: =Curves!Q80 -> 0.94448209 | G24: =Curves!Q81 -> 0.95861205 | H24: =Curves!Q82 -> 0.95873693 | I24: =$B$4*B24*(C24/$B$8)*(1+0.5*(D24-$B$13))*(AVERAGE(E24,F24,G24)/B24)*(H24/$B$12) -> 9507090.3
A25: Scenario 7 | B25: =Curves!Q85 -> 0.95463157 | C25: =Curves!Q86 -> 0.96389894 | D25: =SABR!AT144 -> 0.41772611 | E25: =Curves!Q87 -> 0.9516449 | F25: =Curves!Q88 -> 0.95011547 | G25: =Curves!Q89 -> 0.95780838 | H25: =Curves!Q90 -> 0.95626063 | I25: =$B$4*B25*(C25/$B$8)*(1+0.5*(D25-$B$13))*(AVERAGE(E25,F25,G25)/B25)*(H25/$B$12) -> 9519882.7
A26: Scenario 8 | B26: =Curves!Q93 -> 0.95085969 | C26: =Curves!Q94 -> 0.97201771 | D26: =SABR!AT158 -> 0.4150662 | E26: =Curves!Q95 -> 0.95082457 | F26: =Curves!Q96 -> 0.94234687 | G26: =Curves!Q97 -> 0.95705696 | H26: =Curves!Q98 -> 0.96022971 | I26: =$B$4*B26*(C26/$B$8)*(1+0.5*(D26-$B$13))*(AVERAGE(E26,F26,G26)/B26)*(H26/$B$12) -> 9595761.1
A27: Scenario 9 | B27: =Curves!Q101 -> 0.95063 | C27: =Curves!Q102 -> 0.96317151 | D27: =SABR!AT172 -> 0.41786251 | E27: =Curves!Q103 -> 0.95006942 | F27: =Curves!Q104 -> 0.94108519 | G27: =Curves!Q105 -> 0.9561681 | H27: =Curves!Q106 -> 0.95559115 | I27: =$B$4*B27*(C27/$B$8)*(1+0.5*(D27-$B$13))*(AVERAGE(E27,F27,G27)/B27)*(H27/$B$12) -> 9465968.8
A28: Scenario 10 | B28: =Curves!Q109 -> 0.94992462 | C28: =Curves!Q110 -> 0.97264772 | D28: =SABR!AT186 -> 0.42134031 | E28: =Curves!Q111 -> 0.9572378 | F28: =Curves!Q112 -> 0.94825632 | G28: =Curves!Q113 -> 0.96603972 | H28: =Curves!Q114 -> 0.95521334 | I28: =$B$4*B28*(C28/$B$8)*(1+0.5*(D28-$B$13))*(AVERAGE(E28,F28,G28)/B28)*(H28/$B$12) -> 9653177.9
A31: IR — Full-Reval NPV
A32: Case | B32: DF_SOFR(1Y) | C32: DF_ESTRN(1Y) | D32: SABR EffVol(1Yx10Y) | E32: DF_Treasury(1Y) | F32: DF_Agency_FNMA(1Y) | G32: DF_Eur_Govt(1Y) | H32: DF_EURUSD(1Y) | I32: NPV (USD)
A33: Base | B33: =$B$7 -> 0.957768 | C33: =$B$8 -> 0.96933 | D33: =$B$13 -> 0.39978212 | E33: =$B$9 -> 0.958726 | F33: =$B$10 -> 0.954899 | G33: =$B$11 -> 0.967393 | H33: =$B$12 -> 0.960645 | I33: =$B$4*B33*(C33/$B$8)*(1+0.5*(D33-$B$13))*(AVERAGE(E33,F33,G33)/B33)*(H33/$B$12) -> 9603393.3
A34: Scenario 1 | B34: =Curves!Q37 -> 0.95645567 | C34: =Curves!Q38 -> 0.96826858 | D34: =SABR!AT60 -> 0.40653854 | E34: =$B$9 -> 0.958726 | F34: =$B$10 -> 0.954899 | G34: =$B$11 -> 0.967393 | H34: =$B$12 -> 0.960645 | I34: =$B$4*B34*(C34/$B$8)*(1+0.5*(D34-$B$13))*(AVERAGE(E34,F34,G34)/B34)*(H34/$B$12) -> 9625284.3
A35: Scenario 2 | B35: =Curves!Q45 -> 0.95398447 | C35: =Curves!Q46 -> 0.9689389 | D35: =SABR!AT74 -> 0.40831258 | E35: =$B$9 -> 0.958726 | F35: =$B$10 -> 0.954899 | G35: =$B$11 -> 0.967393 | H35: =$B$12 -> 0.960645 | I35: =$B$4*B35*(C35/$B$8)*(1+0.5*(D35-$B$13))*(AVERAGE(E35,F35,G35)/B35)*(H35/$B$12) -> 9640462.8
A36: Scenario 3 | B36: =Curves!Q53 -> 0.95342826 | C36: =Curves!Q54 -> 0.96769945 | D36: =SABR!AT88 -> 0.40797143 | E36: =$B$9 -> 0.958726 | F36: =$B$10 -> 0.954899 | G36: =$B$11 -> 0.967393 | H36: =$B$12 -> 0.960645 | I36: =$B$4*B36*(C36/$B$8)*(1+0.5*(D36-$B$13))*(AVERAGE(E36,F36,G36)/B36)*(H36/$B$12) -> 9626495.5
A37: Scenario 4 | B37: =Curves!Q61 -> 0.95304179 | C37: =Curves!Q62 -> 0.96526908 | D37: =SABR!AT102 -> 0.41377023 | E37: =$B$9 -> 0.958726 | F37: =$B$10 -> 0.954899 | G37: =$B$11 -> 0.967393 | H37: =$B$12 -> 0.960645 | I37: =$B$4*B37*(C37/$B$8)*(1+0.5*(D37-$B$13))*(AVERAGE(E37,F37,G37)/B37)*(H37/$B$12) -> 9630046.1
A38: Scenario 5 | B38: =Curves!Q69 -> 0.95548798 | C38: =Curves!Q70 -> 0.96483623 | D38: =SABR!AT116 -> 0.41063226 | E38: =$B$9 -> 0.958726 | F38: =$B$10 -> 0.954899 | G38: =$B$11 -> 0.967393 | H38: =$B$12 -> 0.960645 | I38: =$B$4*B38*(C38/$B$8)*(1+0.5*(D38-$B$13))*(AVERAGE(E38,F38,G38)/B38)*(H38/$B$12) -> 9610730
A39: Scenario 6 | B39: =Curves!Q77 -> 0.9549911 | C39: =Curves!Q78 -> 0.96434632 | D39: =SABR!AT130 -> 0.41192843 | E39: =$B$9 -> 0.958726 | F39: =$B$10 -> 0.954899 | G39: =$B$11 -> 0.967393 | H39: =$B$12 -> 0.960645 | I39: =$B$4*B39*(C39/$B$8)*(1+0.5*(D39-$B$13))*(AVERAGE(E39,F39,G39)/B39)*(H39/$B$12) -> 9612041.8
A40: Scenario 7 | B40: =Curves!Q85 -> 0.95463157 | C40: =Curves!Q86 -> 0.96389894 | D40: =SABR!AT144 -> 0.41772611 | E40: =$B$9 -> 0.958726 | F40: =$B$10 -> 0.954899 | G40: =$B$11 -> 0.967393 | H40: =$B$12 -> 0.960645 | I40: =$B$4*B40*(C40/$B$8)*(1+0.5*(D40-$B$13))*(AVERAGE(E40,F40,G40)/B40)*(H40/$B$12) -> 9635265.3
A41: Scenario 8 | B41: =Curves!Q93 -> 0.95085969 | C41: =Curves!Q94 -> 0.97201771 | D41: =SABR!AT158 -> 0.4150662 | E41: =$B$9 -> 0.958726 | F41: =$B$10 -> 0.954899 | G41: =$B$11 -> 0.967393 | H41: =$B$12 -> 0.960645 | I41: =$B$4*B41*(C41/$B$8)*(1+0.5*(D41-$B$13))*(AVERAGE(E41,F41,G41)/B41)*(H41/$B$12) -> 9703614.2
A42: Scenario 9 | B42: =Curves!Q101 -> 0.95063 | C42: =Curves!Q102 -> 0.96317151 | D42: =SABR!AT172 -> 0.41786251 | E42: =$B$9 -> 0.958726 | F42: =$B$10 -> 0.954899 | G42: =$B$11 -> 0.967393 | H42: =$B$12 -> 0.960645 | I42: =$B$4*B42*(C42/$B$8)*(1+0.5*(D42-$B$13))*(AVERAGE(E42,F42,G42)/B42)*(H42/$B$12) -> 9628644.6
A43: Scenario 10 | B43: =Curves!Q109 -> 0.94992462 | C43: =Curves!Q110 -> 0.97264772 | D43: =SABR!AT186 -> 0.42134031 | E43: =$B$9 -> 0.958726 | F43: =$B$10 -> 0.954899 | G43: =$B$11 -> 0.967393 | H43: =$B$12 -> 0.960645 | I43: =$B$4*B43*(C43/$B$8)*(1+0.5*(D43-$B$13))*(AVERAGE(E43,F43,G43)/B43)*(H43/$B$12) -> 9740133
A46: Credit — Full-Reval NPV
A47: Case | B47: DF_SOFR(1Y) | C47: DF_ESTRN(1Y) | D47: SABR EffVol(1Yx10Y) | E47: DF_Treasury(1Y) | F47: DF_Agency_FNMA(1Y) | G47: DF_Eur_Govt(1Y) | H47: DF_EURUSD(1Y) | I47: NPV (USD)
A48: Base | B48: =$B$7 -> 0.957768 | C48: =$B$8 -> 0.96933 | D48: =$B$13 -> 0.39978212 | E48: =$B$9 -> 0.958726 | F48: =$B$10 -> 0.954899 | G48: =$B$11 -> 0.967393 | H48: =$B$12 -> 0.960645 | I48: =$B$4*B48*(C48/$B$8)*(1+0.5*(D48-$B$13))*(AVERAGE(E48,F48,G48)/B48)*(H48/$B$12) -> 9603393.3
...

Sheet PnL_Summary
A1: Full-Reval ES PnL Vectors — PnL = StressedNPV − BaseNPV (Trade 123456, Val Date 7/23/2026)
A2: Stress anchor date: 20-Nov-2008. Cross = all curves shocked. IR = SOFR/ESTRN/SABR shocked only. Credit = Treasury/Agency_FNMA/Eur_Govt shocked only. FX = EURUSD shocked only (others held at Base each time).
A4: Scenario | B4: Cross PnL (USD) | C4: IR PnL (USD) | D4: Credit PnL (USD) | E4: FX PnL (USD) | F4: Sum IR+Credit+FX (USD) | G4: Cross - Sum (diversification, USD)
A5: Scenario 1 | B5: =NPV_Engine!I19-NPV_Engine!I18 -> -36924.584 | C5: =NPV_Engine!I34-NPV_Engine!I33 -> 21890.945 | D5: =NPV_Engine!I49-NPV_Engine!I48 -> -37825.797 | E5: =NPV_Engine!I64-NPV_Engine!I63 -> -20938.439 | F5: =C5+D5+E5 -> -36873.291 | G5: =B5-F5 -> -51.292925
A6: Scenario 2 | B6: =NPV_Engine!I20-NPV_Engine!I18 -> -22419.874 | C6: =NPV_Engine!I35-NPV_Engine!I33 -> 37069.418 | D6: =NPV_Engine!I50-NPV_Engine!I48 -> -31272.096 | E6: =NPV_Engine!I65-NPV_Engine!I63 -> -28079.888 | F6: =C6+D6+E6 -> -22282.565 | G6: =B6-F6 -> -137.30949
A7: Scenario 3 | B7: =NPV_Engine!I21-NPV_Engine!I18 -> -48109.233 | C7: =NPV_Engine!I36-NPV_Engine!I33 -> 23102.212 | D7: =NPV_Engine!I51-NPV_Engine!I48 -> -40575.571 | E7: =NPV_Engine!I66-NPV_Engine!I63 -> -30594.242 | F7: =C7+D7+E7 -> -48067.601 | G7: =B7-F7 -> -41.632677
A8: Scenario 4 | B8: =NPV_Engine!I22-NPV_Engine!I18 -> -28235.349 | C8: =NPV_Engine!I37-NPV_Engine!I33 -> 26652.717 | D8: =NPV_Engine!I52-NPV_Engine!I48 -> -70797.319 | E8: =NPV_Engine!I67-NPV_Engine!I63 -> 16180.448 | F8: =C8+D8+E8 -> -27964.153 | G8: =B8-F8 -> -271.19577
A9: Scenario 5 | B9: =NPV_Engine!I23-NPV_Engine!I18 -> -94989.219 | C9: =NPV_Engine!I38-NPV_Engine!I33 -> 7336.634 | D9: =NPV_Engine!I53-NPV_Engine!I48 -> -64115.106 | E9: =NPV_Engine!I68-NPV_Engine!I63 -> -38388.929 | F9: =C9+D9+E9 -> -95167.401 | G9: =B9-F9 -> 178.18244
A10: Scenario 6 | B10: =NPV_Engine!I24-NPV_Engine!I18 -> -96303.014 | C10: =NPV_Engine!I39-NPV_Engine!I33 -> 8648.4872 | D10: =NPV_Engine!I54-NPV_Engine!I48 -> -85953.213 | E10: =NPV_Engine!I69-NPV_Engine!I63 -> -19074.58 | F10: =C10+D10+E10 -> -96379.306 | G10: =B10-F10 -> 76.292452
A11: Scenario 7 | B11: =NPV_Engine!I25-NPV_Engine!I18 -> -83510.656 | C11: =NPV_Engine!I40-NPV_Engine!I33 -> 31871.964 | D11: =NPV_Engine!I55-NPV_Engine!I48 -> -71497.499 | E11: =NPV_Engine!I70-NPV_Engine!I63 -> -43829.767 | F11: =C11+D11+E11 -> -83455.302 | G11: =B11-F11 -> -55.354135
A12: Scenario 8 | B12: =NPV_Engine!I26-NPV_Engine!I18 -> -7632.241 | C12: =NPV_Engine!I41-NPV_Engine!I33 -> 100220.85 | D12: =NPV_Engine!I56-NPV_Engine!I48 -> -102631.98 | E12: =NPV_Engine!I71-NPV_Engine!I63 -> -4151.5519 | F12: =C12+D12+E12 -> -6562.6807 | G12: =B12-F12 -> -1069.5603
A13: Scenario 9 | B13: =NPV_Engine!I27-NPV_Engine!I18 -> -137424.5 | C13: =NPV_Engine!I42-NPV_Engine!I33 -> 25251.299 | D13: =NPV_Engine!I57-NPV_Engine!I48 -> -112317.63 | E13: =NPV_Engine!I72-NPV_Engine!I63 -> -50522.433 | F13: =C13+D13+E13 -> -137588.77 | G13: =B13-F13 -> 164.27085
A14: Scenario 10 | B14: =NPV_Engine!I28-NPV_Engine!I18 -> 49784.569 | C14: =NPV_Engine!I43-NPV_Engine!I33 -> 136739.7 | D14: =NPV_Engine!I58-NPV_Engine!I48 -> -31613.869 | E14: =NPV_Engine!I73-NPV_Engine!I63 -> -54299.27 | F14: =C14+D14+E14 -> 50826.563 | G14: =B14-F14 -> -1041.9947
A16: Worst (min) PnL | B16: =MIN(B5:B14) -> -137424.5 | C16: =MIN(C5:C14) -> 7336.634 | D16: =MIN(D5:D14) -> -112317.63 | E16: =MIN(E5:E14) -> -54299.27 | F16: =MIN(F5:F14) -> -137588.77 | G16: =MIN(G5:G14) -> -1069.5603
A17: Best (max) PnL | B17: =MAX(B5:B14) -> 49784.569 | C17: =MAX(C5:C14) -> 136739.7 | D17: =MAX(D5:D14) -> -31272.096 | E17: =MAX(E5:E14) -> 16180.448 | F17: =MAX(F5:F14) -> 50826.563 | G17: =MAX(G5:G14) -> 178.18244
A18: ES (avg of 6 worst) | B18: =SUMPRODUCT(SMALL($B$5:$B$14,{1,2,3,4,5,6}))/6 -> -82876.867 | C18: =SUMPRODUCT(SMALL($C$5:$C$14,{1,2,3,4,5,6}))/6 -> 18813.716 | D18: =SUMPRODUCT(SMALL($D$5:$D$14,{1,2,3,4,5,6}))/6 -> -84552.126 | E18: =SUMPRODUCT(SMALL($E$5:$E$14,{1,2,3,4,5,6}))/6 -> -40952.421 | F18: =SUMPRODUCT(SMALL($F$5:$F$14,{1,2,3,4,5,6}))/6 -> -82921.945 | G18: =SUMPRODUCT(SMALL($G$5:$G$14,{1,2,3,4,5,6}))/6 -> -437.78455
A20: ES illustration note: rank the Cross PnL vector and average the worst-tail observations per the chosen ES confidence level to derive the (illustrative) Expected Shortfall capital number. Column G (Cross - Sum of IR/Credit/FX) is the cross-risk-class diversification / interaction term: in an ideal additive world with no cross-curve hedges it would be ~0; a non-zero residual reflects the pricer combining curves multiplicatively (hedging and cross-gamma effects), which is expected in a real full-reval engine.

Sheet LH_NPV_Engine
A1: Liquidity-Horizon Bucketed Full-Reval NPV Engine (Trade 123456)
A2: LH ladder rule: at horizon bucket T, a curve is SHOCKED only if its own Liquidity Horizon >= T; shorter-horizon curves are held at BASE (their risk is already captured at their own, shorter horizon). Credit LH: Agency_FNMA=40, Eur_Govt=20 (Treasury excluded from this LH decomposition per the two-curve Credit set specified). IR LH: SOFR=10, ESTRN=10, Sabr_Swaption(IR_VOL)=60. FX LH: EURUSD=10. Same illustrative pricer as NPV_Engine: NPV = Notional x DF_SOFR x [DF_ESTRN/ESTRN_base] x [1+0.5x(EffVol-EffVol_base)] x [AVG(DF_Treasury,DF_Agency_FNMA,DF_Eur_Govt)/DF_SOFR] x [DF_EURUSD/EURUSD_base]. Treasury is always held at BASE in this sheet.
A4: Credit — LH 10d — Full-Reval NPV | J4: Shocked curves: Agency_FNMA, Eur_Govt
A5: Case | B5: DF_SOFR(1Y) | C5: DF_ESTRN(1Y) | D5: SABR EffVol(1Yx10Y) | E5: DF_Treasury(1Y) | F5: DF_Agency_FNMA(1Y) | G5: DF_Eur_Govt(1Y) | H5: DF_EURUSD(1Y) | I5: NPV (USD)
A6: Base | B6: =Curves!E8 -> 0.957768 | C6: =Curves!E9 -> 0.96933 | D6: =SABR!AT10 -> 0.39978212 | E6: =Curves!E10 -> 0.958726 | F6: =Curves!E11 -> 0.954899 | G6: =Curves!E12 -> 0.967393 | H6: =Curves!E13 -> 0.960645 | I6: =NPV_Engine!$B$4*B6*(C6/NPV_Engine!$B$8)*(1+0.5*(D6-NPV_Engine!$B$13))*(AVERAGE(E6,F6,G6)/B6)*(H6/NPV_Engine!$B$12) -> 9603393.3
A7: Scenario 1 | B7: =Curves!E8 -> 0.957768 | C7: =Curves!E9 -> 0.96933 | D7: =SABR!AT10 -> 0.39978212 | E7: =Curves!E10 -> 0.958726 | F7: =Curves!Q40 -> 0.94931135 | G7: =Curves!Q41 -> 0.96229709 | H7: =Curves!E13 -> 0.960645 | I7: =NPV_Engine!$B$4*B7*(C7/NPV_Engine!$B$8)*(1+0.5*(D7-NPV_Engine!$B$13))*(AVERAGE(E7,F7,G7)/B7)*(H7/NPV_Engine!$B$12) -> 9567781.5
A8: Scenario 2 | B8: =Curves!E8 -> 0.957768 | C8: =Curves!E9 -> 0.96933 | D8: =SABR!AT10 -> 0.39978212 | E8: =Curves!E10 -> 0.958726 | F8: =Curves!Q48 -> 0.95209186 | G8: =Curves!Q49 -> 0.96495558 | H8: =Curves!E13 -> 0.960645 | I8: =NPV_Engine!$B$4*B8*(C8/NPV_Engine!$B$8)*(1+0.5*(D8-NPV_Engine!$B$13))*(AVERAGE(E8,F8,G8)/B8)*(H8/NPV_Engine!$B$12) -> 9585911.5
A9: Scenario 3 | B9: =Curves!E8 -> 0.957768 | C9: =Curves!E9 -> 0.96933 | D9: =SABR!AT10 -> 0.39978212 | E9: =Curves!E10 -> 0.958726 | F9: =Curves!Q56 -> 0.95361271 | G9: =Curves!Q57 -> 0.96122366 | H9: =Curves!E13 -> 0.960645 | I9: =NPV_Engine!$B$4*B9*(C9/NPV_Engine!$B$8)*(1+0.5*(D9-NPV_Engine!$B$13))*(AVERAGE(E9,F9,G9)/B9)*(H9/NPV_Engine!$B$12) -> 9578541.2
A10: Scenario 4 | B10: =Curves!E8 -> 0.957768 | C10: =Curves!E9 -> 0.96933 | D10: =SABR!AT10 -> 0.39978212 | E10: =Curves!E10 -> 0.958726 | F10: =Curves!Q64 -> 0.94623448 | G10: =Curves!Q65 -> 0.9603367 | H10: =Curves!E13 -> 0.960645 | I10: =NPV_Engine!$B$4*B10*(C10/NPV_Engine!$B$8)*(1+0.5*(D10-NPV_Engine!$B$13))*(AVERAGE(E10,F10,G10)/B10)*(H10/NPV_Engine!$B$12) -> 9550990.6
A11: Scenario 5 | B11: =Curves!E8 -> 0.957768 | C11: =Curves!E9 -> 0.96933 | D11: =SABR!AT10 -> 0.39978212 | E11: =Curves!E10 -> 0.958726 | F11: =Curves!Q72 -> 0.94534426 | G11: =Curves!Q73 -> 0.96004351 | H11: =Curves!E13 -> 0.960645 | I11: =NPV_Engine!$B$4*B11*(C11/NPV_Engine!$B$8)*(1+0.5*(D11-NPV_Engine!$B$13))*(AVERAGE(E11,F11,G11)/B11)*(H11/NPV_Engine!$B$12) -> 9547045.9
A12: Scenario 6 | B12: =Curves!E8 -> 0.957768 | C12: =Curves!E9 -> 0.96933 | D12: =SABR!AT10 -> 0.39978212 | E12: =Curves!E10 -> 0.958726 | F12: =Curves!Q80 -> 0.94448209 | G12: =Curves!Q81 -> 0.95861205 | H12: =Curves!E13 -> 0.960645 | I12: =NPV_Engine!$B$4*B12*(C12/NPV_Engine!$B$8)*(1+0.5*(D12-NPV_Engine!$B$13))*(AVERAGE(E12,F12,G12)/B12)*(H12/NPV_Engine!$B$12) -> 9539400.5
A13: Scenario 7 | B13: =Curves!E8 -> 0.957768 | C13: =Curves!E9 -> 0.96933 | D13: =SABR!AT10 -> 0.39978212 | E13: =Curves!E10 -> 0.958726 | F13: =Curves!Q88 -> 0.95011547 | G13: =Curves!Q89 -> 0.95780838 | H13: =Curves!E13 -> 0.960645 | I13: =NPV_Engine!$B$4*B13*(C13/NPV_Engine!$B$8)*(1+0.5*(D13-NPV_Engine!$B$13))*(AVERAGE(E13,F13,G13)/B13)*(H13/NPV_Engine!$B$12) -> 9555499.5
A14: Scenario 8 | B14: =Curves!E8 -> 0.957768 | C14: =Curves!E9 -> 0.96933 | D14: =SABR!AT10 -> 0.39978212 | E14: =Curves!E10 -> 0.958726 | F14: =Curves!Q96 -> 0.94234687 | G14: =Curves!Q97 -> 0.95705696 | H14: =Curves!E13 -> 0.960645 | I14: =NPV_Engine!$B$4*B14*(C14/NPV_Engine!$B$8)*(1+0.5*(D14-NPV_Engine!$B$13))*(AVERAGE(E14,F14,G14)/B14)*(H14/NPV_Engine!$B$12) -> 9527099.4
A15: Scenario 9 | B15: =Curves!E8 -> 0.957768 | C15: =Curves!E9 -> 0.96933 | D15: =SABR!AT10 -> 0.39978212 | E15: =Curves!E10 -> 0.958726 | F15: =Curves!Q104 -> 0.94108519 | G15: =Curves!Q105 -> 0.9561681 | H15: =Curves!E13 -> 0.960645 | I15: =NPV_Engine!$B$4*B15*(C15/NPV_Engine!$B$8)*(1+0.5*(D15-NPV_Engine!$B$13))*(AVERAGE(E15,F15,G15)/B15)*(H15/NPV_Engine!$B$12) -> 9519931
A16: Scenario 10 | B16: =Curves!E8 -> 0.957768 | C16: =Curves!E9 -> 0.96933 | D16: =SABR!AT10 -> 0.39978212 | E16: =Curves!E10 -> 0.958726 | F16: =Curves!Q112 -> 0.94825632 | G16: =Curves!Q113 -> 0.96603972 | H16: =Curves!E13 -> 0.960645 | I16: =NPV_Engine!$B$4*B16*(C16/NPV_Engine!$B$8)*(1+0.5*(D16-NPV_Engine!$B$13))*(AVERAGE(E16,F16,G16)/B16)*(H16/NPV_Engine!$B$12) -> 9576740.1
A19: Credit — LH 20d — Full-Reval NPV | J19: Shocked curves: Agency_FNMA, Eur_Govt
A20: Case | B20: DF_SOFR(1Y) | C20: DF_ESTRN(1Y) | D20: SABR EffVol(1Yx10Y) | E20: DF_Treasury(1Y) | F20: DF_Agency_FNMA(1Y) | G20: DF_Eur_Govt(1Y) | H20: DF_EURUSD(1Y) | I20: NPV (USD)
A21: Base | B21: =Curves!E8 -> 0.957768 | C21: =Curves!E9 -> 0.96933 | D21: =SABR!AT10 -> 0.39978212 | E21: =Curves!E10 -> 0.958726 | F21: =Curves!E11 -> 0.954899 | G21: =Curves!E12 -> 0.967393 | H21: =Curves!E13 -> 0.960645 | I21: =NPV_Engine!$B$4*B21*(C21/NPV_Engine!$B$8)*(1+0.5*(D21-NPV_Engine!$B$13))*(AVERAGE(E21,F21,G21)/B21)*(H21/NPV_Engine!$B$12) -> 9603393.3
A22: Scenario 1 | B22: =Curves!E8 -> 0.957768 | C22: =Curves!E9 -> 0.96933 | D22: =SABR!AT10 -> 0.39978212 | E22: =Curves!E10 -> 0.958726 | F22: =Curves!Q40 -> 0.94931135 | G22: =Curves!Q41 -> 0.96229709 | H22: =Curves!E13 -> 0.960645 | I22: =NPV_Engine!$B$4*B22*(C22/NPV_Engine!$B$8)*(1+0.5*(D22-NPV_Engine!$B$13))*(AVERAGE(E22,F22,G22)/B22)*(H22/NPV_Engine!$B$12) -> 9567781.5
A23: Scenario 2 | B23: =Curves!E8 -> 0.957768 | C23: =Curves!E9 -> 0.96933 | D23: =SABR!AT10 -> 0.39978212 | E23: =Curves!E10 -> 0.958726 | F23: =Curves!Q48 -> 0.95209186 | G23: =Curves!Q49 -> 0.96495558 | H23: =Curves!E13 -> 0.960645 | I23: =NPV_Engine!$B$4*B23*(C23/NPV_Engine!$B$8)*(1+0.5*(D23-NPV_Engine!$B$13))*(AVERAGE(E23,F23,G23)/B23)*(H23/NPV_Engine!$B$12) -> 9585911.5
A24: Scenario 3 | B24: =Curves!E8 -> 0.957768 | C24: =Curves!E9 -> 0.96933 | D24: =SABR!AT10 -> 0.39978212 | E24: =Curves!E10 -> 0.958726 | F24: =Curves!Q56 -> 0.95361271 | G24: =Curves!Q57 -> 0.96122366 | H24: =Curves!E13 -> 0.960645 | I24: =NPV_Engine!$B$4*B24*(C24/NPV_Engine!$B$8)*(1+0.5*(D24-NPV_Engine!$B$13))*(AVERAGE(E24,F24,G24)/B24)*(H24/NPV_Engine!$B$12) -> 9578541.2
A25: Scenario 4 | B25: =Curves!E8 -> 0.957768 | C25: =Curves!E9 -> 0.96933 | D25: =SABR!AT10 -> 0.39978212 | E25: =Curves!E10 -> 0.958726 | F25: =Curves!Q64 -> 0.94623448 | G25: =Curves!Q65 -> 0.9603367 | H25: =Curves!E13 -> 0.960645 | I25: =NPV_Engine!$B$4*B25*(C25/NPV_Engine!$B$8)*(1+0.5*(D25-NPV_Engine!$B$13))*(AVERAGE(E25,F25,G25)/B25)*(H25/NPV_Engine!$B$12) -> 9550990.6
A26: Scenario 5 | B26: =Curves!E8 -> 0.957768 | C26: =Curves!E9 -> 0.96933 | D26: =SABR!AT10 -> 0.39978212 | E26: =Curves!E10 -> 0.958726 | F26: =Curves!Q72 -> 0.94534426 | G26: =Curves!Q73 -> 0.96004351 | H26: =Curves!E13 -> 0.960645 | I26: =NPV_Engine!$B$4*B26*(C26/NPV_Engine!$B$8)*(1+0.5*(D26-NPV_Engine!$B$13))*(AVERAGE(E26,F26,G26)/B26)*(H26/NPV_Engine!$B$12) -> 9547045.9
A27: Scenario 6 | B27: =Curves!E8 -> 0.957768 | C27: =Curves!E9 -> 0.96933 | D27: =SABR!AT10 -> 0.39978212 | E27: =Curves!E10 -> 0.958726 | F27: =Curves!Q80 -> 0.94448209 | G27: =Curves!Q81 -> 0.95861205 | H27: =Curves!E13 -> 0.960645 | I27: =NPV_Engine!$B$4*B27*(C27/NPV_Engine!$B$8)*(1+0.5*(D27-NPV_Engine!$B$13))*(AVERAGE(E27,F27,G27)/B27)*(H27/NPV_Engine!$B$12) -> 9539400.5
A28: Scenario 7 | B28: =Curves!E8 -> 0.957768 | C28: =Curves!E9 -> 0.96933 | D28: =SABR!AT10 -> 0.39978212 | E28: =Curves!E10 -> 0.958726 | F28: =Curves!Q88 -> 0.95011547 | G28: =Curves!Q89 -> 0.95780838 | H28: =Curves!E13 -> 0.960645 | I28: =NPV_Engine!$B$4*B28*(C28/NPV_Engine!$B$8)*(1+0.5*(D28-NPV_Engine!$B$13))*(AVERAGE(E28,F28,G28)/B28)*(H28/NPV_Engine!$B$12) -> 9555499.5
A29: Scenario 8 | B29: =Curves!E8 -> 0.957768 | C29: =Curves!E9 -> 0.96933 | D29: =SABR!AT10 -> 0.39978212 | E29: =Curves!E10 -> 0.958726 | F29: =Curves!Q96 -> 0.94234687 | G29: =Curves!Q97 -> 0.95705696 | H29: =Curves!E13 -> 0.960645 | I29: =NPV_Engine!$B$4*B29*(C29/NPV_Engine!$B$8)*(1+0.5*(D29-NPV_Engine!$B$13))*(AVERAGE(E29,F29,G29)/B29)*(H29/NPV_Engine!$B$12) -> 9527099.4
A30: Scenario 9 | B30: =Curves!E8 -> 0.957768 | C30: =Curves!E9 -> 0.96933 | D30: =SABR!AT10 -> 0.39978212 | E30: =Curves!E10 -> 0.958726 | F30: =Curves!Q104 -> 0.94108519 | G30: =Curves!Q105 -> 0.9561681 | H30: =Curves!E13 -> 0.960645 | I30: =NPV_Engine!$B$4*B30*(C30/NPV_Engine!$B$8)*(1+0.5*(D30-NPV_Engine!$B$13))*(AVERAGE(E30,F30,G30)/B30)*(H30/NPV_Engine!$B$12) -> 9519931
A31: Scenario 10 | B31: =Curves!E8 -> 0.957768 | C31: =Curves!E9 -> 0.96933 | D31: =SABR!AT10 -> 0.39978212 | E31: =Curves!E10 -> 0.958726 | F31: =Curves!Q112 -> 0.94825632 | G31: =Curves!Q113 -> 0.96603972 | H31: =Curves!E13 -> 0.960645 | I31: =NPV_Engine!$B$4*B31*(C31/NPV_Engine!$B$8)*(1+0.5*(D31-NPV_Engine!$B$13))*(AVERAGE(E31,F31,G31)/B31)*(H31/NPV_Engine!$B$12) -> 9576740.1
A34: Credit — LH 40d — Full-Reval NPV | J34: Shocked curves: Agency_FNMA
A35: Case | B35: DF_SOFR(1Y) | C35: DF_ESTRN(1Y) | D35: SABR EffVol(1Yx10Y) | E35: DF_Treasury(1Y) | F35: DF_Agency_FNMA(1Y) | G35: DF_Eur_Govt(1Y) | H35: DF_EURUSD(1Y) | I35: NPV (USD)
A36: Base | B36: =Curves!E8 -> 0.957768 | C36: =Curves!E9 -> 0.96933 | D36: =SABR!AT10 -> 0.39978212 | E36: =Curves!E10 -> 0.958726 | F36: =Curves!E11 -> 0.954899 | G36: =Curves!E12 -> 0.967393 | H36: =Curves!E13 -> 0.960645 | I36: =NPV_Engine!$B$4*B36*(C36/NPV_Engine!$B$8)*(1+0.5*(D36-NPV_Engine!$B$13))*(AVERAGE(E36,F36,G36)/B36)*(H36/NPV_Engine!$B$12) -> 9603393.3
A37: Scenario 1 | B37: =Curves!E8 -> 0.957768 | C37: =Curves!E9 -> 0.96933 | D37: =SABR!AT10 -> 0.39978212 | E37: =Curves!E10 -> 0.958726 | F37: =Curves!Q40 -> 0.94931135 | G37: =Curves!E12 -> 0.967393 | H37: =Curves!E13 -> 0.960645 | I37: =NPV_Engine!$B$4*B37*(C37/NPV_Engine!$B$8)*(1+0.5*(D37-NPV_Engine!$B$13))*(AVERAGE(E37,F37,G37)/B37)*(H37/NPV_Engine!$B$12) -> 9584767.8
A38: Scenario 2 | B38: =Curves!E8 -> 0.957768 | C38: =Curves!E9 -> 0.96933 | D38: =SABR!AT10 -> 0.39978212 | E38: =Curves!E10 -> 0.958726 | F38: =Curves!Q48 -> 0.95209186 | G38: =Curves!E12 -> 0.967393 | H38: =Curves!E13 -> 0.960645 | I38: =NPV_Engine!$B$4*B38*(C38/NPV_Engine!$B$8)*(1+0.5*(D38-NPV_Engine!$B$13))*(AVERAGE(E38,F38,G38)/B38)*(H38/NPV_Engine!$B$12) -> 9594036.2
A39: Scenario 3 | B39: =Curves!E8 -> 0.957768 | C39: =Curves!E9 -> 0.96933 | D39: =SABR!AT10 -> 0.39978212 | E39: =Curves!E10 -> 0.958726 | F39: =Curves!Q56 -> 0.95361271 | G39: =Curves!E12 -> 0.967393 | H39: =Curves!E13 -> 0.960645 | I39: =NPV_Engine!$B$4*B39*(C39/NPV_Engine!$B$8)*(1+0.5*(D39-NPV_Engine!$B$13))*(AVERAGE(E39,F39,G39)/B39)*(H39/NPV_Engine!$B$12) -> 9599105.7
A40: Scenario 4 | B40: =Curves!E8 -> 0.957768 | C40: =Curves!E9 -> 0.96933 | D40: =SABR!AT10 -> 0.39978212 | E40: =Curves!E10 -> 0.958726 | F40: =Curves!Q64 -> 0.94623448 | G40: =Curves!E12 -> 0.967393 | H40: =Curves!E13 -> 0.960645 | I40: =NPV_Engine!$B$4*B40*(C40/NPV_Engine!$B$8)*(1+0.5*(D40-NPV_Engine!$B$13))*(AVERAGE(E40,F40,G40)/B40)*(H40/NPV_Engine!$B$12) -> 9574511.6
A41: Scenario 5 | B41: =Curves!E8 -> 0.957768 | C41: =Curves!E9 -> 0.96933 | D41: =SABR!AT10 -> 0.39978212 | E41: =Curves!E10 -> 0.958726 | F41: =Curves!Q72 -> 0.94534426 | G41: =Curves!E12 -> 0.967393 | H41: =Curves!E13 -> 0.960645 | I41: =NPV_Engine!$B$4*B41*(C41/NPV_Engine!$B$8)*(1+0.5*(D41-NPV_Engine!$B$13))*(AVERAGE(E41,F41,G41)/B41)*(H41/NPV_Engine!$B$12) -> 9571544.2
A42: Scenario 6 | B42: =Curves!E8 -> 0.957768 | C42: =Curves!E9 -> 0.96933 | D42: =SABR!AT10 -> 0.39978212 | E42: =Curves!E10 -> 0.958726 | F42: =Curves!Q80 -> 0.94448209 | G42: =Curves!E12 -> 0.967393 | H42: =Curves!E13 -> 0.960645 | I42: =NPV_Engine!$B$4*B42*(C42/NPV_Engine!$B$8)*(1+0.5*(D42-NPV_Engine!$B$13))*(AVERAGE(E42,F42,G42)/B42)*(H42/NPV_Engine!$B$12) -> 9568670.3
A43: Scenario 7 | B43: =Curves!E8 -> 0.957768 | C43: =Curves!E9 -> 0.96933 | D43: =SABR!AT10 -> 0.39978212 | E43: =Curves!E10 -> 0.958726 | F43: =Curves!Q88 -> 0.95011547 | G43: =Curves!E12 -> 0.967393 | H43: =Curves!E13 -> 0.960645 | I43: =NPV_Engine!$B$4*B43*(C43/NPV_Engine!$B$8)*(1+0.5*(D43-NPV_Engine!$B$13))*(AVERAGE(E43,F43,G43)/B43)*(H43/NPV_Engine!$B$12) -> 9587448.2
