Workbook

Sheet README
A1: SOFR zero curve – ICE vs BBG pre-onboarding comparison (demo)
A2: Synthetic demo on the uploaded SOFR data, Jan-2020 to Sep-2026, 14 tenors 1D–10Y. Spread convention everywhere: ICE − BBG, in bp.
A4: How to read this workbook
A5: 1. Verdict | B5: Executive tenor × year heatmap: GREEN / AMBER / RED and which metric fired. Start here.
A6: 2. Use_Cases | B6: The five demo cases: what was injected, which metrics caught it, which ones missed it, and the linked evidence.
A7: 3. Charts | B7: One chart per use case.
A8: 4. Heatmap_Year | B8: Every metric by tenor × year (plus full history), coloured against Thresholds.
A9: 5. Scorecard | B9: Full-history view per tenor. Shows how whole-history stats dilute a regime problem (e.g. 1D Spearman passes on full history).
A10: 6. Curve_Shape | B10: Curve-level checks per year: butterflies, slope, PCA on daily Δ.
A11: 7. Thresholds | B11: Editable RAG bounds (yellow). Everything recolours and re-verdicts when you change them.
A12: 8. Injection_Log | B12: Exactly what was planted where, so the demo is auditable.
A13: 9. Data sheets | B13: ICE_ZeroRates, BBG_ZeroRates (inputs), Spread_bp (formulas).
A15: Design principles
A16: Changes, not levels | B16: Correlation and KS are run on daily Δ. Levels of two trending series correlate ~1 even when day-to-day moves disagree.
A17: Buckets, not days | B17: Every metric is computed per tenor × calendar year so 2020–2026 fits on one screen; a red cell tells you where to drill down.
A18: Complementary detectors | B18: No single test catches everything: co-movement (Spearman, direction), distribution (KS, vol, tail), level (spread, robust z), trend (60d gap, opposite-trend) and shape (residual, butterflies).
A19: Calibrated thresholds | B19: Bounds were set from the clean tenor-years in this dataset with a margin. On real data, recalibrate on a period you trust before go-live (TBC).
A21: Key findings from the demo
A22: Correlation alone is not enough | B22: The 2Y divergence (60bp gap) still passes Spearman (0.852) and KS (0.057): slow drift is invisible in daily noise. Only the trend and level metrics catch it.
A23: Full history hides regimes | B23: The 1D stale block in 2021 gives full-history Spearman 0.868 and KS 0.049 (both green); by year, 2021 is RED on eight metrics.
A24: Single spikes hide in correlation | B24: The 5Y 83bp print barely moves Spearman (0.868) but explodes vol ratio (3.1x), tail ratio (4.3x) and robust z (99).
A25: Shape issues need a shape metric | B25: The 9M dip passes every Δ-based test; only the shape residual, the 6M-9M-1Y butterfly and max |spread| see it.
A26: Caveat | B26: The data is synthetic: the vendor noise (~0.85bp) makes clean Spearman ≈0.90. Real ICE vs BBG on the same curve should be tighter, so thresholds will tighten too.

Sheet Verdict
A1: Executive verdict – tenor × year
A2: Worst RAG across all 13 metrics (live formulas on Heatmap_Year + Thresholds). Right-hand table names the red metrics.
K3: Red metrics fired
A4: Tenor | B4: 2020 | C4: 2021 | D4: 2022 | E4: 2023 | F4: 2024 | G4: 2025 | H4: 2026 | I4: Full | K4: Tenor | L4: 2020 | M4: 2021 | N4: 2022 | O4: 2023 | P4: 2024 | Q4: 2025 | R4: 2026 | S4: Full
A5: 1D | B5: =IF((ABS(Heatmap_Year!B6)>Thresholds!$F$5)*1+(Heatmap_Year!B23>Thresholds!$F$6)*1+(Heatmap_Year!B40>Thresholds!$F$7)*1+(Heatmap_Year!B57<Thresholds!$F$8)*1+(Heatmap_Year!B74>Thresholds!$F$9)*1+(ABS(LN(Heatmap_Year!B91))>Thresholds!$F$10)*1+(ABS(LN(Heatmap_Year!B108))>Thresholds!$F$11)*1+(Heatmap_Year!B125<Thresholds!$F$12)*1+(Heatmap_Year!B142>Thresholds!$F$13)*1+(Heatmap_Year!B159>Thresholds!$F$14)*1+(Heatmap_Year!B176>Thresholds!$F$15)*1+(Heatmap_Year!B193>Thresholds!$F$16)*1+(Heatmap_Year!B210>Thresholds!$F$17)*1>0,"RED",IF((ABS(Heatmap_Year!B6)>Thresholds!$E$5)*1+(Heatmap_Year!B23>Thresholds!$E$6)*1+(Heatmap_Year!B40>Thresholds!$E$7)*1+(Heatmap_Year!B57<Thresholds!$E$8)*1+(Heatmap_Year!B74>Thresholds!$E$9)*1+(ABS(LN(Heatmap_Year!B91))>Thresholds!$E$10)*1+(ABS(LN(Heatmap_Year!B108))>Thresholds!$E$11)*1+(Heatmap_Year!B125<Thresholds!$E$12)*1+(Heatmap_Year!B142>Thresholds!$E$13)*1+(Heatmap_Year!B159>Thresholds!$E$14)*1+(Heatmap_Year!B176>Thresholds!$E$15)*1+(Heatmap_Year!B193>Thresholds!$E$16)*1+(Heatmap_Year!B210>Thresholds!$E$17)*1>0,"AMBER","GREEN")) -> GREEN | C5: =IF((ABS(Heatmap_Year!C6)>Thresholds!$F$5)*1+(Heatmap_Year!C23>Thresholds!$F$6)*1+(Heatmap_Year!C40>Thresholds!$F$7)*1+(Heatmap_Year!C57<Thresholds!$F$8)*1+(Heatmap_Year!C74>Thresholds!$F$9)*1+(ABS(LN(Heatmap_Year!C91))>Thresholds!$F$10)*1+(ABS(LN(Heatmap_Year!C108))>Thresholds!$F$11)*1+(Heatmap_Year!C125<Thresholds!$F$12)*1+(Heatmap_Year!C142>Thresholds!$F$13)*1+(Heatmap_Year!C159>Thresholds!$F$14)*1+(Heatmap_Year!C176>Thresholds!$F$15)*1+(Heatmap_Year!C193>Thresholds!$F$16)*1+(Heatmap_Year!C210>Thresholds!$F$17)*1>0,"RED",IF((ABS(Heatmap_Year!C6)>Thresholds!$E$5)*1+(Heatmap_Year!C23>Thresholds!$E$6)*1+(Heatmap_Year!C40>Thresholds!$E$7)*1+(Heatmap_Year!C57<Thresholds!$E$8)*1+(Heatmap_Year!C74>Thresholds!$E$9)*1+(ABS(LN(Heatmap_Year!C91))>Thresholds!$E$10)*1+(ABS(LN(Heatmap_Year!C108))>Thresholds!$E$11)*1+(Heatmap_Year!C125<Thresholds!$E$12)*1+(Heatmap_Year!C142>Thresholds!$E$13)*1+(Heatmap_Year!C159>Thresholds!$E$14)*1+(Heatmap_Year!C176>Thresholds!$E$15)*1+(Heatmap_Year!C193>Thresholds!$E$16)*1+(Heatmap_Year!C210>Thresholds!$E$17)*1>0,"AMBER","GREEN")) -> RED | D5: =IF((ABS(Heatmap_Year!D6)>Thresholds!$F$5)*1+(Heatmap_Year!D23>Thresholds!$F$6)*1+(Heatmap_Year!D40>Thresholds!$F$7)*1+(Heatmap_Year!D57<Thresholds!$F$8)*1+(Heatmap_Year!D74>Thresholds!$F$9)*1+(ABS(LN(Heatmap_Year!D91))>Thresholds!$F$10)*1+(ABS(LN(Heatmap_Year!D108))>Thresholds!$F$11)*1+(Heatmap_Year!D125<Thresholds!$F$12)*1+(Heatmap_Year!D142>Thresholds!$F$13)*1+(Heatmap_Year!D159>Thresholds!$F$14)*1+(Heatmap_Year!D176>Thresholds!$F$15)*1+(Heatmap_Year!D193>Thresholds!$F$16)*1+(Heatmap_Year!D210>Thresholds!$F$17)*1>0,"RED",IF((ABS(Heatmap_Year!D6)>Thresholds!$E$5)*1+(Heatmap_Year!D23>Thresholds!$E$6)*1+(Heatmap_Year!D40>Thresholds!$E$7)*1+(Heatmap_Year!D57<Thresholds!$E$8)*1+(Heatmap_Year!D74>Thresholds!$E$9)*1+(ABS(LN(Heatmap_Year!D91))>Thresholds!$E$10)*1+(ABS(LN(Heatmap_Year!D108))>Thresholds!$E$11)*1+(Heatmap_Year!D125<Thresholds!$E$12)*1+(Heatmap_Year!D142>Thresholds!$E$13)*1+(Heatmap_Year!D159>Thresholds!$E$14)*1+(Heatmap_Year!D176>Thresholds!$E$15)*1+(Heatmap_Year!D193>Thresholds!$E$16)*1+(Heatmap_Year!D210>Thresholds!$E$17)*1>0,"AMBER","GREEN")) -> GREEN | E5: =IF((ABS(Heatmap_Year!E6)>Thresholds!$F$5)*1+(Heatmap_Year!E23>Thresholds!$F$6)*1+(Heatmap_Year!E40>Thresholds!$F$7)*1+(Heatmap_Year!E57<Thresholds!$F$8)*1+(Heatmap_Year!E74>Thresholds!$F$9)*1+(ABS(LN(Heatmap_Year!E91))>Thresholds!$F$10)*1+(ABS(LN(Heatmap_Year!E108))>Thresholds!$F$11)*1+(Heatmap_Year!E125<Thresholds!$F$12)*1+(Heatmap_Year!E142>Thresholds!$F$13)*1+(Heatmap_Year!E159>Thresholds!$F$14)*1+(Heatmap_Year!E176>Thresholds!$F$15)*1+(Heatmap_Year!E193>Thresholds!$F$16)*1+(Heatmap_Year!E210>Thresholds!$F$17)*1>0,"RED",IF((ABS(Heatmap_Year!E6)>Thresholds!$E$5)*1+(Heatmap_Year!E23>Thresholds!$E$6)*1+(Heatmap_Year!E40>Thresholds!$E$7)*1+(Heatmap_Year!E57<Thresholds!$E$8)*1+(Heatmap_Year!E74>Thresholds!$E$9)*1+(ABS(LN(Heatmap_Year!E91))>Thresholds!$E$10)*1+(ABS(LN(Heatmap_Year!E108))>Thresholds!$E$11)*1+(Heatmap_Year!E125<Thresholds!$E$12)*1+(Heatmap_Year!E142>Thresholds!$E$13)*1+(Heatmap_Year!E159>Thresholds!$E$14)*1+(Heatmap_Year!E176>Thresholds!$E$15)*1+(Heatmap_Year!E193>Thresholds!$E$16)*1+(Heatmap_Year!E210>Thresholds!$E$17)*1>0,"AMBER","GREEN")) -> GREEN | F5: =IF((ABS(Heatmap_Year!F6)>Thresholds!$F$5)*1+(Heatmap_Year!F23>Thresholds!$F$6)*1+(Heatmap_Year!F40>Thresholds!$F$7)*1+(Heatmap_Year!F57<Thresholds!$F$8)*1+(Heatmap_Year!F74>Thresholds!$F$9)*1+(ABS(LN(Heatmap_Year!F91))>Thresholds!$F$10)*1+(ABS(LN(Heatmap_Year!F108))>Thresholds!$F$11)*1+(Heatmap_Year!F125<Thresholds!$F$12)*1+(Heatmap_Year!F142>Thresholds!$F$13)*1+(Heatmap_Year!F159>Thresholds!$F$14)*1+(Heatmap_Year!F176>Thresholds!$F$15)*1+(Heatmap_Year!F193>Thresholds!$F$16)*1+(Heatmap_Year!F210>Thresholds!$F$17)*1>0,"RED",IF((ABS(Heatmap_Year!F6)>Thresholds!$E$5)*1+(Heatmap_Year!F23>Thresholds!$E$6)*1+(Heatmap_Year!F40>Thresholds!$E$7)*1+(Heatmap_Year!F57<Thresholds!$E$8)*1+(Heatmap_Year!F74>Thresholds!$E$9)*1+(ABS(LN(Heatmap_Year!F91))>Thresholds!$E$10)*1+(ABS(LN(Heatmap_Year!F108))>Thresholds!$E$11)*1+(Heatmap_Year!F125<Thresholds!$E$12)*1+(Heatmap_Year!F142>Thresholds!$E$13)*1+(Heatmap_Year!F159>Thresholds!$E$14)*1+(Heatmap_Year!F176>Thresholds!$E$15)*1+(Heatmap_Year!F193>Thresholds!$E$16)*1+(Heatmap_Year!F210>Thresholds!$E$17)*1>0,"AMBER","GREEN")) -> GREEN | G5: =IF((ABS(Heatmap_Year!G6)>Thresholds!$F$5)*1+(Heatmap_Year!G23>Thresholds!$F$6)*1+(Heatmap_Year!G40>Thresholds!$F$7)*1+(Heatmap_Year!G57<Thresholds!$F$8)*1+(Heatmap_Year!G74>Thresholds!$F$9)*1+(ABS(LN(Heatmap_Year!G91))>Thresholds!$F$10)*1+(ABS(LN(Heatmap_Year!G108))>Thresholds!$F$11)*1+(Heatmap_Year!G125<Thresholds!$F$12)*1+(Heatmap_Year!G142>Thresholds!$F$13)*1+(Heatmap_Year!G159>Thresholds!$F$14)*1+(Heatmap_Year!G176>Thresholds!$F$15)*1+(Heatmap_Year!G193>Thresholds!$F$16)*1+(Heatmap_Year!G210>Thresholds!$F$17)*1>0,"RED",IF((ABS(Heatmap_Year!G6)>Thresholds!$E$5)*1+(Heatmap_Year!G23>Thresholds!$E$6)*1+(Heatmap_Year!G40>Thresholds!$E$7)*1+(Heatmap_Year!G57<Thresholds!$E$8)*1+(Heatmap_Year!G74>Thresholds!$E$9)*1+(ABS(LN(Heatmap_Year!G91))>Thresholds!$E$10)*1+(ABS(LN(Heatmap_Year!G108))>Thresholds!$E$11)*1+(Heatmap_Year!G125<Thresholds!$E$12)*1+(Heatmap_Year!G142>Thresholds!$E$13)*1+(Heatmap_Year!G159>Thresholds!$E$14)*1+(Heatmap_Year!G176>Thresholds!$E$15)*1+(Heatmap_Year!G193>Thresholds!$E$16)*1+(Heatmap_Year!G210>Thresholds!$E$17)*1>0,"AMBER","GREEN")) -> GREEN | H5: =IF((ABS(Heatmap_Year!H6)>Thresholds!$F$5)*1+(Heatmap_Year!H23>Thresholds!$F$6)*1+(Heatmap_Year!H40>Thresholds!$F$7)*1+(Heatmap_Year!H57<Thresholds!$F$8)*1+(Heatmap_Year!H74>Thresholds!$F$9)*1+(ABS(LN(Heatmap_Year!H91))>Thresholds!$F$10)*1+(ABS(LN(Heatmap_Year!H108))>Thresholds!$F$11)*1+(Heatmap_Year!H125<Thresholds!$F$12)*1+(Heatmap_Year!H142>Thresholds!$F$13)*1+(Heatmap_Year!H159>Thresholds!$F$14)*1+(Heatmap_Year!H176>Thresholds!$F$15)*1+(Heatmap_Year!H193>Thresholds!$F$16)*1+(Heatmap_Year!H210>Thresholds!$F$17)*1>0,"RED",IF((ABS(Heatmap_Year!H6)>Thresholds!$E$5)*1+(Heatmap_Year!H23>Thresholds!$E$6)*1+(Heatmap_Year!H40>Thresholds!$E$7)*1+(Heatmap_Year!H57<Thresholds!$E$8)*1+(Heatmap_Year!H74>Thresholds!$E$9)*1+(ABS(LN(Heatmap_Year!H91))>Thresholds!$E$10)*1+(ABS(LN(Heatmap_Year!H108))>Thresholds!$E$11)*1+(Heatmap_Year!H125<Thresholds!$E$12)*1+(Heatmap_Year!H142>Thresholds!$E$13)*1+(Heatmap_Year!H159>Thresholds!$E$14)*1+(Heatmap_Year!H176>Thresholds!$E$15)*1+(Heatmap_Year!H193>Thresholds!$E$16)*1+(Heatmap_Year!H210>Thresholds!$E$17)*1>0,"AMBER","GREEN")) -> GREEN | I5: =IF((ABS(Heatmap_Year!I6)>Thresholds!$F$5)*1+(Heatmap_Year!I23>Thresholds!$F$6)*1+(Heatmap_Year!I40>Thresholds!$F$7)*1+(Heatmap_Year!I57<Thresholds!$F$8)*1+(Heatmap_Year!I74>Thresholds!$F$9)*1+(ABS(LN(Heatmap_Year!I91))>Thresholds!$F$10)*1+(ABS(LN(Heatmap_Year!I108))>Thresholds!$F$11)*1+(Heatmap_Year!I125<Thresholds!$F$12)*1+(Heatmap_Year!I142>Thresholds!$F$13)*1+(Heatmap_Year!I159>Thresholds!$F$14)*1+(Heatmap_Year!I176>Thresholds!$F$15)*1+(Heatmap_Year!I193>Thresholds!$F$16)*1+(Heatmap_Year!I210>Thresholds!$F$17)*1>0,"RED",IF((ABS(Heatmap_Year!I6)>Thresholds!$E$5)*1+(Heatmap_Year!I23>Thresholds!$E$6)*1+(Heatmap_Year!I40>Thresholds!$E$7)*1+(Heatmap_Year!I57<Thresholds!$E$8)*1+(Heatmap_Year!I74>Thresholds!$E$9)*1+(ABS(LN(Heatmap_Year!I91))>Thresholds!$E$10)*1+(ABS(LN(Heatmap_Year!I108))>Thresholds!$E$11)*1+(Heatmap_Year!I125<Thresholds!$E$12)*1+(Heatmap_Year!I142>Thresholds!$E$13)*1+(Heatmap_Year!I159>Thresholds!$E$14)*1+(Heatmap_Year!I176>Thresholds!$E$15)*1+(Heatmap_Year!I193>Thresholds!$E$16)*1+(Heatmap_Year!I210>Thresholds!$E$17)*1>0,"AMBER","GREEN")) -> RED | K5: 1D | L5: =IF(ABS(Heatmap_Year!B6)>Thresholds!$F$5,"Bias ","")&IF(Heatmap_Year!B23>Thresholds!$F$6,"MaxSpread ","")&IF(Heatmap_Year!B40>Thresholds!$F$7,"Outlier ","")&IF(Heatmap_Year!B57<Thresholds!$F$8,"Spearman ","")&IF(Heatmap_Year!B74>Thresholds!$F$9,"KS ","")&IF(ABS(LN(Heatmap_Year!B91))>Thresholds!$F$10,"Vol ","")&IF(ABS(LN(Heatmap_Year!B108))>Thresholds!$F$11,"Tail ","")&IF(Heatmap_Year!B125<Thresholds!$F$12,"Direction ","")&IF(Heatmap_Year!B142>Thresholds!$F$13,"Stale% ","")&IF(Heatmap_Year!B159>Thresholds!$F$14,"StaleRun ","")&IF(Heatmap_Year!B176>Thresholds!$F$15,"TrendGap ","")&IF(Heatmap_Year!B193>Thresholds!$F$16,"OppTrend ","")&IF(Heatmap_Year!B210>Thresholds!$F$17,"Shape ","") | M5: =IF(ABS(Heatmap_Year!C6)>Thresholds!$F$5,"Bias ","")&IF(Heatmap_Year!C23>Thresholds!$F$6,"MaxSpread ","")&IF(Heatmap_Year!C40>Thresholds!$F$7,"Outlier ","")&IF(Heatmap_Year!C57<Thresholds!$F$8,"Spearman ","")&IF(Heatmap_Year!C74>Thresholds!$F$9,"KS ","")&IF(ABS(LN(Heatmap_Year!C91))>Thresholds!$F$10,"Vol ","")&IF(ABS(LN(Heatmap_Year!C108))>Thresholds!$F$11,"Tail ","")&IF(Heatmap_Year!C125<Thresholds!$F$12,"Direction ","")&IF(Heatmap_Year!C142>Thresholds!$F$13,"Stale% ","")&IF(Heatmap_Year!C159>Thresholds!$F$14,"StaleRun ","")&IF(Heatmap_Year!C176>Thresholds!$F$15,"TrendGap ","")&IF(Heatmap_Year!C193>Thresholds!$F$16,"OppTrend ","")&IF(Heatmap_Year!C210>Thresholds!$F$17,"Shape ","") -> MaxSpread Outlier Spearman KS Direction Stale% StaleRun TrendGap OppTrend Shape | N5: =IF(ABS(Heatmap_Year!D6)>Thresholds!$F$5,"Bias ","")&IF(Heatmap_Year!D23>Thresholds!$F$6,"MaxSpread ","")&IF(Heatmap_Year!D40>Thresholds!$F$7,"Outlier ","")&IF(Heatmap_Year!D57<Thresholds!$F$8,"Spearman ","")&IF(Heatmap_Year!D74>Thresholds!$F$9,"KS ","")&IF(ABS(LN(Heatmap_Year!D91))>Thresholds!$F$10,"Vol ","")&IF(ABS(LN(Heatmap_Year!D108))>Thresholds!$F$11,"Tail ","")&IF(Heatmap_Year!D125<Thresholds!$F$12,"Direction ","")&IF(Heatmap_Year!D142>Thresholds!$F$13,"Stale% ","")&IF(Heatmap_Year!D159>Thresholds!$F$14,"StaleRun ","")&IF(Heatmap_Year!D176>Thresholds!$F$15,"TrendGap ","")&IF(Heatmap_Year!D193>Thresholds!$F$16,"OppTrend ","")&IF(Heatmap_Year!D210>Thresholds!$F$17,"Shape ","") | O5: =IF(ABS(Heatmap_Year!E6)>Thresholds!$F$5,"Bias ","")&IF(Heatmap_Year!E23>Thresholds!$F$6,"MaxSpread ","")&IF(Heatmap_Year!E40>Thresholds!$F$7,"Outlier ","")&IF(Heatmap_Year!E57<Thresholds!$F$8,"Spearman ","")&IF(Heatmap_Year!E74>Thresholds!$F$9,"KS ","")&IF(ABS(LN(Heatmap_Year!E91))>Thresholds!$F$10,"Vol ","")&IF(ABS(LN(Heatmap_Year!E108))>Thresholds!$F$11,"Tail ","")&IF(Heatmap_Year!E125<Thresholds!$F$12,"Direction ","")&IF(Heatmap_Year!E142>Thresholds!$F$13,"Stale% ","")&IF(Heatmap_Year!E159>Thresholds!$F$14,"StaleRun ","")&IF(Heatmap_Year!E176>Thresholds!$F$15,"TrendGap ","")&IF(Heatmap_Year!E193>Thresholds!$F$16,"OppTrend ","")&IF(Heatmap_Year!E210>Thresholds!$F$17,"Shape ","") | P5: =IF(ABS(Heatmap_Year!F6)>Thresholds!$F$5,"Bias ","")&IF(Heatmap_Year!F23>Thresholds!$F$6,"MaxSpread ","")&IF(Heatmap_Year!F40>Thresholds!$F$7,"Outlier ","")&IF(Heatmap_Year!F57<Thresholds!$F$8,"Spearman ","")&IF(Heatmap_Year!F74>Thresholds!$F$9,"KS ","")&IF(ABS(LN(Heatmap_Year!F91))>Thresholds!$F$10,"Vol ","")&IF(ABS(LN(Heatmap_Year!F108))>Thresholds!$F$11,"Tail ","")&IF(Heatmap_Year!F125<Thresholds!$F$12,"Direction ","")&IF(Heatmap_Year!F142>Thresholds!$F$13,"Stale% ","")&IF(Heatmap_Year!F159>Thresholds!$F$14,"StaleRun ","")&IF(Heatmap_Year!F176>Thresholds!$F$15,"TrendGap ","")&IF(Heatmap_Year!F193>Thresholds!$F$16,"OppTrend ","")&IF(Heatmap_Year!F210>Thresholds!$F$17,"Shape ","") | Q5: =IF(ABS(Heatmap_Year!G6)>Thresholds!$F$5,"Bias ","")&IF(Heatmap_Year!G23>Thresholds!$F$6,"MaxSpread ","")&IF(Heatmap_Year!G40>Thresholds!$F$7,"Outlier ","")&IF(Heatmap_Year!G57<Thresholds!$F$8,"Spearman ","")&IF(Heatmap_Year!G74>Thresholds!$F$9,"KS ","")&IF(ABS(LN(Heatmap_Year!G91))>Thresholds!$F$10,"Vol ","")&IF(ABS(LN(Heatmap_Year!G108))>Thresholds!$F$11,"Tail ","")&IF(Heatmap_Year!G125<Thresholds!$F$12,"Direction ","")&IF(Heatmap_Year!G142>Thresholds!$F$13,"Stale% ","")&IF(Heatmap_Year!G159>Thresholds!$F$14,"StaleRun ","")&IF(Heatmap_Year!G176>Thresholds!$F$15,"TrendGap ","")&IF(Heatmap_Year!G193>Thresholds!$F$16,"OppTrend ","")&IF(Heatmap_Year!G210>Thresholds!$F$17,"Shape ","") | R5: =IF(ABS(Heatmap_Year!H6)>Thresholds!$F$5,"Bias ","")&IF(Heatmap_Year!H23>Thresholds!$F$6,"MaxSpread ","")&IF(Heatmap_Year!H40>Thresholds!$F$7,"Outlier ","")&IF(Heatmap_Year!H57<Thresholds!$F$8,"Spearman ","")&IF(Heatmap_Year!H74>Thresholds!$F$9,"KS ","")&IF(ABS(LN(Heatmap_Year!H91))>Thresholds!$F$10,"Vol ","")&IF(ABS(LN(Heatmap_Year!H108))>Thresholds!$F$11,"Tail ","")&IF(Heatmap_Year!H125<Thresholds!$F$12,"Direction ","")&IF(Heatmap_Year!H142>Thresholds!$F$13,"Stale% ","")&IF(Heatmap_Year!H159>Thresholds!$F$14,"StaleRun ","")&IF(Heatmap_Year!H176>Thresholds!$F$15,"TrendGap ","")&IF(Heatmap_Year!H193>Thresholds!$F$16,"OppTrend ","")&IF(Heatmap_Year!H210>Thresholds!$F$17,"Shape ","") | S5: =IF(ABS(Heatmap_Year!I6)>Thresholds!$F$5,"Bias ","")&IF(Heatmap_Year!I23>Thresholds!$F$6,"MaxSpread ","")&IF(Heatmap_Year!I40>Thresholds!$F$7,"Outlier ","")&IF(Heatmap_Year!I57<Thresholds!$F$8,"Spearman ","")&IF(Heatmap_Year!I74>Thresholds!$F$9,"KS ","")&IF(ABS(LN(Heatmap_Year!I91))>Thresholds!$F$10,"Vol ","")&IF(ABS(LN(Heatmap_Year!I108))>Thresholds!$F$11,"Tail ","")&IF(Heatmap_Year!I125<Thresholds!$F$12,"Direction ","")&IF(Heatmap_Year!I142>Thresholds!$F$13,"Stale% ","")&IF(Heatmap_Year!I159>Thresholds!$F$14,"StaleRun ","")&IF(Heatmap_Year!I176>Thresholds!$F$15,"TrendGap ","")&IF(Heatmap_Year!I193>Thresholds!$F$16,"OppTrend ","")&IF(Heatmap_Year!I210>Thresholds!$F$17,"Shape ","") -> MaxSpread Outlier StaleRun TrendGap OppTrend Shape
A6: 1W | B6: =IF((ABS(Heatmap_Year!B7)>Thresholds!$F$5)*1+(Heatmap_Year!B24>Thresholds!$F$6)*1+(Heatmap_Year!B41>Thresholds!$F$7)*1+(Heatmap_Year!B58<Thresholds!$F$8)*1+(Heatmap_Year!B75>Thresholds!$F$9)*1+(ABS(LN(Heatmap_Year!B92))>Thresholds!$F$10)*1+(ABS(LN(Heatmap_Year!B109))>Thresholds!$F$11)*1+(Heatmap_Year!B126<Thresholds!$F$12)*1+(Heatmap_Year!B143>Thresholds!$F$13)*1+(Heatmap_Year!B160>Thresholds!$F$14)*1+(Heatmap_Year!B177>Thresholds!$F$15)*1+(Heatmap_Year!B194>Thresholds!$F$16)*1+(Heatmap_Year!B211>Thresholds!$F$17)*1>0,"RED",IF((ABS(Heatmap_Year!B7)>Thresholds!$E$5)*1+(Heatmap_Year!B24>Thresholds!$E$6)*1+(Heatmap_Year!B41>Thresholds!$E$7)*1+(Heatmap_Year!B58<Thresholds!$E$8)*1+(Heatmap_Year!B75>Thresholds!$E$9)*1+(ABS(LN(Heatmap_Year!B92))>Thresholds!$E$10)*1+(ABS(LN(Heatmap_Year!B109))>Thresholds!$E$11)*1+(Heatmap_Year!B126<Thresholds!$E$12)*1+(Heatmap_Year!B143>Thresholds!$E$13)*1+(Heatmap_Year!B160>Thresholds!$E$14)*1+(Heatmap_Year!B177>Thresholds!$E$15)*1+(Heatmap_Year!B194>Thresholds!$E$16)*1+(Heatmap_Year!B211>Thresholds!$E$17)*1>0,"AMBER","GREEN")) -> GREEN | C6: =IF((ABS(Heatmap_Year!C7)>Thresholds!$F$5)*1+(Heatmap_Year!C24>Thresholds!$F$6)*1+(Heatmap_Year!C41>Thresholds!$F$7)*1+(Heatmap_Year!C58<Thresholds!$F$8)*1+(Heatmap_Year!C75>Thresholds!$F$9)*1+(ABS(LN(Heatmap_Year!C92))>Thresholds!$F$10)*1+(ABS(LN(Heatmap_Year!C109))>Thresholds!$F$11)*1+(Heatmap_Year!C126<Thresholds!$F$12)*1+(Heatmap_Year!C143>Thresholds!$F$13)*1+(Heatmap_Year!C160>Thresholds!$F$14)*1+(Heatmap_Year!C177>Thresholds!$F$15)*1+(Heatmap_Year!C194>Thresholds!$F$16)*1+(Heatmap_Year!C211>Thresholds!$F$17)*1>0,"RED",IF((ABS(Heatmap_Year!C7)>Thresholds!$E$5)*1+(Heatmap_Year!C24>Thresholds!$E$6)*1+(Heatmap_Year!C41>Thresholds!$E$7)*1+(Heatmap_Year!C58<Thresholds!$E$8)*1+(Heatmap_Year!C75>Thresholds!$E$9)*1+(ABS(LN(Heatmap_Year!C92))>Thresholds!$E$10)*1+(ABS(LN(Heatmap_Year!C109))>Thresholds!$E$11)*1+(Heatmap_Year!C126<Thresholds!$E$12)*1+(Heatmap_Year!C143>Thresholds!$E$13)*1+(Heatmap_Year!C160>Thresholds!$E$14)*1+(Heatmap_Year!C177>Thresholds!$E$15)*1+(Heatmap_Year!C194>Thresholds!$E$16)*1+(Heatmap_Year!C211>Thresholds!$E$17)*1>0,"AMBER","GREEN")) -> GREEN | D6: =IF((ABS(Heatmap_Year!D7)>Thresholds!$F$5)*1+(Heatmap_Year!D24>Thresholds!$F$6)*1+(Heatmap_Year!D41>Thresholds!$F$7)*1+(Heatmap_Year!D58<Thresholds!$F$8)*1+(Heatmap_Year!D75>Thresholds!$F$9)*1+(ABS(LN(Heatmap_Year!D92))>Thresholds!$F$10)*1+(ABS(LN(Heatmap_Year!D109))>Thresholds!$F$11)*1+(Heatmap_Year!D126<Thresholds!$F$12)*1+(Heatmap_Year!D143>Thresholds!$F$13)*1+(Heatmap_Year!D160>Thresholds!$F$14)*1+(Heatmap_Year!D177>Thresholds!$F$15)*1+(Heatmap_Year!D194>Thresholds!$F$16)*1+(Heatmap_Year!D211>Thresholds!$F$17)*1>0,"RED",IF((ABS(Heatmap_Year!D7)>Thresholds!$E$5)*1+(Heatmap_Year!D24>Thresholds!$E$6)*1+(Heatmap_Year!D41>Thresholds!$E$7)*1+(Heatmap_Year!D58<Thresholds!$E$8)*1+(Heatmap_Year!D75>Thresholds!$E$9)*1+(ABS(LN(Heatmap_Year!D92))>Thresholds!$E$10)*1+(ABS(LN(Heatmap_Year!D109))>Thresholds!$E$11)*1+(Heatmap_Year!D126<Thresholds!$E$12)*1+(Heatmap_Year!D143>Thresholds!$E$13)*1+(Heatmap_Year!D160>Thresholds!$E$14)*1+(Heatmap_Year!D177>Thresholds!$E$15)*1+(Heatmap_Year!D194>Thresholds!$E$16)*1+(Heatmap_Year!D211>Thresholds!$E$17)*1>0,"AMBER","GREEN")) -> GREEN | E6: =IF((ABS(Heatmap_Year!E7)>Thresholds!$F$5)*1+(Heatmap_Year!E24>Thresholds!$F$6)*1+(Heatmap_Year!E41>Thresholds!$F$7)*1+(Heatmap_Year!E58<Thresholds!$F$8)*1+(Heatmap_Year!E75>Thresholds!$F$9)*1+(ABS(LN(Heatmap_Year!E92))>Thresholds!$F$10)*1+(ABS(LN(Heatmap_Year!E109))>Thresholds!$F$11)*1+(Heatmap_Year!E126<Thresholds!$F$12)*1+(Heatmap_Year!E143>Thresholds!$F$13)*1+(Heatmap_Year!E160>Thresholds!$F$14)*1+(Heatmap_Year!E177>Thresholds!$F$15)*1+(Heatmap_Year!E194>Thresholds!$F$16)*1+(Heatmap_Year!E211>Thresholds!$F$17)*1>0,"RED",IF((ABS(Heatmap_Year!E7)>Thresholds!$E$5)*1+(Heatmap_Year!E24>Thresholds!$E$6)*1+(Heatmap_Year!E41>Thresholds!$E$7)*1+(Heatmap_Year!E58<Thresholds!$E$8)*1+(Heatmap_Year!E75>Thresholds!$E$9)*1+(ABS(LN(Heatmap_Year!E92))>Thresholds!$E$10)*1+(ABS(LN(Heatmap_Year!E109))>Thresholds!$E$11)*1+(Heatmap_Year!E126<Thresholds!$E$12)*1+(Heatmap_Year!E143>Thresholds!$E$13)*1+(Heatmap_Year!E160>Thresholds!$E$14)*1+(Heatmap_Year!E177>Thresholds!$E$15)*1+(Heatmap_Year!E194>Thresholds!$E$16)*1+(Heatmap_Year!E211>Thresholds!$E$17)*1>0,"AMBER","GREEN")) -> GREEN | F6: =IF((ABS(Heatmap_Year!F7)>Thresholds!$F$5)*1+(Heatmap_Year!F24>Thresholds!$F$6)*1+(Heatmap_Year!F41>Thresholds!$F$7)*1+(Heatmap_Year!F58<Thresholds!$F$8)*1+(Heatmap_Year!F75>Thresholds!$F$9)*1+(ABS(LN(Heatmap_Year!F92))>Thresholds!$F$10)*1+(ABS(LN(Heatmap_Year!F109))>Thresholds!$F$11)*1+(Heatmap_Year!F126<Thresholds!$F$12)*1+(Heatmap_Year!F143>Thresholds!$F$13)*1+(Heatmap_Year!F160>Thresholds!$F$14)*1+(Heatmap_Year!F177>Thresholds!$F$15)*1+(Heatmap_Year!F194>Thresholds!$F$16)*1+(Heatmap_Year!F211>Thresholds!$F$17)*1>0,"RED",IF((ABS(Heatmap_Year!F7)>Thresholds!$E$5)*1+(Heatmap_Year!F24>Thresholds!$E$6)*1+(Heatmap_Year!F41>Thresholds!$E$7)*1+(Heatmap_Year!F58<Thresholds!$E$8)*1+(Heatmap_Year!F75>Thresholds!$E$9)*1+(ABS(LN(Heatmap_Year!F92))>Thresholds!$E$10)*1+(ABS(LN(Heatmap_Year!F109))>Thresholds!$E$11)*1+(Heatmap_Year!F126<Thresholds!$E$12)*1+(Heatmap_Year!F143>Thresholds!$E$13)*1+(Heatmap_Year!F160>Thresholds!$E$14)*1+(Heatmap_Year!F177>Thresholds!$E$15)*1+(Heatmap_Year!F194>Thresholds!$E$16)*1+(Heatmap_Year!F211>Thresholds!$E$17)*1>0,"AMBER","GREEN")) -> GREEN | G6: =IF((ABS(Heatmap_Year!G7)>Thresholds!$F$5)*1+(Heatmap_Year!G24>Thresholds!$F$6)*1+(Heatmap_Year!G41>Thresholds!$F$7)*1+(Heatmap_Year!G58<Thresholds!$F$8)*1+(Heatmap_Year!G75>Thresholds!$F$9)*1+(ABS(LN(Heatmap_Year!G92))>Thresholds!$F$10)*1+(ABS(LN(Heatmap_Year!G109))>Thresholds!$F$11)*1+(Heatmap_Year!G126<Thresholds!$F$12)*1+(Heatmap_Year!G143>Thresholds!$F$13)*1+(Heatmap_Year!G160>Thresholds!$F$14)*1+(Heatmap_Year!G177>Thresholds!$F$15)*1+(Heatmap_Year!G194>Thresholds!$F$16)*1+(Heatmap_Year!G211>Thresholds!$F$17)*1>0,"RED",IF((ABS(Heatmap_Year!G7)>Thresholds!$E$5)*1+(Heatmap_Year!G24>Thresholds!$E$6)*1+(Heatmap_Year!G41>Thresholds!$E$7)*1+(Heatmap_Year!G58<Thresholds!$E$8)*1+(Heatmap_Year!G75>Thresholds!$E$9)*1+(ABS(LN(Heatmap_Year!G92))>Thresholds!$E$10)*1+(ABS(LN(Heatmap_Year!G109))>Thresholds!$E$11)*1+(Heatmap_Year!G126<Thresholds!$E$12)*1+(Heatmap_Year!G143>Thresholds!$E$13)*1+(Heatmap_Year!G160>Thresholds!$E$14)*1+(Heatmap_Year!G177>Thresholds!$E$15)*1+(Heatmap_Year!G194>Thresholds!$E$16)*1+(Heatmap_Year!G211>Thresholds!$E$17)*1>0,"AMBER","GREEN")) -> GREEN | H6: =IF((ABS(Heatmap_Year!H7)>Thresholds!$F$5)*1+(Heatmap_Year!H24>Thresholds!$F$6)*1+(Heatmap_Year!H41>Thresholds!$F$7)*1+(Heatmap_Year!H58<Thresholds!$F$8)*1+(Heatmap_Year!H75>Thresholds!$F$9)*1+(ABS(LN(Heatmap_Year!H92))>Thresholds!$F$10)*1+(ABS(LN(Heatmap_Year!H109))>Thresholds!$F$11)*1+(Heatmap_Year!H126<Thresholds!$F$12)*1+(Heatmap_Year!H143>Thresholds!$F$13)*1+(Heatmap_Year!H160>Thresholds!$F$14)*1+(Heatmap_Year!H177>Thresholds!$F$15)*1+(Heatmap_Year!H194>Thresholds!$F$16)*1+(Heatmap_Year!H211>Thresholds!$F$17)*1>0,"RED",IF((ABS(Heatmap_Year!H7)>Thresholds!$E$5)*1+(Heatmap_Year!H24>Thresholds!$E$6)*1+(Heatmap_Year!H41>Thresholds!$E$7)*1+(Heatmap_Year!H58<Thresholds!$E$8)*1+(Heatmap_Year!H75>Thresholds!$E$9)*1+(ABS(LN(Heatmap_Year!H92))>Thresholds!$E$10)*1+(ABS(LN(Heatmap_Year!H109))>Thresholds!$E$11)*1+(Heatmap_Year!H126<Thresholds!$E$12)*1+(Heatmap_Year!H143>Thresholds!$E$13)*1+(Heatmap_Year!H160>Thresholds!$E$14)*1+(Heatmap_Year!H177>Thresholds!$E$15)*1+(Heatmap_Year!H194>Thresholds!$E$16)*1+(Heatmap_Year!H211>Thresholds!$E$17)*1>0,"AMBER","GREEN")) -> GREEN | I6: =IF((ABS(Heatmap_Year!I7)>Thresholds!$F$5)*1+(Heatmap_Year!I24>Thresholds!$F$6)*1+(Heatmap_Year!I41>Thresholds!$F$7)*1+(Heatmap_Year!I58<Thresholds!$F$8)*1+(Heatmap_Year!I75>Thresholds!$F$9)*1+(ABS(LN(Heatmap_Year!I92))>Thresholds!$F$10)*1+(ABS(LN(Heatmap_Year!I109))>Thresholds!$F$11)*1+(Heatmap_Year!I126<Thresholds!$F$12)*1+(Heatmap_Year!I143>Thresholds!$F$13)*1+(Heatmap_Year!I160>Thresholds!$F$14)*1+(Heatmap_Year!I177>Thresholds!$F$15)*1+(Heatmap_Year!I194>Thresholds!$F$16)*1+(Heatmap_Year!I211>Thresholds!$F$17)*1>0,"RED",IF((ABS(Heatmap_Year!I7)>Thresholds!$E$5)*1+(Heatmap_Year!I24>Thresholds!$E$6)*1+(Heatmap_Year!I41>Thresholds!$E$7)*1+(Heatmap_Year!I58<Thresholds!$E$8)*1+(Heatmap_Year!I75>Thresholds!$E$9)*1+(ABS(LN(Heatmap_Year!I92))>Thresholds!$E$10)*1+(ABS(LN(Heatmap_Year!I109))>Thresholds!$E$11)*1+(Heatmap_Year!I126<Thresholds!$E$12)*1+(Heatmap_Year!I143>Thresholds!$E$13)*1+(Heatmap_Year!I160>Thresholds!$E$14)*1+(Heatmap_Year!I177>Thresholds!$E$15)*1+(Heatmap_Year!I194>Thresholds!$E$16)*1+(Heatmap_Year!I211>Thresholds!$E$17)*1>0,"AMBER","GREEN")) -> GREEN | K6: 1W | L6: =IF(ABS(Heatmap_Year!B7)>Thresholds!$F$5,"Bias ","")&IF(Heatmap_Year!B24>Thresholds!$F$6,"MaxSpread ","")&IF(Heatmap_Year!B41>Thresholds!$F$7,"Outlier ","")&IF(Heatmap_Year!B58<Thresholds!$F$8,"Spearman ","")&IF(Heatmap_Year!B75>Thresholds!$F$9,"KS ","")&IF(ABS(LN(Heatmap_Year!B92))>Thresholds!$F$10,"Vol ","")&IF(ABS(LN(Heatmap_Year!B109))>Thresholds!$F$11,"Tail ","")&IF(Heatmap_Year!B126<Thresholds!$F$12,"Direction ","")&IF(Heatmap_Year!B143>Thresholds!$F$13,"Stale% ","")&IF(Heatmap_Year!B160>Thresholds!$F$14,"StaleRun ","")&IF(Heatmap_Year!B177>Thresholds!$F$15,"TrendGap ","")&IF(Heatmap_Year!B194>Thresholds!$F$16,"OppTrend ","")&IF(Heatmap_Year!B211>Thresholds!$F$17,"Shape ","") | M6: =IF(ABS(Heatmap_Year!C7)>Thresholds!$F$5,"Bias ","")&IF(Heatmap_Year!C24>Thresholds!$F$6,"MaxSpread ","")&IF(Heatmap_Year!C41>Thresholds!$F$7,"Outlier ","")&IF(Heatmap_Year!C58<Thresholds!$F$8,"Spearman ","")&IF(Heatmap_Year!C75>Thresholds!$F$9,"KS ","")&IF(ABS(LN(Heatmap_Year!C92))>Thresholds!$F$10,"Vol ","")&IF(ABS(LN(Heatmap_Year!C109))>Thresholds!$F$11,"Tail ","")&IF(Heatmap_Year!C126<Thresholds!$F$12,"Direction ","")&IF(Heatmap_Year!C143>Thresholds!$F$13,"Stale% ","")&IF(Heatmap_Year!C160>Thresholds!$F$14,"StaleRun ","")&IF(Heatmap_Year!C177>Thresholds!$F$15,"TrendGap ","")&IF(Heatmap_Year!C194>Thresholds!$F$16,"OppTrend ","")&IF(Heatmap_Year!C211>Thresholds!$F$17,"Shape ","") | N6: =IF(ABS(Heatmap_Year!D7)>Thresholds!$F$5,"Bias ","")&IF(Heatmap_Year!D24>Thresholds!$F$6,"MaxSpread ","")&IF(Heatmap_Year!D41>Thresholds!$F$7,"Outlier ","")&IF(Heatmap_Year!D58<Thresholds!$F$8,"Spearman ","")&IF(Heatmap_Year!D75>Thresholds!$F$9,"KS ","")&IF(ABS(LN(Heatmap_Year!D92))>Thresholds!$F$10,"Vol ","")&IF(ABS(LN(Heatmap_Year!D109))>Thresholds!$F$11,"Tail ","")&IF(Heatmap_Year!D126<Thresholds!$F$12,"Direction ","")&IF(Heatmap_Year!D143>Thresholds!$F$13,"Stale% ","")&IF(Heatmap_Year!D160>Thresholds!$F$14,"StaleRun ","")&IF(Heatmap_Year!D177>Thresholds!$F$15,"TrendGap ","")&IF(Heatmap_Year!D194>Thresholds!$F$16,"OppTrend ","")&IF(Heatmap_Year!D211>Thresholds!$F$17,"Shape ","") | O6: =IF(ABS(Heatmap_Year!E7)>Thresholds!$F$5,"Bias ","")&IF(Heatmap_Year!E24>Thresholds!$F$6,"MaxSpread ","")&IF(Heatmap_Year!E41>Thresholds!$F$7,"Outlier ","")&IF(Heatmap_Year!E58<Thresholds!$F$8,"Spearman ","")&IF(Heatmap_Year!E75>Thresholds!$F$9,"KS ","")&IF(ABS(LN(Heatmap_Year!E92))>Thresholds!$F$10,"Vol ","")&IF(ABS(LN(Heatmap_Year!E109))>Thresholds!$F$11,"Tail ","")&IF(Heatmap_Year!E126<Thresholds!$F$12,"Direction ","")&IF(Heatmap_Year!E143>Thresholds!$F$13,"Stale% ","")&IF(Heatmap_Year!E160>Thresholds!$F$14,"StaleRun ","")&IF(Heatmap_Year!E177>Thresholds!$F$15,"TrendGap ","")&IF(Heatmap_Year!E194>Thresholds!$F$16,"OppTrend ","")&IF(Heatmap_Year!E211>Thresholds!$F$17,"Shape ","") | P6: =IF(ABS(Heatmap_Year!F7)>Thresholds!$F$5,"Bias ","")&IF(Heatmap_Year!F24>Thresholds!$F$6,"MaxSpread ","")&IF(Heatmap_Year!F41>Thresholds!$F$7,"Outlier ","")&IF(Heatmap_Year!F58<Thresholds!$F$8,"Spearman ","")&IF(Heatmap_Year!F75>Thresholds!$F$9,"KS ","")&IF(ABS(LN(Heatmap_Year!F92))>Thresholds!$F$10,"Vol ","")&IF(ABS(LN(Heatmap_Year!F109))>Thresholds!$F$11,"Tail ","")&IF(Heatmap_Year!F126<Thresholds!$F$12,"Direction ","")&IF(Heatmap_Year!F143>Thresholds!$F$13,"Stale% ","")&IF(Heatmap_Year!F160>Thresholds!$F$14,"StaleRun ","")&IF(Heatmap_Year!F177>Thresholds!$F$15,"TrendGap ","")&IF(Heatmap_Year!F194>Thresholds!$F$16,"OppTrend ","")&IF(Heatmap_Year!F211>Thresholds!$F$17,"Shape ","") | Q6: =IF(ABS(Heatmap_Year!G7)>Thresholds!$F$5,"Bias ","")&IF(Heatmap_Year!G24>Thresholds!$F$6,"MaxSpread ","")&IF(Heatmap_Year!G41>Thresholds!$F$7,"Outlier ","")&IF(Heatmap_Year!G58<Thresholds!$F$8,"Spearman ","")&IF(Heatmap_Year!G75>Thresholds!$F$9,"KS ","")&IF(ABS(LN(Heatmap_Year!G92))>Thresholds!$F$10,"Vol ","")&IF(ABS(LN(Heatmap_Year!G109))>Thresholds!$F$11,"Tail ","")&IF(Heatmap_Year!G126<Thresholds!$F$12,"Direction ","")&IF(Heatmap_Year!G143>Thresholds!$F$13,"Stale% ","")&IF(Heatmap_Year!G160>Thresholds!$F$14,"StaleRun ","")&IF(Heatmap_Year!G177>Thresholds!$F$15,"TrendGap ","")&IF(Heatmap_Year!G194>Thresholds!$F$16,"OppTrend ","")&IF(Heatmap_Year!G211>Thresholds!$F$17,"Shape ","") | R6: =IF(ABS(Heatmap_Year!H7)>Thresholds!$F$5,"Bias ","")&IF(Heatmap_Year!H24>Thresholds!$F$6,"MaxSpread ","")&IF(Heatmap_Year!H41>Thresholds!$F$7,"Outlier ","")&IF(Heatmap_Year!H58<Thresholds!$F$8,"Spearman ","")&IF(Heatmap_Year!H75>Thresholds!$F$9,"KS ","")&IF(ABS(LN(Heatmap_Year!H92))>Thresholds!$F$10,"Vol ","")&IF(ABS(LN(Heatmap_Year!H109))>Thresholds!$F$11,"Tail ","")&IF(Heatmap_Year!H126<Thresholds!$F$12,"Direction ","")&IF(Heatmap_Year!H143>Thresholds!$F$13,"Stale% ","")&IF(Heatmap_Year!H160>Thresholds!$F$14,"StaleRun ","")&IF(Heatmap_Year!H177>Thresholds!$F$15,"TrendGap ","")&IF(Heatmap_Year!H194>Thresholds!$F$16,"OppTrend ","")&IF(Heatmap_Year!H211>Thresholds!$F$17,"Shape ","") | S6: =IF(ABS(Heatmap_Year!I7)>Thresholds!$F$5,"Bias ","")&IF(Heatmap_Year!I24>Thresholds!$F$6,"MaxSpread ","")&IF(Heatmap_Year!I41>Thresholds!$F$7,"Outlier ","")&IF(Heatmap_Year!I58<Thresholds!$F$8,"Spearman ","")&IF(Heatmap_Year!I75>Thresholds!$F$9,"KS ","")&IF(ABS(LN(Heatmap_Year!I92))>Thresholds!$F$10,"Vol ","")&IF(ABS(LN(Heatmap_Year!I109))>Thresholds!$F$11,"Tail ","")&IF(Heatmap_Year!I126<Thresholds!$F$12,"Direction ","")&IF(Heatmap_Year!I143>Thresholds!$F$13,"Stale% ","")&IF(Heatmap_Year!I160>Thresholds!$F$14,"StaleRun ","")&IF(Heatmap_Year!I177>Thresholds!$F$15,"TrendGap ","")&IF(Heatmap_Year!I194>Thresholds!$F$16,"OppTrend ","")&IF(Heatmap_Year!I211>Thresholds!$F$17,"Shape ","")
A7: 2W | B7: =IF((ABS(Heatmap_Year!B8)>Thresholds!$F$5)*1+(Heatmap_Year!B25>Thresholds!$F$6)*1+(Heatmap_Year!B42>Thresholds!$F$7)*1+(Heatmap_Year!B59<Thresholds!$F$8)*1+(Heatmap_Year!B76>Thresholds!$F$9)*1+(ABS(LN(Heatmap_Year!B93))>Thresholds!$F$10)*1+(ABS(LN(Heatmap_Year!B110))>Thresholds!$F$11)*1+(Heatmap_Year!B127<Thresholds!$F$12)*1+(Heatmap_Year!B144>Thresholds!$F$13)*1+(Heatmap_Year!B161>Thresholds!$F$14)*1+(Heatmap_Year!B178>Thresholds!$F$15)*1+(Heatmap_Year!B195>Thresholds!$F$16)*1+(Heatmap_Year!B212>Thresholds!$F$17)*1>0,"RED",IF((ABS(Heatmap_Year!B8)>Thresholds!$E$5)*1+(Heatmap_Year!B25>Thresholds!$E$6)*1+(Heatmap_Year!B42>Thresholds!$E$7)*1+(Heatmap_Year!B59<Thresholds!$E$8)*1+(Heatmap_Year!B76>Thresholds!$E$9)*1+(ABS(LN(Heatmap_Year!B93))>Thresholds!$E$10)*1+(ABS(LN(Heatmap_Year!B110))>Thresholds!$E$11)*1+(Heatmap_Year!B127<Thresholds!$E$12)*1+(Heatmap_Year!B144>Thresholds!$E$13)*1+(Heatmap_Year!B161>Thresholds!$E$14)*1+(Heatmap_Year!B178>Thresholds!$E$15)*1+(Heatmap_Year!B195>Thresholds!$E$16)*1+(Heatmap_Year!B212>Thresholds!$E$17)*1>0,"AMBER","GREEN")) -> GREEN | C7: =IF((ABS(Heatmap_Year!C8)>Thresholds!$F$5)*1+(Heatmap_Year!C25>Thresholds!$F$6)*1+(Heatmap_Year!C42>Thresholds!$F$7)*1+(Heatmap_Year!C59<Thresholds!$F$8)*1+(Heatmap_Year!C76>Thresholds!$F$9)*1+(ABS(LN(Heatmap_Year!C93))>Thresholds!$F$10)*1+(ABS(LN(Heatmap_Year!C110))>Thresholds!$F$11)*1+(Heatmap_Year!C127<Thresholds!$F$12)*1+(Heatmap_Year!C144>Thresholds!$F$13)*1+(Heatmap_Year!C161>Thresholds!$F$14)*1+(Heatmap_Year!C178>Thresholds!$F$15)*1+(Heatmap_Year!C195>Thresholds!$F$16)*1+(Heatmap_Year!C212>Thresholds!$F$17)*1>0,"RED",IF((ABS(Heatmap_Year!C8)>Thresholds!$E$5)*1+(Heatmap_Year!C25>Thresholds!$E$6)*1+(Heatmap_Year!C42>Thresholds!$E$7)*1+(Heatmap_Year!C59<Thresholds!$E$8)*1+(Heatmap_Year!C76>Thresholds!$E$9)*1+(ABS(LN(Heatmap_Year!C93))>Thresholds!$E$10)*1+(ABS(LN(Heatmap_Year!C110))>Thresholds!$E$11)*1+(Heatmap_Year!C127<Thresholds!$E$12)*1+(Heatmap_Year!C144>Thresholds!$E$13)*1+(Heatmap_Year!C161>Thresholds!$E$14)*1+(Heatmap_Year!C178>Thresholds!$E$15)*1+(Heatmap_Year!C195>Thresholds!$E$16)*1+(Heatmap_Year!C212>Thresholds!$E$17)*1>0,"AMBER","GREEN")) -> GREEN | D7: =IF((ABS(Heatmap_Year!D8)>Thresholds!$F$5)*1+(Heatmap_Year!D25>Thresholds!$F$6)*1+(Heatmap_Year!D42>Thresholds!$F$7)*1+(Heatmap_Year!D59<Thresholds!$F$8)*1+(Heatmap_Year!D76>Thresholds!$F$9)*1+(ABS(LN(Heatmap_Year!D93))>Thresholds!$F$10)*1+(ABS(LN(Heatmap_Year!D110))>Thresholds!$F$11)*1+(Heatmap_Year!D127<Thresholds!$F$12)*1+(Heatmap_Year!D144>Thresholds!$F$13)*1+(Heatmap_Year!D161>Thresholds!$F$14)*1+(Heatmap_Year!D178>Thresholds!$F$15)*1+(Heatmap_Year!D195>Thresholds!$F$16)*1+(Heatmap_Year!D212>Thresholds!$F$17)*1>0,"RED",IF((ABS(Heatmap_Year!D8)>Thresholds!$E$5)*1+(Heatmap_Year!D25>Thresholds!$E$6)*1+(Heatmap_Year!D42>Thresholds!$E$7)*1+(Heatmap_Year!D59<Thresholds!$E$8)*1+(Heatmap_Year!D76>Thresholds!$E$9)*1+(ABS(LN(Heatmap_Year!D93))>Thresholds!$E$10)*1+(ABS(LN(Heatmap_Year!D110))>Thresholds!$E$11)*1+(Heatmap_Year!D127<Thresholds!$E$12)*1+(Heatmap_Year!D144>Thresholds!$E$13)*1+(Heatmap_Year!D161>Thresholds!$E$14)*1+(Heatmap_Year!D178>Thresholds!$E$15)*1+(Heatmap_Year!D195>Thresholds!$E$16)*1+(Heatmap_Year!D212>Thresholds!$E$17)*1>0,"AMBER","GREEN")) -> GREEN | E7: =IF((ABS(Heatmap_Year!E8)>Thresholds!$F$5)*1+(Heatmap_Year!E25>Thresholds!$F$6)*1+(Heatmap_Year!E42>Thresholds!$F$7)*1+(Heatmap_Year!E59<Thresholds!$F$8)*1+(Heatmap_Year!E76>Thresholds!$F$9)*1+(ABS(LN(Heatmap_Year!E93))>Thresholds!$F$10)*1+(ABS(LN(Heatmap_Year!E110))>Thresholds!$F$11)*1+(Heatmap_Year!E127<Thresholds!$F$12)*1+(Heatmap_Year!E144>Thresholds!$F$13)*1+(Heatmap_Year!E161>Thresholds!$F$14)*1+(Heatmap_Year!E178>Thresholds!$F$15)*1+(Heatmap_Year!E195>Thresholds!$F$16)*1+(Heatmap_Year!E212>Thresholds!$F$17)*1>0,"RED",IF((ABS(Heatmap_Year!E8)>Thresholds!$E$5)*1+(Heatmap_Year!E25>Thresholds!$E$6)*1+(Heatmap_Year!E42>Thresholds!$E$7)*1+(Heatmap_Year!E59<Thresholds!$E$8)*1+(Heatmap_Year!E76>Thresholds!$E$9)*1+(ABS(LN(Heatmap_Year!E93))>Thresholds!$E$10)*1+(ABS(LN(Heatmap_Year!E110))>Thresholds!$E$11)*1+(Heatmap_Year!E127<Thresholds!$E$12)*1+(Heatmap_Year!E144>Thresholds!$E$13)*1+(Heatmap_Year!E161>Thresholds!$E$14)*1+(Heatmap_Year!E178>Thresholds!$E$15)*1+(Heatmap_Year!E195>Thresholds!$E$16)*1+(Heatmap_Year!E212>Thresholds!$E$17)*1>0,"AMBER","GREEN")) -> GREEN | F7: =IF((ABS(Heatmap_Year!F8)>Thresholds!$F$5)*1+(Heatmap_Year!F25>Thresholds!$F$6)*1+(Heatmap_Year!F42>Thresholds!$F$7)*1+(Heatmap_Year!F59<Thresholds!$F$8)*1+(Heatmap_Year!F76>Thresholds!$F$9)*1+(ABS(LN(Heatmap_Year!F93))>Thresholds!$F$10)*1+(ABS(LN(Heatmap_Year!F110))>Thresholds!$F$11)*1+(Heatmap_Year!F127<Thresholds!$F$12)*1+(Heatmap_Year!F144>Thresholds!$F$13)*1+(Heatmap_Year!F161>Thresholds!$F$14)*1+(Heatmap_Year!F178>Thresholds!$F$15)*1+(Heatmap_Year!F195>Thresholds!$F$16)*1+(Heatmap_Year!F212>Thresholds!$F$17)*1>0,"RED",IF((ABS(Heatmap_Year!F8)>Thresholds!$E$5)*1+(Heatmap_Year!F25>Thresholds!$E$6)*1+(Heatmap_Year!F42>Thresholds!$E$7)*1+(Heatmap_Year!F59<Thresholds!$E$8)*1+(Heatmap_Year!F76>Thresholds!$E$9)*1+(ABS(LN(Heatmap_Year!F93))>Thresholds!$E$10)*1+(ABS(LN(Heatmap_Year!F110))>Thresholds!$E$11)*1+(Heatmap_Year!F127<Thresholds!$E$12)*1+(Heatmap_Year!F144>Thresholds!$E$13)*1+(Heatmap_Year!F161>Thresholds!$E$14)*1+(Heatmap_Year!F178>Thresholds!$E$15)*1+(Heatmap_Year!F195>Thresholds!$E$16)*1+(Heatmap_Year!F212>Thresholds!$E$17)*1>0,"AMBER","GREEN")) -> GREEN | G7: =IF((ABS(Heatmap_Year!G8)>Thresholds!$F$5)*1+(Heatmap_Year!G25>Thresholds!$F$6)*1+(Heatmap_Year!G42>Thresholds!$F$7)*1+(Heatmap_Year!G59<Thresholds!$F$8)*1+(Heatmap_Year!G76>Thresholds!$F$9)*1+(ABS(LN(Heatmap_Year!G93))>Thresholds!$F$10)*1+(ABS(LN(Heatmap_Year!G110))>Thresholds!$F$11)*1+(Heatmap_Year!G127<Thresholds!$F$12)*1+(Heatmap_Year!G144>Thresholds!$F$13)*1+(Heatmap_Year!G161>Thresholds!$F$14)*1+(Heatmap_Year!G178>Thresholds!$F$15)*1+(Heatmap_Year!G195>Thresholds!$F$16)*1+(Heatmap_Year!G212>Thresholds!$F$17)*1>0,"RED",IF((ABS(Heatmap_Year!G8)>Thresholds!$E$5)*1+(Heatmap_Year!G25>Thresholds!$E$6)*1+(Heatmap_Year!G42>Thresholds!$E$7)*1+(Heatmap_Year!G59<Thresholds!$E$8)*1+(Heatmap_Year!G76>Thresholds!$E$9)*1+(ABS(LN(Heatmap_Year!G93))>Thresholds!$E$10)*1+(ABS(LN(Heatmap_Year!G110))>Thresholds!$E$11)*1+(Heatmap_Year!G127<Thresholds!$E$12)*1+(Heatmap_Year!G144>Thresholds!$E$13)*1+(Heatmap_Year!G161>Thresholds!$E$14)*1+(Heatmap_Year!G178>Thresholds!$E$15)*1+(Heatmap_Year!G195>Thresholds!$E$16)*1+(Heatmap_Year!G212>Thresholds!$E$17)*1>0,"AMBER","GREEN")) -> GREEN | H7: =IF((ABS(Heatmap_Year!H8)>Thresholds!$F$5)*1+(Heatmap_Year!H25>Thresholds!$F$6)*1+(Heatmap_Year!H42>Thresholds!$F$7)*1+(Heatmap_Year!H59<Thresholds!$F$8)*1+(Heatmap_Year!H76>Thresholds!$F$9)*1+(ABS(LN(Heatmap_Year!H93))>Thresholds!$F$10)*1+(ABS(LN(Heatmap_Year!H110))>Thresholds!$F$11)*1+(Heatmap_Year!H127<Thresholds!$F$12)*1+(Heatmap_Year!H144>Thresholds!$F$13)*1+(Heatmap_Year!H161>Thresholds!$F$14)*1+(Heatmap_Year!H178>Thresholds!$F$15)*1+(Heatmap_Year!H195>Thresholds!$F$16)*1+(Heatmap_Year!H212>Thresholds!$F$17)*1>0,"RED",IF((ABS(Heatmap_Year!H8)>Thresholds!$E$5)*1+(Heatmap_Year!H25>Thresholds!$E$6)*1+(Heatmap_Year!H42>Thresholds!$E$7)*1+(Heatmap_Year!H59<Thresholds!$E$8)*1+(Heatmap_Year!H76>Thresholds!$E$9)*1+(ABS(LN(Heatmap_Year!H93))>Thresholds!$E$10)*1+(ABS(LN(Heatmap_Year!H110))>Thresholds!$E$11)*1+(Heatmap_Year!H127<Thresholds!$E$12)*1+(Heatmap_Year!H144>Thresholds!$E$13)*1+(Heatmap_Year!H161>Thresholds!$E$14)*1+(Heatmap_Year!H178>Thresholds!$E$15)*1+(Heatmap_Year!H195>Thresholds!$E$16)*1+(Heatmap_Year!H212>Thresholds!$E$17)*1>0,"AMBER","GREEN")) -> GREEN | I7: =IF((ABS(Heatmap_Year!I8)>Thresholds!$F$5)*1+(Heatmap_Year!I25>Thresholds!$F$6)*1+(Heatmap_Year!I42>Thresholds!$F$7)*1+(Heatmap_Year!I59<Thresholds!$F$8)*1+(Heatmap_Year!I76>Thresholds!$F$9)*1+(ABS(LN(Heatmap_Year!I93))>Thresholds!$F$10)*1+(ABS(LN(Heatmap_Year!I110))>Thresholds!$F$11)*1+(Heatmap_Year!I127<Thresholds!$F$12)*1+(Heatmap_Year!I144>Thresholds!$F$13)*1+(Heatmap_Year!I161>Thresholds!$F$14)*1+(Heatmap_Year!I178>Thresholds!$F$15)*1+(Heatmap_Year!I195>Thresholds!$F$16)*1+(Heatmap_Year!I212>Thresholds!$F$17)*1>0,"RED",IF((ABS(Heatmap_Year!I8)>Thresholds!$E$5)*1+(Heatmap_Year!I25>Thresholds!$E$6)*1+(Heatmap_Year!I42>Thresholds!$E$7)*1+(Heatmap_Year!I59<Thresholds!$E$8)*1+(Heatmap_Year!I76>Thresholds!$E$9)*1+(ABS(LN(Heatmap_Year!I93))>Thresholds!$E$10)*1+(ABS(LN(Heatmap_Year!I110))>Thresholds!$E$11)*1+(Heatmap_Year!I127<Thresholds!$E$12)*1+(Heatmap_Year!I144>Thresholds!$E$13)*1+(Heatmap_Year!I161>Thresholds!$E$14)*1+(Heatmap_Year!I178>Thresholds!$E$15)*1+(Heatmap_Year!I195>Thresholds!$E$16)*1+(Heatmap_Year!I212>Thresholds!$E$17)*1>0,"AMBER","GREEN")) -> GREEN | K7: 2W | L7: =IF(ABS(Heatmap_Year!B8)>Thresholds!$F$5,"Bias ","")&IF(Heatmap_Year!B25>Thresholds!$F$6,"MaxSpread ","")&IF(Heatmap_Year!B42>Thresholds!$F$7,"Outlier ","")&IF(Heatmap_Year!B59<Thresholds!$F$8,"Spearman ","")&IF(Heatmap_Year!B76>Thresholds!$F$9,"KS ","")&IF(ABS(LN(Heatmap_Year!B93))>Thresholds!$F$10,"Vol ","")&IF(ABS(LN(Heatmap_Year!B110))>Thresholds!$F$11,"Tail ","")&IF(Heatmap_Year!B127<Thresholds!$F$12,"Direction ","")&IF(Heatmap_Year!B144>Thresholds!$F$13,"Stale% ","")&IF(Heatmap_Year!B161>Thresholds!$F$14,"StaleRun ","")&IF(Heatmap_Year!B178>Thresholds!$F$15,"TrendGap ","")&IF(Heatmap_Year!B195>Thresholds!$F$16,"OppTrend ","")&IF(Heatmap_Year!B212>Thresholds!$F$17,"Shape ","") | M7: =IF(ABS(Heatmap_Year!C8)>Thresholds!$F$5,"Bias ","")&IF(Heatmap_Year!C25>Thresholds!$F$6,"MaxSpread ","")&IF(Heatmap_Year!C42>Thresholds!$F$7,"Outlier ","")&IF(Heatmap_Year!C59<Thresholds!$F$8,"Spearman ","")&IF(Heatmap_Year!C76>Thresholds!$F$9,"KS ","")&IF(ABS(LN(Heatmap_Year!C93))>Thresholds!$F$10,"Vol ","")&IF(ABS(LN(Heatmap_Year!C110))>Thresholds!$F$11,"Tail ","")&IF(Heatmap_Year!C127<Thresholds!$F$12,"Direction ","")&IF(Heatmap_Year!C144>Thresholds!$F$13,"Stale% ","")&IF(Heatmap_Year!C161>Thresholds!$F$14,"StaleRun ","")&IF(Heatmap_Year!C178>Thresholds!$F$15,"TrendGap ","")&IF(Heatmap_Year!C195>Thresholds!$F$16,"OppTrend ","")&IF(Heatmap_Year!C212>Thresholds!$F$17,"Shape ","") | N7: =IF(ABS(Heatmap_Year!D8)>Thresholds!$F$5,"Bias ","")&IF(Heatmap_Year!D25>Thresholds!$F$6,"MaxSpread ","")&IF(Heatmap_Year!D42>Thresholds!$F$7,"Outlier ","")&IF(Heatmap_Year!D59<Thresholds!$F$8,"Spearman ","")&IF(Heatmap_Year!D76>Thresholds!$F$9,"KS ","")&IF(ABS(LN(Heatmap_Year!D93))>Thresholds!$F$10,"Vol ","")&IF(ABS(LN(Heatmap_Year!D110))>Thresholds!$F$11,"Tail ","")&IF(Heatmap_Year!D127<Thresholds!$F$12,"Direction ","")&IF(Heatmap_Year!D144>Thresholds!$F$13,"Stale% ","")&IF(Heatmap_Year!D161>Thresholds!$F$14,"StaleRun ","")&IF(Heatmap_Year!D178>Thresholds!$F$15,"TrendGap ","")&IF(Heatmap_Year!D195>Thresholds!$F$16,"OppTrend ","")&IF(Heatmap_Year!D212>Thresholds!$F$17,"Shape ","") | O7: =IF(ABS(Heatmap_Year!E8)>Thresholds!$F$5,"Bias ","")&IF(Heatmap_Year!E25>Thresholds!$F$6,"MaxSpread ","")&IF(Heatmap_Year!E42>Thresholds!$F$7,"Outlier ","")&IF(Heatmap_Year!E59<Thresholds!$F$8,"Spearman ","")&IF(Heatmap_Year!E76>Thresholds!$F$9,"KS ","")&IF(ABS(LN(Heatmap_Year!E93))>Thresholds!$F$10,"Vol ","")&IF(ABS(LN(Heatmap_Year!E110))>Thresholds!$F$11,"Tail ","")&IF(Heatmap_Year!E127<Thresholds!$F$12,"Direction ","")&IF(Heatmap_Year!E144>Thresholds!$F$13,"Stale% ","")&IF(Heatmap_Year!E161>Thresholds!$F$14,"StaleRun ","")&IF(Heatmap_Year!E178>Thresholds!$F$15,"TrendGap ","")&IF(Heatmap_Year!E195>Thresholds!$F$16,"OppTrend ","")&IF(Heatmap_Year!E212>Thresholds!$F$17,"Shape ","") | P7: =IF(ABS(Heatmap_Year!F8)>Thresholds!$F$5,"Bias ","")&IF(Heatmap_Year!F25>Thresholds!$F$6,"MaxSpread ","")&IF(Heatmap_Year!F42>Thresholds!$F$7,"Outlier ","")&IF(Heatmap_Year!F59<Thresholds!$F$8,"Spearman ","")&IF(Heatmap_Year!F76>Thresholds!$F$9,"KS ","")&IF(ABS(LN(Heatmap_Year!F93))>Thresholds!$F$10,"Vol ","")&IF(ABS(LN(Heatmap_Year!F110))>Thresholds!$F$11,"Tail ","")&IF(Heatmap_Year!F127<Thresholds!$F$12,"Direction ","")&IF(Heatmap_Year!F144>Thresholds!$F$13,"Stale% ","")&IF(Heatmap_Year!F161>Thresholds!$F$14,"StaleRun ","")&IF(Heatmap_Year!F178>Thresholds!$F$15,"TrendGap ","")&IF(Heatmap_Year!F195>Thresholds!$F$16,"OppTrend ","")&IF(Heatmap_Year!F212>Thresholds!$F$17,"Shape ","") | Q7: =IF(ABS(Heatmap_Year!G8)>Thresholds!$F$5,"Bias ","")&IF(Heatmap_Year!G25>Thresholds!$F$6,"MaxSpread ","")&IF(Heatmap_Year!G42>Thresholds!$F$7,"Outlier ","")&IF(Heatmap_Year!G59<Thresholds!$F$8,"Spearman ","")&IF(Heatmap_Year!G76>Thresholds!$F$9,"KS ","")&IF(ABS(LN(Heatmap_Year!G93))>Thresholds!$F$10,"Vol ","")&IF(ABS(LN(Heatmap_Year!G110))>Thresholds!$F$11,"Tail ","")&IF(Heatmap_Year!G127<Thresholds!$F$12,"Direction ","")&IF(Heatmap_Year!G144>Thresholds!$F$13,"Stale% ","")&IF(Heatmap_Year!G161>Thresholds!$F$14,"StaleRun ","")&IF(Heatmap_Year!G178>Thresholds!$F$15,"TrendGap ","")&IF(Heatmap_Year!G195>Thresholds!$F$16,"OppTrend ","")&IF(Heatmap_Year!G212>Thresholds!$F$17,"Shape ","") | R7: =IF(ABS(Heatmap_Year!H8)>Thresholds!$F$5,"Bias ","")&IF(Heatmap_Year!H25>Thresholds!$F$6,"MaxSpread ","")&IF(Heatmap_Year!H42>Thresholds!$F$7,"Outlier ","")&IF(Heatmap_Year!H59<Thresholds!$F$8,"Spearman ","")&IF(Heatmap_Year!H76>Thresholds!$F$9,"KS ","")&IF(ABS(LN(Heatmap_Year!H93))>Thresholds!$F$10,"Vol ","")&IF(ABS(LN(Heatmap_Year!H110))>Thresholds!$F$11,"Tail ","")&IF(Heatmap_Year!H127<Thresholds!$F$12,"Direction ","")&IF(Heatmap_Year!H144>Thresholds!$F$13,"Stale% ","")&IF(Heatmap_Year!H161>Thresholds!$F$14,"StaleRun ","")&IF(Heatmap_Year!H178>Thresholds!$F$15,"TrendGap ","")&IF(Heatmap_Year!H195>Thresholds!$F$16,"OppTrend ","")&IF(Heatmap_Year!H212>Thresholds!$F$17,"Shape ","") | S7: =IF(ABS(Heatmap_Year!I8)>Thresholds!$F$5,"Bias ","")&IF(Heatmap_Year!I25>Thresholds!$F$6,"MaxSpread ","")&IF(Heatmap_Year!I42>Thresholds!$F$7,"Outlier ","")&IF(Heatmap_Year!I59<Thresholds!$F$8,"Spearman ","")&IF(Heatmap_Year!I76>Thresholds!$F$9,"KS ","")&IF(ABS(LN(Heatmap_Year!I93))>Thresholds!$F$10,"Vol ","")&IF(ABS(LN(Heatmap_Year!I110))>Thresholds!$F$11,"Tail ","")&IF(Heatmap_Year!I127<Thresholds!$F$12,"Direction ","")&IF(Heatmap_Year!I144>Thresholds!$F$13,"Stale% ","")&IF(Heatmap_Year!I161>Thresholds!$F$14,"StaleRun ","")&IF(Heatmap_Year!I178>Thresholds!$F$15,"TrendGap ","")&IF(Heatmap_Year!I195>Thresholds!$F$16,"OppTrend ","")&IF(Heatmap_Year!I212>Thresholds!$F$17,"Shape ","")
