Workbook

Sheet ICE_ZeroRates
B1: 1D | C1: 1W | D1: 2W | E1: 3W | F1: 1M | G1: 2M | H1: 3M | I1: 6M | J1: 9M | K1: 1Y | L1: 2Y | M1: 3Y | N1: 5Y | O1: 10Y
A2: 43832 | B2: 1.8042792 | C2: 1.7960403 | D2: 1.807189 | E2: 1.8190092 | F2: 1.8117371 | G2: 1.8261353 | H2: 1.8356838 | I2: 1.8462358 | J2: 1.8690332 | K2: 1.867167 | L2: 1.8908644 | M2: 1.9077074 | N2: 1.9078789 | O2: 1.9169044
A3: 43833 | B3: 1.7920433 | C3: 1.7917968 | D3: 1.7953553 | E3: 1.8022067 | F3: 1.7977199 | G3: 1.8133162 | H3: 1.8205194 | I3: 1.8339693 | J3: 1.8524656 | K3: 1.8779023 | L3: 1.8932258 | M3: 1.8923422 | N3: 1.8995943 | O3: 1.9263839
A4: 43836 | B4: 1.8232572 | C4: 1.8155552 | D4: 1.8276318 | E4: 1.8248791 | F4: 1.8294022 | G4: 1.8295149 | H4: 1.8524382 | I4: 1.865792 | J4: 1.8873891 | K4: 1.8877385 | L4: 1.9157858 | M4: 1.9259362 | N4: 1.9310571 | O4: 1.9521208
A5: 43837 | B5: 1.7419594 | C5: 1.7425305 | D5: 1.7592664 | E5: 1.7589993 | F5: 1.7520738 | G5: 1.7714075 | H5: 1.7732213 | I5: 1.792709 | J5: 1.821524 | K5: 1.8165511 | L5: 1.8581195 | M5: 1.8631579 | N5: 1.8760518 | O5: 1.9032622
A6: 43838 | B6: 1.7421843 | C6: 1.7366454 | D6: 1.7491643 | E6: 1.7486557 | F6: 1.7444336 | G6: 1.7625034 | H6: 1.7816826 | I6: 1.8061505 | J6: 1.8164282 | K6: 1.8169399 | L6: 1.8545879 | M6: 1.8703222 | N6: 1.8843876 | O6: 1.9110141
A7: 43839 | B7: 1.7263344 | C7: 1.7266856 | D7: 1.7267928 | E7: 1.7222412 | F7: 1.7397524 | G7: 1.7506754 | H7: 1.7630639 | I7: 1.775222 | J7: 1.8039427 | K7: 1.8251114 | L7: 1.8434814 | M7: 1.8583949 | N7: 1.8786835 | O7: 1.9194692
A8: 43840 | B8: 1.7461017 | C8: 1.7564204 | D8: 1.7537172 | E8: 1.75841 | F8: 1.7654684 | G8: 1.7856565 | H8: 1.7985004 | I8: 1.8138038 | J8: 1.8255777 | K8: 1.8554072 | L8: 1.8677654 | M8: 1.8823743 | N8: 1.8927934 | O8: 1.9417222
A9: 43843 | B9: 1.769519 | C9: 1.7811528 | D9: 1.7615983 | E9: 1.7818369 | F9: 1.7775498 | G9: 1.7936676 | H9: 1.7889634 | I9: 1.8307805 | J9: 1.8431294 | K9: 1.8505202 | L9: 1.8835492 | M9: 1.889774 | N9: 1.9073679 | O9: 1.9364699
A10: 43844 | B10: 1.7499379 | C10: 1.7692193 | D10: 1.7745551 | E10: 1.766417 | F10: 1.7768452 | G10: 1.7851519 | H10: 1.7990161 | I10: 1.8172222 | J10: 1.8329048 | K10: 1.8576025 | L10: 1.8824526 | M10: 1.9118029 | N10: 1.9196209 | O10: 1.9462995
A11: 43845 | B11: 1.7625784 | C11: 1.7620555 | D11: 1.766058 | E11: 1.7721288 | F11: 1.7652917 | G11: 1.7807291 | H11: 1.7910555 | I11: 1.8091229 | J11: 1.8333044 | K11: 1.8567507 | L11: 1.8843958 | M11: 1.893935 | N11: 1.9156329 | O11: 1.9716899
A12: 43846 | B12: 1.7730223 | C12: 1.7727551 | D12: 1.7784465 | E12: 1.7745398 | F12: 1.7961987 | G12: 1.7976919 | H12: 1.8189503 | I12: 1.8361412 | J12: 1.8627146 | K12: 1.8697976 | L12: 1.9085831 | M12: 1.9276096 | N12: 1.9511702 | O12: 1.9877665
A13: 43847 | B13: 1.7562515 | C13: 1.7722619 | D13: 1.7588313 | E13: 1.7676645 | F13: 1.7720548 | G13: 1.7869949 | H13: 1.7929202 | I13: 1.8231124 | J13: 1.8391271 | K13: 1.8453489 | L13: 1.8921563 | M13: 1.907007 | N13: 1.9298413 | O13: 1.9825326
... A1753: 46283 | B1753: 3.0894263 | C1753: 3.10081 | D1753: 3.1044006 | E1753: 3.1072603 | F1753: 3.1065822 | G1753: 3.120414 | H1753: 3.1313828 | I1753: 3.1601175 | J1753: 3.1805897 | K1753: 3.2025332 | L1753: 3.2458746 | M1753: 3.2827364 | N1753: 3.3192964 | O1753: 3.3771068

Sheet BBG_ZeroRates
B1: 1D | C1: 1W | D1: 2W | E1: 3W | F1: 1M | G1: 2M | H1: 3M | I1: 6M | J1: 9M | K1: 1Y | L1: 2Y | M1: 3Y | N1: 5Y | O1: 10Y
A2: 43832 | B2: 1.8028232 | C2: 1.8075966 | D2: 1.8087359 | E2: 1.8177978 | F2: 1.8141701 | G2: 1.8297022 | H2: 1.8285703 | I2: 1.860728 | J2: 1.8666134 | K2: 1.8740564 | L2: 1.8917854 | M2: 1.8979455 | N2: 1.9068495 | O2: 1.9317231
A3: 43833 | B3: 1.7895046 | C3: 1.7829024 | D3: 1.8014726 | E3: 1.7955803 | F3: 1.810973 | G3: 1.8145477 | H3: 1.8247489 | I3: 1.8546668 | J3: 1.8656947 | K3: 1.8650148 | L3: 1.8883219 | M3: 1.8935826 | N3: 1.9284557 | O3: 1.9258807
A4: 43836 | B4: 1.824909 | C4: 1.8174821 | D4: 1.8173107 | E4: 1.8268969 | F4: 1.8286147 | G4: 1.8463405 | H4: 1.8556994 | I4: 1.8682608 | J4: 1.8775709 | K4: 1.8894406 | L4: 1.9050288 | M4: 1.9261775 | N4: 1.9359105 | O4: 1.9468365
A5: 43837 | B5: 1.7399759 | C5: 1.7503283 | D5: 1.7498418 | E5: 1.755428 | F5: 1.7584356 | G5: 1.7734892 | H5: 1.7782857 | I5: 1.8008846 | J5: 1.8080303 | K5: 1.8304737 | L5: 1.8570906 | M5: 1.8676081 | N5: 1.8927921 | O5: 1.9057804
A6: 43838 | B6: 1.7417583 | C6: 1.7485984 | D6: 1.7615351 | E6: 1.7534918 | F6: 1.742629 | G6: 1.770115 | H6: 1.7721196 | I6: 1.7885561 | J6: 1.8263095 | K6: 1.8369707 | L6: 1.8502132 | M6: 1.8638253 | N6: 1.8849944 | O6: 1.9049933
A7: 43839 | B7: 1.7273444 | C7: 1.726841 | D7: 1.7320406 | E7: 1.7292026 | F7: 1.7466759 | G7: 1.7607819 | H7: 1.7631172 | I7: 1.7870298 | J7: 1.8078476 | K7: 1.8167956 | L7: 1.8573881 | M7: 1.8548668 | N7: 1.8859951 | O7: 1.91059
A8: 43840 | B8: 1.7495163 | C8: 1.7726837 | D8: 1.7768264 | E8: 1.7644448 | F8: 1.7724343 | G8: 1.7787454 | H8: 1.7898327 | I8: 1.80832 | J8: 1.8241557 | K8: 1.8555157 | L8: 1.8740981 | M8: 1.8901047 | N8: 1.90258 | O8: 1.9384855
A9: 43843 | B9: 1.7586867 | C9: 1.7660036 | D9: 1.7667368 | E9: 1.7848452 | F9: 1.7712176 | G9: 1.7857557 | H9: 1.7905646 | I9: 1.8206319 | J9: 1.8396532 | K9: 1.8606204 | L9: 1.8823465 | M9: 1.8959035 | N9: 1.916644 | O9: 1.9405932
A10: 43844 | B10: 1.7795137 | C10: 1.7645027 | D10: 1.7738878 | E10: 1.7795838 | F10: 1.7750377 | G10: 1.7917373 | H10: 1.7980414 | I10: 1.8266318 | J10: 1.8428109 | K10: 1.8544483 | L10: 1.8799025 | M10: 1.9148524 | N10: 1.9268615 | O10: 1.9463241
A11: 43845 | B11: 1.7566945 | C11: 1.7528543 | D11: 1.7702692 | E11: 1.7688545 | F11: 1.773233 | G11: 1.7804384 | H11: 1.7941908 | I11: 1.8255904 | J11: 1.8452209 | K11: 1.8578109 | L11: 1.8776587 | M11: 1.9048946 | N11: 1.9304878 | O11: 1.9612926
A12: 43846 | B12: 1.7676102 | C12: 1.7729198 | D12: 1.7930891 | E12: 1.7802549 | F12: 1.7919455 | G12: 1.8031122 | H12: 1.8138232 | I12: 1.8379121 | J12: 1.8628722 | K12: 1.8724711 | L12: 1.9037098 | M12: 1.9276031 | N12: 1.9437652 | O12: 1.9925346
A13: 43847 | B13: 1.7575628 | C13: 1.7610291 | D13: 1.7713512 | E13: 1.7691948 | F13: 1.7738594 | G13: 1.7955861 | H13: 1.7936579 | I13: 1.8282142 | J13: 1.8498373 | K13: 1.865842 | L13: 1.9091581 | M13: 1.9137575 | N13: 1.93904 | O13: 1.9906147
... A1753: 46283 | B1753: 3.0999951 | C1753: 3.1032204 | D1753: 3.1012378 | E1753: 3.1126897 | F1753: 3.1188231 | G1753: 3.1232722 | H1753: 3.1275167 | I1753: 3.1734401 | J1753: 3.1934012 | K1753: 3.2122127 | L1753: 3.2546986 | M1753: 3.2898988 | N1753: 3.3190375 | O1753: 3.3789725

Sheet Metric_Methodology
A1: Metric | B1: what it means | C1: Excel formula | D1: Python expression | E1: Green | F1: Amber | G1: Red | H1: Interpretation
A2: |Median spread| (bp) | B2: Are the vendors normally centered at the same level? | C2: =ABS(MEDIAN(spread_range))*100 | D2: abs(np.nanmedian((ice-bbg)*100)) | E2: ≤ 2 bp | F2: 2–5 bp | G2: > 5 bp | H2: Robust systematic level bias; median resists isolated outliers.
A3: P5/P95 absolute band (bp) | B3: How wide is the normal vendor disagreement? | C3: =MAX(ABS(PERCENTILE.INC(spread_range,0.05)),ABS(PERCENTILE.INC(spread_range,0.95)))*100 | D3: max(abs(np.nanpercentile(spread_bp,5)),abs(np.nanpercentile(spread_bp,95))) | E3: ≤ 3 bp | F3: 3–7 bp | G3: > 7 bp | H3: Captures the central 90% disagreement band without letting extremes dominate.
A4: Max |spread| (bp) | B4: What is the worst single vendor disagreement? | C4: =MAX(MAX(spread_bp_range),-MIN(spread_bp_range)) | D4: np.nanmax(np.abs(spread_bp)) | E4: ≤ 10 bp | F4: 10–25 bp | G4: > 25 bp | H4: Exception detector. A red result can be one isolated bad point, not a bad history.
A5: Spearman of daily changes | B5: Do the vendors rank daily market moves similarly? | C5: =CORREL(rank_ICE_daily_changes,rank_BBG_daily_changes) | D5: spearmanr(ice.diff().dropna(), bbg.diff().dropna()).statistic | E5: ≥ 0.90 | F5: 0.80–0.90 | G5: < 0.80 | H5: 1 means almost identical rank ordering of moves; 0 means little monotonic relationship.
A6: KS statistic on daily changes | B6: Do daily changes have similar empirical distributions? | C6: Build empirical CDFs for ICE Δ and BBG Δ on the same sorted x-grid; KS = MAX(ABS(CDF_ICE-CDF_BBG)) | D6: ks_2samp(ice.diff().dropna(), bbg.diff().dropna()).statistic | E6: ≤ 0.05 | F6: 0.05–0.10 | G6: > 0.10 | H6: 0 means identical empirical distributions; larger values mean greater distribution separation.
A7: Direction agreement | B7: How often do both vendors say up/down on the same day? | C7: =SUM(same_direction_flags)/COUNT(eligible_days) | D7: np.mean(np.sign(dice)==np.sign(dbbg)) | E7: ≥ 95% | F7: 90–95% | G7: < 90% | H7: Simple executive diagnostic; ideally apply a small move-materiality floor.
A8: Volatility ratio ICE/BBG | B8: Do both vendors show a similar amount of day-to-day movement? | C8: =STDEV.S(ICE_daily_changes)/STDEV.S(BBG_daily_changes) | D8: ice.diff().std()/bbg.diff().std() | E8: 0.90–1.10 | F8: 0.80–0.90 or 1.10–1.20 | G8: <0.80 or >1.20 | H8: 1.0 means equal daily-change volatility. Far from 1 can indicate smoothing, noise, or staleness.
A9: ICE stale while BBG moves | B9: How often is ICE unchanged while Bloomberg materially moves? | C9: =SUM(stale_flags)/COUNT(eligible_days) | D9: np.mean((np.abs(dice)<eps) & (np.abs(dbbg)>move_floor)) | E9: ≤ 1% | F9: 1–3% | G9: > 3% | H9: Targeted stale-data detector. The BBG move floor prevents legitimate unchanged days being mislabeled.

Sheet Scorecard
A1: Tenor | B1: Median spread (bp) | C1: P5 spread (bp) | D1: P95 spread (bp) | E1: Max |spread| (bp) | F1: Spearman Δ | G1: KS Δ | H1: Direction agreement | I1: Full-history vol ratio | J1: ICE-stale/BBG-moves %
A2: 1D | B2: -0.34 | C2: -1.99 | D2: 1.27 | E2: 16.48 | F2: 0.869 | G2: 0.045 | H2: 0.806 | I2: 1 | J2: 0.057
A3: 1W | B3: -0.37 | C3: -1.73 | D3: 1.03 | E3: 3.51 | F3: 0.91 | G3: 0.018 | H3: 0.879 | I3: 1.004 | J3: 0
A4: 2W | B4: -0.41 | C4: -1.72 | D4: 1.03 | E4: 3.59 | F4: 0.914 | G4: 0.019 | H4: 0.874 | I4: 1.008 | J4: 0
A5: 3W | B5: -0.38 | C5: -1.78 | D5: 1.04 | E5: 3.19 | F5: 0.907 | G5: 0.017 | H5: 0.853 | I5: 1.003 | J5: 0
A6: 1M | B6: -0.4 | C6: -1.77 | D6: 0.99 | E6: 3.12 | F6: 0.916 | G6: 0.017 | H6: 0.87 | I6: 1.009 | J6: 0
A7: 2M | B7: -0.38 | C7: -1.86 | D7: 0.96 | E7: 3.59 | F7: 0.905 | G7: 0.019 | H7: 0.871 | I7: 1.004 | J7: 0
A8: 3M | B8: -0.4 | C8: -1.75 | D8: 0.99 | E8: 3.26 | F8: 0.911 | G8: 0.017 | H8: 0.877 | I8: 1.002 | J8: 0
A9: 6M | B9: -0.43 | C9: -1.89 | D9: 0.99 | E9: 3.44 | F9: 0.899 | G9: 0.029 | H9: 0.864 | I9: 0.999 | J9: 0
A10: 9M | B10: -0.36 | C10: -1.77 | D10: 1.01 | E10: 3.87 | F10: 0.906 | G10: 0.016 | H10: 0.866 | I10: 1.003 | J10: 0
A11: 1Y | B11: -0.38 | C11: -1.78 | D11: 1.01 | E11: 3.49 | F11: 0.911 | G11: 0.015 | H11: 0.871 | I11: 0.995 | J11: 0
A12: 2Y | B12: -0.36 | C12: -1.78 | D12: 7.89 | E12: 60.13 | F12: 0.897 | G12: 0.017 | H12: 0.859 | I12: 1.001 | J12: 0
A13: 3Y | B13: -0.4 | C13: -1.7 | D13: 1.08 | E13: 3.3 | F13: 0.898 | G13: 0.017 | H13: 0.861 | I13: 1.007 | J13: 0
... A15: 10Y | B15: -0.33 | C15: -1.75 | D15: 1.07 | E15: 3.02 | F15: 0.897 | G15: 0.012 | H15: 0.844 | I15: 1.003 | J15: 0

Sheet Thresholds
A1: Metric | B1: Green | C1: Amber | D1: Red | E1: Rationale / interpretation
A2: |Median spread| (bp) | B2: ≤ 2 | C2: 2–5 | D2: > 5 | E2: Persistent level bias; robust to isolated outliers.
A3: P5/P95 absolute band (bp) | B3: ≤ 3 | C3: 3–7 | D3: > 7 | E3: Normal vendor disagreement band; catches broad dispersion.
A4: Max |spread| (bp) | B4: ≤ 10 | C4: 10–25 | D4: > 25 | E4: Exception detector for isolated bad observations.
A5: Spearman of daily changes | B5: ≥ 0.88 | C5: 0.80–0.88 | D5: < 0.80 | E5: Trend/co-movement test; rank based and less outlier-sensitive.
A6: KS statistic on daily changes | B6: ≤ 0.05 | C6: 0.05–0.10 | D6: > 0.10 | E6: Distribution-shape comparison. Use statistic diagnostically, not p-value alone.
A7: Direction agreement | B7: ≥ 85% | C7: 75–85% | D7: < 75% | E7: Simple economic check: vendors move in same direction.
A8: Volatility ratio ICE/BBG | B8: 0.80–1.25 | C8: 0.60–0.80 or 1.25–1.50 | D8: < 0.60 or > 1.50 | E8: Detects materially different variability/staleness/noise.
A9: ICE stale while BBG moves | B9: ≤ 1% | C9: 1–3% | D9: > 3% | E9: Direct staleness diagnostic; especially useful at short tenors.
A11: Important calibration notes
A12: 1 | B12: These are proposed pre-onboarding benchmarking tolerances, not Basel/NPR regulatory thresholds.
A13: 2 | B13: Calibrate by asset class, tenor and source construction after observing clean overlap periods.
A14: 3 | B14: Overall status uses the worst individual test so exceptions are not diluted by strong full-history statistics.
A16: Reference
A17: Basel PLA analogy | B17: Spearman correlation and KS are used together in the PLA framework; thresholds above are NOT PLA thresholds and are proposed for vendor onboarding benchmarking. | E17: https://www.bis.org/basel_framework/chapter/MAR/32.htm
A18: Method principle | B18: Benchmark globally → identify exceptions → investigate exceptions. Avoid exhaustive date-by-date reconciliation unless an exception requires drill-down.

Sheet Executive_Heatmap
A1: ICE vs Bloomberg SOFR Zero Curve — Pre-Onboarding Executive Benchmark
A2: Objective: establish broad historical comparability, then investigate only material tenor/test exceptions — not day-by-day reconciliation.
A5: Tenor | B5: Level Bias | C5: Normal Band | D5: Max Exception | E5: Trend / Spearman | F5: Distribution / KS | G5: Direction | H5: Volatility | I5: Staleness | J5: Overall
A6: 1D | B6: =IF(ABS(Scorecard!B2)<=2,"GREEN",IF(ABS(Scorecard!B2)<=5,"AMBER","RED")) -> GREEN | C6: =IF(MAX(ABS(Scorecard!C2),ABS(Scorecard!D2))<=3,"GREEN",IF(MAX(ABS(Scorecard!C2),ABS(Scorecard!D2))<=7,"AMBER","RED")) -> GREEN | D6: =IF(Scorecard!E2<=10,"GREEN",IF(Scorecard!E2<=25,"AMBER","RED")) -> AMBER | E6: =IF(Scorecard!F2>=0.88,"GREEN",IF(Scorecard!F2>=0.8,"AMBER","RED")) -> AMBER | F6: =IF(Scorecard!G2<=0.05,"GREEN",IF(Scorecard!G2<=0.1,"AMBER","RED")) -> GREEN | G6: =IF(Scorecard!H2>=0.85,"GREEN",IF(Scorecard!H2>=0.75,"AMBER","RED")) -> AMBER | H6: =IF(AND(Scorecard!I2>=0.8,Scorecard!I2<=1.25),"GREEN",IF(AND(Scorecard!I2>=0.6,Scorecard!I2<=1.5),"AMBER","RED")) -> GREEN | I6: =IF(Scorecard!J2<=0.01,"GREEN",IF(Scorecard!J2<=0.03,"AMBER","RED")) -> RED | J6: =IF(COUNTIF(B6:I6,"RED")>0,"INVESTIGATE",IF(COUNTIF(B6:I6,"AMBER")>0,"REVIEW","COMPARABLE")) -> INVESTIGATE
A7: 1W | B7: =IF(ABS(Scorecard!B3)<=2,"GREEN",IF(ABS(Scorecard!B3)<=5,"AMBER","RED")) -> GREEN | C7: =IF(MAX(ABS(Scorecard!C3),ABS(Scorecard!D3))<=3,"GREEN",IF(MAX(ABS(Scorecard!C3),ABS(Scorecard!D3))<=7,"AMBER","RED")) -> GREEN | D7: =IF(Scorecard!E3<=10,"GREEN",IF(Scorecard!E3<=25,"AMBER","RED")) -> GREEN | E7: =IF(Scorecard!F3>=0.88,"GREEN",IF(Scorecard!F3>=0.8,"AMBER","RED")) -> GREEN | F7: =IF(Scorecard!G3<=0.05,"GREEN",IF(Scorecard!G3<=0.1,"AMBER","RED")) -> GREEN | G7: =IF(Scorecard!H3>=0.85,"GREEN",IF(Scorecard!H3>=0.75,"AMBER","RED")) -> GREEN | H7: =IF(AND(Scorecard!I3>=0.8,Scorecard!I3<=1.25),"GREEN",IF(AND(Scorecard!I3>=0.6,Scorecard!I3<=1.5),"AMBER","RED")) -> GREEN | I7: =IF(Scorecard!J3<=0.01,"GREEN",IF(Scorecard!J3<=0.03,"AMBER","RED")) -> GREEN | J7: =IF(COUNTIF(B7:I7,"RED")>0,"INVESTIGATE",IF(COUNTIF(B7:I7,"AMBER")>0,"REVIEW","COMPARABLE")) -> COMPARABLE
A8: 2W | B8: =IF(ABS(Scorecard!B4)<=2,"GREEN",IF(ABS(Scorecard!B4)<=5,"AMBER","RED")) -> GREEN | C8: =IF(MAX(ABS(Scorecard!C4),ABS(Scorecard!D4))<=3,"GREEN",IF(MAX(ABS(Scorecard!C4),ABS(Scorecard!D4))<=7,"AMBER","RED")) -> GREEN | D8: =IF(Scorecard!E4<=10,"GREEN",IF(Scorecard!E4<=25,"AMBER","RED")) -> GREEN | E8: =IF(Scorecard!F4>=0.88,"GREEN",IF(Scorecard!F4>=0.8,"AMBER","RED")) -> GREEN | F8: =IF(Scorecard!G4<=0.05,"GREEN",IF(Scorecard!G4<=0.1,"AMBER","RED")) -> GREEN | G8: =IF(Scorecard!H4>=0.85,"GREEN",IF(Scorecard!H4>=0.75,"AMBER","RED")) -> GREEN | H8: =IF(AND(Scorecard!I4>=0.8,Scorecard!I4<=1.25),"GREEN",IF(AND(Scorecard!I4>=0.6,Scorecard!I4<=1.5),"AMBER","RED")) -> GREEN | I8: =IF(Scorecard!J4<=0.01,"GREEN",IF(Scorecard!J4<=0.03,"AMBER","RED")) -> GREEN | J8: =IF(COUNTIF(B8:I8,"RED")>0,"INVESTIGATE",IF(COUNTIF(B8:I8,"AMBER")>0,"REVIEW","COMPARABLE")) -> COMPARABLE
A9: 3W | B9: =IF(ABS(Scorecard!B5)<=2,"GREEN",IF(ABS(Scorecard!B5)<=5,"AMBER","RED")) -> GREEN | C9: =IF(MAX(ABS(Scorecard!C5),ABS(Scorecard!D5))<=3,"GREEN",IF(MAX(ABS(Scorecard!C5),ABS(Scorecard!D5))<=7,"AMBER","RED")) -> GREEN | D9: =IF(Scorecard!E5<=10,"GREEN",IF(Scorecard!E5<=25,"AMBER","RED")) -> GREEN | E9: =IF(Scorecard!F5>=0.88,"GREEN",IF(Scorecard!F5>=0.8,"AMBER","RED")) -> GREEN | F9: =IF(Scorecard!G5<=0.05,"GREEN",IF(Scorecard!G5<=0.1,"AMBER","RED")) -> GREEN | G9: =IF(Scorecard!H5>=0.85,"GREEN",IF(Scorecard!H5>=0.75,"AMBER","RED")) -> GREEN | H9: =IF(AND(Scorecard!I5>=0.8,Scorecard!I5<=1.25),"GREEN",IF(AND(Scorecard!I5>=0.6,Scorecard!I5<=1.5),"AMBER","RED")) -> GREEN | I9: =IF(Scorecard!J5<=0.01,"GREEN",IF(Scorecard!J5<=0.03,"AMBER","RED")) -> GREEN | J9: =IF(COUNTIF(B9:I9,"RED")>0,"INVESTIGATE",IF(COUNTIF(B9:I9,"AMBER")>0,"REVIEW","COMPARABLE")) -> COMPARABLE
A10: 1M | B10: =IF(ABS(Scorecard!B6)<=2,"GREEN",IF(ABS(Scorecard!B6)<=5,"AMBER","RED")) -> GREEN | C10: =IF(MAX(ABS(Scorecard!C6),ABS(Scorecard!D6))<=3,"GREEN",IF(MAX(ABS(Scorecard!C6),ABS(Scorecard!D6))<=7,"AMBER","RED")) -> GREEN | D10: =IF(Scorecard!E6<=10,"GREEN",IF(Scorecard!E6<=25,"AMBER","RED")) -> GREEN | E10: =IF(Scorecard!F6>=0.88,"GREEN",IF(Scorecard!F6>=0.8,"AMBER","RED")) -> GREEN | F10: =IF(Scorecard!G6<=0.05,"GREEN",IF(Scorecard!G6<=0.1,"AMBER","RED")) -> GREEN | G10: =IF(Scorecard!H6>=0.85,"GREEN",IF(Scorecard!H6>=0.75,"AMBER","RED")) -> GREEN | H10: =IF(AND(Scorecard!I6>=0.8,Scorecard!I6<=1.25),"GREEN",IF(AND(Scorecard!I6>=0.6,Scorecard!I6<=1.5),"AMBER","RED")) -> GREEN | I10: =IF(Scorecard!J6<=0.01,"GREEN",IF(Scorecard!J6<=0.03,"AMBER","RED")) -> GREEN | J10: =IF(COUNTIF(B10:I10,"RED")>0,"INVESTIGATE",IF(COUNTIF(B10:I10,"AMBER")>0,"REVIEW","COMPARABLE")) -> COMPARABLE
A11: 2M | B11: =IF(ABS(Scorecard!B7)<=2,"GREEN",IF(ABS(Scorecard!B7)<=5,"AMBER","RED")) -> GREEN | C11: =IF(MAX(ABS(Scorecard!C7),ABS(Scorecard!D7))<=3,"GREEN",IF(MAX(ABS(Scorecard!C7),ABS(Scorecard!D7))<=7,"AMBER","RED")) -> GREEN | D11: =IF(Scorecard!E7<=10,"GREEN",IF(Scorecard!E7<=25,"AMBER","RED")) -> GREEN | E11: =IF(Scorecard!F7>=0.88,"GREEN",IF(Scorecard!F7>=0.8,"AMBER","RED")) -> GREEN | F11: =IF(Scorecard!G7<=0.05,"GREEN",IF(Scorecard!G7<=0.1,"AMBER","RED")) -> GREEN | G11: =IF(Scorecard!H7>=0.85,"GREEN",IF(Scorecard!H7>=0.75,"AMBER","RED")) -> GREEN | H11: =IF(AND(Scorecard!I7>=0.8,Scorecard!I7<=1.25),"GREEN",IF(AND(Scorecard!I7>=0.6,Scorecard!I7<=1.5),"AMBER","RED")) -> GREEN | I11: =IF(Scorecard!J7<=0.01,"GREEN",IF(Scorecard!J7<=0.03,"AMBER","RED")) -> GREEN | J11: =IF(COUNTIF(B11:I11,"RED")>0,"INVESTIGATE",IF(COUNTIF(B11:I11,"AMBER")>0,"REVIEW","COMPARABLE")) -> COMPARABLE
A12: 3M | B12: =IF(ABS(Scorecard!B8)<=2,"GREEN",IF(ABS(Scorecard!B8)<=5,"AMBER","RED")) -> GREEN | C12: =IF(MAX(ABS(Scorecard!C8),ABS(Scorecard!D8))<=3,"GREEN",IF(MAX(ABS(Scorecard!C8),ABS(Scorecard!D8))<=7,"AMBER","RED")) -> GREEN | D12: =IF(Scorecard!E8<=10,"GREEN",IF(Scorecard!E8<=25,"AMBER","RED")) -> GREEN | E12: =IF(Scorecard!F8>=0.88,"GREEN",IF(Scorecard!F8>=0.8,"AMBER","RED")) -> GREEN | F12: =IF(Scorecard!G8<=0.05,"GREEN",IF(Scorecard!G8<=0.1,"AMBER","RED")) -> GREEN | G12: =IF(Scorecard!H8>=0.85,"GREEN",IF(Scorecard!H8>=0.75,"AMBER","RED")) -> GREEN | H12: =IF(AND(Scorecard!I8>=0.8,Scorecard!I8<=1.25),"GREEN",IF(AND(Scorecard!I8>=0.6,Scorecard!I8<=1.5),"AMBER","RED")) -> GREEN | I12: =IF(Scorecard!J8<=0.01,"GREEN",IF(Scorecard!J8<=0.03,"AMBER","RED")) -> GREEN | J12: =IF(COUNTIF(B12:I12,"RED")>0,"INVESTIGATE",IF(COUNTIF(B12:I12,"AMBER")>0,"REVIEW","COMPARABLE")) -> COMPARABLE
A13: 6M | B13: =IF(ABS(Scorecard!B9)<=2,"GREEN",IF(ABS(Scorecard!B9)<=5,"AMBER","RED")) -> GREEN | C13: =IF(MAX(ABS(Scorecard!C9),ABS(Scorecard!D9))<=3,"GREEN",IF(MAX(ABS(Scorecard!C9),ABS(Scorecard!D9))<=7,"AMBER","RED")) -> GREEN | D13: =IF(Scorecard!E9<=10,"GREEN",IF(Scorecard!E9<=25,"AMBER","RED")) -> GREEN | E13: =IF(Scorecard!F9>=0.88,"GREEN",IF(Scorecard!F9>=0.8,"AMBER","RED")) -> GREEN | F13: =IF(Scorecard!G9<=0.05,"GREEN",IF(Scorecard!G9<=0.1,"AMBER","RED")) -> GREEN | G13: =IF(Scorecard!H9>=0.85,"GREEN",IF(Scorecard!H9>=0.75,"AMBER","RED")) -> GREEN | H13: =IF(AND(Scorecard!I9>=0.8,Scorecard!I9<=1.25),"GREEN",IF(AND(Scorecard!I9>=0.6,Scorecard!I9<=1.5),"AMBER","RED")) -> GREEN | I13: =IF(Scorecard!J9<=0.01,"GREEN",IF(Scorecard!J9<=0.03,"AMBER","RED")) -> GREEN | J13: =IF(COUNTIF(B13:I13,"RED")>0,"INVESTIGATE",IF(COUNTIF(B13:I13,"AMBER")>0,"REVIEW","COMPARABLE")) -> COMPARABLE
A14: 9M | B14: =IF(ABS(Scorecard!B10)<=2,"GREEN",IF(ABS(Scorecard!B10)<=5,"AMBER","RED")) -> GREEN | C14: =IF(MAX(ABS(Scorecard!C10),ABS(Scorecard!D10))<=3,"GREEN",IF(MAX(ABS(Scorecard!C10),ABS(Scorecard!D10))<=7,"AMBER","RED")) -> GREEN | D14: =IF(Scorecard!E10<=10,"GREEN",IF(Scorecard!E10<=25,"AMBER","RED")) -> GREEN | E14: =IF(Scorecard!F10>=0.88,"GREEN",IF(Scorecard!F10>=0.8,"AMBER","RED")) -> GREEN | F14: =IF(Scorecard!G10<=0.05,"GREEN",IF(Scorecard!G10<=0.1,"AMBER","RED")) -> GREEN | G14: =IF(Scorecard!H10>=0.85,"GREEN",IF(Scorecard!H10>=0.75,"AMBER","RED")) -> GREEN | H14: =IF(AND(Scorecard!I10>=0.8,Scorecard!I10<=1.25),"GREEN",IF(AND(Scorecard!I10>=0.6,Scorecard!I10<=1.5),"AMBER","RED")) -> GREEN | I14: =IF(Scorecard!J10<=0.01,"GREEN",IF(Scorecard!J10<=0.03,"AMBER","RED")) -> GREEN | J14: =IF(COUNTIF(B14:I14,"RED")>0,"INVESTIGATE",IF(COUNTIF(B14:I14,"AMBER")>0,"REVIEW","COMPARABLE")) -> COMPARABLE
A15: 1Y | B15: =IF(ABS(Scorecard!B11)<=2,"GREEN",IF(ABS(Scorecard!B11)<=5,"AMBER","RED")) -> GREEN | C15: =IF(MAX(ABS(Scorecard!C11),ABS(Scorecard!D11))<=3,"GREEN",IF(MAX(ABS(Scorecard!C11),ABS(Scorecard!D11))<=7,"AMBER","RED")) -> GREEN | D15: =IF(Scorecard!E11<=10,"GREEN",IF(Scorecard!E11<=25,"AMBER","RED")) -> GREEN | E15: =IF(Scorecard!F11>=0.88,"GREEN",IF(Scorecard!F11>=0.8,"AMBER","RED")) -> GREEN | F15: =IF(Scorecard!G11<=0.05,"GREEN",IF(Scorecard!G11<=0.1,"AMBER","RED")) -> GREEN | G15: =IF(Scorecard!H11>=0.85,"GREEN",IF(Scorecard!H11>=0.75,"AMBER","RED")) -> GREEN | H15: =IF(AND(Scorecard!I11>=0.8,Scorecard!I11<=1.25),"GREEN",IF(AND(Scorecard!I11>=0.6,Scorecard!I11<=1.5),"AMBER","RED")) -> GREEN | I15: =IF(Scorecard!J11<=0.01,"GREEN",IF(Scorecard!J11<=0.03,"AMBER","RED")) -> GREEN | J15: =IF(COUNTIF(B15:I15,"RED")>0,"INVESTIGATE",IF(COUNTIF(B15:I15,"AMBER")>0,"REVIEW","COMPARABLE")) -> COMPARABLE
A16: 2Y | B16: =IF(ABS(Scorecard!B12)<=2,"GREEN",IF(ABS(Scorecard!B12)<=5,"AMBER","RED")) -> GREEN | C16: =IF(MAX(ABS(Scorecard!C12),ABS(Scorecard!D12))<=3,"GREEN",IF(MAX(ABS(Scorecard!C12),ABS(Scorecard!D12))<=7,"AMBER","RED")) -> RED | D16: =IF(Scorecard!E12<=10,"GREEN",IF(Scorecard!E12<=25,"AMBER","RED")) -> RED | E16: =IF(Scorecard!F12>=0.88,"GREEN",IF(Scorecard!F12>=0.8,"AMBER","RED")) -> GREEN | F16: =IF(Scorecard!G12<=0.05,"GREEN",IF(Scorecard!G12<=0.1,"AMBER","RED")) -> GREEN | G16: =IF(Scorecard!H12>=0.85,"GREEN",IF(Scorecard!H12>=0.75,"AMBER","RED")) -> GREEN | H16: =IF(AND(Scorecard!I12>=0.8,Scorecard!I12<=1.25),"GREEN",IF(AND(Scorecard!I12>=0.6,Scorecard!I12<=1.5),"AMBER","RED")) -> GREEN | I16: =IF(Scorecard!J12<=0.01,"GREEN",IF(Scorecard!J12<=0.03,"AMBER","RED")) -> GREEN | J16: =IF(COUNTIF(B16:I16,"RED")>0,"INVESTIGATE",IF(COUNTIF(B16:I16,"AMBER")>0,"REVIEW","COMPARABLE")) -> INVESTIGATE
A17: 3Y | B17: =IF(ABS(Scorecard!B13)<=2,"GREEN",IF(ABS(Scorecard!B13)<=5,"AMBER","RED")) -> GREEN | C17: =IF(MAX(ABS(Scorecard!C13),ABS(Scorecard!D13))<=3,"GREEN",IF(MAX(ABS(Scorecard!C13),ABS(Scorecard!D13))<=7,"AMBER","RED")) -> GREEN | D17: =IF(Scorecard!E13<=10,"GREEN",IF(Scorecard!E13<=25,"AMBER","RED")) -> GREEN | E17: =IF(Scorecard!F13>=0.88,"GREEN",IF(Scorecard!F13>=0.8,"AMBER","RED")) -> GREEN | F17: =IF(Scorecard!G13<=0.05,"GREEN",IF(Scorecard!G13<=0.1,"AMBER","RED")) -> GREEN | G17: =IF(Scorecard!H13>=0.85,"GREEN",IF(Scorecard!H13>=0.75,"AMBER","RED")) -> GREEN | H17: =IF(AND(Scorecard!I13>=0.8,Scorecard!I13<=1.25),"GREEN",IF(AND(Scorecard!I13>=0.6,Scorecard!I13<=1.5),"AMBER","RED")) -> GREEN | I17: =IF(Scorecard!J13<=0.01,"GREEN",IF(Scorecard!J13<=0.03,"AMBER","RED")) -> GREEN | J17: =IF(COUNTIF(B17:I17,"RED")>0,"INVESTIGATE",IF(COUNTIF(B17:I17,"AMBER")>0,"REVIEW","COMPARABLE")) -> COMPARABLE
... A19: 10Y | B19: =IF(ABS(Scorecard!B15)<=2,"GREEN",IF(ABS(Scorecard!B15)<=5,"AMBER","RED")) -> GREEN | C19: =IF(MAX(ABS(Scorecard!C15),ABS(Scorecard!D15))<=3,"GREEN",IF(MAX(ABS(Scorecard!C15),ABS(Scorecard!D15))<=7,"AMBER","RED")) -> GREEN | D19: =IF(Scorecard!E15<=10,"GREEN",IF(Scorecard!E15<=25,"AMBER","RED")) -> GREEN | E19: =IF(Scorecard!F15>=0.88,"GREEN",IF(Scorecard!F15>=0.8,"AMBER","RED")) -> GREEN | F19: =IF(Scorecard!G15<=0.05,"GREEN",IF(Scorecard!G15<=0.1,"AMBER","RED")) -> GREEN | G19: =IF(Scorecard!H15>=0.85,"GREEN",IF(Scorecard!H15>=0.75,"AMBER","RED")) -> AMBER | H19: =IF(AND(Scorecard!I15>=0.8,Scorecard!I15<=1.25),"GREEN",IF(AND(Scorecard!I15>=0.6,Scorecard!I15<=1.5),"AMBER","RED")) -> GREEN | I19: =IF(Scorecard!J15<=0.01,"GREEN",IF(Scorecard!J15<=0.03,"AMBER","RED")) -> GREEN | J19: =IF(COUNTIF(B19:I19,"RED")>0,"INVESTIGATE",IF(COUNTIF(B19:I19,"AMBER")>0,"REVIEW","COMPARABLE")) -> REVIEW
A22: Executive summary | F22: Expected demo findings
A23: KPI | B23: Formula / Result | C23: Interpretation | D23: Action | F23: Tenor | G23: Designed issue | H23: Primary detector | I23: Why full-history tests alone can miss it | J23: Disposition
A24: Comparable tenors | B24: =COUNTIF(J6:J19,"COMPARABLE") -> 10 | C24: No material exception under proposed tolerances | D24: Accept at high level | F24: 1D | G24: 2021 ICE staleness | H24: Staleness + volatility | I24: Overall level can remain close while observations freeze | J24: Investigate 2021 period
A25: Review tenors | B25: =COUNTIF(J6:J19,"REVIEW") -> 1 | C25: At least one amber test, no red | D25: Targeted review | F25: 2Y | G25: Persistent 2024 divergence | H25: Max spread + percentile band | I25: Full-history Spearman/KS can dilute a regime-specific break | J25: Investigate divergence window
A26: Investigate tenors | B26: =COUNTIF(J6:J19,"INVESTIGATE") -> 3 | C26: At least one red test | D26: Investigate before onboarding | F26: 5Y | G26: Single large bad observation | H26: Max |spread| + curve RMSE | I26: One observation barely changes long-history correlation | J26: Investigate isolated date
A27: Overall conclusion | B27: =IF(B26=0,"Histories broadly comparable under proposed tolerances","Histories broadly comparable, with "&B26&" tenor(s) requiring targeted investigation") -> Histories broadly comparable, with 3 tenor(s) requiring targeted investigation | C27: Do not convert this into day-by-day reconciliation | D27: Investigate only flagged periods/tests

Sheet Curve_Metrics
B1: Curve RMSE (bp) | C1: Curve median abs spread (bp) | D1: Worst tenor spread (bp)
A2: 43832 | B2: 0.75067045 | C2: 0.29999536 | D2: 1.4818633
A3: 43833 | B3: 1.1923098 | C3: 0.63718886 | D3: 2.8861452
A4: 43836 | B4: 0.69899659 | C4: 0.2864956 | D4: 1.6825571
A5: 43837 | B5: 0.83963116 | C5: 0.57131192 | D5: 1.6740284
A6: 43838 | B6: 0.99230084 | C6: 0.70542752 | D6: 2.003074
A7: 43839 | B7: 0.75075873 | C7: 0.69425107 | D7: 1.3906682
A8: 43840 | B8: 0.94726753 | C8: 0.66218883 | D8: 2.3109147
A9: 43843 | B9: 0.77768149 | C9: 0.62308268 | D9: 1.5149265
A10: 43844 | B10: 0.99398869 | C10: 0.39353594 | D10: 2.9575814
A11: 43845 | B11: 0.89813261 | C11: 0.73391371 | D11: 1.6467584
A12: 43846 | B12: 0.57431318 | C12: 0.48206923 | D12: 1.4642599
A13: 43847 | B13: 1.0035172 | C13: 0.83365948 | D13: 2.0493098
... A1753: 46283 | B1753: 0.80088178 | C1753: 0.62958544 | D1753: 1.3322644

Sheet Top_Exceptions
A1: Date | B1: Curve RMSE (bp) | C1: Curve median abs spread (bp) | D1: Worst tenor spread (bp) | E1: Worst tenor
A2: 45092 | B2: 22.27 | C2: 0.58 | D2: 83.28 | E2: 5Y
A3: 45565 | B3: 16.09 | C3: 0.78 | D3: 60.13 | E3: 2Y
A4: 45562 | B4: 15.94 | C4: 0.68 | D4: 59.55 | E4: 2Y
A5: 45561 | B5: 15.79 | C5: 1.05 | D5: 58.91 | E5: 2Y
A6: 45559 | B6: 15.77 | C6: 0.81 | D6: 58.93 | E6: 2Y
A7: 45560 | B7: 15.71 | C7: 0.57 | D7: 58.66 | E7: 2Y
A8: 45558 | B8: 15.57 | C8: 0.48 | D8: 58.18 | E8: 2Y
A9: 45555 | B9: 15.55 | C9: 0.73 | D9: 58.11 | E9: 2Y
A10: 45554 | B10: 15.52 | C10: 0.61 | D10: 57.97 | E10: 2Y
A11: 45553 | B11: 15.13 | C11: 0.65 | D11: 56.53 | E11: 2Y

Sheet Test_Illustrations
A1: ICE vs Bloomberg — Metric Illustrations
A3: Median spread / P5-P95 / Max spread
A4: Day | B4: ICE | C4: BBG | D4: ICE-BBG (bp) | E4: ICE Δ | F4: BBG Δ | G4: Same direction? | H4: ICE stale?
A5: 1 | B5: 4 | C5: 4.01 | D5: =(B5-C5)*100 -> -1
A6: 2 | B6: 4.05 | C6: 4.06 | D6: =(B6-C6)*100 -> -1 | E6: =B6-B5 -> 0.05 | F6: =C6-C5 -> 0.05 | G6: =IF(OR(E6=0,F6=0),IF(E6=F6,1,0),IF(E6*F6>0,1,0)) -> 1 | H6: =IF(AND(ABS(E6)<0.000001,ABS(F6)>0.005),1,0) -> 0
A7: 3 | B7: 4.1 | C7: 4.11 | D7: =(B7-C7)*100 -> -1 | E7: =B7-B6 -> 0.05 | F7: =C7-C6 -> 0.05 | G7: =IF(OR(E7=0,F7=0),IF(E7=F7,1,0),IF(E7*F7>0,1,0)) -> 1 | H7: =IF(AND(ABS(E7)<0.000001,ABS(F7)>0.005),1,0) -> 0
A8: 4 | B8: 4.15 | C8: 4.16 | D8: =(B8-C8)*100 -> -1 | E8: =B8-B7 -> 0.05 | F8: =C8-C7 -> 0.05 | G8: =IF(OR(E8=0,F8=0),IF(E8=F8,1,0),IF(E8*F8>0,1,0)) -> 1 | H8: =IF(AND(ABS(E8)<0.000001,ABS(F8)>0.005),1,0) -> 0
A9: 5 | B9: 4.2 | C9: 4.21 | D9: =(B9-C9)*100 -> -1 | E9: =B9-B8 -> 0.05 | F9: =C9-C8 -> 0.05 | G9: =IF(OR(E9=0,F9=0),IF(E9=F9,1,0),IF(E9*F9>0,1,0)) -> 1 | H9: =IF(AND(ABS(E9)<0.000001,ABS(F9)>0.005),1,0) -> 0
A10: 6 | B10: 4.25 | C10: 4.26 | D10: =(B10-C10)*100 -> -1 | E10: =B10-B9 -> 0.05 | F10: =C10-C9 -> 0.05 | G10: =IF(OR(E10=0,F10=0),IF(E10=F10,1,0),IF(E10*F10>0,1,0)) -> 1 | H10: =IF(AND(ABS(E10)<0.000001,ABS(F10)>0.005),1,0) -> 0
A11: 7 | B11: 4.3 | C11: 4.7 | D11: =(B11-C11)*100 -> -40 | E11: =B11-B10 -> 0.05 | F11: =C11-C10 -> 0.44 | G11: =IF(OR(E11=0,F11=0),IF(E11=F11,1,0),IF(E11*F11>0,1,0)) -> 1 | H11: =IF(AND(ABS(E11)<0.000001,ABS(F11)>0.005),1,0) -> 0
A22: Spearman / Direction agreement
A23: Day | B23: ICE | C23: BBG | D23: ICE-BBG (bp) | E23: ICE Δ | F23: BBG Δ | G23: Same direction? | H23: ICE stale?
A24: 1 | B24: 4 | C24: 4.01 | D24: =(B24-C24)*100 -> -1
A25: 2 | B25: 4.05 | C25: 4.06 | D25: =(B25-C25)*100 -> -1 | E25: =B25-B24 -> 0.05 | F25: =C25-C24 -> 0.05 | G25: =IF(OR(E25=0,F25=0),IF(E25=F25,1,0),IF(E25*F25>0,1,0)) -> 1 | H25: =IF(AND(ABS(E25)<0.000001,ABS(F25)>0.005),1,0) -> 0
A26: 3 | B26: 4.02 | C26: 4.04 | D26: =(B26-C26)*100 -> -2 | E26: =B26-B25 -> -0.03 | F26: =C26-C25 -> -0.02 | G26: =IF(OR(E26=0,F26=0),IF(E26=F26,1,0),IF(E26*F26>0,1,0)) -> 1 | H26: =IF(AND(ABS(E26)<0.000001,ABS(F26)>0.005),1,0) -> 0
A27: 4 | B27: 4.12 | C27: 4.13 | D27: =(B27-C27)*100 -> -1 | E27: =B27-B26 -> 0.1 | F27: =C27-C26 -> 0.09 | G27: =IF(OR(E27=0,F27=0),IF(E27=F27,1,0),IF(E27*F27>0,1,0)) -> 1 | H27: =IF(AND(ABS(E27)<0.000001,ABS(F27)>0.005),1,0) -> 0
A28: 5 | B28: 4.13 | C28: 4.15 | D28: =(B28-C28)*100 -> -2 | E28: =B28-B27 -> 0.01 | F28: =C28-C27 -> 0.02 | G28: =IF(OR(E28=0,F28=0),IF(E28=F28,1,0),IF(E28*F28>0,1,0)) -> 1 | H28: =IF(AND(ABS(E28)<0.000001,ABS(F28)>0.005),1,0) -> 0
A29: 6 | B29: 4.08 | C29: 4.1 | D29: =(B29-C29)*100 -> -2 | E29: =B29-B28 -> -0.05 | F29: =C29-C28 -> -0.05 | G29: =IF(OR(E29=0,F29=0),IF(E29=F29,1,0),IF(E29*F29>0,1,0)) -> 1 | H29: =IF(AND(ABS(E29)<0.000001,ABS(F29)>0.005),1,0) -> 0
A30: 7 | B30: 4.18 | C30: 4.19 | D30: =(B30-C30)*100 -> -1 | E30: =B30-B29 -> 0.1 | F30: =C30-C29 -> 0.09 | G30: =IF(OR(E30=0,F30=0),IF(E30=F30,1,0),IF(E30*F30>0,1,0)) -> 1 | H30: =IF(AND(ABS(E30)<0.000001,ABS(F30)>0.005),1,0) -> 0
A41: Volatility / Staleness
A42: Day | B42: ICE | C42: BBG | D42: ICE-BBG (bp) | E42: ICE Δ | F42: BBG Δ | G42: Same direction? | H42: ICE stale?
A43: 1 | B43: 0.1 | C43: 0.1 | D43: =(B43-C43)*100 -> 0
A44: 2 | B44: 0.1 | C44: 0.11 | D44: =(B44-C44)*100 -> -1 | E44: =B44-B43 -> 0 | F44: =C44-C43 -> 0.01 | G44: =IF(OR(E44=0,F44=0),IF(E44=F44,1,0),IF(E44*F44>0,1,0)) -> 0 | H44: =IF(AND(ABS(E44)<0.000001,ABS(F44)>0.005),1,0) -> 1
A45: 3 | B45: 0.1 | C45: 0.12 | D45: =(B45-C45)*100 -> -2 | E45: =B45-B44 -> 0 | F45: =C45-C44 -> 0.01 | G45: =IF(OR(E45=0,F45=0),IF(E45=F45,1,0),IF(E45*F45>0,1,0)) -> 0 | H45: =IF(AND(ABS(E45)<0.000001,ABS(F45)>0.005),1,0) -> 1
A46: 4 | B46: 0.1 | C46: 0.1 | D46: =(B46-C46)*100 -> 0 | E46: =B46-B45 -> 0 | F46: =C46-C45 -> -0.02 | G46: =IF(OR(E46=0,F46=0),IF(E46=F46,1,0),IF(E46*F46>0,1,0)) -> 0 | H46: =IF(AND(ABS(E46)<0.000001,ABS(F46)>0.005),1,0) -> 1
A47: 5 | B47: 0.1 | C47: 0.13 | D47: =(B47-C47)*100 -> -3 | E47: =B47-B46 -> 0 | F47: =C47-C46 -> 0.03 | G47: =IF(OR(E47=0,F47=0),IF(E47=F47,1,0),IF(E47*F47>0,1,0)) -> 0 | H47: =IF(AND(ABS(E47)<0.000001,ABS(F47)>0.005),1,0) -> 1
A48: 6 | B48: 0.1 | C48: 0.11 | D48: =(B48-C48)*100 -> -1 | E48: =B48-B47 -> 0 | F48: =C48-C47 -> -0.02 | G48: =IF(OR(E48=0,F48=0),IF(E48=F48,1,0),IF(E48*F48>0,1,0)) -> 0 | H48: =IF(AND(ABS(E48)<0.000001,ABS(F48)>0.005),1,0) -> 1
A49: 7 | B49: 0.1 | C49: 0.14 | D49: =(B49-C49)*100 -> -4 | E49: =B49-B48 -> 0 | F49: =C49-C48 -> 0.03 | G49: =IF(OR(E49=0,F49=0),IF(E49=F49,1,0),IF(E49*F49>0,1,0)) -> 0 | H49: =IF(AND(ABS(E49)<0.000001,ABS(F49)>0.005),1,0) -> 1
A60: KS distribution illustration
A61: Day | B61: ICE | C61: BBG | D61: ICE-BBG (bp) | E61: ICE Δ | F61: BBG Δ | G61: Same direction? | H61: ICE stale?
A62: 1 | B62: 0 | C62: 0 | D62: =(B62-C62)*100 -> 0
A63: 2 | B63: -0.03 | C63: -0.12 | D63: =(B63-C63)*100 -> 9 | E63: =B63-B62 -> -0.03 | F63: =C63-C62 -> -0.12 | G63: =IF(OR(E63=0,F63=0),IF(E63=F63,1,0),IF(E63*F63>0,1,0)) -> 1 | H63: =IF(AND(ABS(E63)<0.000001,ABS(F63)>0.005),1,0) -> 0
A64: 3 | B64: 0.02 | C64: 0.09 | D64: =(B64-C64)*100 -> -7 | E64: =B64-B63 -> 0.05 | F64: =C64-C63 -> 0.21 | G64: =IF(OR(E64=0,F64=0),IF(E64=F64,1,0),IF(E64*F64>0,1,0)) -> 1 | H64: =IF(AND(ABS(E64)<0.000001,ABS(F64)>0.005),1,0) -> 0
A65: 4 | B65: 0.05 | C65: 0.18 | D65: =(B65-C65)*100 -> -13 | E65: =B65-B64 -> 0.03 | F65: =C65-C64 -> 0.09 | G65: =IF(OR(E65=0,F65=0),IF(E65=F65,1,0),IF(E65*F65>0,1,0)) -> 1 | H65: =IF(AND(ABS(E65)<0.000001,ABS(F65)>0.005),1,0) -> 0
A66: 5 | B66: -0.02 | C66: -0.1 | D66: =(B66-C66)*100 -> 8 | E66: =B66-B65 -> -0.07 | F66: =C66-C65 -> -0.28 | G66: =IF(OR(E66=0,F66=0),IF(E66=F66,1,0),IF(E66*F66>0,1,0)) -> 1 | H66: =IF(AND(ABS(E66)<0.000001,ABS(F66)>0.005),1,0) -> 0
A67: 6 | B67: 0.03 | C67: 0.13 | D67: =(B67-C67)*100 -> -10 | E67: =B67-B66 -> 0.05 | F67: =C67-C66 -> 0.23 | G67: =IF(OR(E67=0,F67=0),IF(E67=F67,1,0),IF(E67*F67>0,1,0)) -> 1 | H67: =IF(AND(ABS(E67)<0.000001,ABS(F67)>0.005),1,0) -> 0
A68: 7 | B68: -0.01 | C68: -0.08 | D68: =(B68-C68)*100 -> 7 | E68: =B68-B67 -> -0.04 | F68: =C68-C67 -> -0.21 | G68: =IF(OR(E68=0,F68=0),IF(E68=F68,1,0),IF(E68*F68>0,1,0)) -> 1 | H68: =IF(AND(ABS(E68)<0.000001,ABS(F68)>0.005),1,0) -> 0
A78: Illustration metric | B78: Value | C78: Meaning | D78: Note
A79: |Median spread| (bp) | B79: =ABS(MEDIAN(D5:D11)) -> 1 | C79: Typical level bias | D79: Small despite one large outlier
A80: P5/P95 absolute band (bp) | B80: =MAX(ABS(_xludf.PERCENTILE.INC(D5:D11,0.05)),ABS(_xludf.PERCENTILE.INC(D5:D11,0.95))) -> #NAME? | C80: Normal disagreement band | D80: Central 90%
...
