Workbook

Sheet Inputs
A1: Shifted relative shocks with historical shift - JPY TONAR illustration
A2: Blue = input (edit), black = formula, green = link from another sheet. Yellow = key assumption. All rates stored as decimals (0.5% = 0.005).
A4: Parameter | B4: Value | C4: Symbol / Eq. | D4: Comment
A5: Desk SABR shift | B5: 0.005 | C5: θ | D5: User assumption: θ = 0.50%. Taken from desk, never changed by scenario generation.
A6: Historical window start rate | B6: 0.005 | C6: S(t_h) | D6: User assumption: 0.50%
A7: Historical window end rate | B7: 0.0025 | C7: S(t_h+Δ) | D7: User assumption: 0.25%
A8: Historical absolute move | B8: =B7-B6 -> -0.0025 | C8: ΔS | D8: = S(t_h+Δ) - S(t_h) → -25bp
A9: Historical move (bp) | B9: =B8*10000 -> -25
A10: Minimum historical TONAR | B10: -0.0049 | C10: min S(t_h) | D10: User: JPY TONAR low ≈ -0.49%
A11: Buffer b | B11: 0.0011 | C11: b | D11: Assumption: 11bp buffer chosen so η = 0.60% (≠ θ, to show rescaling). Set to 0.0001 to get η = θ = 0.50%.
A12: Historical shift η | B12: =-B10+B11 -> 0.006 | C12: η (Eq. 15) | D12: η = max{-S(t_h)} + b
A13: Check: S(t_h)+η > 0 for history | B13: =IF(B10+B12>0,"OK","FAIL") -> OK | D13: Required for z_h to be defined
A14: Horizon | B14: 10 | C14: Δ (days) | D14: Informational only - the shock is the window move
A17: Key equations used
A18: Eq. 12 - shock (measured with η) | B18: z_h = [S(t_h+Δ) - S(t_h)] / (S(t_h) + η)^β
A19: Scaling term | B19: x_h = (S0 + θ)^(β-1) · z_h
A20: Eq. 14 - shocked rate (applied with θ) | B20: S(Δ) = (S0 + θ) · exp{ x_h - ½ x_h² } - θ
A21: Multiplier F | B21: F = exp{ x_h - ½ x_h² } → shifted rate today is multiplied by F; F > 0 so S(Δ) > -θ always
A22: Eq. 6 (linear, for comparison) | B22: S(Δ) ≈ S0 + (S0 + θ)^β · z_h (Eq. 14 equals this to 2nd order)
A23: Scaling factor | B23: Applied shock today / historical absolute shock
A24: Eq. 15 - historical shift | B24: η = max{-S(t_h)} + b

Sheet Two_Histories_S0_4pct
A1: Shocked rate at S0 = 4% for two historical moves, β ∈ {0, 0.5, 1}, θ ∈ {1%, η}
A2: Blue cells are inputs. η = max{-S(t_h)} + b (Eq.15). θ = η removes the shift mismatch; the level effect remains.
A4: Input | B4: Value | C4: Comment
A5: Today's rate S0 | B5: 0.04 | C5: User assumption
A6: Lowest historical rate | B6: -0.0049 | C6: User: -0.49%
A7: Buffer b | B7: 0.0011 | C7: Chosen so η = 0.60%
A8: η (Eq.15) | B8: =-B6+B7 -> 0.006 | C8: = 0.49% + 0.11%
A9: θ case 1 | B9: 0.01 | C9: Desk-style shift 1%
A10: θ case 2 (= η) | B10: =B8 -> 0.006 | C10: Shift equal to η
A11: History A start | B11: 0.005 | C11: 0.50%
A12: History A end | B12: 0.0025 | C12: 0.25% (-25bp)
A13: History B start | B13: 0.0001 | C13: 0.01%
A14: History B end | B14: 0.005 | C14: 0.50% (+49bp)
A17: History | B17: β | C17: θ | D17: S(t_h) | E17: S(t_h+Δ) | F17: ΔS (bp) | G17: S(t_h)+η | H17: z_h (Eq.12) | I17: R0 = S0+θ | J17: x_h | K17: ½x² | L17: F = exp(x-½x²) | M17: Shocked rate (Eq.14) | N17: Applied shock (bp) | O17: Scaling factor | P17: Linear Eq.6 (bp) | Q17: Eq.14 - Eq.6 (bp) | R17: x ≤ 1?
A18: A: 0.50% → 0.25% | B18: 0 | C18: =$B$9 -> 0.01 | D18: =$B$11 -> 0.005 | E18: =$B$12 -> 0.0025 | F18: =(E18-D18)*10000 -> -25 | G18: =D18+$B$8 -> 0.011 | H18: =(E18-D18)/G18^B18 -> -0.0025 | I18: =$B$5+C18 -> 0.05 | J18: =I18^(B18-1)*H18 -> -0.05 | K18: =0.5*J18^2 -> 0.00125 | L18: =EXP(J18-K18) -> 0.95004113 | M18: =I18*L18-C18 -> 0.037502057 | N18: =(M18-$B$5)*10000 -> -24.979435 | O18: =N18/F18 -> 0.99917739 | P18: =I18^B18*H18*10000 -> -25 | Q18: =N18-P18 -> 0.020565279 | R18: =IF(J18<=1,"OK","x>1") -> OK
A19: A: 0.50% → 0.25% | B19: 0.5 | C19: =$B$9 -> 0.01 | D19: =$B$11 -> 0.005 | E19: =$B$12 -> 0.0025 | F19: =(E19-D19)*10000 -> -25 | G19: =D19+$B$8 -> 0.011 | H19: =(E19-D19)/G19^B19 -> -0.023836565 | I19: =$B$5+C19 -> 0.05 | J19: =I19^(B19-1)*H19 -> -0.10660036 | K19: =0.5*J19^2 -> 0.0056818182 | L19: =EXP(J19-K19) -> 0.89379201 | M19: =I19*L19-C19 -> 0.034689601 | N19: =(M19-$B$5)*10000 -> -53.103993 | O19: =N19/F19 -> 2.1241597 | P19: =I19^B19*H19*10000 -> -53.300179 | Q19: =N19-P19 -> 0.19618656 | R19: =IF(J19<=1,"OK","x>1") -> OK
A20: A: 0.50% → 0.25% | B20: 1 | C20: =$B$9 -> 0.01 | D20: =$B$11 -> 0.005 | E20: =$B$12 -> 0.0025 | F20: =(E20-D20)*10000 -> -25 | G20: =D20+$B$8 -> 0.011 | H20: =(E20-D20)/G20^B20 -> -0.22727273 | I20: =$B$5+C20 -> 0.05 | J20: =I20^(B20-1)*H20 -> -0.22727273 | K20: =0.5*J20^2 -> 0.025826446 | L20: =EXP(J20-K20) -> 0.77639088 | M20: =I20*L20-C20 -> 0.028819544 | N20: =(M20-$B$5)*10000 -> -111.80456 | O20: =N20/F20 -> 4.4721824 | P20: =I20^B20*H20*10000 -> -113.63636 | Q20: =N20-P20 -> 1.8318039 | R20: =IF(J20<=1,"OK","x>1") -> OK
A21: A: 0.50% → 0.25% | B21: 0 | C21: =$B$10 -> 0.006 | D21: =$B$11 -> 0.005 | E21: =$B$12 -> 0.0025 | F21: =(E21-D21)*10000 -> -25 | G21: =D21+$B$8 -> 0.011 | H21: =(E21-D21)/G21^B21 -> -0.0025 | I21: =$B$5+C21 -> 0.046 | J21: =I21^(B21-1)*H21 -> -0.054347826 | K21: =0.5*J21^2 -> 0.0014768431 | L21: =EXP(J21-K21) -> 0.94570493 | M21: =I21*L21-C21 -> 0.037502427 | N21: =(M21-$B$5)*10000 -> -24.975731 | O21: =N21/F21 -> 0.99902924 | P21: =I21^B21*H21*10000 -> -25 | Q21: =N21-P21 -> 0.024268982 | R21: =IF(J21<=1,"OK","x>1") -> OK
A22: A: 0.50% → 0.25% | B22: 0.5 | C22: =$B$10 -> 0.006 | D22: =$B$11 -> 0.005 | E22: =$B$12 -> 0.0025 | F22: =(E22-D22)*10000 -> -25 | G22: =D22+$B$8 -> 0.011 | H22: =(E22-D22)/G22^B22 -> -0.023836565 | I22: =$B$5+C22 -> 0.046 | J22: =I22^(B22-1)*H22 -> -0.11113856 | K22: =0.5*J22^2 -> 0.0061758893 | L22: =EXP(J22-K22) -> 0.88930551 | M22: =I22*L22-C22 -> 0.034908054 | N22: =(M22-$B$5)*10000 -> -50.919465 | O22: =N22/F22 -> 2.0367786 | P22: =I22^B22*H22*10000 -> -51.123736 | Q22: =N22-P22 -> 0.20427093 | R22: =IF(J22<=1,"OK","x>1") -> OK
A23: A: 0.50% → 0.25% | B23: 1 | C23: =$B$10 -> 0.006 | D23: =$B$11 -> 0.005 | E23: =$B$12 -> 0.0025 | F23: =(E23-D23)*10000 -> -25 | G23: =D23+$B$8 -> 0.011 | H23: =(E23-D23)/G23^B23 -> -0.22727273 | I23: =$B$5+C23 -> 0.046 | J23: =I23^(B23-1)*H23 -> -0.22727273 | K23: =0.5*J23^2 -> 0.025826446 | L23: =EXP(J23-K23) -> 0.77639088 | M23: =I23*L23-C23 -> 0.029713981 | N23: =(M23-$B$5)*10000 -> -102.86019 | O23: =N23/F23 -> 4.1144078 | P23: =I23^B23*H23*10000 -> -104.54545 | Q23: =N23-P23 -> 1.6852596 | R23: =IF(J23<=1,"OK","x>1") -> OK
A24: B: 0.01% → 0.50% | B24: 0 | C24: =$B$9 -> 0.01 | D24: =$B$13 -> 0.0001 | E24: =$B$14 -> 0.005 | F24: =(E24-D24)*10000 -> 49 | G24: =D24+$B$8 -> 0.0061 | H24: =(E24-D24)/G24^B24 -> 0.0049 | I24: =$B$5+C24 -> 0.05 | J24: =I24^(B24-1)*H24 -> 0.098 | K24: =0.5*J24^2 -> 0.004802 | L24: =EXP(J24-K24) -> 1.0976791 | M24: =I24*L24-C24 -> 0.044883953 | N24: =(M24-$B$5)*10000 -> 48.839527 | O24: =N24/F24 -> 0.99672504 | P24: =I24^B24*H24*10000 -> 49 | Q24: =N24-P24 -> -0.1604729 | R24: =IF(J24<=1,"OK","x>1") -> OK
A25: B: 0.01% → 0.50% | B25: 0.5 | C25: =$B$9 -> 0.01 | D25: =$B$13 -> 0.0001 | E25: =$B$14 -> 0.005 | F25: =(E25-D25)*10000 -> 49 | G25: =D25+$B$8 -> 0.0061 | H25: =(E25-D25)/G25^B25 -> 0.062738071 | I25: =$B$5+C25 -> 0.05 | J25: =I25^(B25-1)*H25 -> 0.28057318 | K25: =0.5*J25^2 -> 0.039360656 | L25: =EXP(J25-K25) -> 1.2727915 | M25: =I25*L25-C25 -> 0.053639576 | N25: =(M25-$B$5)*10000 -> 136.39576 | O25: =N25/F25 -> 2.7835868 | P25: =I25^B25*H25*10000 -> 140.28659 | Q25: =N25-P25 -> -3.8908367 | R25: =IF(J25<=1,"OK","x>1") -> OK
A26: B: 0.01% → 0.50% | B26: 1 | C26: =$B$9 -> 0.01 | D26: =$B$13 -> 0.0001 | E26: =$B$14 -> 0.005 | F26: =(E26-D26)*10000 -> 49 | G26: =D26+$B$8 -> 0.0061 | H26: =(E26-D26)/G26^B26 -> 0.80327869 | I26: =$B$5+C26 -> 0.05 | J26: =I26^(B26-1)*H26 -> 0.80327869 | K26: =0.5*J26^2 -> 0.32262833 | L26: =EXP(J26-K26) -> 1.6171258 | M26: =I26*L26-C26 -> 0.070856289 | N26: =(M26-$B$5)*10000 -> 308.56289 | O26: =N26/F26 -> 6.2972018 | P26: =I26^B26*H26*10000 -> 401.63934 | Q26: =N26-P26 -> -93.076455 | R26: =IF(J26<=1,"OK","x>1") -> OK
A27: B: 0.01% → 0.50% | B27: 0 | C27: =$B$10 -> 0.006 | D27: =$B$13 -> 0.0001 | E27: =$B$14 -> 0.005 | F27: =(E27-D27)*10000 -> 49 | G27: =D27+$B$8 -> 0.0061 | H27: =(E27-D27)/G27^B27 -> 0.0049 | I27: =$B$5+C27 -> 0.046 | J27: =I27^(B27-1)*H27 -> 0.10652174 | K27: =0.5*J27^2 -> 0.0056734405 | L27: =EXP(J27-K27) -> 1.1061088 | M27: =I27*L27-C27 -> 0.044881006 | N27: =(M27-$B$5)*10000 -> 48.810062 | O27: =N27/F27 -> 0.99612372 | P27: =I27^B27*H27*10000 -> 49 | Q27: =N27-P27 -> -0.1899378 | R27: =IF(J27<=1,"OK","x>1") -> OK
A28: B: 0.01% → 0.50% | B28: 0.5 | C28: =$B$10 -> 0.006 | D28: =$B$13 -> 0.0001 | E28: =$B$14 -> 0.005 | F28: =(E28-D28)*10000 -> 49 | G28: =D28+$B$8 -> 0.0061 | H28: =(E28-D28)/G28^B28 -> 0.062738071 | I28: =$B$5+C28 -> 0.046 | J28: =I28^(B28-1)*H28 -> 0.29251777 | K28: =0.5*J28^2 -> 0.042783321 | L28: =EXP(J28-K28) -> 1.2836845 | M28: =I28*L28-C28 -> 0.053049486 | N28: =(M28-$B$5)*10000 -> 130.49486 | O28: =N28/F28 -> 2.6631604 | P28: =I28^B28*H28*10000 -> 134.55817 | Q28: =N28-P28 -> -4.0633108 | R28: =IF(J28<=1,"OK","x>1") -> OK
A29: B: 0.01% → 0.50% | B29: 1 | C29: =$B$10 -> 0.006 | D29: =$B$13 -> 0.0001 | E29: =$B$14 -> 0.005 | F29: =(E29-D29)*10000 -> 49 | G29: =D29+$B$8 -> 0.0061 | H29: =(E29-D29)/G29^B29 -> 0.80327869 | I29: =$B$5+C29 -> 0.046 | J29: =I29^(B29-1)*H29 -> 0.80327869 | K29: =0.5*J29^2 -> 0.32262833 | L29: =EXP(J29-K29) -> 1.6171258 | M29: =I29*L29-C29 -> 0.068387786 | N29: =(M29-$B$5)*10000 -> 283.87786 | O29: =N29/F29 -> 5.7934257 | P29: =I29^B29*H29*10000 -> 369.5082 | Q29: =N29-P29 -> -85.630339 | R29: =IF(J29<=1,"OK","x>1") -> OK
A32: Summary 1 - Shocked rate
A33: History / θ | B33: β = 0 | C33: β = 0.5 | D33: β = 1
A34: A, θ = 1% | B34: =M18 -> 0.037502057 | C34: =M19 -> 0.034689601 | D34: =M20 -> 0.028819544
A35: A, θ = η | B35: =M21 -> 0.037502427 | C35: =M22 -> 0.034908054 | D35: =M23 -> 0.029713981
A36: B, θ = 1% | B36: =M24 -> 0.044883953 | C36: =M25 -> 0.053639576 | D36: =M26 -> 0.070856289
A37: B, θ = η | B37: =M27 -> 0.044881006 | C37: =M28 -> 0.053049486 | D37: =M29 -> 0.068387786
A40: Summary 2 - Applied shock (bp) [A = -25bp, B = +49bp historical]
A41: History / θ | B41: β = 0 | C41: β = 0.5 | D41: β = 1
A42: A, θ = 1% | B42: =N18 -> -24.979435 | C42: =N19 -> -53.103993 | D42: =N20 -> -111.80456
A43: A, θ = η | B43: =N21 -> -24.975731 | C43: =N22 -> -50.919465 | D43: =N23 -> -102.86019
A44: B, θ = 1% | B44: =N24 -> 48.839527 | C44: =N25 -> 136.39576 | D44: =N26 -> 308.56289
A45: B, θ = η | B45: =N27 -> 48.810062 | C45: =N28 -> 130.49486 | D45: =N29 -> 283.87786
A48: Summary 3 - Scaling factor
A49: History / θ | B49: β = 0 | C49: β = 0.5 | D49: β = 1
...

Sheet Sheet2
E2: Lowest negative rate =- 0.49% + 0.11 buffer
A3: Today's rate | B3: History rates | C3: β | D3: θ | E3: η Calibrated (eq 15) | F3: Shocked rate (Eq.14) | G3: Applied shock (bp) | H3: S(t_h) | I3: S(t_h+Δ) | J3: ΔS (bp) | K3: S(t_h)+η | L3: z_h (Eq.12) | M3: R0 = S0+θ | N3: x_h | O3: ½x² | P3: F = exp(x-½x²) | Q3: Scaling factor | R3: Linear Eq.6 (bp) | S3: Eq.14 - Eq.6 (bp) | T3: x ≤ 1?
A4: 0.04 | B4: A: 0.50% → 0.25% | C4: 0 | D4: 0.01 | E4: 0.006 | F4: 0.037502057 | G4: -24.979435 | H4: 0.005 | I4: 0.0025 | J4: -25 | K4: 0.011 | L4: -0.0025 | M4: 0.05 | N4: -0.05 | O4: 0.00125 | P4: 0.95004113 | Q4: 0.99917739 | R4: -25 | S4: 0.020565279 | T4: Yes
A5: 0.04 | B5: A: 0.50% → 0.25% | C5: 0.5 | D5: 0.01 | E5: 0.006 | F5: 0.034689601 | G5: -53.103993 | H5: 0.005 | I5: 0.0025 | J5: -25 | K5: 0.011 | L5: -0.023836565 | M5: 0.05 | N5: -0.10660036 | O5: 0.0056818182 | P5: 0.89379201 | Q5: 2.1241597 | R5: -53.300179 | S5: 0.19618656 | T5: Yes
A6: 0.04 | B6: A: 0.50% → 0.25% | C6: 1 | D6: 0.01 | E6: 0.006 | F6: 0.028819544 | G6: -111.80456 | H6: 0.005 | I6: 0.0025 | J6: -25 | K6: 0.011 | L6: -0.22727273 | M6: 0.05 | N6: -0.22727273 | O6: 0.025826446 | P6: 0.77639088 | Q6: 4.4721824 | R6: -113.63636 | S6: 1.8318039 | T6: Yes
A7: 0.04 | B7: A: 0.50% → 0.25% | C7: 0 | D7: 0.006 | E7: 0.006 | F7: 0.037502427 | G7: -24.975731 | H7: 0.005 | I7: 0.0025 | J7: -25 | K7: 0.011 | L7: -0.0025 | M7: 0.046 | N7: -0.054347826 | O7: 0.0014768431 | P7: 0.94570493 | Q7: 0.99902924 | R7: -25 | S7: 0.024268982 | T7: Yes
A8: 0.04 | B8: A: 0.50% → 0.25% | C8: 0.5 | D8: 0.006 | E8: 0.006 | F8: 0.034908054 | G8: -50.919465 | H8: 0.005 | I8: 0.0025 | J8: -25 | K8: 0.011 | L8: -0.023836565 | M8: 0.046 | N8: -0.11113856 | O8: 0.0061758893 | P8: 0.88930551 | Q8: 2.0367786 | R8: -51.123736 | S8: 0.20427093 | T8: Yes
A9: 0.04 | B9: A: 0.50% → 0.25% | C9: 1 | D9: 0.006 | E9: 0.006 | F9: 0.029713981 | G9: -102.86019 | H9: 0.005 | I9: 0.0025 | J9: -25 | K9: 0.011 | L9: -0.22727273 | M9: 0.046 | N9: -0.22727273 | O9: 0.025826446 | P9: 0.77639088 | Q9: 4.1144078 | R9: -104.54545 | S9: 1.6852596 | T9: Yes
A10: 0.04 | B10: B: 0.01% → 0.50% | C10: 0 | D10: 0.01 | E10: 0.006 | F10: 0.044883953 | G10: 48.839527 | H10: 0.0001 | I10: 0.005 | J10: 49 | K10: 0.0061 | L10: 0.0049 | M10: 0.05 | N10: 0.098 | O10: 0.004802 | P10: 1.0976791 | Q10: 0.99672504 | R10: 49 | S10: -0.1604729 | T10: Yes
A11: 0.04 | B11: B: 0.01% → 0.50% | C11: 0.5 | D11: 0.01 | E11: 0.006 | F11: 0.053639576 | G11: 136.39576 | H11: 0.0001 | I11: 0.005 | J11: 49 | K11: 0.0061 | L11: 0.062738071 | M11: 0.05 | N11: 0.28057318 | O11: 0.039360656 | P11: 1.2727915 | Q11: 2.7835868 | R11: 140.28659 | S11: -3.8908367 | T11: Yes
A12: 0.04 | B12: B: 0.01% → 0.50% | C12: 1 | D12: 0.01 | E12: 0.006 | F12: 0.070856289 | G12: 308.56289 | H12: 0.0001 | I12: 0.005 | J12: 49 | K12: 0.0061 | L12: 0.80327869 | M12: 0.05 | N12: 0.80327869 | O12: 0.32262833 | P12: 1.6171258 | Q12: 6.2972018 | R12: 401.63934 | S12: -93.076455 | T12: Yes
A13: 0.04 | B13: B: 0.01% → 0.50% | C13: 0 | D13: 0.006 | E13: 0.006 | F13: 0.044881006 | G13: 48.810062 | H13: 0.0001 | I13: 0.005 | J13: 49 | K13: 0.0061 | L13: 0.0049 | M13: 0.046 | N13: 0.10652174 | O13: 0.0056734405 | P13: 1.1061088 | Q13: 0.99612372 | R13: 49 | S13: -0.1899378 | T13: Yes
A14: 0.04 | B14: B: 0.01% → 0.50% | C14: 0.5 | D14: 0.006 | E14: 0.006 | F14: 0.053049486 | G14: 130.49486 | H14: 0.0001 | I14: 0.005 | J14: 49 | K14: 0.0061 | L14: 0.062738071 | M14: 0.046 | N14: 0.29251777 | O14: 0.042783321 | P14: 1.2836845 | Q14: 2.6631604 | R14: 134.55817 | S14: -4.0633108 | T14: Yes
A15: 0.04 | B15: B: 0.01% → 0.50% | C15: 1 | D15: 0.006 | E15: 0.006 | F15: 0.068387786 | G15: 283.87786 | H15: 0.0001 | I15: 0.005 | J15: 49 | K15: 0.0061 | L15: 0.80327869 | M15: 0.046 | N15: 0.80327869 | O15: 0.32262833 | P15: 1.6171258 | Q15: 5.7934257 | R15: 369.5082 | S15: -85.630339 | T15: Yes
A17: 0.04 | B17: C: -0.49% → 0.01% | C17: 0 | D17: 0.01 | E17: 0.006 | F17: 0.044982943 | G17: 49.829428 | H17: -0.0049 | I17: 0.0001 | J17: 50 | K17: 0.0011 | L17: 0.005 | M17: 0.05 | N17: 0.1 | O17: 0.005 | P17: 1.0996589 | Q17: 0.99658855 | R17: 50 | S17: -0.17057244
A18: 0.04 | B18: C: -0.49% → 0.01% | C18: 0.5 | D18: 0.01 | E18: 0.006 | F18: 0.068175019 | G18: 281.75019 | H18: -0.0049 | I18: 0.0001 | J18: 50 | K18: 0.0011 | L18: 0.15075567 | M18: 0.05 | N18: 0.67419986 | O18: 0.22727273 | P18: 1.5635004 | Q18: 5.6350037 | R18: 337.09993 | S18: -55.349746
A19: 0.04 | B19: C: -0.49% → 0.01% | C19: 1 | D19: 0.01 | E19: 0.006 | F19: -0.0098463535 | G19: -498.46354 | H19: -0.0049 | I19: 0.0001 | J19: 50 | K19: 0.0011 | L19: 4.5454545 | M19: 0.05 | N19: 4.5454545 | O19: 10.330579 | P19: 0.0030729294 | Q19: -9.9692707 | R19: 2272.7273 | S19: -2771.1908
A20: 0.04 | B20: C: -0.49% → 0.01% | C20: 0 | D20: 0.006 | E20: 0.006 | F20: 0.04497981 | G20: 49.798102 | H20: -0.0049 | I20: 0.0001 | J20: 50 | K20: 0.0011 | L20: 0.005 | M20: 0.046 | N20: 0.10869565 | O20: 0.0059073724 | P20: 1.1082567 | Q20: 0.99596204 | R20: 50 | S20: -0.20189782
A21: 0.04 | B21: C: -0.49% → 0.01% | C21: 0.5 | D21: 0.006 | E21: 0.006 | F21: 0.066566818 | G21: 265.66818 | H21: -0.0049 | I21: 0.0001 | J21: 50 | K21: 0.0011 | L21: 0.15075567 | M21: 0.046 | N21: 0.70290195 | O21: 0.24703557 | P21: 1.5775395 | Q21: 5.3133637 | R21: 323.3349 | S21: -57.666712
A22: 0.04 | B22: C: -0.49% → 0.01% | C22: 1 | D22: 0.006 | E22: 0.006 | F22: -0.0058586452 | G22: -458.58645 | H22: -0.0049 | I22: 0.0001 | J22: 50 | K22: 0.0011 | L22: 4.5454545 | M22: 0.046 | N22: 4.5454545 | O22: 10.330579 | P22: 0.0030729294 | Q22: -9.171729 | R22: 2090.9091 | S22: -2549.4955

Sheet Eq14_x_gt_1_Issue
A1: Eq.14 issue: past x = 1, a LARGER historical rise gives a SMALLER (then negative) shock today
A2: F(x) = exp(x - ½x²) has dF/dx = (1 - x)·F, so F rises until x = 1 (F = e^0.5 = 1.6487) and then falls back to 0. The shocked rate can therefore never exceed (S0+θ)·1.6487 - θ, and bigger up-moves are pushed back down.
A4: Case 1 input | B4: Value | C4: Comment
A5: β | B5: 1 | C5: Shifted lognormal
A6: S0 today | B6: 0.04 | C6: 4%
A7: θ | B7: 0.01 | C7: Desk shift
A8: η | B8: 0.006 | C8: 0.49% + 11bp
A9: S(t_h) window start | B9: 0.0001 | C9: 0.01% - near zero
A10: Rise giving x = 1 (bp) | B10: =(B9+B8)^B5*(B6+B7)^(1-B5)*10000 -> 61 | C10: ΔS* = (S_h+η)^β·(S0+θ)^(1-β)
A11: Max possible shocked rate | B11: =(B6+B7)*EXP(0.5)-B7 -> 0.072436064 | C11: (S0+θ)·e^0.5 - θ
A12: Max possible up-shock (bp) | B12: =(B11-B6)*10000 -> 324.36064 | C12: Hard ceiling, whatever the history
A14: Historical end S(t_h+Δ) | B14: Historical rise (bp) | C14: z_h | D14: x_h | E14: F = exp(x-½x²) | F14: Shocked rate (Eq.14) | G14: Applied shock (bp) | H14: Linear Eq.6 (bp) | I14: Zone
A15: 0.001 | B15: =(A15-$B$9)*10000 -> 9 | C15: =(A15-$B$9)/($B$9+$B$8)^$B$5 -> 0.14754098 | D15: =($B$6+$B$7)^($B$5-1)*C15 -> 0.14754098 | E15: =EXP(D15-0.5*D15^2) -> 1.1464346 | F15: =($B$6+$B$7)*E15-$B$7 -> 0.047321732 | G15: =(F15-$B$6)*10000 -> 73.21732 | H15: =($B$6+$B$7)^$B$5*C15*10000 -> 73.770492 | I15: =IF(D15<=1,"increasing",IF(ROUND(G15,6)>0,"x>1: shock shrinks",IF(ROUND(G15,6)=0,"x = 2: shock = 0","x>2: SIGN FLIP"))) -> increasing
A16: 0.0025 | B16: =(A16-$B$9)*10000 -> 24 | C16: =(A16-$B$9)/($B$9+$B$8)^$B$5 -> 0.39344262 | D16: =($B$6+$B$7)^($B$5-1)*C16 -> 0.39344262 | E16: =EXP(D16-0.5*D16^2) -> 1.3716907 | F16: =($B$6+$B$7)*E16-$B$7 -> 0.058584536 | G16: =(F16-$B$6)*10000 -> 185.84536 | H16: =($B$6+$B$7)^$B$5*C16*10000 -> 196.72131 | I16: =IF(D16<=1,"increasing",IF(ROUND(G16,6)>0,"x>1: shock shrinks",IF(ROUND(G16,6)=0,"x = 2: shock = 0","x>2: SIGN FLIP"))) -> increasing
A17: 0.004 | B17: =(A17-$B$9)*10000 -> 39 | C17: =(A17-$B$9)/($B$9+$B$8)^$B$5 -> 0.63934426 | D17: =($B$6+$B$7)^($B$5-1)*C17 -> 0.63934426 | E17: =EXP(D17-0.5*D17^2) -> 1.544907 | F17: =($B$6+$B$7)*E17-$B$7 -> 0.06724535 | G17: =(F17-$B$6)*10000 -> 272.4535 | H17: =($B$6+$B$7)^$B$5*C17*10000 -> 319.67213 | I17: =IF(D17<=1,"increasing",IF(ROUND(G17,6)>0,"x>1: shock shrinks",IF(ROUND(G17,6)=0,"x = 2: shock = 0","x>2: SIGN FLIP"))) -> increasing
A18: 0.0062 | B18: =(A18-$B$9)*10000 -> 61 | C18: =(A18-$B$9)/($B$9+$B$8)^$B$5 -> 1 | D18: =($B$6+$B$7)^($B$5-1)*C18 -> 1 | E18: =EXP(D18-0.5*D18^2) -> 1.6487213 | F18: =($B$6+$B$7)*E18-$B$7 -> 0.072436064 | G18: =(F18-$B$6)*10000 -> 324.36064 | H18: =($B$6+$B$7)^$B$5*C18*10000 -> 500 | I18: =IF(D18<=1,"increasing",IF(ROUND(G18,6)>0,"x>1: shock shrinks",IF(ROUND(G18,6)=0,"x = 2: shock = 0","x>2: SIGN FLIP"))) -> increasing
A19: 0.008 | B19: =(A19-$B$9)*10000 -> 79 | C19: =(A19-$B$9)/($B$9+$B$8)^$B$5 -> 1.295082 | D19: =($B$6+$B$7)^($B$5-1)*C19 -> 1.295082 | E19: =EXP(D19-0.5*D19^2) -> 1.5784815 | F19: =($B$6+$B$7)*E19-$B$7 -> 0.068924076 | G19: =(F19-$B$6)*10000 -> 289.24076 | H19: =($B$6+$B$7)^$B$5*C19*10000 -> 647.54098 | I19: =IF(D19<=1,"increasing",IF(ROUND(G19,6)>0,"x>1: shock shrinks",IF(ROUND(G19,6)=0,"x = 2: shock = 0","x>2: SIGN FLIP"))) -> x>1: shock shrinks
A20: 0.01 | B20: =(A20-$B$9)*10000 -> 99 | C20: =(A20-$B$9)/($B$9+$B$8)^$B$5 -> 1.6229508 | D20: =($B$6+$B$7)^($B$5-1)*C20 -> 1.6229508 | E20: =EXP(D20-0.5*D20^2) -> 1.3579363 | F20: =($B$6+$B$7)*E20-$B$7 -> 0.057896816 | G20: =(F20-$B$6)*10000 -> 178.96816 | H20: =($B$6+$B$7)^$B$5*C20*10000 -> 811.47541 | I20: =IF(D20<=1,"increasing",IF(ROUND(G20,6)>0,"x>1: shock shrinks",IF(ROUND(G20,6)=0,"x = 2: shock = 0","x>2: SIGN FLIP"))) -> x>1: shock shrinks
A21: 0.0125 | B21: =(A21-$B$9)*10000 -> 124 | C21: =(A21-$B$9)/($B$9+$B$8)^$B$5 -> 2.0327869 | D21: =($B$6+$B$7)^($B$5-1)*C21 -> 2.0327869 | E21: =EXP(D21-0.5*D21^2) -> 0.96722477 | F21: =($B$6+$B$7)*E21-$B$7 -> 0.038361238 | G21: =(F21-$B$6)*10000 -> -16.387617 | H21: =($B$6+$B$7)^$B$5*C21*10000 -> 1016.3934 | I21: =IF(D21<=1,"increasing",IF(ROUND(G21,6)>0,"x>1: shock shrinks",IF(ROUND(G21,6)=0,"x = 2: shock = 0","x>2: SIGN FLIP"))) -> x>2: SIGN FLIP
A22: 0.015 | B22: =(A22-$B$9)*10000 -> 149 | C22: =(A22-$B$9)/($B$9+$B$8)^$B$5 -> 2.442623 | D22: =($B$6+$B$7)^($B$5-1)*C22 -> 2.442623 | E22: =EXP(D22-0.5*D22^2) -> 0.58241007 | F22: =($B$6+$B$7)*E22-$B$7 -> 0.019120504 | G22: =(F22-$B$6)*10000 -> -208.79496 | H22: =($B$6+$B$7)^$B$5*C22*10000 -> 1221.3115 | I22: =IF(D22<=1,"increasing",IF(ROUND(G22,6)>0,"x>1: shock shrinks",IF(ROUND(G22,6)=0,"x = 2: shock = 0","x>2: SIGN FLIP"))) -> x>2: SIGN FLIP
A23: 0.02 | B23: =(A23-$B$9)*10000 -> 199 | C23: =(A23-$B$9)/($B$9+$B$8)^$B$5 -> 3.2622951 | D23: =($B$6+$B$7)^($B$5-1)*C23 -> 3.2622951 | E23: =EXP(D23-0.5*D23^2) -> 0.12758282 | F23: =($B$6+$B$7)*E23-$B$7 -> -0.0036208588 | G23: =(F23-$B$6)*10000 -> -436.20859 | H23: =($B$6+$B$7)^$B$5*C23*10000 -> 1631.1475 | I23: =IF(D23<=1,"increasing",IF(ROUND(G23,6)>0,"x>1: shock shrinks",IF(ROUND(G23,6)=0,"x = 2: shock = 0","x>2: SIGN FLIP"))) -> x>2: SIGN FLIP
A24: 0.025 | B24: =(A24-$B$9)*10000 -> 249 | C24: =(A24-$B$9)/($B$9+$B$8)^$B$5 -> 4.0819672 | D24: =($B$6+$B$7)^($B$5-1)*C24 -> 4.0819672 | E24: =EXP(D24-0.5*D24^2) -> 0.01427478 | F24: =($B$6+$B$7)*E24-$B$7 -> -0.009286261 | G24: =(F24-$B$6)*10000 -> -492.86261 | H24: =($B$6+$B$7)^$B$5*C24*10000 -> 2040.9836 | I24: =IF(D24<=1,"increasing",IF(ROUND(G24,6)>0,"x>1: shock shrinks",IF(ROUND(G24,6)=0,"x = 2: shock = 0","x>2: SIGN FLIP"))) -> x>2: SIGN FLIP
A25: 0.03 | B25: =(A25-$B$9)*10000 -> 299 | C25: =(A25-$B$9)/($B$9+$B$8)^$B$5 -> 4.9016393 | D25: =($B$6+$B$7)^($B$5-1)*C25 -> 4.9016393 | E25: =EXP(D25-0.5*D25^2) -> 0.00081575639 | F25: =($B$6+$B$7)*E25-$B$7 -> -0.0099592122 | G25: =(F25-$B$6)*10000 -> -499.59212 | H25: =($B$6+$B$7)^$B$5*C25*10000 -> 2450.8197 | I25: =IF(D25<=1,"increasing",IF(ROUND(G25,6)>0,"x>1: shock shrinks",IF(ROUND(G25,6)=0,"x = 2: shock = 0","x>2: SIGN FLIP"))) -> x>2: SIGN FLIP
A26: 0.04 | B26: =(A26-$B$9)*10000 -> 399 | C26: =(A26-$B$9)/($B$9+$B$8)^$B$5 -> 6.5409836 | D26: =($B$6+$B$7)^($B$5-1)*C26 -> 6.5409836 | E26: =EXP(D26-0.5*D26^2) -> 3.5496393e-07 | F26: =($B$6+$B$7)*E26-$B$7 -> -0.0099999823 | G26: =(F26-$B$6)*10000 -> -499.99982 | H26: =($B$6+$B$7)^$B$5*C26*10000 -> 3270.4918 | I26: =IF(D26<=1,"increasing",IF(ROUND(G26,6)>0,"x>1: shock shrinks",IF(ROUND(G26,6)=0,"x = 2: shock = 0","x>2: SIGN FLIP"))) -> x>2: SIGN FLIP
A28: Sign flip happens when x > 2 (then x - ½x² < 0, so F < 1): a historical RISE becomes a FALL today.
A31: Case 2 input | B31: Value | C31: Comment
A32: β | B32: 0 | C32: Normal-like - still affected near the floor
A33: S0 today | B33: -0.004 | C33: -0.40%: 10bp above the floor
A34: θ | B34: 0.005 | C34: Desk shift 0.50% → floor -0.50%
A35: S(t_h) window start | B35: 0 | C35: Irrelevant for β = 0 (z = ΔS)
A36: η | B36: 0.006 | C36: Only enters z when β > 0
A37: Rise giving x = 1 (bp) | B37: =(B36+B35)^B32*(B33+B34)^(1-B32)*10000 -> 10 | C37: Only 10bp!
A39: Historical rise (bp) | B39: z_h = ΔS | C39: x_h = z/(S0+θ) | D39: F = exp(x-½x²) | E39: Shocked rate (Eq.14) | F39: Applied shock (bp) | G39: Linear Eq.6 (bp) | H39: Zone
A40: 2 | B40: =A40/10000/($B$35+$B$36)^$B$32 -> 0.0002 | C40: =($B$33+$B$34)^($B$32-1)*B40 -> 0.2 | D40: =EXP(C40-0.5*C40^2) -> 1.1972174 | E40: =($B$33+$B$34)*D40-$B$34 -> -0.0038027826 | F40: =(E40-$B$33)*10000 -> 1.9721736 | G40: =($B$33+$B$34)^$B$32*B40*10000 -> 2 | H40: =IF(C40<=1,"increasing",IF(ROUND(F40,6)>0,"x>1: shock shrinks",IF(ROUND(F40,6)=0,"x = 2: shock = 0","x>2: SIGN FLIP"))) -> increasing
A41: 5 | B41: =A41/10000/($B$35+$B$36)^$B$32 -> 0.0005 | C41: =($B$33+$B$34)^($B$32-1)*B41 -> 0.5 | D41: =EXP(C41-0.5*C41^2) -> 1.4549914 | E41: =($B$33+$B$34)*D41-$B$34 -> -0.0035450086 | F41: =(E41-$B$33)*10000 -> 4.5499141 | G41: =($B$33+$B$34)^$B$32*B41*10000 -> 5 | H41: =IF(C41<=1,"increasing",IF(ROUND(F41,6)>0,"x>1: shock shrinks",IF(ROUND(F41,6)=0,"x = 2: shock = 0","x>2: SIGN FLIP"))) -> increasing
A42: 10 | B42: =A42/10000/($B$35+$B$36)^$B$32 -> 0.001 | C42: =($B$33+$B$34)^($B$32-1)*B42 -> 1 | D42: =EXP(C42-0.5*C42^2) -> 1.6487213 | E42: =($B$33+$B$34)*D42-$B$34 -> -0.0033512787 | F42: =(E42-$B$33)*10000 -> 6.4872127 | G42: =($B$33+$B$34)^$B$32*B42*10000 -> 10 | H42: =IF(C42<=1,"increasing",IF(ROUND(F42,6)>0,"x>1: shock shrinks",IF(ROUND(F42,6)=0,"x = 2: shock = 0","x>2: SIGN FLIP"))) -> increasing
A43: 15 | B43: =A43/10000/($B$35+$B$36)^$B$32 -> 0.0015 | C43: =($B$33+$B$34)^($B$32-1)*B43 -> 1.5 | D43: =EXP(C43-0.5*C43^2) -> 1.4549914 | E43: =($B$33+$B$34)*D43-$B$34 -> -0.0035450086 | F43: =(E43-$B$33)*10000 -> 4.5499141 | G43: =($B$33+$B$34)^$B$32*B43*10000 -> 15 | H43: =IF(C43<=1,"increasing",IF(ROUND(F43,6)>0,"x>1: shock shrinks",IF(ROUND(F43,6)=0,"x = 2: shock = 0","x>2: SIGN FLIP"))) -> x>1: shock shrinks
A44: 20 | B44: =A44/10000/($B$35+$B$36)^$B$32 -> 0.002 | C44: =($B$33+$B$34)^($B$32-1)*B44 -> 2 | D44: =EXP(C44-0.5*C44^2) -> 1 | E44: =($B$33+$B$34)*D44-$B$34 -> -0.004 | F44: =(E44-$B$33)*10000 -> 0 | G44: =($B$33+$B$34)^$B$32*B44*10000 -> 20 | H44: =IF(C44<=1,"increasing",IF(ROUND(F44,6)>0,"x>1: shock shrinks",IF(ROUND(F44,6)=0,"x = 2: shock = 0","x>2: SIGN FLIP"))) -> x = 2: shock = 0
A45: 25 | B45: =A45/10000/($B$35+$B$36)^$B$32 -> 0.0025 | C45: =($B$33+$B$34)^($B$32-1)*B45 -> 2.5 | D45: =EXP(C45-0.5*C45^2) -> 0.53526143 | E45: =($B$33+$B$34)*D45-$B$34 -> -0.0044647386 | F45: =(E45-$B$33)*10000 -> -4.6473857 | G45: =($B$33+$B$34)^$B$32*B45*10000 -> 25 | H45: =IF(C45<=1,"increasing",IF(ROUND(F45,6)>0,"x>1: shock shrinks",IF(ROUND(F45,6)=0,"x = 2: shock = 0","x>2: SIGN FLIP"))) -> x>2: SIGN FLIP
A46: 35 | B46: =A46/10000/($B$35+$B$36)^$B$32 -> 0.0035 | C46: =($B$33+$B$34)^($B$32-1)*B46 -> 3.5 | D46: =EXP(C46-0.5*C46^2) -> 0.072439757 | E46: =($B$33+$B$34)*D46-$B$34 -> -0.0049275602 | F46: =(E46-$B$33)*10000 -> -9.2756024 | G46: =($B$33+$B$34)^$B$32*B46*10000 -> 35 | H46: =IF(C46<=1,"increasing",IF(ROUND(F46,6)>0,"x>1: shock shrinks",IF(ROUND(F46,6)=0,"x = 2: shock = 0","x>2: SIGN FLIP"))) -> x>2: SIGN FLIP
...

Sheet Scenario_Grid
A1: Scenario grid: β ∈ {0, 0.5, 1} × S0 ∈ {0%, 2%, 3%, 4%} - historical move 0.50% → 0.25% (-25bp)
A2: β and S0 (blue) are editable. Everything else is formula-driven from the Inputs sheet.
A4: β | B4: Today S0 | C4: S(t_h) | D4: S(t_h+Δ) | E4: ΔS hist | F4: η | G4: S(t_h)+η | H4: (S(t_h)+η)^β | I4: z_h (Eq.12) | J4: θ | K4: R0 = S0+θ | L4: R0^β | M4: R0^(β-1) | N4: x_h = R0^(β-1)·z | O4: ½ x_h² | P4: x - ½x² | Q4: Multiplier F = exp(x-½x²) | R4: Shocked R = R0·F | S4: Shocked S(Δ) (Eq.14) | T4: Applied shock (bp) | U4: Historical shock (bp) | V4: Scaling factor | W4: Linear Eq.6 shock (bp) | X4: Eq.14 - Eq.6 (bp) | Y4: Plain absolute shock S0+ΔS | Z4: x ≤ 1 check
A5: 0 | B5: 0 | C5: =Inputs!$B$6 -> 0.005 | D5: =Inputs!$B$7 -> 0.0025 | E5: =D5-C5 -> -0.0025 | F5: =Inputs!$B$12 -> 0.006 | G5: =C5+F5 -> 0.011 | H5: =G5^A5 -> 1 | I5: =E5/H5 -> -0.0025 | J5: =Inputs!$B$5 -> 0.005 | K5: =B5+J5 -> 0.005 | L5: =K5^A5 -> 1 | M5: =K5^(A5-1) -> 200 | N5: =M5*I5 -> -0.5 | O5: =0.5*N5^2 -> 0.125 | P5: =N5-O5 -> -0.625 | Q5: =EXP(P5) -> 0.53526143 | R5: =K5*Q5 -> 0.0026763071 | S5: =R5-J5 -> -0.0023236929 | T5: =(S5-B5)*10000 -> -23.236929 | U5: =E5*10000 -> -25 | V5: =T5/U5 -> 0.92947714 | W5: =L5*I5*10000 -> -25 | X5: =T5-W5 -> 1.7630714 | Y5: =B5+E5 -> -0.0025 | Z5: =IF(N5<=1,"OK","x>1: non-monotone zone") -> OK
A6: 0 | B6: 0.02 | C6: =Inputs!$B$6 -> 0.005 | D6: =Inputs!$B$7 -> 0.0025 | E6: =D6-C6 -> -0.0025 | F6: =Inputs!$B$12 -> 0.006 | G6: =C6+F6 -> 0.011 | H6: =G6^A6 -> 1 | I6: =E6/H6 -> -0.0025 | J6: =Inputs!$B$5 -> 0.005 | K6: =B6+J6 -> 0.025 | L6: =K6^A6 -> 1 | M6: =K6^(A6-1) -> 40 | N6: =M6*I6 -> -0.1 | O6: =0.5*N6^2 -> 0.005 | P6: =N6-O6 -> -0.105 | Q6: =EXP(P6) -> 0.90032452 | R6: =K6*Q6 -> 0.022508113 | S6: =R6-J6 -> 0.017508113 | T6: =(S6-B6)*10000 -> -24.918869 | U6: =E6*10000 -> -25 | V6: =T6/U6 -> 0.99675477 | W6: =L6*I6*10000 -> -25 | X6: =T6-W6 -> 0.081130647 | Y6: =B6+E6 -> 0.0175 | Z6: =IF(N6<=1,"OK","x>1: non-monotone zone") -> OK
A7: 0 | B7: 0.03 | C7: =Inputs!$B$6 -> 0.005 | D7: =Inputs!$B$7 -> 0.0025 | E7: =D7-C7 -> -0.0025 | F7: =Inputs!$B$12 -> 0.006 | G7: =C7+F7 -> 0.011 | H7: =G7^A7 -> 1 | I7: =E7/H7 -> -0.0025 | J7: =Inputs!$B$5 -> 0.005 | K7: =B7+J7 -> 0.035 | L7: =K7^A7 -> 1 | M7: =K7^(A7-1) -> 28.571429 | N7: =M7*I7 -> -0.071428571 | O7: =0.5*N7^2 -> 0.0025510204 | P7: =N7-O7 -> -0.073979592 | Q7: =EXP(P7) -> 0.92869065 | R7: =K7*Q7 -> 0.032504173 | S7: =R7-J7 -> 0.027504173 | T7: =(S7-B7)*10000 -> -24.958274 | U7: =E7*10000 -> -25 | V7: =T7/U7 -> 0.99833095 | W7: =L7*I7*10000 -> -25 | X7: =T7-W7 -> 0.041726281 | Y7: =B7+E7 -> 0.0275 | Z7: =IF(N7<=1,"OK","x>1: non-monotone zone") -> OK
A8: 0 | B8: 0.04 | C8: =Inputs!$B$6 -> 0.005 | D8: =Inputs!$B$7 -> 0.0025 | E8: =D8-C8 -> -0.0025 | F8: =Inputs!$B$12 -> 0.006 | G8: =C8+F8 -> 0.011 | H8: =G8^A8 -> 1 | I8: =E8/H8 -> -0.0025 | J8: =Inputs!$B$5 -> 0.005 | K8: =B8+J8 -> 0.045 | L8: =K8^A8 -> 1 | M8: =K8^(A8-1) -> 22.222222 | N8: =M8*I8 -> -0.055555556 | O8: =0.5*N8^2 -> 0.0015432099 | P8: =N8-O8 -> -0.057098765 | Q8: =EXP(P8) -> 0.94450078 | R8: =K8*Q8 -> 0.042502535 | S8: =R8-J8 -> 0.037502535 | T8: =(S8-B8)*10000 -> -24.974649 | U8: =E8*10000 -> -25 | V8: =T8/U8 -> 0.99898595 | W8: =L8*I8*10000 -> -25 | X8: =T8-W8 -> 0.025351329 | Y8: =B8+E8 -> 0.0375 | Z8: =IF(N8<=1,"OK","x>1: non-monotone zone") -> OK
A9: 0.5 | B9: 0 | C9: =Inputs!$B$6 -> 0.005 | D9: =Inputs!$B$7 -> 0.0025 | E9: =D9-C9 -> -0.0025 | F9: =Inputs!$B$12 -> 0.006 | G9: =C9+F9 -> 0.011 | H9: =G9^A9 -> 0.10488088 | I9: =E9/H9 -> -0.023836565 | J9: =Inputs!$B$5 -> 0.005 | K9: =B9+J9 -> 0.005 | L9: =K9^A9 -> 0.070710678 | M9: =K9^(A9-1) -> 14.142136 | N9: =M9*I9 -> -0.33709993 | O9: =0.5*N9^2 -> 0.056818182 | P9: =N9-O9 -> -0.39391811 | Q9: =EXP(P9) -> 0.67440928 | R9: =K9*Q9 -> 0.0033720464 | S9: =R9-J9 -> -0.0016279536 | T9: =(S9-B9)*10000 -> -16.279536 | U9: =E9*10000 -> -25 | V9: =T9/U9 -> 0.65118144 | W9: =L9*I9*10000 -> -16.854997 | X9: =T9-W9 -> 0.57546053 | Y9: =B9+E9 -> -0.0025 | Z9: =IF(N9<=1,"OK","x>1: non-monotone zone") -> OK
A10: 0.5 | B10: 0.02 | C10: =Inputs!$B$6 -> 0.005 | D10: =Inputs!$B$7 -> 0.0025 | E10: =D10-C10 -> -0.0025 | F10: =Inputs!$B$12 -> 0.006 | G10: =C10+F10 -> 0.011 | H10: =G10^A10 -> 0.10488088 | I10: =E10/H10 -> -0.023836565 | J10: =Inputs!$B$5 -> 0.005 | K10: =B10+J10 -> 0.025 | L10: =K10^A10 -> 0.15811388 | M10: =K10^(A10-1) -> 6.3245553 | N10: =M10*I10 -> -0.15075567 | O10: =0.5*N10^2 -> 0.011363636 | P10: =N10-O10 -> -0.16211931 | Q10: =EXP(P10) -> 0.85033975 | R10: =K10*Q10 -> 0.021258494 | S10: =R10-J10 -> 0.016258494 | T10: =(S10-B10)*10000 -> -37.415064 | U10: =E10*10000 -> -25 | V10: =T10/U10 -> 1.4966025 | W10: =L10*I10*10000 -> -37.688918 | X10: =T10-W10 -> 0.27385447 | Y10: =B10+E10 -> 0.0175 | Z10: =IF(N10<=1,"OK","x>1: non-monotone zone") -> OK
A11: 0.5 | B11: 0.03 | C11: =Inputs!$B$6 -> 0.005 | D11: =Inputs!$B$7 -> 0.0025 | E11: =D11-C11 -> -0.0025 | F11: =Inputs!$B$12 -> 0.006 | G11: =C11+F11 -> 0.011 | H11: =G11^A11 -> 0.10488088 | I11: =E11/H11 -> -0.023836565 | J11: =Inputs!$B$5 -> 0.005 | K11: =B11+J11 -> 0.035 | L11: =K11^A11 -> 0.18708287 | M11: =K11^(A11-1) -> 5.3452248 | N11: =M11*I11 -> -0.1274118 | O11: =0.5*N11^2 -> 0.0081168831 | P11: =N11-O11 -> -0.13552868 | Q11: =EXP(P11) -> 0.87325412 | R11: =K11*Q11 -> 0.030563894 | S11: =R11-J11 -> 0.025563894 | T11: =(S11-B11)*10000 -> -44.361059 | U11: =E11*10000 -> -25 | V11: =T11/U11 -> 1.7744424 | W11: =L11*I11*10000 -> -44.594129 | X11: =T11-W11 -> 0.23307013 | Y11: =B11+E11 -> 0.0275 | Z11: =IF(N11<=1,"OK","x>1: non-monotone zone") -> OK
A12: 0.5 | B12: 0.04 | C12: =Inputs!$B$6 -> 0.005 | D12: =Inputs!$B$7 -> 0.0025 | E12: =D12-C12 -> -0.0025 | F12: =Inputs!$B$12 -> 0.006 | G12: =C12+F12 -> 0.011 | H12: =G12^A12 -> 0.10488088 | I12: =E12/H12 -> -0.023836565 | J12: =Inputs!$B$5 -> 0.005 | K12: =B12+J12 -> 0.045 | L12: =K12^A12 -> 0.21213203 | M12: =K12^(A12-1) -> 4.7140452 | N12: =M12*I12 -> -0.11236664 | O12: =0.5*N12^2 -> 0.0063131313 | P12: =N12-O12 -> -0.11867978 | Q12: =EXP(P12) -> 0.88809214 | R12: =K12*Q12 -> 0.039964147 | S12: =R12-J12 -> 0.034964147 | T12: =(S12-B12)*10000 -> -50.358535 | U12: =E12*10000 -> -25 | V12: =T12/U12 -> 2.0143414 | W12: =L12*I12*10000 -> -50.56499 | X12: =T12-W12 -> 0.2064547 | Y12: =B12+E12 -> 0.0375 | Z12: =IF(N12<=1,"OK","x>1: non-monotone zone") -> OK
A13: 1 | B13: 0 | C13: =Inputs!$B$6 -> 0.005 | D13: =Inputs!$B$7 -> 0.0025 | E13: =D13-C13 -> -0.0025 | F13: =Inputs!$B$12 -> 0.006 | G13: =C13+F13 -> 0.011 | H13: =G13^A13 -> 0.011 | I13: =E13/H13 -> -0.22727273 | J13: =Inputs!$B$5 -> 0.005 | K13: =B13+J13 -> 0.005 | L13: =K13^A13 -> 0.005 | M13: =K13^(A13-1) -> 1 | N13: =M13*I13 -> -0.22727273 | O13: =0.5*N13^2 -> 0.025826446 | P13: =N13-O13 -> -0.25309917 | Q13: =EXP(P13) -> 0.77639088 | R13: =K13*Q13 -> 0.0038819544 | S13: =R13-J13 -> -0.0011180456 | T13: =(S13-B13)*10000 -> -11.180456 | U13: =E13*10000 -> -25 | V13: =T13/U13 -> 0.44721824 | W13: =L13*I13*10000 -> -11.363636 | X13: =T13-W13 -> 0.18318039 | Y13: =B13+E13 -> -0.0025 | Z13: =IF(N13<=1,"OK","x>1: non-monotone zone") -> OK
A14: 1 | B14: 0.02 | C14: =Inputs!$B$6 -> 0.005 | D14: =Inputs!$B$7 -> 0.0025 | E14: =D14-C14 -> -0.0025 | F14: =Inputs!$B$12 -> 0.006 | G14: =C14+F14 -> 0.011 | H14: =G14^A14 -> 0.011 | I14: =E14/H14 -> -0.22727273 | J14: =Inputs!$B$5 -> 0.005 | K14: =B14+J14 -> 0.025 | L14: =K14^A14 -> 0.025 | M14: =K14^(A14-1) -> 1 | N14: =M14*I14 -> -0.22727273 | O14: =0.5*N14^2 -> 0.025826446 | P14: =N14-O14 -> -0.25309917 | Q14: =EXP(P14) -> 0.77639088 | R14: =K14*Q14 -> 0.019409772 | S14: =R14-J14 -> 0.014409772 | T14: =(S14-B14)*10000 -> -55.90228 | U14: =E14*10000 -> -25 | V14: =T14/U14 -> 2.2360912 | W14: =L14*I14*10000 -> -56.818182 | X14: =T14-W14 -> 0.91590196 | Y14: =B14+E14 -> 0.0175 | Z14: =IF(N14<=1,"OK","x>1: non-monotone zone") -> OK
A15: 1 | B15: 0.03 | C15: =Inputs!$B$6 -> 0.005 | D15: =Inputs!$B$7 -> 0.0025 | E15: =D15-C15 -> -0.0025 | F15: =Inputs!$B$12 -> 0.006 | G15: =C15+F15 -> 0.011 | H15: =G15^A15 -> 0.011 | I15: =E15/H15 -> -0.22727273 | J15: =Inputs!$B$5 -> 0.005 | K15: =B15+J15 -> 0.035 | L15: =K15^A15 -> 0.035 | M15: =K15^(A15-1) -> 1 | N15: =M15*I15 -> -0.22727273 | O15: =0.5*N15^2 -> 0.025826446 | P15: =N15-O15 -> -0.25309917 | Q15: =EXP(P15) -> 0.77639088 | R15: =K15*Q15 -> 0.027173681 | S15: =R15-J15 -> 0.022173681 | T15: =(S15-B15)*10000 -> -78.263192 | U15: =E15*10000 -> -25 | V15: =T15/U15 -> 3.1305277 | W15: =L15*I15*10000 -> -79.545455 | X15: =T15-W15 -> 1.2822627 | Y15: =B15+E15 -> 0.0275 | Z15: =IF(N15<=1,"OK","x>1: non-monotone zone") -> OK
A16: 1 | B16: 0.04 | C16: =Inputs!$B$6 -> 0.005 | D16: =Inputs!$B$7 -> 0.0025 | E16: =D16-C16 -> -0.0025 | F16: =Inputs!$B$12 -> 0.006 | G16: =C16+F16 -> 0.011 | H16: =G16^A16 -> 0.011 | I16: =E16/H16 -> -0.22727273 | J16: =Inputs!$B$5 -> 0.005 | K16: =B16+J16 -> 0.045 | L16: =K16^A16 -> 0.045 | M16: =K16^(A16-1) -> 1 | N16: =M16*I16 -> -0.22727273 | O16: =0.5*N16^2 -> 0.025826446 | P16: =N16-O16 -> -0.25309917 | Q16: =EXP(P16) -> 0.77639088 | R16: =K16*Q16 -> 0.03493759 | S16: =R16-J16 -> 0.02993759 | T16: =(S16-B16)*10000 -> -100.6241 | U16: =E16*10000 -> -25 | V16: =T16/U16 -> 4.0249641 | W16: =L16*I16*10000 -> -102.27273 | X16: =T16-W16 -> 1.6486235 | Y16: =B16+E16 -> 0.0375 | Z16: =IF(N16<=1,"OK","x>1: non-monotone zone") -> OK
A19: Summary 1 - Shocked TONAR S(Δ) (Eq. 14) | H19: Chart data - applied shock (bp) vs today's rate
A20: β \ S0 | B20: 0% | C20: 2% | D20: 3% | E20: 4% | H20: S0 | I20: β = 0 | J20: β = 0.5 | K20: β = 1 | L20: Plain absolute
A21: =A5 -> 0 | B21: =S5 -> -0.0023236929 | C21: =S6 -> 0.017508113 | D21: =S7 -> 0.027504173 | E21: =S8 -> 0.037502535 | H21: =B5 -> 0 | I21: =T5 -> -23.236929 | J21: =T9 -> -16.279536 | K21: =T13 -> -11.180456 | L21: =U5 -> -25
A22: =A9 -> 0.5 | B22: =S9 -> -0.0016279536 | C22: =S10 -> 0.016258494 | D22: =S11 -> 0.025563894 | E22: =S12 -> 0.034964147 | H22: =B6 -> 0.02 | I22: =T6 -> -24.918869 | J22: =T10 -> -37.415064 | K22: =T14 -> -55.90228 | L22: =U6 -> -25
A23: =A13 -> 1 | B23: =S13 -> -0.0011180456 | C23: =S14 -> 0.014409772 | D23: =S15 -> 0.022173681 | E23: =S16 -> 0.02993759 | H23: =B7 -> 0.03 | I23: =T7 -> -24.958274 | J23: =T11 -> -44.361059 | K23: =T15 -> -78.263192 | L23: =U7 -> -25
H24: =B8 -> 0.04 | I24: =T8 -> -24.974649 | J24: =T12 -> -50.358535 | K24: =T16 -> -100.6241 | L24: =U8 -> -25
A25: Summary 2 - Applied shock today (bp) [historical = -25bp]
A26: β \ S0 | B26: 0% | C26: 2% | D26: 3% | E26: 4%
A27: =A5 -> 0 | B27: =T5 -> -23.236929 | C27: =T6 -> -24.918869 | D27: =T7 -> -24.958274 | E27: =T8 -> -24.974649
A28: =A9 -> 0.5 | B28: =T9 -> -16.279536 | C28: =T10 -> -37.415064 | D28: =T11 -> -44.361059 | E28: =T12 -> -50.358535
A29: =A13 -> 1 | B29: =T13 -> -11.180456 | C29: =T14 -> -55.90228 | D29: =T15 -> -78.263192 | E29: =T16 -> -100.6241
A31: Summary 3 - Scaling factor (applied / historical)
A32: β \ S0 | B32: 0% | C32: 2% | D32: 3% | E32: 4%
A33: =A5 -> 0 | B33: =V5 -> 0.92947714 | C33: =V6 -> 0.99675477 | D33: =V7 -> 0.99833095 | E33: =V8 -> 0.99898595
A34: =A9 -> 0.5 | B34: =V9 -> 0.65118144 | C34: =V10 -> 1.4966025 | D34: =V11 -> 1.7744424 | E34: =V12 -> 2.0143414
A35: =A13 -> 1 | B35: =V13 -> 0.44721824 | C35: =V14 -> 2.2360912 | D35: =V15 -> 3.1305277 | E35: =V16 -> 4.0249641
A37: Summary 4 - Multiplier F = exp(x - ½x²) on the shifted rate
A38: β \ S0 | B38: 0% | C38: 2% | D38: 3% | E38: 4%
A39: =A5 -> 0 | B39: =Q5 -> 0.53526143 | C39: =Q6 -> 0.90032452 | D39: =Q7 -> 0.92869065 | E39: =Q8 -> 0.94450078
A40: =A9 -> 0.5 | B40: =Q9 -> 0.67440928 | C40: =Q10 -> 0.85033975 | D40: =Q11 -> 0.87325412 | E40: =Q12 -> 0.88809214
A41: =A13 -> 1 | B41: =Q13 -> 0.77639088 | C41: =Q14 -> 0.77639088 | D41: =Q15 -> 0.77639088 | E41: =Q16 -> 0.77639088
A43: Summary 5 - z_h (Eq. 12) [same across S0: depends on history + η + β only]
A44: β \ S0 | B44: 0% | C44: 2% | D44: 3% | E44: 4%
A45: =A5 -> 0 | B45: =I5 -> -0.0025 | C45: =I6 -> -0.0025 | D45: =I7 -> -0.0025 | E45: =I8 -> -0.0025
A46: =A9 -> 0.5 | B46: =I9 -> -0.023836565 | C46: =I10 -> -0.023836565 | D46: =I11 -> -0.023836565 | E46: =I12 -> -0.023836565
...

Sheet Step_by_Step
A1: Worked example - one scenario, every equation in order
A2: Change β and S0 (blue) to walk through any case. Default: β = 0.5, S0 = 2%.
A4: Step | B4: Eq. | C4: What | D4: Formula | E4: Value | F4: Comment
A5: Inputs | C5: β (desk SABR backbone) | D5: input | E5: 0.5 | F5: Desk parameter, not calibrated by risk
A6: Inputs | C6: Today's TONAR S0 | D6: input | E6: 0.02
A7: Inputs | C7: θ (desk shift) | D7: = Inputs!B5 | E7: =Inputs!B5 -> 0.005
A8: Inputs | C8: S(t_h) window start | D8: = Inputs!B6 | E8: =Inputs!B6 -> 0.005
A9: Inputs | C9: S(t_h+Δ) window end | D9: = Inputs!B7 | E9: =Inputs!B7 -> 0.0025
A10: 1. Historical shift | B10: 15 | C10: η = max{-S(t_h)} + b | D10: = Inputs!B12 | E10: =Inputs!B12 -> 0.006 | F10: 0.49% + 0.11% = 0.60%
A11: 2. Historical move | C11: ΔS = S(t_h+Δ) - S(t_h) | D11: = E9 - E8 | E11: =E9-E8 -> -0.0025 | F11: -25bp
A12: 3. Shifted hist. level | B12: 12 | C12: S(t_h) + η | D12: = E8 + E10 | E12: =E8+E10 -> 0.011 | F12: Must be > 0
A13: 4. Denominator | B13: 12 | C13: (S(t_h) + η)^β | D13: = E12 ^ E5 | E13: =E12^E5 -> 0.10488088 | F13: Local SABR vol scale in history
A14: 5. Shock z_h | B14: 12 | C14: z_h = ΔS / (S(t_h)+η)^β | D14: = E11 / E13 | E14: =E11/E13 -> -0.023836565 | F14: Realisation of σ·ΔW. Units: rate^(1-β)
A15: 6. Shifted rate today | B15: 3 | C15: R0 = S0 + θ | D15: = E6 + E7 | E15: =E6+E7 -> 0.025
A16: 7. Re-scaling term | B16: 13/14 | C16: R0^(β-1) | D16: = E15 ^ (E5 - 1) | E16: =E15^(E5-1) -> 6.3245553 | F16: Converts σ·ΔW into a relative move of the shifted rate today
A17: 8. Scaled shock x_h | B17: 13/14 | C17: x_h = R0^(β-1) · z_h | D17: = E16 * E14 | E17: =E16*E14 -> -0.15075567 | F17: Relative (log) move of S+θ, 1st order
A18: 9. Itô correction | B18: 13 | C18: ½ x_h² | D18: = 0.5 * E17^2 | E18: =0.5*E17^2 -> 0.011363636 | F18: z_h² used as realisation of σ²Δ
A19: 10. Log move | B19: 13 | C19: Δ ln(S+θ) = x_h - ½ x_h² | D19: = E17 - E18 | E19: =E17-E18 -> -0.16211931
A20: 11. Multiplier F | B20: 14 | C20: F = exp(x_h - ½ x_h²) | D20: = EXP(E19) | E20: =EXP(E19) -> 0.85033975 | F20: Always > 0; max e^0.5 = 1.6487 at x = 1
A21: 12. Shocked shifted rate | B21: 14 | C21: R(Δ) = R0 · F | D21: = E15 * E20 | E21: =E15*E20 -> 0.021258494
A22: 13. Shocked rate | B22: 14 | C22: S(Δ) = R0 · F - θ | D22: = E21 - E7 | E22: =E21-E7 -> 0.016258494 | F22: Guaranteed > -θ
A23: 14. Applied shock | C23: S(Δ) - S0 (bp) | D23: = (E22 - E6) * 10000 | E23: =(E22-E6)*10000 -> -37.415064
A24: 15. Scaling factor | C24: Applied / historical | D24: = E23 / (E11*10000) | E24: =E23/(E11*10000) -> 1.4966025
A25: Check A | B25: 6 | C25: Linear Eq.6: R0^β · z_h (bp) | D25: = E15^E5 * E14 * 10000 | E25: =E15^E5*E14*10000 -> -37.688918 | F25: 1st-order equivalent
A26: Check B | C26: Eq.14 - Eq.6 (bp) | D26: = E23 - E25 | E26: =E23-E25 -> 0.27385447 | F26: Small: 3rd-order term only
A27: Check C | B27: 4/6 | C27: Desk-θ martingale shock (η=θ) (bp) | D27: = (E15^E5)*E11/(E8+E7)^E5*10000 | E27: =(E15^E5)*E11/(E8+E7)^E5*10000 -> -39.528471 | F27: What you get if θ were used to measure history (Eq.4→6)

Sheet Eta_vs_Theta
A1: Point 3 - when η ≠ θ (or simply when levels differ), shock sizes get rescaled
A2: Case from the note: β = 1, η = 1%, θ = 1%, history 0.10% → 0.80% (+70bp), applied at S0 = 4%.
A4: Item | B4: Value | C4: Formula / comment
A5: β | B5: 1 | C5: input
A6: η (historical shift) | B6: 0.01 | C6: input
A7: θ (desk shift) | B7: 0.01 | C7: input
A8: S(t_h) | B8: 0.001 | C8: input 0.10%
A9: S(t_h+Δ) | B9: 0.008 | C9: input 0.80%
A10: S0 today | B10: 0.04 | C10: input 4%
A11: ΔS hist (bp) | B11: =(B9-B8)*10000 -> 70 | C11: +70bp
A12: z_h (Eq.12) | B12: =(B9-B8)/(B8+B6)^B5 -> 0.63636364 | C12: = 0.70% / 1.10% ≈ 0.636
A13: R0 = S0+θ | B13: =B10+B7 -> 0.05
A14: x_h = R0^(β-1)·z | B14: =B13^(B5-1)*B12 -> 0.63636364 | C14: β=1 → x = z
A15: F = exp(x-½x²) | B15: =EXP(B14-0.5*B14^2) -> 1.5432403
A16: Shocked S(Δ) (Eq.14) | B16: =B13*B15-B7 -> 0.067162015
A17: Applied shock (bp) | B17: =(B16-B10)*10000 -> 271.62015 | C17: ≈ +272bp
A18: Scaling factor | B18: =B17/B11 -> 3.8802879 | C18: ≈ 3.9x the historical move
A19: Why | C19: Relative move 63.6% measured on a 1.10% shifted base, re-applied to a 5.00% shifted base
A22: Table A - Applied shock (bp) for the +70bp history, θ = 1%, S0 = 4%: sensitivity to η and β
A23: Each cell: S0 → (S0+θ)·exp(x-½x²) - θ with x = (S0+θ)^(β-1)·ΔS/(S(t_h)+η)^β. β = 0 is immune to η; β = 1 is most sensitive.
A24: η \ β | B24: 0 | C24: 0.5 | D24: 1
A25: 0.002 | B25: =((($B$10)+($B$7))*EXP((($B$10)+($B$7))^(B$24-1)*(($B$9)-($B$8))/(($B$8)+$A25)^B$24-0.5*((($B$10)+($B$7))^(B$24-1)*(($B$9)-($B$8))/(($B$8)+$A25)^B$24)^2)-($B$7)-($B$10))*10000 -> 69.528086 | C25: =((($B$10)+($B$7))*EXP((($B$10)+($B$7))^(C$24-1)*(($B$9)-($B$8))/(($B$8)+$A25)^C$24-0.5*((($B$10)+($B$7))^(C$24-1)*(($B$9)-($B$8))/(($B$8)+$A25)^C$24)^2)-($B$7)-($B$10))*10000 -> 252.06471 | D25: =((($B$10)+($B$7))*EXP((($B$10)+($B$7))^(D$24-1)*(($B$9)-($B$8))/(($B$8)+$A25)^D$24-0.5*((($B$10)+($B$7))^(D$24-1)*(($B$9)-($B$8))/(($B$8)+$A25)^D$24)^2)-($B$7)-($B$10))*10000 -> -161.09521
A26: 0.005 | B26: =((($B$10)+($B$7))*EXP((($B$10)+($B$7))^(B$24-1)*(($B$9)-($B$8))/(($B$8)+$A26)^B$24-0.5*((($B$10)+($B$7))^(B$24-1)*(($B$9)-($B$8))/(($B$8)+$A26)^B$24)^2)-($B$7)-($B$10))*10000 -> 69.528086 | C26: =((($B$10)+($B$7))*EXP((($B$10)+($B$7))^(C$24-1)*(($B$9)-($B$8))/(($B$8)+$A26)^C$24-0.5*((($B$10)+($B$7))^(C$24-1)*(($B$9)-($B$8))/(($B$8)+$A26)^C$24)^2)-($B$7)-($B$10))*10000 -> 190.27262 | D26: =((($B$10)+($B$7))*EXP((($B$10)+($B$7))^(D$24-1)*(($B$9)-($B$8))/(($B$8)+$A26)^D$24-0.5*((($B$10)+($B$7))^(D$24-1)*(($B$9)-($B$8))/(($B$8)+$A26)^D$24)^2)-($B$7)-($B$10))*10000 -> 312.99033
A27: 0.01 | B27: =((($B$10)+($B$7))*EXP((($B$10)+($B$7))^(B$24-1)*(($B$9)-($B$8))/(($B$8)+$A27)^B$24-0.5*((($B$10)+($B$7))^(B$24-1)*(($B$9)-($B$8))/(($B$8)+$A27)^B$24)^2)-($B$7)-($B$10))*10000 -> 69.528086 | C27: =((($B$10)+($B$7))*EXP((($B$10)+($B$7))^(C$24-1)*(($B$9)-($B$8))/(($B$8)+$A27)^C$24-0.5*((($B$10)+($B$7))^(C$24-1)*(($B$9)-($B$8))/(($B$8)+$A27)^C$24)^2)-($B$7)-($B$10))*10000 -> 144.54436 | D27: =((($B$10)+($B$7))*EXP((($B$10)+($B$7))^(D$24-1)*(($B$9)-($B$8))/(($B$8)+$A27)^D$24-0.5*((($B$10)+($B$7))^(D$24-1)*(($B$9)-($B$8))/(($B$8)+$A27)^D$24)^2)-($B$7)-($B$10))*10000 -> 271.62015
A28: 0.02 | B28: =((($B$10)+($B$7))*EXP((($B$10)+($B$7))^(B$24-1)*(($B$9)-($B$8))/(($B$8)+$A28)^B$24-0.5*((($B$10)+($B$7))^(B$24-1)*(($B$9)-($B$8))/(($B$8)+$A28)^B$24)^2)-($B$7)-($B$10))*10000 -> 69.528086 | C28: =((($B$10)+($B$7))*EXP((($B$10)+($B$7))^(C$24-1)*(($B$9)-($B$8))/(($B$8)+$A28)^C$24-0.5*((($B$10)+($B$7))^(C$24-1)*(($B$9)-($B$8))/(($B$8)+$A28)^C$24)^2)-($B$7)-($B$10))*10000 -> 106.25425 | D28: =((($B$10)+($B$7))*EXP((($B$10)+($B$7))^(D$24-1)*(($B$9)-($B$8))/(($B$8)+$A28)^D$24-0.5*((($B$10)+($B$7))^(D$24-1)*(($B$9)-($B$8))/(($B$8)+$A28)^D$24)^2)-($B$7)-($B$10))*10000 -> 160.09639
A29: 0.03 | B29: =((($B$10)+($B$7))*EXP((($B$10)+($B$7))^(B$24-1)*(($B$9)-($B$8))/(($B$8)+$A29)^B$24-0.5*((($B$10)+($B$7))^(B$24-1)*(($B$9)-($B$8))/(($B$8)+$A29)^B$24)^2)-($B$7)-($B$10))*10000 -> 69.528086 | C29: =((($B$10)+($B$7))*EXP((($B$10)+($B$7))^(C$24-1)*(($B$9)-($B$8))/(($B$8)+$A29)^C$24-0.5*((($B$10)+($B$7))^(C$24-1)*(($B$9)-($B$8))/(($B$8)+$A29)^C$24)^2)-($B$7)-($B$10))*10000 -> 87.926432 | D29: =((($B$10)+($B$7))*EXP((($B$10)+($B$7))^(D$24-1)*(($B$9)-($B$8))/(($B$8)+$A29)^D$24-0.5*((($B$10)+($B$7))^(D$24-1)*(($B$9)-($B$8))/(($B$8)+$A29)^D$24)^2)-($B$7)-($B$10))*10000 -> 110.89205
A30: 0.05 | B30: =((($B$10)+($B$7))*EXP((($B$10)+($B$7))^(B$24-1)*(($B$9)-($B$8))/(($B$8)+$A30)^B$24-0.5*((($B$10)+($B$7))^(B$24-1)*(($B$9)-($B$8))/(($B$8)+$A30)^B$24)^2)-($B$7)-($B$10))*10000 -> 69.528086 | C30: =((($B$10)+($B$7))*EXP((($B$10)+($B$7))^(C$24-1)*(($B$9)-($B$8))/(($B$8)+$A30)^C$24-0.5*((($B$10)+($B$7))^(C$24-1)*(($B$9)-($B$8))/(($B$8)+$A30)^C$24)^2)-($B$7)-($B$10))*10000 -> 68.852351 | D30: =((($B$10)+($B$7))*EXP((($B$10)+($B$7))^(D$24-1)*(($B$9)-($B$8))/(($B$8)+$A30)^D$24-0.5*((($B$10)+($B$7))^(D$24-1)*(($B$9)-($B$8))/(($B$8)+$A30)^D$24)^2)-($B$7)-($B$10))*10000 -> 68.182998
A31: Note η = 0.20%, β = 1: x = 0.70%/0.30% = 2.33 > 1, so exp(x-½x²) < 1 and a +70bp historical RISE becomes a FALL today (Eq.14 cap - see Eq14_Cap_and_Floor).
A33: Table B - JPY case (0.50% → 0.25%, -25bp), θ = Inputs!B5: applied shock (bp) by η and S0, for β = 1
A34: η must exceed 0.49% (min TONAR). Larger η → smaller |z| → smaller shocks today for β > 0. η = θ = 0.50% is the 'no rescaling' reference.
A35: η \ S0 | B35: 0 | C35: 0.02 | D35: 0.03 | E35: 0.04
A36: 0.005 | B36: =(((B$35)+(Inputs!$B$5))*EXP(((B$35)+(Inputs!$B$5))^(1-1)*((Inputs!$B$7)-(Inputs!$B$6))/((Inputs!$B$6)+$A36)^1-0.5*(((B$35)+(Inputs!$B$5))^(1-1)*((Inputs!$B$7)-(Inputs!$B$6))/((Inputs!$B$6)+$A36)^1)^2)-(Inputs!$B$5)-(B$35))*10000 -> -12.25802 | C36: =(((C$35)+(Inputs!$B$5))*EXP(((C$35)+(Inputs!$B$5))^(1-1)*((Inputs!$B$7)-(Inputs!$B$6))/((Inputs!$B$6)+$A36)^1-0.5*(((C$35)+(Inputs!$B$5))^(1-1)*((Inputs!$B$7)-(Inputs!$B$6))/((Inputs!$B$6)+$A36)^1)^2)-(Inputs!$B$5)-(C$35))*10000 -> -61.2901 | D36: =(((D$35)+(Inputs!$B$5))*EXP(((D$35)+(Inputs!$B$5))^(1-1)*((Inputs!$B$7)-(Inputs!$B$6))/((Inputs!$B$6)+$A36)^1-0.5*(((D$35)+(Inputs!$B$5))^(1-1)*((Inputs!$B$7)-(Inputs!$B$6))/((Inputs!$B$6)+$A36)^1)^2)-(Inputs!$B$5)-(D$35))*10000 -> -85.806139 | E36: =(((E$35)+(Inputs!$B$5))*EXP(((E$35)+(Inputs!$B$5))^(1-1)*((Inputs!$B$7)-(Inputs!$B$6))/((Inputs!$B$6)+$A36)^1-0.5*(((E$35)+(Inputs!$B$5))^(1-1)*((Inputs!$B$7)-(Inputs!$B$6))/((Inputs!$B$6)+$A36)^1)^2)-(Inputs!$B$5)-(E$35))*10000 -> -110.32218
A37: 0.006 | B37: =(((B$35)+(Inputs!$B$5))*EXP(((B$35)+(Inputs!$B$5))^(1-1)*((Inputs!$B$7)-(Inputs!$B$6))/((Inputs!$B$6)+$A37)^1-0.5*(((B$35)+(Inputs!$B$5))^(1-1)*((Inputs!$B$7)-(Inputs!$B$6))/((Inputs!$B$6)+$A37)^1)^2)-(Inputs!$B$5)-(B$35))*10000 -> -11.180456 | C37: =(((C$35)+(Inputs!$B$5))*EXP(((C$35)+(Inputs!$B$5))^(1-1)*((Inputs!$B$7)-(Inputs!$B$6))/((Inputs!$B$6)+$A37)^1-0.5*(((C$35)+(Inputs!$B$5))^(1-1)*((Inputs!$B$7)-(Inputs!$B$6))/((Inputs!$B$6)+$A37)^1)^2)-(Inputs!$B$5)-(C$35))*10000 -> -55.90228 | D37: =(((D$35)+(Inputs!$B$5))*EXP(((D$35)+(Inputs!$B$5))^(1-1)*((Inputs!$B$7)-(Inputs!$B$6))/((Inputs!$B$6)+$A37)^1-0.5*(((D$35)+(Inputs!$B$5))^(1-1)*((Inputs!$B$7)-(Inputs!$B$6))/((Inputs!$B$6)+$A37)^1)^2)-(Inputs!$B$5)-(D$35))*10000 -> -78.263192 | E37: =(((E$35)+(Inputs!$B$5))*EXP(((E$35)+(Inputs!$B$5))^(1-1)*((Inputs!$B$7)-(Inputs!$B$6))/((Inputs!$B$6)+$A37)^1-0.5*(((E$35)+(Inputs!$B$5))^(1-1)*((Inputs!$B$7)-(Inputs!$B$6))/((Inputs!$B$6)+$A37)^1)^2)-(Inputs!$B$5)-(E$35))*10000 -> -100.6241
A38: 0.01 | B38: =(((B$35)+(Inputs!$B$5))*EXP(((B$35)+(Inputs!$B$5))^(1-1)*((Inputs!$B$7)-(Inputs!$B$6))/((Inputs!$B$6)+$A38)^1-0.5*(((B$35)+(Inputs!$B$5))^(1-1)*((Inputs!$B$7)-(Inputs!$B$6))/((Inputs!$B$6)+$A38)^1)^2)-(Inputs!$B$5)-(B$35))*10000 -> -8.2596849 | C38: =(((C$35)+(Inputs!$B$5))*EXP(((C$35)+(Inputs!$B$5))^(1-1)*((Inputs!$B$7)-(Inputs!$B$6))/((Inputs!$B$6)+$A38)^1-0.5*(((C$35)+(Inputs!$B$5))^(1-1)*((Inputs!$B$7)-(Inputs!$B$6))/((Inputs!$B$6)+$A38)^1)^2)-(Inputs!$B$5)-(C$35))*10000 -> -41.298425 | D38: =(((D$35)+(Inputs!$B$5))*EXP(((D$35)+(Inputs!$B$5))^(1-1)*((Inputs!$B$7)-(Inputs!$B$6))/((Inputs!$B$6)+$A38)^1-0.5*(((D$35)+(Inputs!$B$5))^(1-1)*((Inputs!$B$7)-(Inputs!$B$6))/((Inputs!$B$6)+$A38)^1)^2)-(Inputs!$B$5)-(D$35))*10000 -> -57.817795 | E38: =(((E$35)+(Inputs!$B$5))*EXP(((E$35)+(Inputs!$B$5))^(1-1)*((Inputs!$B$7)-(Inputs!$B$6))/((Inputs!$B$6)+$A38)^1-0.5*(((E$35)+(Inputs!$B$5))^(1-1)*((Inputs!$B$7)-(Inputs!$B$6))/((Inputs!$B$6)+$A38)^1)^2)-(Inputs!$B$5)-(E$35))*10000 -> -74.337164
A39: 0.02 | B39: =(((B$35)+(Inputs!$B$5))*EXP(((B$35)+(Inputs!$B$5))^(1-1)*((Inputs!$B$7)-(Inputs!$B$6))/((Inputs!$B$6)+$A39)^1-0.5*(((B$35)+(Inputs!$B$5))^(1-1)*((Inputs!$B$7)-(Inputs!$B$6))/((Inputs!$B$6)+$A39)^1)^2)-(Inputs!$B$5)-(B$35))*10000 -> -4.9837739 | C39: =(((C$35)+(Inputs!$B$5))*EXP(((C$35)+(Inputs!$B$5))^(1-1)*((Inputs!$B$7)-(Inputs!$B$6))/((Inputs!$B$6)+$A39)^1-0.5*(((C$35)+(Inputs!$B$5))^(1-1)*((Inputs!$B$7)-(Inputs!$B$6))/((Inputs!$B$6)+$A39)^1)^2)-(Inputs!$B$5)-(C$35))*10000 -> -24.918869 | D39: =(((D$35)+(Inputs!$B$5))*EXP(((D$35)+(Inputs!$B$5))^(1-1)*((Inputs!$B$7)-(Inputs!$B$6))/((Inputs!$B$6)+$A39)^1-0.5*(((D$35)+(Inputs!$B$5))^(1-1)*((Inputs!$B$7)-(Inputs!$B$6))/((Inputs!$B$6)+$A39)^1)^2)-(Inputs!$B$5)-(D$35))*10000 -> -34.886417 | E39: =(((E$35)+(Inputs!$B$5))*EXP(((E$35)+(Inputs!$B$5))^(1-1)*((Inputs!$B$7)-(Inputs!$B$6))/((Inputs!$B$6)+$A39)^1-0.5*(((E$35)+(Inputs!$B$5))^(1-1)*((Inputs!$B$7)-(Inputs!$B$6))/((Inputs!$B$6)+$A39)^1)^2)-(Inputs!$B$5)-(E$35))*10000 -> -44.853965
A40: 0.05 | B40: =(((B$35)+(Inputs!$B$5))*EXP(((B$35)+(Inputs!$B$5))^(1-1)*((Inputs!$B$7)-(Inputs!$B$6))/((Inputs!$B$6)+$A40)^1-0.5*(((B$35)+(Inputs!$B$5))^(1-1)*((Inputs!$B$7)-(Inputs!$B$6))/((Inputs!$B$6)+$A40)^1)^2)-(Inputs!$B$5)-(B$35))*10000 -> -2.2711803 | C40: =(((C$35)+(Inputs!$B$5))*EXP(((C$35)+(Inputs!$B$5))^(1-1)*((Inputs!$B$7)-(Inputs!$B$6))/((Inputs!$B$6)+$A40)^1-0.5*(((C$35)+(Inputs!$B$5))^(1-1)*((Inputs!$B$7)-(Inputs!$B$6))/((Inputs!$B$6)+$A40)^1)^2)-(Inputs!$B$5)-(C$35))*10000 -> -11.355901 | D40: =(((D$35)+(Inputs!$B$5))*EXP(((D$35)+(Inputs!$B$5))^(1-1)*((Inputs!$B$7)-(Inputs!$B$6))/((Inputs!$B$6)+$A40)^1-0.5*(((D$35)+(Inputs!$B$5))^(1-1)*((Inputs!$B$7)-(Inputs!$B$6))/((Inputs!$B$6)+$A40)^1)^2)-(Inputs!$B$5)-(D$35))*10000 -> -15.898262 | E40: =(((E$35)+(Inputs!$B$5))*EXP(((E$35)+(Inputs!$B$5))^(1-1)*((Inputs!$B$7)-(Inputs!$B$6))/((Inputs!$B$6)+$A40)^1-0.5*(((E$35)+(Inputs!$B$5))^(1-1)*((Inputs!$B$7)-(Inputs!$B$6))/((Inputs!$B$6)+$A40)^1)^2)-(Inputs!$B$5)-(E$35))*10000 -> -20.440623
A42: Table C - same as Table B for β = 0.5
A43: η \ S0 | B43: 0 | C43: 0.02 | D43: 0.03 | E43: 0.04
A44: 0.005 | B44: =(((B$43)+(Inputs!$B$5))*EXP(((B$43)+(Inputs!$B$5))^(0.5-1)*((Inputs!$B$7)-(Inputs!$B$6))/((Inputs!$B$6)+$A44)^0.5-0.5*(((B$43)+(Inputs!$B$5))^(0.5-1)*((Inputs!$B$7)-(Inputs!$B$6))/((Inputs!$B$6)+$A44)^0.5)^2)-(Inputs!$B$5)-(B$43))*10000 -> -17.017747 | C44: =(((C$43)+(Inputs!$B$5))*EXP(((C$43)+(Inputs!$B$5))^(0.5-1)*((Inputs!$B$7)-(Inputs!$B$6))/((Inputs!$B$6)+$A44)^0.5-0.5*(((C$43)+(Inputs!$B$5))^(0.5-1)*((Inputs!$B$7)-(Inputs!$B$6))/((Inputs!$B$6)+$A44)^0.5)^2)-(Inputs!$B$5)-(C$43))*10000 -> -39.213234 | D44: =(((D$43)+(Inputs!$B$5))*EXP(((D$43)+(Inputs!$B$5))^(0.5-1)*((Inputs!$B$7)-(Inputs!$B$6))/((Inputs!$B$6)+$A44)^0.5-0.5*(((D$43)+(Inputs!$B$5))^(0.5-1)*((Inputs!$B$7)-(Inputs!$B$6))/((Inputs!$B$6)+$A44)^0.5)^2)-(Inputs!$B$5)-(D$43))*10000 -> -46.502321 | E44: =(((E$43)+(Inputs!$B$5))*EXP(((E$43)+(Inputs!$B$5))^(0.5-1)*((Inputs!$B$7)-(Inputs!$B$6))/((Inputs!$B$6)+$A44)^0.5-0.5*(((E$43)+(Inputs!$B$5))^(0.5-1)*((Inputs!$B$7)-(Inputs!$B$6))/((Inputs!$B$6)+$A44)^0.5)^2)-(Inputs!$B$5)-(E$43))*10000 -> -52.795203
A45: 0.006 | B45: =(((B$43)+(Inputs!$B$5))*EXP(((B$43)+(Inputs!$B$5))^(0.5-1)*((Inputs!$B$7)-(Inputs!$B$6))/((Inputs!$B$6)+$A45)^0.5-0.5*(((B$43)+(Inputs!$B$5))^(0.5-1)*((Inputs!$B$7)-(Inputs!$B$6))/((Inputs!$B$6)+$A45)^0.5)^2)-(Inputs!$B$5)-(B$43))*10000 -> -16.279536 | C45: =(((C$43)+(Inputs!$B$5))*EXP(((C$43)+(Inputs!$B$5))^(0.5-1)*((Inputs!$B$7)-(Inputs!$B$6))/((Inputs!$B$6)+$A45)^0.5-0.5*(((C$43)+(Inputs!$B$5))^(0.5-1)*((Inputs!$B$7)-(Inputs!$B$6))/((Inputs!$B$6)+$A45)^0.5)^2)-(Inputs!$B$5)-(C$43))*10000 -> -37.415064 | D45: =(((D$43)+(Inputs!$B$5))*EXP(((D$43)+(Inputs!$B$5))^(0.5-1)*((Inputs!$B$7)-(Inputs!$B$6))/((Inputs!$B$6)+$A45)^0.5-0.5*(((D$43)+(Inputs!$B$5))^(0.5-1)*((Inputs!$B$7)-(Inputs!$B$6))/((Inputs!$B$6)+$A45)^0.5)^2)-(Inputs!$B$5)-(D$43))*10000 -> -44.361059 | E45: =(((E$43)+(Inputs!$B$5))*EXP(((E$43)+(Inputs!$B$5))^(0.5-1)*((Inputs!$B$7)-(Inputs!$B$6))/((Inputs!$B$6)+$A45)^0.5-0.5*(((E$43)+(Inputs!$B$5))^(0.5-1)*((Inputs!$B$7)-(Inputs!$B$6))/((Inputs!$B$6)+$A45)^0.5)^2)-(Inputs!$B$5)-(E$43))*10000 -> -50.358535
...

Sheet Rescaling_272bp
A1: Why +70bp of history becomes +272bp today - rescaling decomposition
A2: Case: β = 1, η = 1%, θ = 1%, history 0.10% → 0.80% (+70bp), applied at S0 = 4%. Blue cells are editable.
A4: Step | B4: Eq. | C4: Formula | D4: Value | E4: Reading
A6: β | C6: input | D6: 1 | E6: Desk backbone
A7: η historical shift | B7: 15 | C7: input | D7: 0.01 | E7: Used ONLY to measure history
A8: θ desk shift | B8: 1 | C8: input | D8: 0.01 | E8: Used ONLY to apply today
A9: S(t_h) | C9: input | D9: 0.001 | E9: 0.10%
A10: S(t_h+Δ) | C10: input | D10: 0.008 | E10: 0.80%
A11: S0 today | C11: input | D11: 0.04 | E11: 4.00%
A12: ΔS historical (bp) | C12: (D10-D9)·10000 | D12: =(D10-D9)*10000 -> 70 | E12: +70bp
A13: Historical shifted base | B13: 12 | C13: S(t_h)+η | D13: =D9+D7 -> 0.011 | E13: 1.10% - a LOW base
A14: z_h | B14: 12 | C14: ΔS / (S(t_h)+η)^β | D14: =(D10-D9)/D13^D6 -> 0.63636364 | E14: β=1 → relative move of +63.6%
A15: Today's shifted base R0 | B15: 14 | C15: S0+θ | D15: =D11+D8 -> 0.05 | E15: 5.00% - a HIGH base
A16: x_h | B16: 14 | C16: R0^(β-1)·z_h | D16: =D15^(D6-1)*D14 -> 0.63636364 | E16: Relative move applied to R0
A17: Itô term | B17: 13 | C17: ½x_h² | D17: =0.5*D16^2 -> 0.20247934 | E17: Large because x is large
A18: Multiplier F | B18: 14 | C18: exp(x - ½x²) | D18: =EXP(D16-D17) -> 1.5432403 | E18: R0 is multiplied by 1.543
A19: Shocked S(Δ) | B19: 14 | C19: R0·F - θ | D19: =D15*D18-D8 -> 0.067162015 | E19: 6.72%
A20: Applied shock (bp) | B20: 14 | C20: (S(Δ)-S0)·10000 | D20: =(D19-D11)*10000 -> 271.62015 | E20: ≈ +272bp
A21: Scaling factor | C21: applied / historical | D21: =D20/D12 -> 3.8802879 | E21: ≈ 3.9x
A24: Decomposition A - from +70bp to +272bp (bp)
A25: Layer | B25: Shock (bp) | C25: Increment (bp) | D25: Explanation
A26: 1. Plain absolute shock | B26: =D12 -> 70 | C26: =B26 -> 70 | D26: What an absolute-shock HS would apply
A27: 2. Linear relative shock (Eq.6 with η) | B27: =D15^D6*D14*10000 -> 318.18182 | C27: =B27-B26 -> 248.18182 | D27: = R0^β · z_h. Base ratio (R0/(S_h+η))^β inflates the move
A28: 3. Eq.14 exponential (final) | B28: =D20 -> 271.62015 | C28: =B28-B27 -> -46.561668 | D28: Itô / convexity correction e^(x-½x²) vs 1+x pulls it back
A31: Decomposition B - the rescaling ratio (S0+θ)^β / (S(t_h)+η)^β split into two drivers
A32: Linear shock = ΔS × [level effect] × [shift-mismatch effect]. In this case η = θ, so ALL the rescaling comes from the level change; set η ≠ θ above to see the 2nd driver.
A33: Driver | B33: Factor | C33: Formula | D33: Explanation
A34: Level effect | B34: =((D11+D8)/(D9+D8))^D6 -> 4.5454545 | C34: ((S0+θ)/(S(t_h)+θ))^β | D34: Rates moved from 0.10% to 4% - relative moves get re-applied to a bigger base
A35: Shift-mismatch effect | B35: =((D9+D8)/(D9+D7))^D6 -> 1 | C35: ((S(t_h)+θ)/(S(t_h)+η))^β | D35: = 1 when η = θ. >1 if η < θ (history measured on smaller base → bigger z)
A36: Total rescaling ratio | B36: =B34*B35 -> 4.5454545 | C36: (S0+θ)^β/(S(t_h)+η)^β | D36: Multiplies ΔS to give the linear shock
A37: Check: ΔS × ratio (bp) | B37: =D12*B36 -> 318.18182 | D37: Should equal layer 2 above
A40: Table C - η ≠ θ combinations (same +70bp history, S0 and β from above)
A41: Case | B41: η | C41: θ | D41: z_h | E41: R0 = S0+θ | F41: x_h | G41: F | H41: Shocked S(Δ) | I41: Applied (bp) | J41: Scaling | K41: Level eff. | L41: Shift-mismatch eff. | M41: x ≤ 1?
A42: Base: η = θ = 1% | B42: 0.01 | C42: 0.01 | D42: =($D$10-$D$9)/($D$9+B42)^$D$6 -> 0.63636364 | E42: =$D$11+C42 -> 0.05 | F42: =E42^($D$6-1)*D42 -> 0.63636364 | G42: =EXP(F42-0.5*F42^2) -> 1.5432403 | H42: =E42*G42-C42 -> 0.067162015 | I42: =(H42-$D$11)*10000 -> 271.62015 | J42: =I42/$D$12 -> 3.8802879 | K42: =(E42/($D$9+C42))^$D$6 -> 4.5454545 | L42: =(($D$9+C42)/($D$9+B42))^$D$6 -> 1 | M42: =IF(F42<=1,"OK","x>1 flip zone") -> OK
A43: η < θ | B43: 0.005 | C43: 0.01 | D43: =($D$10-$D$9)/($D$9+B43)^$D$6 -> 1.1666667 | E43: =$D$11+C43 -> 0.05 | F43: =E43^($D$6-1)*D43 -> 1.1666667 | G43: =EXP(F43-0.5*F43^2) -> 1.6259807 | H43: =E43*G43-C43 -> 0.071299033 | I43: =(H43-$D$11)*10000 -> 312.99033 | J43: =I43/$D$12 -> 4.4712904 | K43: =(E43/($D$9+C43))^$D$6 -> 4.5454545 | L43: =(($D$9+C43)/($D$9+B43))^$D$6 -> 1.8333333 | M43: =IF(F43<=1,"OK","x>1 flip zone") -> x>1 flip zone
A44: η > θ | B44: 0.02 | C44: 0.01 | D44: =($D$10-$D$9)/($D$9+B44)^$D$6 -> 0.33333333 | E44: =$D$11+C44 -> 0.05 | F44: =E44^($D$6-1)*D44 -> 0.33333333 | G44: =EXP(F44-0.5*F44^2) -> 1.3201928 | H44: =E44*G44-C44 -> 0.056009639 | I44: =(H44-$D$11)*10000 -> 160.09639 | J44: =I44/$D$12 -> 2.2870913 | K44: =(E44/($D$9+C44))^$D$6 -> 4.5454545 | L44: =(($D$9+C44)/($D$9+B44))^$D$6 -> 0.52380952 | M44: =IF(F44<=1,"OK","x>1 flip zone") -> OK
A45: η much > θ | B45: 0.05 | C45: 0.01 | D45: =($D$10-$D$9)/($D$9+B45)^$D$6 -> 0.1372549 | E45: =$D$11+C45 -> 0.05 | F45: =E45^($D$6-1)*D45 -> 0.1372549 | G45: =EXP(F45-0.5*F45^2) -> 1.136366 | H45: =E45*G45-C45 -> 0.0468183 | I45: =(H45-$D$11)*10000 -> 68.182998 | J45: =I45/$D$12 -> 0.97404283 | K45: =(E45/($D$9+C45))^$D$6 -> 4.5454545 | L45: =(($D$9+C45)/($D$9+B45))^$D$6 -> 0.21568627 | M45: =IF(F45<=1,"OK","x>1 flip zone") -> OK
A46: θ < η | B46: 0.01 | C46: 0.005 | D46: =($D$10-$D$9)/($D$9+B46)^$D$6 -> 0.63636364 | E46: =$D$11+C46 -> 0.045 | F46: =E46^($D$6-1)*D46 -> 0.63636364 | G46: =EXP(F46-0.5*F46^2) -> 1.5432403 | H46: =E46*G46-C46 -> 0.064445814 | I46: =(H46-$D$11)*10000 -> 244.45814 | J46: =I46/$D$12 -> 3.4922591 | K46: =(E46/($D$9+C46))^$D$6 -> 7.5 | L46: =(($D$9+C46)/($D$9+B46))^$D$6 -> 0.54545455 | M46: =IF(F46<=1,"OK","x>1 flip zone") -> OK
